Workbook

Sheet 入力・概要
A1: MVVS 0.5sq×2芯＋UL1007 AWG20 差動／3導体同相解析
A2: 同相解析は、P＝2芯一括、S＝編組シールド、G＝AWG20 GND線の3物理導体モデルです。理想シールド近似により、内部モード(P-S)と外部モード(S-G)へ厳密に変換して解きます。
A5: 形状・代表物性（黄色セルを変更） | D5: 派生値
A6: 線路長 | B6: 6 | C6: m | D6: ケーブル・GND線中心間距離 | E6: =(B7+B10)/2 | F6: mm
A7: MVVSケーブル仕上外径 | B7: 6.2 | C7: mm | D7: シールド－GND導体最短距離 | E7: =E6-B8/2-B11/2 | F7: mm
A8: MVVSシールド外径 | B8: 4.3 | C8: mm | D8: 外部2円柱パラメータ χ | E8: =ACOSH(((E6/1000)^2-(B8/2000)^2-(B11/2000)^2)/(2*(B8/2000)*(B11/2000))) | F8: －
A9: MVVS 1芯絶縁外径 | B9: 1.9 | C9: mm | D9: 内部モード Z01 | E9: =1/(299792458*B13*B12*1E-12) | F9: Ω
A10: UL1007仕上外径 | B10: 1.8 | C10: mm | D10: 内部モード L1 | E10: =E9/(299792458*B13)*1E9 | F10: nH/m
A11: UL1007導体外径 | B11: 0.95 | C11: mm | D11: 内部モード片道遅延 | E11: =B6/(299792458*B13)*1E9 | F11: ns
A12: 内部モード C(P-S) | B12: 200 | C12: pF/m（代表値） | D12: 内部モード 1/4波長 | E12: =1/(4*E11*1E-9)/1E6 | F12: MHz
A13: 内部モード速度係数 | B13: 0.62 | C13: － | D13: 外部モード C2 | E13: =2*PI()*8.854187817E-12*B14/E8*1E12 | F13: pF/m
A14: 外部モード実効比誘電率 | B14: 2.2 | C14: －（PVC＋空気の代表値） | D14: 外部モード L2 | E14: =4*PI()*1E-7*E8/(2*PI())*1E9 | F14: nH/m
A15: 内部誘電損失 tanδ | B15: 0.03 | C15: － | D15: 外部モード Z02 | E15: =SQRT(E14*1E-9/(E13*1E-12)) | F15: Ω
A16: 外部誘電損失 tanδ | B16: 0.02 | C16: － | D16: 外部モード速度係数 | E16: =1/SQRT(B14) | F16: －
A17: 1芯導体抵抗 | B17: 0.0378 | C17: Ω/m（37.8 Ω/km） | D17: 外部モード片道遅延 | E17: =B6/(299792458*E16)*1E9 | F17: ns
A18: シールド長手抵抗 | B18: 0.025 | C18: Ω/m（代表値） | D18: 外部モード 1/4波長 | E18: =1/(4*E17*1E-9)/1E6 | F18: MHz
A19: GND線導体抵抗 | B19: 0.035 | C19: Ω/m（代表値） | D19: P導体束抵抗 | E19: =B17/2 | F19: Ω/m
A20: 内部追加損失 k√f | B20: 0.003 | C20: Np/√MHz | D20: 内部モード直流ループ抵抗 | E20: =(E19+B18)*B6 | F20: Ω（6m）
A21: 外部追加損失 k√f | B21: 0.004 | C21: Np/√MHz | D21: 外部モード直流ループ抵抗 | E21: =(B18+B19)*B6 | F21: Ω（6m）
D22: 2個Cの低周波合成容量 | E22: =B24+B27 | F22: µF
A23: 遠端負荷・差動条件 | D23: 同一値時の合成ESR | E23: =IF(AND(B25=B28),B25/2,NA()) | F23: Ω
A24: コンデンサ1 容量 | B24: 10 | C24: µF | D24: 同一値時の合成ESL | E24: =IF(AND(B26=B29),B26/2,NA()) | F24: nH
A25: コンデンサ1 ESR | B25: 0.05 | C25: Ω | D25: 概算低周波直列共振 | E25: =1/(2*PI()*SQRT(((E10+E14)*1E-9*B6+E24*1E-9)*E22*1E-6))/1E3 | F25: kHz
A26: コンデンサ1 ESL | B26: 20 | C26: nH | D26: 差動1/4波長 | E26: =B31*299792458/(4*B6)/1E6 | F26: MHz
A27: コンデンサ2 容量 | B27: 10 | C27: µF | D27: 差動1/2波長 | E27: =B31*299792458/(2*B6)/1E6 | F27: MHz
A28: コンデンサ2 ESR | B28: 0.05 | C28: Ω
A29: コンデンサ2 ESL | B29: 20 | C29: nH | D29: 3導体モデルの境界条件
A30: 差動特性インピーダンス Z0d | B30: 100 | C30: Ω | D30: 近端：SとGはFG1で短絡 → VSG(0)=0。 遠端：Sは開放 → IS(l)=0。Pは10 µF×2の並列負荷でGへ接続。 モード電圧：v1=VP−VS（内部）、v2=VS−VG（外部） モード電流：i1=IP、i2=IP+IS=−IG 遠端IS=0より i2(l)=i1(l)。外部モードを近端短絡線路として遠端から見たZext=Z02·tanh(γ2l)を、コンデンサ負荷へ直列加算し、内部モードを終端します。
A31: 差動速度係数 VFd | B31: 0.64 | C31: －
A32: 差動 tanδ | B32: 0.025 | C32: －
A33: 差動追加損失 k√f | B33: 0.003 | C33: Np/√MHz
A34: 遠端短絡抵抗 | B34: 0.01 | C34: Ω
A35: 遠端短絡インダクタンス | B35: 10 | C35: nH
A36: 測定治具直列抵抗 | B36: 0 | C36: Ω
A37: 測定治具直列インダクタンス | B37: 0 | C37: nH
A38: 開始周波数 | B38: 1000 | C38: Hz
A39: 終了周波数 | B39: 25000000 | C39: Hz
A40: 計算点数 | B40: 501 | C40: 点（最大801）

Sheet 3導体RLGC
A1: 3導体MTLのモード定数とRLGC行列
A2: 導体座標：V=[VP−VG, VS−VG]ᵀ、I=[IP, IS]ᵀ。理想シールド近似では、内部(P-S)・外部(S-G)モードへ対角化できます。
A5: モード | B5: Z0 [Ω] | C5: L [nH/m] | D5: C [pF/m]
A6: 内部 P-S | B6: ='入力・概要'!E9 | C6: ='入力・概要'!E10 | D6: ='入力・概要'!B12
A7: 外部 S-G | B7: ='入力・概要'!E15 | C7: ='入力・概要'!E14 | D7: ='入力・概要'!E13
A8: 備考 | B8: 代表値 | C8: 単位長 | D8: 低損失近似
A11: L行列 [nH/m] | B11: P | C11: S | E11: C行列 [pF/m] | F11: P | G11: S
A12: P | B12: ='入力・概要'!E10+'入力・概要'!E14 | C12: ='入力・概要'!E14 | E12: P | F12: ='入力・概要'!B12 | G12: =-'入力・概要'!B12
A13: S | B13: ='入力・概要'!E14 | C13: ='入力・概要'!E14 | E13: S | F13: =-'入力・概要'!B12 | G13: ='入力・概要'!B12+'入力・概要'!E13
A14: 変換式 | B14: L11=L1+L2 | C14: L12=L22=L2 | E14: 変換式 | F14: C11=C1 | G14: C12=-C1, C22=C1+C2
A17: R行列 DC [Ω/m] | B17: P | C17: S | E17: G行列 @1MHz [µS/m] | F17: P | G17: S
A18: P | B18: =('入力・概要'!E19+'入力・概要'!B18)+('入力・概要'!B18+'入力・概要'!B19) | C18: =('入力・概要'!B18+'入力・概要'!B19) | E18: P | F18: =2*PI()*1E6*'入力・概要'!B12*1E-12*'入力・概要'!B15*1E6 | G18: =-2*PI()*1E6*'入力・概要'!B12*1E-12*'入力・概要'!B15*1E6
A19: S | B19: =('入力・概要'!B18+'入力・概要'!B19) | C19: =('入力・概要'!B18+'入力・概要'!B19) | E19: S | F19: =-2*PI()*1E6*'入力・概要'!B12*1E-12*'入力・概要'!B15*1E6 | G19: =2*PI()*1E6*('入力・概要'!B12*1E-12*'入力・概要'!B15+'入力・概要'!E13*1E-12*'入力・概要'!B16)*1E6
A20: 変換式 | B20: R11=r1+r2 | C20: R12=R22=r2 | E20: 変換式 | F20: G11=g1 | G20: G12=-g1, G22=g1+g2
A23: 行列形：dV/dz=−(R+jωL)I、dI/dz=−(G+jωC)V。 本ブックの同相計算は、このRLGC行列を内部・外部の固有モードへ変換した解析解です。分割ラダー近似ではなく、理想シールド構造に対する3導体MTLのモード解になります。 ただし編組の開口による直接P-G結合、シールド移送インピーダンス、配置のねじれは含みません。

Sheet 差動モデル
A1: 差動モード：AC115VU－AC115VN
A3: No. | B3: 周波数 [Hz] | C3: ω | D3: 減衰A | E3: 電気角θ | F3: tanh Re | G3: tanh Im | H3: 負荷 Re | I3: 負荷 Im | J3: 分子 Re | K3: 分子 Im | L3: 分母 Re | M3: 分母 Im | N3: 線路 Re | O3: 線路 Im | P3: 最終 Re | Q3: 最終 Im | R3: |ZDM| [Ω] | S3: 位相 [deg] | T3: log10(f) | U3: log10(|ZDM|)
A4: 1 | B4: =IF(A4<='入力・概要'!$B$40,10^(LOG10('入力・概要'!$B$38)+(A4-1)*(LOG10('入力・概要'!$B$39)-LOG10('入力・概要'!$B$38))/('入力・概要'!$B$40-1)),"") | C4: =IF(B4="","",2*PI()*B4) | D4: =IF(B4="","",ATANH(MIN(0.999999,(2*'入力・概要'!$B$17*'入力・概要'!$B$6)/'入力・概要'!$B$30))+'入力・概要'!$B$33*SQRT(B4/1E6)+(2*PI()*B4*'入力・概要'!$B$6/(299792458*'入力・概要'!$B$31))*'入力・概要'!$B$32/2) | E4: =IF(B4="","",2*PI()*B4*'入力・概要'!$B$6/(299792458*'入力・概要'!$B$31)) | F4: =IF(B4="","",SINH(2*D4)/(COSH(2*D4)+COS(2*E4))) | G4: =IF(B4="","",SIN(2*E4)/(COSH(2*D4)+COS(2*E4))) | H4: =IF(B4="","",'入力・概要'!$B$34) | I4: =IF(B4="","",C4*'入力・概要'!$B$35*1E-9) | J4: =IF(B4="","",H4+'入力・概要'!$B$30*F4) | K4: =IF(B4="","",I4+'入力・概要'!$B$30*G4) | L4: =IF(B4="","",'入力・概要'!$B$30+H4*F4-I4*G4) | M4: =IF(B4="","",H4*G4+I4*F4) | N4: =IF(B4="","",'入力・概要'!$B$30*(J4*L4+K4*M4)/(L4^2+M4^2)) | O4: =IF(B4="","",'入力・概要'!$B$30*(K4*L4-J4*M4)/(L4^2+M4^2)) | P4: =IF(B4="","",N4+'入力・概要'!$B$36) | Q4: =IF(B4="","",O4+C4*'入力・概要'!$B$37*1E-9) | R4: =IF(B4="","",SQRT(P4^2+Q4^2)) | S4: =IF(B4="","",IF(P4>0,DEGREES(ATAN(Q4/P4)),IF(P4<0,IF(Q4>=0,DEGREES(ATAN(Q4/P4))+180,DEGREES(ATAN(Q4/P4))-180),IF(Q4>0,90,IF(Q4<0,-90,0))))) | T4: =IF(B4="","",LOG10(B4)) | U4: =IF(R4="","",LOG10(MAX(R4,1E-12)))
A5: 2 | B5: =IF(A5<='入力・概要'!$B$40,10^(LOG10('入力・概要'!$B$38)+(A5-1)*(LOG10('入力・概要'!$B$39)-LOG10('入力・概要'!$B$38))/('入力・概要'!$B$40-1)),"") | C5: =IF(B5="","",2*PI()*B5) | D5: =IF(B5="","",ATANH(MIN(0.999999,(2*'入力・概要'!$B$17*'入力・概要'!$B$6)/'入力・概要'!$B$30))+'入力・概要'!$B$33*SQRT(B5/1E6)+(2*PI()*B5*'入力・概要'!$B$6/(299792458*'入力・概要'!$B$31))*'入力・概要'!$B$32/2) | E5: =IF(B5="","",2*PI()*B5*'入力・概要'!$B$6/(299792458*'入力・概要'!$B$31)) | F5: =IF(B5="","",SINH(2*D5)/(COSH(2*D5)+COS(2*E5))) | G5: =IF(B5="","",SIN(2*E5)/(COSH(2*D5)+COS(2*E5))) | H5: =IF(B5="","",'入力・概要'!$B$34) | I5: =IF(B5="","",C5*'入力・概要'!$B$35*1E-9) | J5: =IF(B5="","",H5+'入力・概要'!$B$30*F5) | K5: =IF(B5="","",I5+'入力・概要'!$B$30*G5) | L5: =IF(B5="","",'入力・概要'!$B$30+H5*F5-I5*G5) | M5: =IF(B5="","",H5*G5+I5*F5) | N5: =IF(B5="","",'入力・概要'!$B$30*(J5*L5+K5*M5)/(L5^2+M5^2)) | O5: =IF(B5="","",'入力・概要'!$B$30*(K5*L5-J5*M5)/(L5^2+M5^2)) | P5: =IF(B5="","",N5+'入力・概要'!$B$36) | Q5: =IF(B5="","",O5+C5*'入力・概要'!$B$37*1E-9) | R5: =IF(B5="","",SQRT(P5^2+Q5^2)) | S5: =IF(B5="","",IF(P5>0,DEGREES(ATAN(Q5/P5)),IF(P5<0,IF(Q5>=0,DEGREES(ATAN(Q5/P5))+180,DEGREES(ATAN(Q5/P5))-180),IF(Q5>0,90,IF(Q5<0,-90,0))))) | T5: =IF(B5="","",LOG10(B5)) | U5: =IF(R5="","",LOG10(MAX(R5,1E-12)))
A6: 3 | B6: =IF(A6<='入力・概要'!$B$40,10^(LOG10('入力・概要'!$B$38)+(A6-1)*(LOG10('入力・概要'!$B$39)-LOG10('入力・概要'!$B$38))/('入力・概要'!$B$40-1)),"") | C6: =IF(B6="","",2*PI()*B6) | D6: =IF(B6="","",ATANH(MIN(0.999999,(2*'入力・概要'!$B$17*'入力・概要'!$B$6)/'入力・概要'!$B$30))+'入力・概要'!$B$33*SQRT(B6/1E6)+(2*PI()*B6*'入力・概要'!$B$6/(299792458*'入力・概要'!$B$31))*'入力・概要'!$B$32/2) | E6: =IF(B6="","",2*PI()*B6*'入力・概要'!$B$6/(299792458*'入力・概要'!$B$31)) | F6: =IF(B6="","",SINH(2*D6)/(COSH(2*D6)+COS(2*E6))) | G6: =IF(B6="","",SIN(2*E6)/(COSH(2*D6)+COS(2*E6))) | H6: =IF(B6="","",'入力・概要'!$B$34) | I6: =IF(B6="","",C6*'入力・概要'!$B$35*1E-9) | J6: =IF(B6="","",H6+'入力・概要'!$B$30*F6) | K6: =IF(B6="","",I6+'入力・概要'!$B$30*G6) | L6: =IF(B6="","",'入力・概要'!$B$30+H6*F6-I6*G6) | M6: =IF(B6="","",H6*G6+I6*F6) | N6: =IF(B6="","",'入力・概要'!$B$30*(J6*L6+K6*M6)/(L6^2+M6^2)) | O6: =IF(B6="","",'入力・概要'!$B$30*(K6*L6-J6*M6)/(L6^2+M6^2)) | P6: =IF(B6="","",N6+'入力・概要'!$B$36) | Q6: =IF(B6="","",O6+C6*'入力・概要'!$B$37*1E-9) | R6: =IF(B6="","",SQRT(P6^2+Q6^2)) | S6: =IF(B6="","",IF(P6>0,DEGREES(ATAN(Q6/P6)),IF(P6<0,IF(Q6>=0,DEGREES(ATAN(Q6/P6))+180,DEGREES(ATAN(Q6/P6))-180),IF(Q6>0,90,IF(Q6<0,-90,0))))) | T6: =IF(B6="","",LOG10(B6)) | U6: =IF(R6="","",LOG10(MAX(R6,1E-12)))
A7: 4 | B7: =IF(A7<='入力・概要'!$B$40,10^(LOG10('入力・概要'!$B$38)+(A7-1)*(LOG10('入力・概要'!$B$39)-LOG10('入力・概要'!$B$38))/('入力・概要'!$B$40-1)),"") | C7: =IF(B7="","",2*PI()*B7) | D7: =IF(B7="","",ATANH(MIN(0.999999,(2*'入力・概要'!$B$17*'入力・概要'!$B$6)/'入力・概要'!$B$30))+'入力・概要'!$B$33*SQRT(B7/1E6)+(2*PI()*B7*'入力・概要'!$B$6/(299792458*'入力・概要'!$B$31))*'入力・概要'!$B$32/2) | E7: =IF(B7="","",2*PI()*B7*'入力・概要'!$B$6/(299792458*'入力・概要'!$B$31)) | F7: =IF(B7="","",SINH(2*D7)/(COSH(2*D7)+COS(2*E7))) | G7: =IF(B7="","",SIN(2*E7)/(COSH(2*D7)+COS(2*E7))) | H7: =IF(B7="","",'入力・概要'!$B$34) | I7: =IF(B7="","",C7*'入力・概要'!$B$35*1E-9) | J7: =IF(B7="","",H7+'入力・概要'!$B$30*F7) | K7: =IF(B7="","",I7+'入力・概要'!$B$30*G7) | L7: =IF(B7="","",'入力・概要'!$B$30+H7*F7-I7*G7) | M7: =IF(B7="","",H7*G7+I7*F7) | N7: =IF(B7="","",'入力・概要'!$B$30*(J7*L7+K7*M7)/(L7^2+M7^2)) | O7: =IF(B7="","",'入力・概要'!$B$30*(K7*L7-J7*M7)/(L7^2+M7^2)) | P7: =IF(B7="","",N7+'入力・概要'!$B$36) | Q7: =IF(B7="","",O7+C7*'入力・概要'!$B$37*1E-9) | R7: =IF(B7="","",SQRT(P7^2+Q7^2)) | S7: =IF(B7="","",IF(P7>0,DEGREES(ATAN(Q7/P7)),IF(P7<0,IF(Q7>=0,DEGREES(ATAN(Q7/P7))+180,DEGREES(ATAN(Q7/P7))-180),IF(Q7>0,90,IF(Q7<0,-90,0))))) | T7: =IF(B7="","",LOG10(B7)) | U7: =IF(R7="","",LOG10(MAX(R7,1E-12)))
A8: 5 | B8: =IF(A8<='入力・概要'!$B$40,10^(LOG10('入力・概要'!$B$38)+(A8-1)*(LOG10('入力・概要'!$B$39)-LOG10('入力・概要'!$B$38))/('入力・概要'!$B$40-1)),"") | C8: =IF(B8="","",2*PI()*B8) | D8: =IF(B8="","",ATANH(MIN(0.999999,(2*'入力・概要'!$B$17*'入力・概要'!$B$6)/'入力・概要'!$B$30))+'入力・概要'!$B$33*SQRT(B8/1E6)+(2*PI()*B8*'入力・概要'!$B$6/(299792458*'入力・概要'!$B$31))*'入力・概要'!$B$32/2) | E8: =IF(B8="","",2*PI()*B8*'入力・概要'!$B$6/(299792458*'入力・概要'!$B$31)) | F8: =IF(B8="","",SINH(2*D8)/(COSH(2*D8)+COS(2*E8))) | G8: =IF(B8="","",SIN(2*E8)/(COSH(2*D8)+COS(2*E8))) | H8: =IF(B8="","",'入力・概要'!$B$34) | I8: =IF(B8="","",C8*'入力・概要'!$B$35*1E-9) | J8: =IF(B8="","",H8+'入力・概要'!$B$30*F8) | K8: =IF(B8="","",I8+'入力・概要'!$B$30*G8) | L8: =IF(B8="","",'入力・概要'!$B$30+H8*F8-I8*G8) | M8: =IF(B8="","",H8*G8+I8*F8) | N8: =IF(B8="","",'入力・概要'!$B$30*(J8*L8+K8*M8)/(L8^2+M8^2)) | O8: =IF(B8="","",'入力・概要'!$B$30*(K8*L8-J8*M8)/(L8^2+M8^2)) | P8: =IF(B8="","",N8+'入力・概要'!$B$36) | Q8: =IF(B8="","",O8+C8*'入力・概要'!$B$37*1E-9) | R8: =IF(B8="","",SQRT(P8^2+Q8^2)) | S8: =IF(B8="","",IF(P8>0,DEGREES(ATAN(Q8/P8)),IF(P8<0,IF(Q8>=0,DEGREES(ATAN(Q8/P8))+180,DEGREES(ATAN(Q8/P8))-180),IF(Q8>0,90,IF(Q8<0,-90,0))))) | T8: =IF(B8="","",LOG10(B8)) | U8: =IF(R8="","",LOG10(MAX(R8,1E-12)))
A9: 6 | B9: =IF(A9<='入力・概要'!$B$40,10^(LOG10('入力・概要'!$B$38)+(A9-1)*(LOG10('入力・概要'!$B$39)-LOG10('入力・概要'!$B$38))/('入力・概要'!$B$40-1)),"") | C9: =IF(B9="","",2*PI()*B9) | D9: =IF(B9="","",ATANH(MIN(0.999999,(2*'入力・概要'!$B$17*'入力・概要'!$B$6)/'入力・概要'!$B$30))+'入力・概要'!$B$33*SQRT(B9/1E6)+(2*PI()*B9*'入力・概要'!$B$6/(299792458*'入力・概要'!$B$31))*'入力・概要'!$B$32/2) | E9: =IF(B9="","",2*PI()*B9*'入力・概要'!$B$6/(299792458*'入力・概要'!$B$31)) | F9: =IF(B9="","",SINH(2*D9)/(COSH(2*D9)+COS(2*E9))) | G9: =IF(B9="","",SIN(2*E9)/(COSH(2*D9)+COS(2*E9))) | H9: =IF(B9="","",'入力・概要'!$B$34) | I9: =IF(B9="","",C9*'入力・概要'!$B$35*1E-9) | J9: =IF(B9="","",H9+'入力・概要'!$B$30*F9) | K9: =IF(B9="","",I9+'入力・概要'!$B$30*G9) | L9: =IF(B9="","",'入力・概要'!$B$30+H9*F9-I9*G9) | M9: =IF(B9="","",H9*G9+I9*F9) | N9: =IF(B9="","",'入力・概要'!$B$30*(J9*L9+K9*M9)/(L9^2+M9^2)) | O9: =IF(B9="","",'入力・概要'!$B$30*(K9*L9-J9*M9)/(L9^2+M9^2)) | P9: =IF(B9="","",N9+'入力・概要'!$B$36) | Q9: =IF(B9="","",O9+C9*'入力・概要'!$B$37*1E-9) | R9: =IF(B9="","",SQRT(P9^2+Q9^2)) | S9: =IF(B9="","",IF(P9>0,DEGREES(ATAN(Q9/P9)),IF(P9<0,IF(Q9>=0,DEGREES(ATAN(Q9/P9))+180,DEGREES(ATAN(Q9/P9))-180),IF(Q9>0,90,IF(Q9<0,-90,0))))) | T9: =IF(B9="","",LOG10(B9)) | U9: =IF(R9="","",LOG10(MAX(R9,1E-12)))
A10: 7 | B10: =IF(A10<='入力・概要'!$B$40,10^(LOG10('入力・概要'!$B$38)+(A10-1)*(LOG10('入力・概要'!$B$39)-LOG10('入力・概要'!$B$38))/('入力・概要'!$B$40-1)),"") | C10: =IF(B10="","",2*PI()*B10) | D10: =IF(B10="","",ATANH(MIN(0.999999,(2*'入力・概要'!$B$17*'入力・概要'!$B$6)/'入力・概要'!$B$30))+'入力・概要'!$B$33*SQRT(B10/1E6)+(2*PI()*B10*'入力・概要'!$B$6/(299792458*'入力・概要'!$B$31))*'入力・概要'!$B$32/2) | E10: =IF(B10="","",2*PI()*B10*'入力・概要'!$B$6/(299792458*'入力・概要'!$B$31)) | F10: =IF(B10="","",SINH(2*D10)/(COSH(2*D10)+COS(2*E10))) | G10: =IF(B10="","",SIN(2*E10)/(COSH(2*D10)+COS(2*E10))) | H10: =IF(B10="","",'入力・概要'!$B$34) | I10: =IF(B10="","",C10*'入力・概要'!$B$35*1E-9) | J10: =IF(B10="","",H10+'入力・概要'!$B$30*F10) | K10: =IF(B10="","",I10+'入力・概要'!$B$30*G10) | L10: =IF(B10="","",'入力・概要'!$B$30+H10*F10-I10*G10) | M10: =IF(B10="","",H10*G10+I10*F10) | N10: =IF(B10="","",'入力・概要'!$B$30*(J10*L10+K10*M10)/(L10^2+M10^2)) | O10: =IF(B10="","",'入力・概要'!$B$30*(K10*L10-J10*M10)/(L10^2+M10^2)) | P10: =IF(B10="","",N10+'入力・概要'!$B$36) | Q10: =IF(B10="","",O10+C10*'入力・概要'!$B$37*1E-9) | R10: =IF(B10="","",SQRT(P10^2+Q10^2)) | S10: =IF(B10="","",IF(P10>0,DEGREES(ATAN(Q10/P10)),IF(P10<0,IF(Q10>=0,DEGREES(ATAN(Q10/P10))+180,DEGREES(ATAN(Q10/P10))-180),IF(Q10>0,90,IF(Q10<0,-90,0))))) | T10: =IF(B10="","",LOG10(B10)) | U10: =IF(R10="","",LOG10(MAX(R10,1E-12)))
A11: 8 | B11: =IF(A11<='入力・概要'!$B$40,10^(LOG10('入力・概要'!$B$38)+(A11-1)*(LOG10('入力・概要'!$B$39)-LOG10('入力・概要'!$B$38))/('入力・概要'!$B$40-1)),"") | C11: =IF(B11="","",2*PI()*B11) | D11: =IF(B11="","",ATANH(MIN(0.999999,(2*'入力・概要'!$B$17*'入力・概要'!$B$6)/'入力・概要'!$B$30))+'入力・概要'!$B$33*SQRT(B11/1E6)+(2*PI()*B11*'入力・概要'!$B$6/(299792458*'入力・概要'!$B$31))*'入力・概要'!$B$32/2) | E11: =IF(B11="","",2*PI()*B11*'入力・概要'!$B$6/(299792458*'入力・概要'!$B$31)) | F11: =IF(B11="","",SINH(2*D11)/(COSH(2*D11)+COS(2*E11))) | G11: =IF(B11="","",SIN(2*E11)/(COSH(2*D11)+COS(2*E11))) | H11: =IF(B11="","",'入力・概要'!$B$34) | I11: =IF(B11="","",C11*'入力・概要'!$B$35*1E-9) | J11: =IF(B11="","",H11+'入力・概要'!$B$30*F11) | K11: =IF(B11="","",I11+'入力・概要'!$B$30*G11) | L11: =IF(B11="","",'入力・概要'!$B$30+H11*F11-I11*G11) | M11: =IF(B11="","",H11*G11+I11*F11) | N11: =IF(B11="","",'入力・概要'!$B$30*(J11*L11+K11*M11)/(L11^2+M11^2)) | O11: =IF(B11="","",'入力・概要'!$B$30*(K11*L11-J11*M11)/(L11^2+M11^2)) | P11: =IF(B11="","",N11+'入力・概要'!$B$36) | Q11: =IF(B11="","",O11+C11*'入力・概要'!$B$37*1E-9) | R11: =IF(B11="","",SQRT(P11^2+Q11^2)) | S11: =IF(B11="","",IF(P11>0,DEGREES(ATAN(Q11/P11)),IF(P11<0,IF(Q11>=0,DEGREES(ATAN(Q11/P11))+180,DEGREES(ATAN(Q11/P11))-180),IF(Q11>0,90,IF(Q11<0,-90,0))))) | T11: =IF(B11="","",LOG10(B11)) | U11: =IF(R11="","",LOG10(MAX(R11,1E-12)))
A12: 9 | B12: =IF(A12<='入力・概要'!$B$40,10^(LOG10('入力・概要'!$B$38)+(A12-1)*(LOG10('入力・概要'!$B$39)-LOG10('入力・概要'!$B$38))/('入力・概要'!$B$40-1)),"") | C12: =IF(B12="","",2*PI()*B12) | D12: =IF(B12="","",ATANH(MIN(0.999999,(2*'入力・概要'!$B$17*'入力・概要'!$B$6)/'入力・概要'!$B$30))+'入力・概要'!$B$33*SQRT(B12/1E6)+(2*PI()*B12*'入力・概要'!$B$6/(299792458*'入力・概要'!$B$31))*'入力・概要'!$B$32/2) | E12: =IF(B12="","",2*PI()*B12*'入力・概要'!$B$6/(299792458*'入力・概要'!$B$31)) | F12: =IF(B12="","",SINH(2*D12)/(COSH(2*D12)+COS(2*E12))) | G12: =IF(B12="","",SIN(2*E12)/(COSH(2*D12)+COS(2*E12))) | H12: =IF(B12="","",'入力・概要'!$B$34) | I12: =IF(B12="","",C12*'入力・概要'!$B$35*1E-9) | J12: =IF(B12="","",H12+'入力・概要'!$B$30*F12) | K12: =IF(B12="","",I12+'入力・概要'!$B$30*G12) | L12: =IF(B12="","",'入力・概要'!$B$30+H12*F12-I12*G12) | M12: =IF(B12="","",H12*G12+I12*F12) | N12: =IF(B12="","",'入力・概要'!$B$30*(J12*L12+K12*M12)/(L12^2+M12^2)) | O12: =IF(B12="","",'入力・概要'!$B$30*(K12*L12-J12*M12)/(L12^2+M12^2)) | P12: =IF(B12="","",N12+'入力・概要'!$B$36) | Q12: =IF(B12="","",O12+C12*'入力・概要'!$B$37*1E-9) | R12: =IF(B12="","",SQRT(P12^2+Q12^2)) | S12: =IF(B12="","",IF(P12>0,DEGREES(ATAN(Q12/P12)),IF(P12<0,IF(Q12>=0,DEGREES(ATAN(Q12/P12))+180,DEGREES(ATAN(Q12/P12))-180),IF(Q12>0,90,IF(Q12<0,-90,0))))) | T12: =IF(B12="","",LOG10(B12)) | U12: =IF(R12="","",LOG10(MAX(R12,1E-12)))
A13: 10 | B13: =IF(A13<='入力・概要'!$B$40,10^(LOG10('入力・概要'!$B$38)+(A13-1)*(LOG10('入力・概要'!$B$39)-LOG10('入力・概要'!$B$38))/('入力・概要'!$B$40-1)),"") | C13: =IF(B13="","",2*PI()*B13) | D13: =IF(B13="","",ATANH(MIN(0.999999,(2*'入力・概要'!$B$17*'入力・概要'!$B$6)/'入力・概要'!$B$30))+'入力・概要'!$B$33*SQRT(B13/1E6)+(2*PI()*B13*'入力・概要'!$B$6/(299792458*'入力・概要'!$B$31))*'入力・概要'!$B$32/2) | E13: =IF(B13="","",2*PI()*B13*'入力・概要'!$B$6/(299792458*'入力・概要'!$B$31)) | F13: =IF(B13="","",SINH(2*D13)/(COSH(2*D13)+COS(2*E13))) | G13: =IF(B13="","",SIN(2*E13)/(COSH(2*D13)+COS(2*E13))) | H13: =IF(B13="","",'入力・概要'!$B$34) | I13: =IF(B13="","",C13*'入力・概要'!$B$35*1E-9) | J13: =IF(B13="","",H13+'入力・概要'!$B$30*F13) | K13: =IF(B13="","",I13+'入力・概要'!$B$30*G13) | L13: =IF(B13="","",'入力・概要'!$B$30+H13*F13-I13*G13) | M13: =IF(B13="","",H13*G13+I13*F13) | N13: =IF(B13="","",'入力・概要'!$B$30*(J13*L13+K13*M13)/(L13^2+M13^2)) | O13: =IF(B13="","",'入力・概要'!$B$30*(K13*L13-J13*M13)/(L13^2+M13^2)) | P13: =IF(B13="","",N13+'入力・概要'!$B$36) | Q13: =IF(B13="","",O13+C13*'入力・概要'!$B$37*1E-9) | R13: =IF(B13="","",SQRT(P13^2+Q13^2)) | S13: =IF(B13="","",IF(P13>0,DEGREES(ATAN(Q13/P13)),IF(P13<0,IF(Q13>=0,DEGREES(ATAN(Q13/P13))+180,DEGREES(ATAN(Q13/P13))-180),IF(Q13>0,90,IF(Q13<0,-90,0))))) | T13: =IF(B13="","",LOG10(B13)) | U13: =IF(R13="","",LOG10(MAX(R13,1E-12)))
A14: 11 | B14: =IF(A14<='入力・概要'!$B$40,10^(LOG10('入力・概要'!$B$38)+(A14-1)*(LOG10('入力・概要'!$B$39)-LOG10('入力・概要'!$B$38))/('入力・概要'!$B$40-1)),"") | C14: =IF(B14="","",2*PI()*B14) | D14: =IF(B14="","",ATANH(MIN(0.999999,(2*'入力・概要'!$B$17*'入力・概要'!$B$6)/'入力・概要'!$B$30))+'入力・概要'!$B$33*SQRT(B14/1E6)+(2*PI()*B14*'入力・概要'!$B$6/(299792458*'入力・概要'!$B$31))*'入力・概要'!$B$32/2) | E14: =IF(B14="","",2*PI()*B14*'入力・概要'!$B$6/(299792458*'入力・概要'!$B$31)) | F14: =IF(B14="","",SINH(2*D14)/(COSH(2*D14)+COS(2*E14))) | G14: =IF(B14="","",SIN(2*E14)/(COSH(2*D14)+COS(2*E14))) | H14: =IF(B14="","",'入力・概要'!$B$34) | I14: =IF(B14="","",C14*'入力・概要'!$B$35*1E-9) | J14: =IF(B14="","",H14+'入力・概要'!$B$30*F14) | K14: =IF(B14="","",I14+'入力・概要'!$B$30*G14) | L14: =IF(B14="","",'入力・概要'!$B$30+H14*F14-I14*G14) | M14: =IF(B14="","",H14*G14+I14*F14) | N14: =IF(B14="","",'入力・概要'!$B$30*(J14*L14+K14*M14)/(L14^2+M14^2)) | O14: =IF(B14="","",'入力・概要'!$B$30*(K14*L14-J14*M14)/(L14^2+M14^2)) | P14: =IF(B14="","",N14+'入力・概要'!$B$36) | Q14: =IF(B14="","",O14+C14*'入力・概要'!$B$37*1E-9) | R14: =IF(B14="","",SQRT(P14^2+Q14^2)) | S14: =IF(B14="","",IF(P14>0,DEGREES(ATAN(Q14/P14)),IF(P14<0,IF(Q14>=0,DEGREES(ATAN(Q14/P14))+180,DEGREES(ATAN(Q14/P14))-180),IF(Q14>0,90,IF(Q14<0,-90,0))))) | T14: =IF(B14="","",LOG10(B14)) | U14: =IF(R14="","",LOG10(MAX(R14,1E-12)))
A15: 12 | B15: =IF(A15<='入力・概要'!$B$40,10^(LOG10('入力・概要'!$B$38)+(A15-1)*(LOG10('入力・概要'!$B$39)-LOG10('入力・概要'!$B$38))/('入力・概要'!$B$40-1)),"") | C15: =IF(B15="","",2*PI()*B15) | D15: =IF(B15="","",ATANH(MIN(0.999999,(2*'入力・概要'!$B$17*'入力・概要'!$B$6)/'入力・概要'!$B$30))+'入力・概要'!$B$33*SQRT(B15/1E6)+(2*PI()*B15*'入力・概要'!$B$6/(299792458*'入力・概要'!$B$31))*'入力・概要'!$B$32/2) | E15: =IF(B15="","",2*PI()*B15*'入力・概要'!$B$6/(299792458*'入力・概要'!$B$31)) | F15: =IF(B15="","",SINH(2*D15)/(COSH(2*D15)+COS(2*E15))) | G15: =IF(B15="","",SIN(2*E15)/(COSH(2*D15)+COS(2*E15))) | H15: =IF(B15="","",'入力・概要'!$B$34) | I15: =IF(B15="","",C15*'入力・概要'!$B$35*1E-9) | J15: =IF(B15="","",H15+'入力・概要'!$B$30*F15) | K15: =IF(B15="","",I15+'入力・概要'!$B$30*G15) | L15: =IF(B15="","",'入力・概要'!$B$30+H15*F15-I15*G15) | M15: =IF(B15="","",H15*G15+I15*F15) | N15: =IF(B15="","",'入力・概要'!$B$30*(J15*L15+K15*M15)/(L15^2+M15^2)) | O15: =IF(B15="","",'入力・概要'!$B$30*(K15*L15-J15*M15)/(L15^2+M15^2)) | P15: =IF(B15="","",N15+'入力・概要'!$B$36) | Q15: =IF(B15="","",O15+C15*'入力・概要'!$B$37*1E-9) | R15: =IF(B15="","",SQRT(P15^2+Q15^2)) | S15: =IF(B15="","",IF(P15>0,DEGREES(ATAN(Q15/P15)),IF(P15<0,IF(Q15>=0,DEGREES(ATAN(Q15/P15))+180,DEGREES(ATAN(Q15/P15))-180),IF(Q15>0,90,IF(Q15<0,-90,0))))) | T15: =IF(B15="","",LOG10(B15)) | U15: =IF(R15="","",LOG10(MAX(R15,1E-12)))
... A804: 801 | B804: =IF(A804<='入力・概要'!$B$40,10^(LOG10('入力・概要'!$B$38)+(A804-1)*(LOG10('入力・概要'!$B$39)-LOG10('入力・概要'!$B$38))/('入力・概要'!$B$40-1)),"") | C804: =IF(B804="","",2*PI()*B804) | D804: =IF(B804="","",ATANH(MIN(0.999999,(2*'入力・概要'!$B$17*'入力・概要'!$B$6)/'入力・概要'!$B$30))+'入力・概要'!$B$33*SQRT(B804/1E6)+(2*PI()*B804*'入力・概要'!$B$6/(299792458*'入力・概要'!$B$31))*'入力・概要'!$B$32/2) | E804: =IF(B804="","",2*PI()*B804*'入力・概要'!$B$6/(299792458*'入力・概要'!$B$31)) | F804: =IF(B804="","",SINH(2*D804)/(COSH(2*D804)+COS(2*E804))) | G804: =IF(B804="","",SIN(2*E804)/(COSH(2*D804)+COS(2*E804))) | H804: =IF(B804="","",'入力・概要'!$B$34) | I804: =IF(B804="","",C804*'入力・概要'!$B$35*1E-9) | J804: =IF(B804="","",H804+'入力・概要'!$B$30*F804) | K804: =IF(B804="","",I804+'入力・概要'!$B$30*G804) | L804: =IF(B804="","",'入力・概要'!$B$30+H804*F804-I804*G804) | M804: =IF(B804="","",H804*G804+I804*F804) | N804: =IF(B804="","",'入力・概要'!$B$30*(J804*L804+K804*M804)/(L804^2+M804^2)) | O804: =IF(B804="","",'入力・概要'!$B$30*(K804*L804-J804*M804)/(L804^2+M804^2)) | P804: =IF(B804="","",N804+'入力・概要'!$B$36) | Q804: =IF(B804="","",O804+C804*'入力・概要'!$B$37*1E-9) | R804: =IF(B804="","",SQRT(P804^2+Q804^2)) | S804: =IF(B804="","",IF(P804>0,DEGREES(ATAN(Q804/P804)),IF(P804<0,IF(Q804>=0,DEGREES(ATAN(Q804/P804))+180,DEGREES(ATAN(Q804/P804))-180),IF(Q804>0,90,IF(Q804<0,-90,0))))) | T804: =IF(B804="","",LOG10(B804)) | U804: =IF(R804="","",LOG10(MAX(R804,1E-12)))

Sheet 同相3導体
A1: 同相モード：P(2芯一括)－FG1 3導体MTLモード解
A3: No. | B3: 周波数 [Hz] | C3: ω | D3: 内部A1 | E3: 内部θ1 | F3: tanh1 Re | G3: tanh1 Im | H3: 外部A2 | I3: 外部θ2 | J3: tanh2 Re | K3: tanh2 Im | L3: C1 Re | M3: C1 Im | N3: C2 Re | O3: C2 Im | P3: 負荷 Re | Q3: 負荷 Im | R3: 外部Zext Re | S3: 外部Zext Im | T3: 内部実効負荷 Re | U3: 内部実効負荷 Im | V3: 分子 Re | W3: 分子 Im | X3: 分母 Re | Y3: 分母 Im | Z3: Zin Re | AA3: Zin Im | AB3: |ZCM| [Ω] | AC3: 位相 [deg] | AD3: log10(f) | AE3: log10(|ZCM|) | AF3: |Zload| | AG3: |Zext|
A4: 1 | B4: =IF(A4<='入力・概要'!$B$40,10^(LOG10('入力・概要'!$B$38)+(A4-1)*(LOG10('入力・概要'!$B$39)-LOG10('入力・概要'!$B$38))/('入力・概要'!$B$40-1)),"") | C4: =IF(B4="","",2*PI()*B4) | D4: =IF(B4="","",ATANH(MIN(0.999999,'入力・概要'!$E$20/'入力・概要'!$E$9))+'入力・概要'!$B$20*SQRT(B4/1E6)+E4*'入力・概要'!$B$15/2) | E4: =IF(B4="","",C4*('入力・概要'!$E$11*1E-9)) | F4: =IF(B4="","",SINH(2*D4)/(COSH(2*D4)+COS(2*E4))) | G4: =IF(B4="","",SIN(2*E4)/(COSH(2*D4)+COS(2*E4))) | H4: =IF(B4="","",ATANH(MIN(0.999999,'入力・概要'!$E$21/'入力・概要'!$E$15))+'入力・概要'!$B$21*SQRT(B4/1E6)+I4*'入力・概要'!$B$16/2) | I4: =IF(B4="","",C4*('入力・概要'!$E$17*1E-9)) | J4: =IF(B4="","",SINH(2*H4)/(COSH(2*H4)+COS(2*I4))) | K4: =IF(B4="","",SIN(2*I4)/(COSH(2*H4)+COS(2*I4))) | L4: =IF(B4="","",'入力・概要'!$B$25) | M4: =IF(B4="","",C4*'入力・概要'!$B$26*1E-9-1/(C4*'入力・概要'!$B$24*1E-6)) | N4: =IF(B4="","",'入力・概要'!$B$28) | O4: =IF(B4="","",C4*'入力・概要'!$B$29*1E-9-1/(C4*'入力・概要'!$B$27*1E-6)) | P4: =IF(B4="","",((L4*N4-M4*O4)*(L4+N4)+(L4*O4+M4*N4)*(M4+O4))/((L4+N4)^2+(M4+O4)^2)) | Q4: =IF(B4="","",((L4*O4+M4*N4)*(L4+N4)-(L4*N4-M4*O4)*(M4+O4))/((L4+N4)^2+(M4+O4)^2)) | R4: =IF(B4="","",'入力・概要'!$E$15*J4) | S4: =IF(B4="","",'入力・概要'!$E$15*K4) | T4: =IF(B4="","",P4+R4) | U4: =IF(B4="","",Q4+S4) | V4: =IF(B4="","",T4+'入力・概要'!$E$9*F4) | W4: =IF(B4="","",U4+'入力・概要'!$E$9*G4) | X4: =IF(B4="","",'入力・概要'!$E$9+T4*F4-U4*G4) | Y4: =IF(B4="","",T4*G4+U4*F4) | Z4: =IF(B4="","",'入力・概要'!$E$9*(V4*X4+W4*Y4)/(X4^2+Y4^2)+'入力・概要'!$B$36) | AA4: =IF(B4="","",'入力・概要'!$E$9*(W4*X4-V4*Y4)/(X4^2+Y4^2)+C4*'入力・概要'!$B$37*1E-9) | AB4: =IF(B4="","",SQRT(Z4^2+AA4^2)) | AC4: =IF(B4="","",IF(Z4>0,DEGREES(ATAN(AA4/Z4)),IF(Z4<0,IF(AA4>=0,DEGREES(ATAN(AA4/Z4))+180,DEGREES(ATAN(AA4/Z4))-180),IF(AA4>0,90,IF(AA4<0,-90,0))))) | AD4: =IF(B4="","",LOG10(B4)) | AE4: =IF(AB4="","",LOG10(MAX(AB4,1E-12))) | AF4: =IF(B4="","",SQRT(P4^2+Q4^2)) | AG4: =IF(B4="","",SQRT(R4^2+S4^2))
A5: 2 | B5: =IF(A5<='入力・概要'!$B$40,10^(LOG10('入力・概要'!$B$38)+(A5-1)*(LOG10('入力・概要'!$B$39)-LOG10('入力・概要'!$B$38))/('入力・概要'!$B$40-1)),"") | C5: =IF(B5="","",2*PI()*B5) | D5: =IF(B5="","",ATANH(MIN(0.999999,'入力・概要'!$E$20/'入力・概要'!$E$9))+'入力・概要'!$B$20*SQRT(B5/1E6)+E5*'入力・概要'!$B$15/2) | E5: =IF(B5="","",C5*('入力・概要'!$E$11*1E-9)) | F5: =IF(B5="","",SINH(2*D5)/(COSH(2*D5)+COS(2*E5))) | G5: =IF(B5="","",SIN(2*E5)/(COSH(2*D5)+COS(2*E5))) | H5: =IF(B5="","",ATANH(MIN(0.999999,'入力・概要'!$E$21/'入力・概要'!$E$15))+'入力・概要'!$B$21*SQRT(B5/1E6)+I5*'入力・概要'!$B$16/2) | I5: =IF(B5="","",C5*('入力・概要'!$E$17*1E-9)) | J5: =IF(B5="","",SINH(2*H5)/(COSH(2*H5)+COS(2*I5))) | K5: =IF(B5="","",SIN(2*I5)/(COSH(2*H5)+COS(2*I5))) | L5: =IF(B5="","",'入力・概要'!$B$25) | M5: =IF(B5="","",C5*'入力・概要'!$B$26*1E-9-1/(C5*'入力・概要'!$B$24*1E-6)) | N5: =IF(B5="","",'入力・概要'!$B$28) | O5: =IF(B5="","",C5*'入力・概要'!$B$29*1E-9-1/(C5*'入力・概要'!$B$27*1E-6)) | P5: =IF(B5="","",((L5*N5-M5*O5)*(L5+N5)+(L5*O5+M5*N5)*(M5+O5))/((L5+N5)^2+(M5+O5)^2)) | Q5: =IF(B5="","",((L5*O5+M5*N5)*(L5+N5)-(L5*N5-M5*O5)*(M5+O5))/((L5+N5)^2+(M5+O5)^2)) | R5: =IF(B5="","",'入力・概要'!$E$15*J5) | S5: =IF(B5="","",'入力・概要'!$E$15*K5) | T5: =IF(B5="","",P5+R5) | U5: =IF(B5="","",Q5+S5) | V5: =IF(B5="","",T5+'入力・概要'!$E$9*F5) | W5: =IF(B5="","",U5+'入力・概要'!$E$9*G5) | X5: =IF(B5="","",'入力・概要'!$E$9+T5*F5-U5*G5) | Y5: =IF(B5="","",T5*G5+U5*F5) | Z5: =IF(B5="","",'入力・概要'!$E$9*(V5*X5+W5*Y5)/(X5^2+Y5^2)+'入力・概要'!$B$36) | AA5: =IF(B5="","",'入力・概要'!$E$9*(W5*X5-V5*Y5)/(X5^2+Y5^2)+C5*'入力・概要'!$B$37*1E-9) | AB5: =IF(B5="","",SQRT(Z5^2+AA5^2)) | AC5: =IF(B5="","",IF(Z5>0,DEGREES(ATAN(AA5/Z5)),IF(Z5<0,IF(AA5>=0,DEGREES(ATAN(AA5/Z5))+180,DEGREES(ATAN(AA5/Z5))-180),IF(AA5>0,90,IF(AA5<0,-90,0))))) | AD5: =IF(B5="","",LOG10(B5)) | AE5: =IF(AB5="","",LOG10(MAX(AB5,1E-12))) | AF5: =IF(B5="","",SQRT(P5^2+Q5^2)) | AG5: =IF(B5="","",SQRT(R5^2+S5^2))
A6: 3 | B6: =IF(A6<='入力・概要'!$B$40,10^(LOG10('入力・概要'!$B$38)+(A6-1)*(LOG10('入力・概要'!$B$39)-LOG10('入力・概要'!$B$38))/('入力・概要'!$B$40-1)),"") | C6: =IF(B6="","",2*PI()*B6) | D6: =IF(B6="","",ATANH(MIN(0.999999,'入力・概要'!$E$20/'入力・概要'!$E$9))+'入力・概要'!$B$20*SQRT(B6/1E6)+E6*'入力・概要'!$B$15/2) | E6: =IF(B6="","",C6*('入力・概要'!$E$11*1E-9)) | F6: =IF(B6="","",SINH(2*D6)/(COSH(2*D6)+COS(2*E6))) | G6: =IF(B6="","",SIN(2*E6)/(COSH(2*D6)+COS(2*E6))) | H6: =IF(B6="","",ATANH(MIN(0.999999,'入力・概要'!$E$21/'入力・概要'!$E$15))+'入力・概要'!$B$21*SQRT(B6/1E6)+I6*'入力・概要'!$B$16/2) | I6: =IF(B6="","",C6*('入力・概要'!$E$17*1E-9)) | J6: =IF(B6="","",SINH(2*H6)/(COSH(2*H6)+COS(2*I6))) | K6: =IF(B6="","",SIN(2*I6)/(COSH(2*H6)+COS(2*I6))) | L6: =IF(B6="","",'入力・概要'!$B$25) | M6: =IF(B6="","",C6*'入力・概要'!$B$26*1E-9-1/(C6*'入力・概要'!$B$24*1E-6)) | N6: =IF(B6="","",'入力・概要'!$B$28) | O6: =IF(B6="","",C6*'入力・概要'!$B$29*1E-9-1/(C6*'入力・概要'!$B$27*1E-6)) | P6: =IF(B6="","",((L6*N6-M6*O6)*(L6+N6)+(L6*O6+M6*N6)*(M6+O6))/((L6+N6)^2+(M6+O6)^2)) | Q6: =IF(B6="","",((L6*O6+M6*N6)*(L6+N6)-(L6*N6-M6*O6)*(M6+O6))/((L6+N6)^2+(M6+O6)^2)) | R6: =IF(B6="","",'入力・概要'!$E$15*J6) | S6: =IF(B6="","",'入力・概要'!$E$15*K6) | T6: =IF(B6="","",P6+R6) | U6: =IF(B6="","",Q6+S6) | V6: =IF(B6="","",T6+'入力・概要'!$E$9*F6) | W6: =IF(B6="","",U6+'入力・概要'!$E$9*G6) | X6: =IF(B6="","",'入力・概要'!$E$9+T6*F6-U6*G6) | Y6: =IF(B6="","",T6*G6+U6*F6) | Z6: =IF(B6="","",'入力・概要'!$E$9*(V6*X6+W6*Y6)/(X6^2+Y6^2)+'入力・概要'!$B$36) | AA6: =IF(B6="","",'入力・概要'!$E$9*(W6*X6-V6*Y6)/(X6^2+Y6^2)+C6*'入力・概要'!$B$37*1E-9) | AB6: =IF(B6="","",SQRT(Z6^2+AA6^2)) | AC6: =IF(B6="","",IF(Z6>0,DEGREES(ATAN(AA6/Z6)),IF(Z6<0,IF(AA6>=0,DEGREES(ATAN(AA6/Z6))+180,DEGREES(ATAN(AA6/Z6))-180),IF(AA6>0,90,IF(AA6<0,-90,0))))) | AD6: =IF(B6="","",LOG10(B6)) | AE6: =IF(AB6="","",LOG10(MAX(AB6,1E-12))) | AF6: =IF(B6="","",SQRT(P6^2+Q6^2)) | AG6: =IF(B6="","",SQRT(R6^2+S6^2))
A7: 4 | B7: =IF(A7<='入力・概要'!$B$40,10^(LOG10('入力・概要'!$B$38)+(A7-1)*(LOG10('入力・概要'!$B$39)-LOG10('入力・概要'!$B$38))/('入力・概要'!$B$40-1)),"") | C7: =IF(B7="","",2*PI()*B7) | D7: =IF(B7="","",ATANH(MIN(0.999999,'入力・概要'!$E$20/'入力・概要'!$E$9))+'入力・概要'!$B$20*SQRT(B7/1E6)+E7*'入力・概要'!$B$15/2) | E7: =IF(B7="","",C7*('入力・概要'!$E$11*1E-9)) | F7: =IF(B7="","",SINH(2*D7)/(COSH(2*D7)+COS(2*E7))) | G7: =IF(B7="","",SIN(2*E7)/(COSH(2*D7)+COS(2*E7))) | H7: =IF(B7="","",ATANH(MIN(0.999999,'入力・概要'!$E$21/'入力・概要'!$E$15))+'入力・概要'!$B$21*SQRT(B7/1E6)+I7*'入力・概要'!$B$16/2) | I7: =IF(B7="","",C7*('入力・概要'!$E$17*1E-9)) | J7: =IF(B7="","",SINH(2*H7)/(COSH(2*H7)+COS(2*I7))) | K7: =IF(B7="","",SIN(2*I7)/(COSH(2*H7)+COS(2*I7))) | L7: =IF(B7="","",'入力・概要'!$B$25) | M7: =IF(B7="","",C7*'入力・概要'!$B$26*1E-9-1/(C7*'入力・概要'!$B$24*1E-6)) | N7: =IF(B7="","",'入力・概要'!$B$28) | O7: =IF(B7="","",C7*'入力・概要'!$B$29*1E-9-1/(C7*'入力・概要'!$B$27*1E-6)) | P7: =IF(B7="","",((L7*N7-M7*O7)*(L7+N7)+(L7*O7+M7*N7)*(M7+O7))/((L7+N7)^2+(M7+O7)^2)) | Q7: =IF(B7="","",((L7*O7+M7*N7)*(L7+N7)-(L7*N7-M7*O7)*(M7+O7))/((L7+N7)^2+(M7+O7)^2)) | R7: =IF(B7="","",'入力・概要'!$E$15*J7) | S7: =IF(B7="","",'入力・概要'!$E$15*K7) | T7: =IF(B7="","",P7+R7) | U7: =IF(B7="","",Q7+S7) | V7: =IF(B7="","",T7+'入力・概要'!$E$9*F7) | W7: =IF(B7="","",U7+'入力・概要'!$E$9*G7) | X7: =IF(B7="","",'入力・概要'!$E$9+T7*F7-U7*G7) | Y7: =IF(B7="","",T7*G7+U7*F7) | Z7: =IF(B7="","",'入力・概要'!$E$9*(V7*X7+W7*Y7)/(X7^2+Y7^2)+'入力・概要'!$B$36) | AA7: =IF(B7="","",'入力・概要'!$E$9*(W7*X7-V7*Y7)/(X7^2+Y7^2)+C7*'入力・概要'!$B$37*1E-9) | AB7: =IF(B7="","",SQRT(Z7^2+AA7^2)) | AC7: =IF(B7="","",IF(Z7>0,DEGREES(ATAN(AA7/Z7)),IF(Z7<0,IF(AA7>=0,DEGREES(ATAN(AA7/Z7))+180,DEGREES(ATAN(AA7/Z7))-180),IF(AA7>0,90,IF(AA7<0,-90,0))))) | AD7: =IF(B7="","",LOG10(B7)) | AE7: =IF(AB7="","",LOG10(MAX(AB7,1E-12))) | AF7: =IF(B7="","",SQRT(P7^2+Q7^2)) | AG7: =IF(B7="","",SQRT(R7^2+S7^2))
A8: 5 | B8: =IF(A8<='入力・概要'!$B$40,10^(LOG10('入力・概要'!$B$38)+(A8-1)*(LOG10('入力・概要'!$B$39)-LOG10('入力・概要'!$B$38))/('入力・概要'!$B$40-1)),"") | C8: =IF(B8="","",2*PI()*B8) | D8: =IF(B8="","",ATANH(MIN(0.999999,'入力・概要'!$E$20/'入力・概要'!$E$9))+'入力・概要'!$B$20*SQRT(B8/1E6)+E8*'入力・概要'!$B$15/2) | E8: =IF(B8="","",C8*('入力・概要'!$E$11*1E-9)) | F8: =IF(B8="","",SINH(2*D8)/(COSH(2*D8)+COS(2*E8))) | G8: =IF(B8="","",SIN(2*E8)/(COSH(2*D8)+COS(2*E8))) | H8: =IF(B8="","",ATANH(MIN(0.999999,'入力・概要'!$E$21/'入力・概要'!$E$15))+'入力・概要'!$B$21*SQRT(B8/1E6)+I8*'入力・概要'!$B$16/2) | I8: =IF(B8="","",C8*('入力・概要'!$E$17*1E-9)) | J8: =IF(B8="","",SINH(2*H8)/(COSH(2*H8)+COS(2*I8))) | K8: =IF(B8="","",SIN(2*I8)/(COSH(2*H8)+COS(2*I8))) | L8: =IF(B8="","",'入力・概要'!$B$25) | M8: =IF(B8="","",C8*'入力・概要'!$B$26*1E-9-1/(C8*'入力・概要'!$B$24*1E-6)) | N8: =IF(B8="","",'入力・概要'!$B$28) | O8: =IF(B8="","",C8*'入力・概要'!$B$29*1E-9-1/(C8*'入力・概要'!$B$27*1E-6)) | P8: =IF(B8="","",((L8*N8-M8*O8)*(L8+N8)+(L8*O8+M8*N8)*(M8+O8))/((L8+N8)^2+(M8+O8)^2)) | Q8: =IF(B8="","",((L8*O8+M8*N8)*(L8+N8)-(L8*N8-M8*O8)*(M8+O8))/((L8+N8)^2+(M8+O8)^2)) | R8: =IF(B8="","",'入力・概要'!$E$15*J8) | S8: =IF(B8="","",'入力・概要'!$E$15*K8) | T8: =IF(B8="","",P8+R8) | U8: =IF(B8="","",Q8+S8) | V8: =IF(B8="","",T8+'入力・概要'!$E$9*F8) | W8: =IF(B8="","",U8+'入力・概要'!$E$9*G8) | X8: =IF(B8="","",'入力・概要'!$E$9+T8*F8-U8*G8) | Y8: =IF(B8="","",T8*G8+U8*F8) | Z8: =IF(B8="","",'入力・概要'!$E$9*(V8*X8+W8*Y8)/(X8^2+Y8^2)+'入力・概要'!$B$36) | AA8: =IF(B8="","",'入力・概要'!$E$9*(W8*X8-V8*Y8)/(X8^2+Y8^2)+C8*'入力・概要'!$B$37*1E-9) | AB8: =IF(B8="","",SQRT(Z8^2+AA8^2)) | AC8: =IF(B8="","",IF(Z8>0,DEGREES(ATAN(AA8/Z8)),IF(Z8<0,IF(AA8>=0,DEGREES(ATAN(AA8/Z8))+180,DEGREES(ATAN(AA8/Z8))-180),IF(AA8>0,90,IF(AA8<0,-90,0))))) | AD8: =IF(B8="","",LOG10(B8)) | AE8: =IF(AB8="","",LOG10(MAX(AB8,1E-12))) | AF8: =IF(B8="","",SQRT(P8^2+Q8^2)) | AG8: =IF(B8="","",SQRT(R8^2+S8^2))
A9: 6 | B9: =IF(A9<='入力・概要'!$B$40,10^(LOG10('入力・概要'!$B$38)+(A9-1)*(LOG10('入力・概要'!$B$39)-LOG10('入力・概要'!$B$38))/('入力・概要'!$B$40-1)),"") | C9: =IF(B9="","",2*PI()*B9) | D9: =IF(B9="","",ATANH(MIN(0.999999,'入力・概要'!$E$20/'入力・概要'!$E$9))+'入力・概要'!$B$20*SQRT(B9/1E6)+E9*'入力・概要'!$B$15/2) | E9: =IF(B9="","",C9*('入力・概要'!$E$11*1E-9)) | F9: =IF(B9="","",SINH(2*D9)/(COSH(2*D9)+COS(2*E9))) | G9: =IF(B9="","",SIN(2*E9)/(COSH(2*D9)+COS(2*E9))) | H9: =IF(B9="","",ATANH(MIN(0.999999,'入力・概要'!$E$21/'入力・概要'!$E$15))+'入力・概要'!$B$21*SQRT(B9/1E6)+I9*'入力・概要'!$B$16/2) | I9: =IF(B9="","",C9*('入力・概要'!$E$17*1E-9)) | J9: =IF(B9="","",SINH(2*H9)/(COSH(2*H9)+COS(2*I9))) | K9: =IF(B9="","",SIN(2*I9)/(COSH(2*H9)+COS(2*I9))) | L9: =IF(B9="","",'入力・概要'!$B$25) | M9: =IF(B9="","",C9*'入力・概要'!$B$26*1E-9-1/(C9*'入力・概要'!$B$24*1E-6)) | N9: =IF(B9="","",'入力・概要'!$B$28) | O9: =IF(B9="","",C9*'入力・概要'!$B$29*1E-9-1/(C9*'入力・概要'!$B$27*1E-6)) | P9: =IF(B9="","",((L9*N9-M9*O9)*(L9+N9)+(L9*O9+M9*N9)*(M9+O9))/((L9+N9)^2+(M9+O9)^2)) | Q9: =IF(B9="","",((L9*O9+M9*N9)*(L9+N9)-(L9*N9-M9*O9)*(M9+O9))/((L9+N9)^2+(M9+O9)^2)) | R9: =IF(B9="","",'入力・概要'!$E$15*J9) | S9: =IF(B9="","",'入力・概要'!$E$15*K9) | T9: =IF(B9="","",P9+R9) | U9: =IF(B9="","",Q9+S9) | V9: =IF(B9="","",T9+'入力・概要'!$E$9*F9) | W9: =IF(B9="","",U9+'入力・概要'!$E$9*G9) | X9: =IF(B9="","",'入力・概要'!$E$9+T9*F9-U9*G9) | Y9: =IF(B9="","",T9*G9+U9*F9) | Z9: =IF(B9="","",'入力・概要'!$E$9*(V9*X9+W9*Y9)/(X9^2+Y9^2)+'入力・概要'!$B$36) | AA9: =IF(B9="","",'入力・概要'!$E$9*(W9*X9-V9*Y9)/(X9^2+Y9^2)+C9*'入力・概要'!$B$37*1E-9) | AB9: =IF(B9="","",SQRT(Z9^2+AA9^2)) | AC9: =IF(B9="","",IF(Z9>0,DEGREES(ATAN(AA9/Z9)),IF(Z9<0,IF(AA9>=0,DEGREES(ATAN(AA9/Z9))+180,DEGREES(ATAN(AA9/Z9))-180),IF(AA9>0,90,IF(AA9<0,-90,0))))) | AD9: =IF(B9="","",LOG10(B9)) | AE9: =IF(AB9="","",LOG10(MAX(AB9,1E-12))) | AF9: =IF(B9="","",SQRT(P9^2+Q9^2)) | AG9: =IF(B9="","",SQRT(R9^2+S9^2))
A10: 7 | B10: =IF(A10<='入力・概要'!$B$40,10^(LOG10('入力・概要'!$B$38)+(A10-1)*(LOG10('入力・概要'!$B$39)-LOG10('入力・概要'!$B$38))/('入力・概要'!$B$40-1)),"") | C10: =IF(B10="","",2*PI()*B10) | D10: =IF(B10="","",ATANH(MIN(0.999999,'入力・概要'!$E$20/'入力・概要'!$E$9))+'入力・概要'!$B$20*SQRT(B10/1E6)+E10*'入力・概要'!$B$15/2) | E10: =IF(B10="","",C10*('入力・概要'!$E$11*1E-9)) | F10: =IF(B10="","",SINH(2*D10)/(COSH(2*D10)+COS(2*E10))) | G10: =IF(B10="","",SIN(2*E10)/(COSH(2*D10)+COS(2*E10))) | H10: =IF(B10="","",ATANH(MIN(0.999999,'入力・概要'!$E$21/'入力・概要'!$E$15))+'入力・概要'!$B$21*SQRT(B10/1E6)+I10*'入力・概要'!$B$16/2) | I10: =IF(B10="","",C10*('入力・概要'!$E$17*1E-9)) | J10: =IF(B10="","",SINH(2*H10)/(COSH(2*H10)+COS(2*I10))) | K10: =IF(B10="","",SIN(2*I10)/(COSH(2*H10)+COS(2*I10))) | L10: =IF(B10="","",'入力・概要'!$B$25) | M10: =IF(B10="","",C10*'入力・概要'!$B$26*1E-9-1/(C10*'入力・概要'!$B$24*1E-6)) | N10: =IF(B10="","",'入力・概要'!$B$28) | O10: =IF(B10="","",C10*'入力・概要'!$B$29*1E-9-1/(C10*'入力・概要'!$B$27*1E-6)) | P10: =IF(B10="","",((L10*N10-M10*O10)*(L10+N10)+(L10*O10+M10*N10)*(M10+O10))/((L10+N10)^2+(M10+O10)^2)) | Q10: =IF(B10="","",((L10*O10+M10*N10)*(L10+N10)-(L10*N10-M10*O10)*(M10+O10))/((L10+N10)^2+(M10+O10)^2)) | R10: =IF(B10="","",'入力・概要'!$E$15*J10) | S10: =IF(B10="","",'入力・概要'!$E$15*K10) | T10: =IF(B10="","",P10+R10) | U10: =IF(B10="","",Q10+S10) | V10: =IF(B10="","",T10+'入力・概要'!$E$9*F10) | W10: =IF(B10="","",U10+'入力・概要'!$E$9*G10) | X10: =IF(B10="","",'入力・概要'!$E$9+T10*F10-U10*G10) | Y10: =IF(B10="","",T10*G10+U10*F10) | Z10: =IF(B10="","",'入力・概要'!$E$9*(V10*X10+W10*Y10)/(X10^2+Y10^2)+'入力・概要'!$B$36) | AA10: =IF(B10="","",'入力・概要'!$E$9*(W10*X10-V10*Y10)/(X10^2+Y10^2)+C10*'入力・概要'!$B$37*1E-9) | AB10: =IF(B10="","",SQRT(Z10^2+AA10^2)) | AC10: =IF(B10="","",IF(Z10>0,DEGREES(ATAN(AA10/Z10)),IF(Z10<0,IF(AA10>=0,DEGREES(ATAN(AA10/Z10))+180,DEGREES(ATAN(AA10/Z10))-180),IF(AA10>0,90,IF(AA10<0,-90,0))))) | AD10: =IF(B10="","",LOG10(B10)) | AE10: =IF(AB10="","",LOG10(MAX(AB10,1E-12))) | AF10: =IF(B10="","",SQRT(P10^2+Q10^2)) | AG10: =IF(B10="","",SQRT(R10^2+S10^2))
A11: 8 | B11: =IF(A11<='入力・概要'!$B$40,10^(LOG10('入力・概要'!$B$38)+(A11-1)*(LOG10('入力・概要'!$B$39)-LOG10('入力・概要'!$B$38))/('入力・概要'!$B$40-1)),"") | C11: =IF(B11="","",2*PI()*B11) | D11: =IF(B11="","",ATANH(MIN(0.999999,'入力・概要'!$E$20/'入力・概要'!$E$9))+'入力・概要'!$B$20*SQRT(B11/1E6)+E11*'入力・概要'!$B$15/2) | E11: =IF(B11="","",C11*('入力・概要'!$E$11*1E-9)) | F11: =IF(B11="","",SINH(2*D11)/(COSH(2*D11)+COS(2*E11))) | G11: =IF(B11="","",SIN(2*E11)/(COSH(2*D11)+COS(2*E11))) | H11: =IF(B11="","",ATANH(MIN(0.999999,'入力・概要'!$E$21/'入力・概要'!$E$15))+'入力・概要'!$B$21*SQRT(B11/1E6)+I11*'入力・概要'!$B$16/2) | I11: =IF(B11="","",C11*('入力・概要'!$E$17*1E-9)) | J11: =IF(B11="","",SINH(2*H11)/(COSH(2*H11)+COS(2*I11))) | K11: =IF(B11="","",SIN(2*I11)/(COSH(2*H11)+COS(2*I11))) | L11: =IF(B11="","",'入力・概要'!$B$25) | M11: =IF(B11="","",C11*'入力・概要'!$B$26*1E-9-1/(C11*'入力・概要'!$B$24*1E-6)) | N11: =IF(B11="","",'入力・概要'!$B$28) | O11: =IF(B11="","",C11*'入力・概要'!$B$29*1E-9-1/(C11*'入力・概要'!$B$27*1E-6)) | P11: =IF(B11="","",((L11*N11-M11*O11)*(L11+N11)+(L11*O11+M11*N11)*(M11+O11))/((L11+N11)^2+(M11+O11)^2)) | Q11: =IF(B11="","",((L11*O11+M11*N11)*(L11+N11)-(L11*N11-M11*O11)*(M11+O11))/((L11+N11)^2+(M11+O11)^2)) | R11: =IF(B11="","",'入力・概要'!$E$15*J11) | S11: =IF(B11="","",'入力・概要'!$E$15*K11) | T11: =IF(B11="","",P11+R11) | U11: =IF(B11="","",Q11+S11) | V11: =IF(B11="","",T11+'入力・概要'!$E$9*F11) | W11: =IF(B11="","",U11+'入力・概要'!$E$9*G11) | X11: =IF(B11="","",'入力・概要'!$E$9+T11*F11-U11*G11) | Y11: =IF(B11="","",T11*G11+U11*F11) | Z11: =IF(B11="","",'入力・概要'!$E$9*(V11*X11+W11*Y11)/(X11^2+Y11^2)+'入力・概要'!$B$36) | AA11: =IF(B11="","",'入力・概要'!$E$9*(W11*X11-V11*Y11)/(X11^2+Y11^2)+C11*'入力・概要'!$B$37*1E-9) | AB11: =IF(B11="","",SQRT(Z11^2+AA11^2)) | AC11: =IF(B11="","",IF(Z11>0,DEGREES(ATAN(AA11/Z11)),IF(Z11<0,IF(AA11>=0,DEGREES(ATAN(AA11/Z11))+180,DEGREES(ATAN(AA11/Z11))-180),IF(AA11>0,90,IF(AA11<0,-90,0))))) | AD11: =IF(B11="","",LOG10(B11)) | AE11: =IF(AB11="","",LOG10(MAX(AB11,1E-12))) | AF11: =IF(B11="","",SQRT(P11^2+Q11^2)) | AG11: =IF(B11="","",SQRT(R11^2+S11^2))
A12: 9 | B12: =IF(A12<='入力・概要'!$B$40,10^(LOG10('入力・概要'!$B$38)+(A12-1)*(LOG10('入力・概要'!$B$39)-LOG10('入力・概要'!$B$38))/('入力・概要'!$B$40-1)),"") | C12: =IF(B12="","",2*PI()*B12) | D12: =IF(B12="","",ATANH(MIN(0.999999,'入力・概要'!$E$20/'入力・概要'!$E$9))+'入力・概要'!$B$20*SQRT(B12/1E6)+E12*'入力・概要'!$B$15/2) | E12: =IF(B12="","",C12*('入力・概要'!$E$11*1E-9)) | F12: =IF(B12="","",SINH(2*D12)/(COSH(2*D12)+COS(2*E12))) | G12: =IF(B12="","",SIN(2*E12)/(COSH(2*D12)+COS(2*E12))) | H12: =IF(B12="","",ATANH(MIN(0.999999,'入力・概要'!$E$21/'入力・概要'!$E$15))+'入力・概要'!$B$21*SQRT(B12/1E6)+I12*'入力・概要'!$B$16/2) | I12: =IF(B12="","",C12*('入力・概要'!$E$17*1E-9)) | J12: =IF(B12="","",SINH(2*H12)/(COSH(2*H12)+COS(2*I12))) | K12: =IF(B12="","",SIN(2*I12)/(COSH(2*H12)+COS(2*I12))) | L12: =IF(B12="","",'入力・概要'!$B$25) | M12: =IF(B12="","",C12*'入力・概要'!$B$26*1E-9-1/(C12*'入力・概要'!$B$24*1E-6)) | N12: =IF(B12="","",'入力・概要'!$B$28) | O12: =IF(B12="","",C12*'入力・概要'!$B$29*1E-9-1/(C12*'入力・概要'!$B$27*1E-6)) | P12: =IF(B12="","",((L12*N12-M12*O12)*(L12+N12)+(L12*O12+M12*N12)*(M12+O12))/((L12+N12)^2+(M12+O12)^2)) | Q12: =IF(B12="","",((L12*O12+M12*N12)*(L12+N12)-(L12*N12-M12*O12)*(M12+O12))/((L12+N12)^2+(M12+O12)^2)) | R12: =IF(B12="","",'入力・概要'!$E$15*J12) | S12: =IF(B12="","",'入力・概要'!$E$15*K12) | T12: =IF(B12="","",P12+R12) | U12: =IF(B12="","",Q12+S12) | V12: =IF(B12="","",T12+'入力・概要'!$E$9*F12) | W12: =IF(B12="","",U12+'入力・概要'!$E$9*G12) | X12: =IF(B12="","",'入力・概要'!$E$9+T12*F12-U12*G12) | Y12: =IF(B12="","",T12*G12+U12*F12) | Z12: =IF(B12="","",'入力・概要'!$E$9*(V12*X12+W12*Y12)/(X12^2+Y12^2)+'入力・概要'!$B$36) | AA12: =IF(B12="","",'入力・概要'!$E$9*(W12*X12-V12*Y12)/(X12^2+Y12^2)+C12*'入力・概要'!$B$37*1E-9) | AB12: =IF(B12="","",SQRT(Z12^2+AA12^2)) | AC12: =IF(B12="","",IF(Z12>0,DEGREES(ATAN(AA12/Z12)),IF(Z12<0,IF(AA12>=0,DEGREES(ATAN(AA12/Z12))+180,DEGREES(ATAN(AA12/Z12))-180),IF(AA12>0,90,IF(AA12<0,-90,0))))) | AD12: =IF(B12="","",LOG10(B12)) | AE12: =IF(AB12="","",LOG10(MAX(AB12,1E-12))) | AF12: =IF(B12="","",SQRT(P12^2+Q12^2)) | AG12: =IF(B12="","",SQRT(R12^2+S12^2))
A13: 10 | B13: =IF(A13<='入力・概要'!$B$40,10^(LOG10('入力・概要'!$B$38)+(A13-1)*(LOG10('入力・概要'!$B$39)-LOG10('入力・概要'!$B$38))/('入力・概要'!$B$40-1)),"") | C13: =IF(B13="","",2*PI()*B13) | D13: =IF(B13="","",ATANH(MIN(0.999999,'入力・概要'!$E$20/'入力・概要'!$E$9))+'入力・概要'!$B$20*SQRT(B13/1E6)+E13*'入力・概要'!$B$15/2) | E13: =IF(B13="","",C13*('入力・概要'!$E$11*1E-9)) | F13: =IF(B13="","",SINH(2*D13)/(COSH(2*D13)+COS(2*E13))) | G13: =IF(B13="","",SIN(2*E13)/(COSH(2*D13)+COS(2*E13))) | H13: =IF(B13="","",ATANH(MIN(0.999999,'入力・概要'!$E$21/'入力・概要'!$E$15))+'入力・概要'!$B$21*SQRT(B13/1E6)+I13*'入力・概要'!$B$16/2) | I13: =IF(B13="","",C13*('入力・概要'!$E$17*1E-9)) | J13: =IF(B13="","",SINH(2*H13)/(COSH(2*H13)+COS(2*I13))) | K13: =IF(B13="","",SIN(2*I13)/(COSH(2*H13)+COS(2*I13))) | L13: =IF(B13="","",'入力・概要'!$B$25) | M13: =IF(B13="","",C13*'入力・概要'!$B$26*1E-9-1/(C13*'入力・概要'!$B$24*1E-6)) | N13: =IF(B13="","",'入力・概要'!$B$28) | O13: =IF(B13="","",C13*'入力・概要'!$B$29*1E-9-1/(C13*'入力・概要'!$B$27*1E-6)) | P13: =IF(B13="","",((L13*N13-M13*O13)*(L13+N13)+(L13*O13+M13*N13)*(M13+O13))/((L13+N13)^2+(M13+O13)^2)) | Q13: =IF(B13="","",((L13*O13+M13*N13)*(L13+N13)-(L13*N13-M13*O13)*(M13+O13))/((L13+N13)^2+(M13+O13)^2)) | R13: =IF(B13="","",'入力・概要'!$E$15*J13) | S13: =IF(B13="","",'入力・概要'!$E$15*K13) | T13: =IF(B13="","",P13+R13) | U13: =IF(B13="","",Q13+S13) | V13: =IF(B13="","",T13+'入力・概要'!$E$9*F13) | W13: =IF(B13="","",U13+'入力・概要'!$E$9*G13) | X13: =IF(B13="","",'入力・概要'!$E$9+T13*F13-U13*G13) | Y13: =IF(B13="","",T13*G13+U13*F13) | Z13: =IF(B13="","",'入力・概要'!$E$9*(V13*X13+W13*Y13)/(X13^2+Y13^2)+'入力・概要'!$B$36) | AA13: =IF(B13="","",'入力・概要'!$E$9*(W13*X13-V13*Y13)/(X13^2+Y13^2)+C13*'入力・概要'!$B$37*1E-9) | AB13: =IF(B13="","",SQRT(Z13^2+AA13^2)) | AC13: =IF(B13="","",IF(Z13>0,DEGREES(ATAN(AA13/Z13)),IF(Z13<0,IF(AA13>=0,DEGREES(ATAN(AA13/Z13))+180,DEGREES(ATAN(AA13/Z13))-180),IF(AA13>0,90,IF(AA13<0,-90,0))))) | AD13: =IF(B13="","",LOG10(B13)) | AE13: =IF(AB13="","",LOG10(MAX(AB13,1E-12))) | AF13: =IF(B13="","",SQRT(P13^2+Q13^2)) | AG13: =IF(B13="","",SQRT(R13^2+S13^2))
A14: 11 | B14: =IF(A14<='入力・概要'!$B$40,10^(LOG10('入力・概要'!$B$38)+(A14-1)*(LOG10('入力・概要'!$B$39)-LOG10('入力・概要'!$B$38))/('入力・概要'!$B$40-1)),"") | C14: =IF(B14="","",2*PI()*B14) | D14: =IF(B14="","",ATANH(MIN(0.999999,'入力・概要'!$E$20/'入力・概要'!$E$9))+'入力・概要'!$B$20*SQRT(B14/1E6)+E14*'入力・概要'!$B$15/2) | E14: =IF(B14="","",C14*('入力・概要'!$E$11*1E-9)) | F14: =IF(B14="","",SINH(2*D14)/(COSH(2*D14)+COS(2*E14))) | G14: =IF(B14="","",SIN(2*E14)/(COSH(2*D14)+COS(2*E14))) | H14: =IF(B14="","",ATANH(MIN(0.999999,'入力・概要'!$E$21/'入力・概要'!$E$15))+'入力・概要'!$B$21*SQRT(B14/1E6)+I14*'入力・概要'!$B$16/2) | I14: =IF(B14="","",C14*('入力・概要'!$E$17*1E-9)) | J14: =IF(B14="","",SINH(2*H14)/(COSH(2*H14)+COS(2*I14))) | K14: =IF(B14="","",SIN(2*I14)/(COSH(2*H14)+COS(2*I14))) | L14: =IF(B14="","",'入力・概要'!$B$25) | M14: =IF(B14="","",C14*'入力・概要'!$B$26*1E-9-1/(C14*'入力・概要'!$B$24*1E-6)) | N14: =IF(B14="","",'入力・概要'!$B$28) | O14: =IF(B14="","",C14*'入力・概要'!$B$29*1E-9-1/(C14*'入力・概要'!$B$27*1E-6)) | P14: =IF(B14="","",((L14*N14-M14*O14)*(L14+N14)+(L14*O14+M14*N14)*(M14+O14))/((L14+N14)^2+(M14+O14)^2)) | Q14: =IF(B14="","",((L14*O14+M14*N14)*(L14+N14)-(L14*N14-M14*O14)*(M14+O14))/((L14+N14)^2+(M14+O14)^2)) | R14: =IF(B14="","",'入力・概要'!$E$15*J14) | S14: =IF(B14="","",'入力・概要'!$E$15*K14) | T14: =IF(B14="","",P14+R14) | U14: =IF(B14="","",Q14+S14) | V14: =IF(B14="","",T14+'入力・概要'!$E$9*F14) | W14: =IF(B14="","",U14+'入力・概要'!$E$9*G14) | X14: =IF(B14="","",'入力・概要'!$E$9+T14*F14-U14*G14) | Y14: =IF(B14="","",T14*G14+U14*F14) | Z14: =IF(B14="","",'入力・概要'!$E$9*(V14*X14+W14*Y14)/(X14^2+Y14^2)+'入力・概要'!$B$36) | AA14: =IF(B14="","",'入力・概要'!$E$9*(W14*X14-V14*Y14)/(X14^2+Y14^2)+C14*'入力・概要'!$B$37*1E-9) | AB14: =IF(B14="","",SQRT(Z14^2+AA14^2)) | AC14: =IF(B14="","",IF(Z14>0,DEGREES(ATAN(AA14/Z14)),IF(Z14<0,IF(AA14>=0,DEGREES(ATAN(AA14/Z14))+180,DEGREES(ATAN(AA14/Z14))-180),IF(AA14>0,90,IF(AA14<0,-90,0))))) | AD14: =IF(B14="","",LOG10(B14)) | AE14: =IF(AB14="","",LOG10(MAX(AB14,1E-12))) | AF14: =IF(B14="","",SQRT(P14^2+Q14^2)) | AG14: =IF(B14="","",SQRT(R14^2+S14^2))
A15: 12 | B15: =IF(A15<='入力・概要'!$B$40,10^(LOG10('入力・概要'!$B$38)+(A15-1)*(LOG10('入力・概要'!$B$39)-LOG10('入力・概要'!$B$38))/('入力・概要'!$B$40-1)),"") | C15: =IF(B15="","",2*PI()*B15) | D15: =IF(B15="","",ATANH(MIN(0.999999,'入力・概要'!$E$20/'入力・概要'!$E$9))+'入力・概要'!$B$20*SQRT(B15/1E6)+E15*'入力・概要'!$B$15/2) | E15: =IF(B15="","",C15*('入力・概要'!$E$11*1E-9)) | F15: =IF(B15="","",SINH(2*D15)/(COSH(2*D15)+COS(2*E15))) | G15: =IF(B15="","",SIN(2*E15)/(COSH(2*D15)+COS(2*E15))) | H15: =IF(B15="","",ATANH(MIN(0.999999,'入力・概要'!$E$21/'入力・概要'!$E$15))+'入力・概要'!$B$21*SQRT(B15/1E6)+I15*'入力・概要'!$B$16/2) | I15: =IF(B15="","",C15*('入力・概要'!$E$17*1E-9)) | J15: =IF(B15="","",SINH(2*H15)/(COSH(2*H15)+COS(2*I15))) | K15: =IF(B15="","",SIN(2*I15)/(COSH(2*H15)+COS(2*I15))) | L15: =IF(B15="","",'入力・概要'!$B$25) | M15: =IF(B15="","",C15*'入力・概要'!$B$26*1E-9-1/(C15*'入力・概要'!$B$24*1E-6)) | N15: =IF(B15="","",'入力・概要'!$B$28) | O15: =IF(B15="","",C15*'入力・概要'!$B$29*1E-9-1/(C15*'入力・概要'!$B$27*1E-6)) | P15: =IF(B15="","",((L15*N15-M15*O15)*(L15+N15)+(L15*O15+M15*N15)*(M15+O15))/((L15+N15)^2+(M15+O15)^2)) | Q15: =IF(B15="","",((L15*O15+M15*N15)*(L15+N15)-(L15*N15-M15*O15)*(M15+O15))/((L15+N15)^2+(M15+O15)^2)) | R15: =IF(B15="","",'入力・概要'!$E$15*J15) | S15: =IF(B15="","",'入力・概要'!$E$15*K15) | T15: =IF(B15="","",P15+R15) | U15: =IF(B15="","",Q15+S15) | V15: =IF(B15="","",T15+'入力・概要'!$E$9*F15) | W15: =IF(B15="","",U15+'入力・概要'!$E$9*G15) | X15: =IF(B15="","",'入力・概要'!$E$9+T15*F15-U15*G15) | Y15: =IF(B15="","",T15*G15+U15*F15) | Z15: =IF(B15="","",'入力・概要'!$E$9*(V15*X15+W15*Y15)/(X15^2+Y15^2)+'入力・概要'!$B$36) | AA15: =IF(B15="","",'入力・概要'!$E$9*(W15*X15-V15*Y15)/(X15^2+Y15^2)+C15*'入力・概要'!$B$37*1E-9) | AB15: =IF(B15="","",SQRT(Z15^2+AA15^2)) | AC15: =IF(B15="","",IF(Z15>0,DEGREES(ATAN(AA15/Z15)),IF(Z15<0,IF(AA15>=0,DEGREES(ATAN(AA15/Z15))+180,DEGREES(ATAN(AA15/Z15))-180),IF(AA15>0,90,IF(AA15<0,-90,0))))) | AD15: =IF(B15="","",LOG10(B15)) | AE15: =IF(AB15="","",LOG10(MAX(AB15,1E-12))) | AF15: =IF(B15="","",SQRT(P15^2+Q15^2)) | AG15: =IF(B15="","",SQRT(R15^2+S15^2))
... A804: 801 | B804: =IF(A804<='入力・概要'!$B$40,10^(LOG10('入力・概要'!$B$38)+(A804-1)*(LOG10('入力・概要'!$B$39)-LOG10('入力・概要'!$B$38))/('入力・概要'!$B$40-1)),"") | C804: =IF(B804="","",2*PI()*B804) | D804: =IF(B804="","",ATANH(MIN(0.999999,'入力・概要'!$E$20/'入力・概要'!$E$9))+'入力・概要'!$B$20*SQRT(B804/1E6)+E804*'入力・概要'!$B$15/2) | E804: =IF(B804="","",C804*('入力・概要'!$E$11*1E-9)) | F804: =IF(B804="","",SINH(2*D804)/(COSH(2*D804)+COS(2*E804))) | G804: =IF(B804="","",SIN(2*E804)/(COSH(2*D804)+COS(2*E804))) | H804: =IF(B804="","",ATANH(MIN(0.999999,'入力・概要'!$E$21/'入力・概要'!$E$15))+'入力・概要'!$B$21*SQRT(B804/1E6)+I804*'入力・概要'!$B$16/2) | I804: =IF(B804="","",C804*('入力・概要'!$E$17*1E-9)) | J804: =IF(B804="","",SINH(2*H804)/(COSH(2*H804)+COS(2*I804))) | K804: =IF(B804="","",SIN(2*I804)/(COSH(2*H804)+COS(2*I804))) | L804: =IF(B804="","",'入力・概要'!$B$25) | M804: =IF(B804="","",C804*'入力・概要'!$B$26*1E-9-1/(C804*'入力・概要'!$B$24*1E-6)) | N804: =IF(B804="","",'入力・概要'!$B$28) | O804: =IF(B804="","",C804*'入力・概要'!$B$29*1E-9-1/(C804*'入力・概要'!$B$27*1E-6)) | P804: =IF(B804="","",((L804*N804-M804*O804)*(L804+N804)+(L804*O804+M804*N804)*(M804+O804))/((L804+N804)^2+(M804+O804)^2)) | Q804: =IF(B804="","",((L804*O804+M804*N804)*(L804+N804)-(L804*N804-M804*O804)*(M804+O804))/((L804+N804)^2+(M804+O804)^2)) | R804: =IF(B804="","",'入力・概要'!$E$15*J804) | S804: =IF(B804="","",'入力・概要'!$E$15*K804) | T804: =IF(B804="","",P804+R804) | U804: =IF(B804="","",Q804+S804) | V804: =IF(B804="","",T804+'入力・概要'!$E$9*F804) | W804: =IF(B804="","",U804+'入力・概要'!$E$9*G804) | X804: =IF(B804="","",'入力・概要'!$E$9+T804*F804-U804*G804) | Y804: =IF(B804="","",T804*G804+U804*F804) | Z804: =IF(B804="","",'入力・概要'!$E$9*(V804*X804+W804*Y804)/(X804^2+Y804^2)+'入力・概要'!$B$36) | AA804: =IF(B804="","",'入力・概要'!$E$9*(W804*X804-V804*Y804)/(X804^2+Y804^2)+C804*'入力・概要'!$B$37*1E-9) | AB804: =IF(B804="","",SQRT(Z804^2+AA804^2)) | AC804: =IF(B804="","",IF(Z804>0,DEGREES(ATAN(AA804/Z804)),IF(Z804<0,IF(AA804>=0,DEGREES(ATAN(AA804/Z804))+180,DEGREES(ATAN(AA804/Z804))-180),IF(AA804>0,90,IF(AA804<0,-90,0))))) | AD804: =IF(B804="","",LOG10(B804)) | AE804: =IF(AB804="","",LOG10(MAX(AB804,1E-12))) | AF804: =IF(B804="","",SQRT(P804^2+Q804^2)) | AG804: =IF(B804="","",SQRT(R804^2+S804^2))

Sheet 実測比較_差動
A1: 実測比較：差動モード
A2: A～C列へ周波数[Hz]・実測|Z|[Ω]・実測位相[deg]を貼り付けます。最も近いモデル周波数を参照します。
A4: 周波数 [Hz] | B4: 実測 |Z| [Ω] | C4: 実測位相 [deg] | D4: モデル |Z| [Ω] | E4: モデル位相 [deg] | F4: 振幅誤差 [%] | G4: 位相誤差 [deg] | H4: log10(f) | I4: log10(実測) | J4: log10(モデル) | K4: モデル行 | L4: モデル周波数 | M4: 判定
D5: =IF(K5="","",INDEX('差動モデル'!$R:$R,K5)) | E5: =IF(K5="","",INDEX('差動モデル'!$S:$S,K5)) | F5: =IF(OR(A5="",B5=""),"",100*(D5-B5)/MAX(B5,1E-12)) | G5: =IF(OR(A5="",C5=""),"",E5-C5) | H5: =IF(A5="","",LOG10(A5)) | I5: =IF(B5="","",LOG10(MAX(B5,1E-12))) | J5: =IF(D5="","",LOG10(MAX(D5,1E-12))) | K5: =IF(A5="","",ROUND(1+(LOG10(A5)-LOG10('入力・概要'!$B$38))*('入力・概要'!$B$40-1)/(LOG10('入力・概要'!$B$39)-LOG10('入力・概要'!$B$38)),0)+3) | L5: =IF(K5="","",INDEX('差動モデル'!$B:$B,K5)) | M5: =IF(A5="","",IF(ABS(L5/A5-1)<0.01,"周波数差<1%","周波数差あり"))
D6: =IF(K6="","",INDEX('差動モデル'!$R:$R,K6)) | E6: =IF(K6="","",INDEX('差動モデル'!$S:$S,K6)) | F6: =IF(OR(A6="",B6=""),"",100*(D6-B6)/MAX(B6,1E-12)) | G6: =IF(OR(A6="",C6=""),"",E6-C6) | H6: =IF(A6="","",LOG10(A6)) | I6: =IF(B6="","",LOG10(MAX(B6,1E-12))) | J6: =IF(D6="","",LOG10(MAX(D6,1E-12))) | K6: =IF(A6="","",ROUND(1+(LOG10(A6)-LOG10('入力・概要'!$B$38))*('入力・概要'!$B$40-1)/(LOG10('入力・概要'!$B$39)-LOG10('入力・概要'!$B$38)),0)+3) | L6: =IF(K6="","",INDEX('差動モデル'!$B:$B,K6)) | M6: =IF(A6="","",IF(ABS(L6/A6-1)<0.01,"周波数差<1%","周波数差あり"))
D7: =IF(K7="","",INDEX('差動モデル'!$R:$R,K7)) | E7: =IF(K7="","",INDEX('差動モデル'!$S:$S,K7)) | F7: =IF(OR(A7="",B7=""),"",100*(D7-B7)/MAX(B7,1E-12)) | G7: =IF(OR(A7="",C7=""),"",E7-C7) | H7: =IF(A7="","",LOG10(A7)) | I7: =IF(B7="","",LOG10(MAX(B7,1E-12))) | J7: =IF(D7="","",LOG10(MAX(D7,1E-12))) | K7: =IF(A7="","",ROUND(1+(LOG10(A7)-LOG10('入力・概要'!$B$38))*('入力・概要'!$B$40-1)/(LOG10('入力・概要'!$B$39)-LOG10('入力・概要'!$B$38)),0)+3) | L7: =IF(K7="","",INDEX('差動モデル'!$B:$B,K7)) | M7: =IF(A7="","",IF(ABS(L7/A7-1)<0.01,"周波数差<1%","周波数差あり"))
D8: =IF(K8="","",INDEX('差動モデル'!$R:$R,K8)) | E8: =IF(K8="","",INDEX('差動モデル'!$S:$S,K8)) | F8: =IF(OR(A8="",B8=""),"",100*(D8-B8)/MAX(B8,1E-12)) | G8: =IF(OR(A8="",C8=""),"",E8-C8) | H8: =IF(A8="","",LOG10(A8)) | I8: =IF(B8="","",LOG10(MAX(B8,1E-12))) | J8: =IF(D8="","",LOG10(MAX(D8,1E-12))) | K8: =IF(A8="","",ROUND(1+(LOG10(A8)-LOG10('入力・概要'!$B$38))*('入力・概要'!$B$40-1)/(LOG10('入力・概要'!$B$39)-LOG10('入力・概要'!$B$38)),0)+3) | L8: =IF(K8="","",INDEX('差動モデル'!$B:$B,K8)) | M8: =IF(A8="","",IF(ABS(L8/A8-1)<0.01,"周波数差<1%","周波数差あり"))
D9: =IF(K9="","",INDEX('差動モデル'!$R:$R,K9)) | E9: =IF(K9="","",INDEX('差動モデル'!$S:$S,K9)) | F9: =IF(OR(A9="",B9=""),"",100*(D9-B9)/MAX(B9,1E-12)) | G9: =IF(OR(A9="",C9=""),"",E9-C9) | H9: =IF(A9="","",LOG10(A9)) | I9: =IF(B9="","",LOG10(MAX(B9,1E-12))) | J9: =IF(D9="","",LOG10(MAX(D9,1E-12))) | K9: =IF(A9="","",ROUND(1+(LOG10(A9)-LOG10('入力・概要'!$B$38))*('入力・概要'!$B$40-1)/(LOG10('入力・概要'!$B$39)-LOG10('入力・概要'!$B$38)),0)+3) | L9: =IF(K9="","",INDEX('差動モデル'!$B:$B,K9)) | M9: =IF(A9="","",IF(ABS(L9/A9-1)<0.01,"周波数差<1%","周波数差あり"))
D10: =IF(K10="","",INDEX('差動モデル'!$R:$R,K10)) | E10: =IF(K10="","",INDEX('差動モデル'!$S:$S,K10)) | F10: =IF(OR(A10="",B10=""),"",100*(D10-B10)/MAX(B10,1E-12)) | G10: =IF(OR(A10="",C10=""),"",E10-C10) | H10: =IF(A10="","",LOG10(A10)) | I10: =IF(B10="","",LOG10(MAX(B10,1E-12))) | J10: =IF(D10="","",LOG10(MAX(D10,1E-12))) | K10: =IF(A10="","",ROUND(1+(LOG10(A10)-LOG10('入力・概要'!$B$38))*('入力・概要'!$B$40-1)/(LOG10('入力・概要'!$B$39)-LOG10('入力・概要'!$B$38)),0)+3) | L10: =IF(K10="","",INDEX('差動モデル'!$B:$B,K10)) | M10: =IF(A10="","",IF(ABS(L10/A10-1)<0.01,"周波数差<1%","周波数差あり"))
D11: =IF(K11="","",INDEX('差動モデル'!$R:$R,K11)) | E11: =IF(K11="","",INDEX('差動モデル'!$S:$S,K11)) | F11: =IF(OR(A11="",B11=""),"",100*(D11-B11)/MAX(B11,1E-12)) | G11: =IF(OR(A11="",C11=""),"",E11-C11) | H11: =IF(A11="","",LOG10(A11)) | I11: =IF(B11="","",LOG10(MAX(B11,1E-12))) | J11: =IF(D11="","",LOG10(MAX(D11,1E-12))) | K11: =IF(A11="","",ROUND(1+(LOG10(A11)-LOG10('入力・概要'!$B$38))*('入力・概要'!$B$40-1)/(LOG10('入力・概要'!$B$39)-LOG10('入力・概要'!$B$38)),0)+3) | L11: =IF(K11="","",INDEX('差動モデル'!$B:$B,K11)) | M11: =IF(A11="","",IF(ABS(L11/A11-1)<0.01,"周波数差<1%","周波数差あり"))
D12: =IF(K12="","",INDEX('差動モデル'!$R:$R,K12)) | E12: =IF(K12="","",INDEX('差動モデル'!$S:$S,K12)) | F12: =IF(OR(A12="",B12=""),"",100*(D12-B12)/MAX(B12,1E-12)) | G12: =IF(OR(A12="",C12=""),"",E12-C12) | H12: =IF(A12="","",LOG10(A12)) | I12: =IF(B12="","",LOG10(MAX(B12,1E-12))) | J12: =IF(D12="","",LOG10(MAX(D12,1E-12))) | K12: =IF(A12="","",ROUND(1+(LOG10(A12)-LOG10('入力・概要'!$B$38))*('入力・概要'!$B$40-1)/(LOG10('入力・概要'!$B$39)-LOG10('入力・概要'!$B$38)),0)+3) | L12: =IF(K12="","",INDEX('差動モデル'!$B:$B,K12)) | M12: =IF(A12="","",IF(ABS(L12/A12-1)<0.01,"周波数差<1%","周波数差あり"))
D13: =IF(K13="","",INDEX('差動モデル'!$R:$R,K13)) | E13: =IF(K13="","",INDEX('差動モデル'!$S:$S,K13)) | F13: =IF(OR(A13="",B13=""),"",100*(D13-B13)/MAX(B13,1E-12)) | G13: =IF(OR(A13="",C13=""),"",E13-C13) | H13: =IF(A13="","",LOG10(A13)) | I13: =IF(B13="","",LOG10(MAX(B13,1E-12))) | J13: =IF(D13="","",LOG10(MAX(D13,1E-12))) | K13: =IF(A13="","",ROUND(1+(LOG10(A13)-LOG10('入力・概要'!$B$38))*('入力・概要'!$B$40-1)/(LOG10('入力・概要'!$B$39)-LOG10('入力・概要'!$B$38)),0)+3) | L13: =IF(K13="","",INDEX('差動モデル'!$B:$B,K13)) | M13: =IF(A13="","",IF(ABS(L13/A13-1)<0.01,"周波数差<1%","周波数差あり"))
D14: =IF(K14="","",INDEX('差動モデル'!$R:$R,K14)) | E14: =IF(K14="","",INDEX('差動モデル'!$S:$S,K14)) | F14: =IF(OR(A14="",B14=""),"",100*(D14-B14)/MAX(B14,1E-12)) | G14: =IF(OR(A14="",C14=""),"",E14-C14) | H14: =IF(A14="","",LOG10(A14)) | I14: =IF(B14="","",LOG10(MAX(B14,1E-12))) | J14: =IF(D14="","",LOG10(MAX(D14,1E-12))) | K14: =IF(A14="","",ROUND(1+(LOG10(A14)-LOG10('入力・概要'!$B$38))*('入力・概要'!$B$40-1)/(LOG10('入力・概要'!$B$39)-LOG10('入力・概要'!$B$38)),0)+3) | L14: =IF(K14="","",INDEX('差動モデル'!$B:$B,K14)) | M14: =IF(A14="","",IF(ABS(L14/A14-1)<0.01,"周波数差<1%","周波数差あり"))
D15: =IF(K15="","",INDEX('差動モデル'!$R:$R,K15)) | E15: =IF(K15="","",INDEX('差動モデル'!$S:$S,K15)) | F15: =IF(OR(A15="",B15=""),"",100*(D15-B15)/MAX(B15,1E-12)) | G15: =IF(OR(A15="",C15=""),"",E15-C15) | H15: =IF(A15="","",LOG10(A15)) | I15: =IF(B15="","",LOG10(MAX(B15,1E-12))) | J15: =IF(D15="","",LOG10(MAX(D15,1E-12))) | K15: =IF(A15="","",ROUND(1+(LOG10(A15)-LOG10('入力・概要'!$B$38))*('入力・概要'!$B$40-1)/(LOG10('入力・概要'!$B$39)-LOG10('入力・概要'!$B$38)),0)+3) | L15: =IF(K15="","",INDEX('差動モデル'!$B:$B,K15)) | M15: =IF(A15="","",IF(ABS(L15/A15-1)<0.01,"周波数差<1%","周波数差あり"))
D16: =IF(K16="","",INDEX('差動モデル'!$R:$R,K16)) | E16: =IF(K16="","",INDEX('差動モデル'!$S:$S,K16)) | F16: =IF(OR(A16="",B16=""),"",100*(D16-B16)/MAX(B16,1E-12)) | G16: =IF(OR(A16="",C16=""),"",E16-C16) | H16: =IF(A16="","",LOG10(A16)) | I16: =IF(B16="","",LOG10(MAX(B16,1E-12))) | J16: =IF(D16="","",LOG10(MAX(D16,1E-12))) | K16: =IF(A16="","",ROUND(1+(LOG10(A16)-LOG10('入力・概要'!$B$38))*('入力・概要'!$B$40-1)/(LOG10('入力・概要'!$B$39)-LOG10('入力・概要'!$B$38)),0)+3) | L16: =IF(K16="","",INDEX('差動モデル'!$B:$B,K16)) | M16: =IF(A16="","",IF(ABS(L16/A16-1)<0.01,"周波数差<1%","周波数差あり"))
... D1004: =IF(K1004="","",INDEX('差動モデル'!$R:$R,K1004)) | E1004: =IF(K1004="","",INDEX('差動モデル'!$S:$S,K1004)) | F1004: =IF(OR(A1004="",B1004=""),"",100*(D1004-B1004)/MAX(B1004,1E-12)) | G1004: =IF(OR(A1004="",C1004=""),"",E1004-C1004) | H1004: =IF(A1004="","",LOG10(A1004)) | I1004: =IF(B1004="","",LOG10(MAX(B1004,1E-12))) | J1004: =IF(D1004="","",LOG10(MAX(D1004,1E-12))) | K1004: =IF(A1004="","",ROUND(1+(LOG10(A1004)-LOG10('入力・概要'!$B$38))*('入力・概要'!$B$40-1)/(LOG10('入力・概要'!$B$39)-LOG10('入力・概要'!$B$38)),0)+3) | L1004: =IF(K1004="","",INDEX('差動モデル'!$B:$B,K1004)) | M1004: =IF(A1004="","",IF(ABS(L1004/A1004-1)<0.01,"周波数差<1%","周波数差あり"))

Sheet 実測比較_同相
A1: 実測比較：同相3導体モデル
A2: A～C列へ周波数[Hz]・実測|Z|[Ω]・実測位相[deg]を貼り付けます。最も近いモデル周波数を参照します。
A4: 周波数 [Hz] | B4: 実測 |Z| [Ω] | C4: 実測位相 [deg] | D4: モデル |Z| [Ω] | E4: モデル位相 [deg] | F4: 振幅誤差 [%] | G4: 位相誤差 [deg] | H4: log10(f) | I4: log10(実測) | J4: log10(モデル) | K4: モデル行 | L4: モデル周波数 | M4: 判定
D5: =IF(K5="","",INDEX('同相3導体'!$AB:$AB,K5)) | E5: =IF(K5="","",INDEX('同相3導体'!$AC:$AC,K5)) | F5: =IF(OR(A5="",B5=""),"",100*(D5-B5)/MAX(B5,1E-12)) | G5: =IF(OR(A5="",C5=""),"",E5-C5) | H5: =IF(A5="","",LOG10(A5)) | I5: =IF(B5="","",LOG10(MAX(B5,1E-12))) | J5: =IF(D5="","",LOG10(MAX(D5,1E-12))) | K5: =IF(A5="","",ROUND(1+(LOG10(A5)-LOG10('入力・概要'!$B$38))*('入力・概要'!$B$40-1)/(LOG10('入力・概要'!$B$39)-LOG10('入力・概要'!$B$38)),0)+3) | L5: =IF(K5="","",INDEX('同相3導体'!$B:$B,K5)) | M5: =IF(A5="","",IF(ABS(L5/A5-1)<0.01,"周波数差<1%","周波数差あり"))
D6: =IF(K6="","",INDEX('同相3導体'!$AB:$AB,K6)) | E6: =IF(K6="","",INDEX('同相3導体'!$AC:$AC,K6)) | F6: =IF(OR(A6="",B6=""),"",100*(D6-B6)/MAX(B6,1E-12)) | G6: =IF(OR(A6="",C6=""),"",E6-C6) | H6: =IF(A6="","",LOG10(A6)) | I6: =IF(B6="","",LOG10(MAX(B6,1E-12))) | J6: =IF(D6="","",LOG10(MAX(D6,1E-12))) | K6: =IF(A6="","",ROUND(1+(LOG10(A6)-LOG10('入力・概要'!$B$38))*('入力・概要'!$B$40-1)/(LOG10('入力・概要'!$B$39)-LOG10('入力・概要'!$B$38)),0)+3) | L6: =IF(K6="","",INDEX('同相3導体'!$B:$B,K6)) | M6: =IF(A6="","",IF(ABS(L6/A6-1)<0.01,"周波数差<1%","周波数差あり"))
D7: =IF(K7="","",INDEX('同相3導体'!$AB:$AB,K7)) | E7: =IF(K7="","",INDEX('同相3導体'!$AC:$AC,K7)) | F7: =IF(OR(A7="",B7=""),"",100*(D7-B7)/MAX(B7,1E-12)) | G7: =IF(OR(A7="",C7=""),"",E7-C7) | H7: =IF(A7="","",LOG10(A7)) | I7: =IF(B7="","",LOG10(MAX(B7,1E-12))) | J7: =IF(D7="","",LOG10(MAX(D7,1E-12))) | K7: =IF(A7="","",ROUND(1+(LOG10(A7)-LOG10('入力・概要'!$B$38))*('入力・概要'!$B$40-1)/(LOG10('入力・概要'!$B$39)-LOG10('入力・概要'!$B$38)),0)+3) | L7: =IF(K7="","",INDEX('同相3導体'!$B:$B,K7)) | M7: =IF(A7="","",IF(ABS(L7/A7-1)<0.01,"周波数差<1%","周波数差あり"))
D8: =IF(K8="","",INDEX('同相3導体'!$AB:$AB,K8)) | E8: =IF(K8="","",INDEX('同相3導体'!$AC:$AC,K8)) | F8: =IF(OR(A8="",B8=""),"",100*(D8-B8)/MAX(B8,1E-12)) | G8: =IF(OR(A8="",C8=""),"",E8-C8) | H8: =IF(A8="","",LOG10(A8)) | I8: =IF(B8="","",LOG10(MAX(B8,1E-12))) | J8: =IF(D8="","",LOG10(MAX(D8,1E-12))) | K8: =IF(A8="","",ROUND(1+(LOG10(A8)-LOG10('入力・概要'!$B$38))*('入力・概要'!$B$40-1)/(LOG10('入力・概要'!$B$39)-LOG10('入力・概要'!$B$38)),0)+3) | L8: =IF(K8="","",INDEX('同相3導体'!$B:$B,K8)) | M8: =IF(A8="","",IF(ABS(L8/A8-1)<0.01,"周波数差<1%","周波数差あり"))
D9: =IF(K9="","",INDEX('同相3導体'!$AB:$AB,K9)) | E9: =IF(K9="","",INDEX('同相3導体'!$AC:$AC,K9)) | F9: =IF(OR(A9="",B9=""),"",100*(D9-B9)/MAX(B9,1E-12)) | G9: =IF(OR(A9="",C9=""),"",E9-C9) | H9: =IF(A9="","",LOG10(A9)) | I9: =IF(B9="","",LOG10(MAX(B9,1E-12))) | J9: =IF(D9="","",LOG10(MAX(D9,1E-12))) | K9: =IF(A9="","",ROUND(1+(LOG10(A9)-LOG10('入力・概要'!$B$38))*('入力・概要'!$B$40-1)/(LOG10('入力・概要'!$B$39)-LOG10('入力・概要'!$B$38)),0)+3) | L9: =IF(K9="","",INDEX('同相3導体'!$B:$B,K9)) | M9: =IF(A9="","",IF(ABS(L9/A9-1)<0.01,"周波数差<1%","周波数差あり"))
D10: =IF(K10="","",INDEX('同相3導体'!$AB:$AB,K10)) | E10: =IF(K10="","",INDEX('同相3導体'!$AC:$AC,K10)) | F10: =IF(OR(A10="",B10=""),"",100*(D10-B10)/MAX(B10,1E-12)) | G10: =IF(OR(A10="",C10=""),"",E10-C10) | H10: =IF(A10="","",LOG10(A10)) | I10: =IF(B10="","",LOG10(MAX(B10,1E-12))) | J10: =IF(D10="","",LOG10(MAX(D10,1E-12))) | K10: =IF(A10="","",ROUND(1+(LOG10(A10)-LOG10('入力・概要'!$B$38))*('入力・概要'!$B$40-1)/(LOG10('入力・概要'!$B$39)-LOG10('入力・概要'!$B$38)),0)+3) | L10: =IF(K10="","",INDEX('同相3導体'!$B:$B,K10)) | M10: =IF(A10="","",IF(ABS(L10/A10-1)<0.01,"周波数差<1%","周波数差あり"))
D11: =IF(K11="","",INDEX('同相3導体'!$AB:$AB,K11)) | E11: =IF(K11="","",INDEX('同相3導体'!$AC:$AC,K11)) | F11: =IF(OR(A11="",B11=""),"",100*(D11-B11)/MAX(B11,1E-12)) | G11: =IF(OR(A11="",C11=""),"",E11-C11) | H11: =IF(A11="","",LOG10(A11)) | I11: =IF(B11="","",LOG10(MAX(B11,1E-12))) | J11: =IF(D11="","",LOG10(MAX(D11,1E-12))) | K11: =IF(A11="","",ROUND(1+(LOG10(A11)-LOG10('入力・概要'!$B$38))*('入力・概要'!$B$40-1)/(LOG10('入力・概要'!$B$39)-LOG10('入力・概要'!$B$38)),0)+3) | L11: =IF(K11="","",INDEX('同相3導体'!$B:$B,K11)) | M11: =IF(A11="","",IF(ABS(L11/A11-1)<0.01,"周波数差<1%","周波数差あり"))
D12: =IF(K12="","",INDEX('同相3導体'!$AB:$AB,K12)) | E12: =IF(K12="","",INDEX('同相3導体'!$AC:$AC,K12)) | F12: =IF(OR(A12="",B12=""),"",100*(D12-B12)/MAX(B12,1E-12)) | G12: =IF(OR(A12="",C12=""),"",E12-C12) | H12: =IF(A12="","",LOG10(A12)) | I12: =IF(B12="","",LOG10(MAX(B12,1E-12))) | J12: =IF(D12="","",LOG10(MAX(D12,1E-12))) | K12: =IF(A12="","",ROUND(1+(LOG10(A12)-LOG10('入力・概要'!$B$38))*('入力・概要'!$B$40-1)/(LOG10('入力・概要'!$B$39)-LOG10('入力・概要'!$B$38)),0)+3) | L12: =IF(K12="","",INDEX('同相3導体'!$B:$B,K12)) | M12: =IF(A12="","",IF(ABS(L12/A12-1)<0.01,"周波数差<1%","周波数差あり"))
D13: =IF(K13="","",INDEX('同相3導体'!$AB:$AB,K13)) | E13: =IF(K13="","",INDEX('同相3導体'!$AC:$AC,K13)) | F13: =IF(OR(A13="",B13=""),"",100*(D13-B13)/MAX(B13,1E-12)) | G13: =IF(OR(A13="",C13=""),"",E13-C13) | H13: =IF(A13="","",LOG10(A13)) | I13: =IF(B13="","",LOG10(MAX(B13,1E-12))) | J13: =IF(D13="","",LOG10(MAX(D13,1E-12))) | K13: =IF(A13="","",ROUND(1+(LOG10(A13)-LOG10('入力・概要'!$B$38))*('入力・概要'!$B$40-1)/(LOG10('入力・概要'!$B$39)-LOG10('入力・概要'!$B$38)),0)+3) | L13: =IF(K13="","",INDEX('同相3導体'!$B:$B,K13)) | M13: =IF(A13="","",IF(ABS(L13/A13-1)<0.01,"周波数差<1%","周波数差あり"))
