Workbook

Sheet 入力条件
A1: DDモータ計算シート（Kollmorgen白書準拠・SPWM/SVPWM切替対応） | B1: DDモータ計算シート（Kollmorgen白書準拠・SPWM/SVPWM切替対応） | C1: DDモータ計算シート（Kollmorgen白書準拠・SPWM/SVPWM切替対応） | D1: DDモータ計算シート（Kollmorgen白書準拠・SPWM/SVPWM切替対応）
D2: 黄色セル=定義照合/主要計算確認対象
A3: 入力項目 | B3: 値 | C3: 単位 | D3: 備考
A4: 線間巻線抵抗 R_ll | B4: 6.26 | C4: Ω | D4: Kollmorgen表記・line-line
A5: 線間インダクタンス L_ll | B5: 0.023 | C5: H | D5: Kollmorgen表記・line-line
A6: トルク定数 Kt | B6: 8.87 | C6: Nm/Arms | D6: 正弦波通電・Y結線では線RMS=相RMS
A7: 起動時電流 I_start | B7: 6.8094701 | C7: Arms | D7: Y結線では線RMS=相RMS
A8: 定常時電流 I_ss | B8: 3.4047351 | C8: Arms | D8: Y結線では線RMS=相RMS
A9: 定常時回転速度 n_ss | B9: 10 | C9: rpm
A10: 加速時間 t_acc | B10: 1 | C10: s | D10: 0 rpm → 10 rpm
A11: 極ペア数 p | B11: 32 | C11: -
A12: Ke上書き Ke_ll,rms（任意） | C12: Vrms/krpm | D12: 空欄ならKtから推定（Kollmorgen白書: line-line rms）
A13: インバータ設計設定
A14: 変調方式 | B14: SVPWM | C14: - | D14: ここを SPWM / SVPWM で切替
A15: 線間基本波rms / Vdc 係数 k_mod | B15: =IF(B14="SPWM",0.612372435695794,1/SQRT(2)) -> 0.70710678 | C15: - | D15: SPWM: 0.612, SVPWM: 0.707
A16: 相基本波peak / Vdc 係数 k_ph,max | B16: =IF(B14="SPWM",0.5,1/SQRT(3)) -> 0.57735027 | C16: - | D16: SPWM: 0.500, SVPWM: 0.577
A17: DCバス換算の採用式 | B17: Vdc = Vll,rms / k_mod = Vph,peak / k_ph,max | C17: - | D17: 相peak基準版と線間rms基準版は同値
A19: 計算前提 | B19: 内容
A20: モータモデル | B20: 3相PMSM相当
A21: 制御前提 | B21: 正弦波電流、id = 0制御
A22: 発熱の扱い | B22: 巻線の銅損を発熱量として計算
A23: 効率の扱い | B23: 機械出力 / (機械出力 + 銅損)
A25: 回生制動（停止時）入力
A26: 慣性モーメント J | B26: 3 | C26: kg·m² | D26: 停止前の等価慣性モーメント
A27: 減速時間 t_dec | B27: 1 | C27: s | D27: 10 rpm → 0 rpm を1 sで停止
A28: DCバス容量 C_dc | B28: 0.01 | C28: F | D28: 回生電圧上昇予測に必要（初期値: 10 mF、適宜変更）
A29: 回生開始DCバス電圧 Vdc_init | B29: =結果概要!B12 -> 61.831209 | C29: V | D29: 初期値は推奨最小DCバス。実機のDCバス公称値へ上書き可
A30: 回生計算の前提 | B30: 運動エネルギー→DCコンデンサ。理想版と銅損考慮版を併記 | C30: - | D30: 理想版: 全慣性エネルギーがC_dcへ流入 / 実効版: 銅損を差し引く
A31: 起動過渡（L·di/dt）入力
A32: 起動電流立上り時間 t_I,start | B32: 10 | C32: ms | D32: 0→I_start までの目標時間
A33: 電流ループ帯域 f_ci（参考） | B33: 1000 | C33: Hz | D33: small-signal補正余裕の参考
A34: 電流誤差割合 ε_ci（参考） | B34: 0.1 | C34: - | D34: 例: 0.1 = 10%
A35: 起動L·di/dtモデル | B35: 立上り時間基準を主計算 / 帯域基準は参考 | C35: - | D35: KollmorgenのL-Rモデルに寄せた簡易近似

Sheet 計算詳細
A1: 計算詳細（Kollmorgen白書準拠・Y結線・SPWM/SVPWM切替対応） | B1: 計算詳細（Kollmorgen白書準拠・Y結線・SPWM/SVPWM切替対応） | C1: 計算詳細（Kollmorgen白書準拠・Y結線・SPWM/SVPWM切替対応） | D1: 計算詳細（Kollmorgen白書準拠・Y結線・SPWM/SVPWM切替対応） | E1: 計算詳細（Kollmorgen白書準拠・Y結線・SPWM/SVPWM切替対応） | F1: 計算詳細（Kollmorgen白書準拠・Y結線・SPWM/SVPWM切替対応） | G1: 計算詳細（Kollmorgen白書準拠・Y結線・SPWM/SVPWM切替対応） | H1: 計算詳細（Kollmorgen白書準拠・Y結線・SPWM/SVPWM切替対応）
H2: 黄色セル=定義照合/主要計算確認対象
A3: 項目 | B3: 一般式 | C3: Excel式（文字列） | D3: 計算結果 | E3: 単位 | F3: 式の説明 | G3: 補足 | H3: 導出メモ
A4: 起動時電流ピーク値 I_start,peak | B4: √2 × I_start | C4: SQRT(2)×'入力条件'!B7 | D4: =SQRT(2)*入力条件!B7 -> 9.630045 | E4: Apeak | F4: RMS電流をピーク値へ変換。 | G4: dq式で使用 | H4: I_peak=√2 I_rms。
A5: 定常時電流ピーク値 I_ss,peak | B5: √2 × I_ss | C5: SQRT(2)×'入力条件'!B8 | D5: =SQRT(2)*入力条件!B8 -> 4.8150225 | E5: Apeak | F5: RMS電流をピーク値へ変換。 | H5: 同上。
A6: 定常時機械角速度 ω_m,ss | B6: n_ss × 2π / 60 | C6: '入力条件'!B9×2π/60 | D6: =入力条件!B9*2*PI()/60 -> 1.0471976 | E6: rad/s | F6: 回転速度[rpm]を機械角速度へ変換。 | H6: ω_m=n×2π/60。
A7: 定常時電気角速度 ω_e,ss | B7: p × ω_m,ss | C7: '入力条件'!B11×D6 | D7: =入力条件!B11*D6 -> 33.510322 | E7: rad/s | F7: d軸電圧の誘導項計算に使用。 | H7: ω_e=pω_m。
A8: Ke推定（線間rms / 機械rad/s） | B8: Kt / √2 | C8: ('入力条件'!B6)/SQRT(2) | D8: =入力条件!B6/SQRT(2) -> 6.2720371 | E8: V/(rad/s) | F8: Kollmorgen白書: line-line crest Ke = Kt なので、rms は /√2。 | G8: 正弦波・Y結線前提 | H8: Ke_ll,crest[V/(rad/s)] = Kt[Nm/Arms], したがって Ke_ll,rms = Kt/√2。
A9: Ke推定（線間rms / krpm） | B9: Ke_rms × 1000×2π/60 | C9: D8×(1000×2π/60) | D9: =D8*(1000*2*PI()/60) -> 656.80619 | E9: Vrms/krpm | F9: Kollmorgenカタログ表記へ換算。 | H9: 1000 rpm = 1000×2π/60 rad/s。
A10: Ke有効（線間rms / krpm） | B10: IF(override, override, Ke_est) | C10: IF('入力条件'!B12="",D9,'入力条件'!B12) | D10: =IF(入力条件!B12="",D9,入力条件!B12) -> 656.80619 | E10: Vrms/krpm | F10: Ke上書き入力があれば優先。 | H10: 空欄ならKtからの推定値。
A11: Ke有効（線間rms / 機械rad/s） | B11: Ke_active / (1000×2π/60) | C11: D10/(1000×2π/60) | D11: =D10/(1000*2*PI()/60) -> 6.2720371 | E11: V/(rad/s) | F11: 計算に使う有効Ke（line-line rms）。 | H11: SVPWM最低DCバス計算で使用。
A12: 定常時逆起電力 E_ll,rms,ss | B12: Ke_active × ω_m,ss | C12: D11×D6 | D12: =D11*D6 -> 6.5680619 | E12: Vrms | F12: 線間rms基準の逆起電力。 | H12: Kollmorgenカタログの Ke_ll,rms と同じ基準。
A13: 定常時逆起電力 E_ph,peak,ss | B13: E_ll,rms × √(2/3) | C13: D12×SQRT(2/3) | D13: =D12*SQRT(2/3) -> 5.3628001 | E13: Vpeak | F13: 相peak基準へ換算。 | G13: dq式のq軸で使用 | H13: Vll,rms=√(3/2)Vph,peak。
A14: 起動時 q軸電圧 v_q,start | B14: R_phase × I_start,peak | C14: ('入力条件'!B4/2)×D4 | D14: =(入力条件!B4/2)*D4 -> 30.142041 | E14: Vpeak | F14: 起動瞬間は逆起電力0。 | G14: R_phase=R_ll/2 | H14: Y結線の相抵抗を使用。
A15: 起動時必要相電圧 V_ph,peak,start | B15: |v_q,start| | C15: ABS(D14) | D15: =ABS(D14) -> 30.142041 | E15: Vpeak | F15: 相peak基準の必要電圧。 | H15: 起動時は d軸成分0。
A16: 起動時必要線間電圧 V_ll,rms,start | B16: √(3/2) × V_ph,peak,start | C16: SQRT(3/2)×D15 | D16: =SQRT(3/2)*D15 -> 36.91631 | E16: Vrms | F16: 線間rms基準へ換算。 | H16: Vll,rms=√(3/2)Vph,peak。
A17: 起動時必要DCバス（相peak基準） | B17: V_ph,peak,start / k_ph,max | C17: D15/'入力条件'!B16 | D17: =D15/入力条件!B16 -> 52.207546 | E17: Vdc | F17: 相peak基準でのDCバス式。 | G17: SPWM/SVPWM切替対応 | H17: SVPWMでは Vph,peak,max=Vdc/√3。
A18: 起動時必要DCバス（線間rms基準） | B18: V_ll,rms,start / k_mod | C18: D16/'入力条件'!B15 | D18: =D16/入力条件!B15 -> 52.207546 | E18: Vdc | F18: 線間rms基準でのDCバス式。 | G18: SPWM/SVPWM切替対応 | H18: SVPWMでは Vll,rms,max=0.707Vdc。
A20: 定常時 d軸電圧 v_d,ss | B20: -ω_e × L_phase × I_ss,peak | C20: -D7×('入力条件'!B5/2)×D5 | D20: =-D7*(入力条件!B5/2)*D5 -> -1.855559 | E20: Vpeak | F20: インダクタンスによる誘導項。 | G20: L_phase=L_ll/2 | H20: ω_e=pω_m。
A21: 定常時 q軸電圧 v_q,ss | B21: R_phase × I_ss,peak + E_ph,peak,ss | C21: ('入力条件'!B4/2)×D5 + D13 | D21: =(入力条件!B4/2)*D5 + D13 -> 20.433821 | E21: Vpeak | F21: 抵抗降下と逆起電力の和。 | H21: KollmorgenのKe_ll,rmsを相peakへ換算して使用。
A22: 定常時必要相電圧 V_ph,peak,ss | B22: √(v_d,ss² + v_q,ss²) | C22: SQRT(D20^2 + D21^2) | D22: =SQRT(D20^2 + D21^2) -> 20.517898 | E22: Vpeak | F22: 相peak基準の必要電圧。 | H22: dqベクトルの大きさ。
A23: 定常時必要線間電圧 V_ll,rms,ss | B23: √(3/2) × V_ph,peak,ss | C23: SQRT(3/2)×D22 | D23: =SQRT(3/2)*D22 -> 25.12919 | E23: Vrms | F23: 線間rms基準へ換算。
A24: 定常時必要DCバス（相peak基準） | B24: V_ph,peak,ss / k_ph,max | C24: D22/'入力条件'!B16 | D24: =D22/入力条件!B16 -> 35.538041 | E24: Vdc | F24: 相peak基準版。
A25: 定常時必要DCバス（線間rms基準） | B25: V_ll,rms,ss / k_mod | C25: D23/'入力条件'!B15 | D25: =D23/入力条件!B15 -> 35.538041 | E25: Vdc | F25: 線間rms基準版。
A27: 加速ワースト d軸電圧 v_d,acc | B27: -ω_e × L_phase × I_start,peak | C27: -D7×('入力条件'!B5/2)×D4 | D27: =-D7*(入力条件!B5/2)*D4 -> -3.7111179 | E27: Vpeak | F27: 起動電流一定のワースト条件。 | G27: L_phase=L_ll/2
A28: 加速ワースト q軸電圧 v_q,acc | B28: R_phase × I_start,peak + E_ph,peak,ss | C28: ('入力条件'!B4/2)×D4 + D13 | D28: =(入力条件!B4/2)*D4 + D13 -> 35.504841 | E28: Vpeak | F28: 起動電流一定のワースト条件。 | G28: R_phase=R_ll/2
A29: 加速ワースト必要相電圧 V_ph,peak,acc | B29: √(v_d,acc² + v_q,acc²) | C29: SQRT(D27^2 + D28^2) | D29: =SQRT(D27^2 + D28^2) -> 35.698265 | E29: Vpeak | F29: 起動区間全体の設計支配条件。
A30: 加速ワースト必要線間電圧 V_ll,rms,acc | B30: √(3/2) × V_ph,peak,acc | C30: SQRT(3/2)×D29 | D30: =SQRT(3/2)*D29 -> 43.721267 | E30: Vrms | F30: 線間rms基準へ換算。
A31: 加速ワースト必要DCバス（相peak基準） | B31: V_ph,peak,acc / k_ph,max | C31: D29/'入力条件'!B16 | D31: =D29/入力条件!B16 -> 61.831209 | E31: Vdc | F31: 相peak基準版。
A32: 加速ワースト必要DCバス（線間rms基準） | B32: V_ll,rms,acc / k_mod | C32: D30/'入力条件'!B15 | D32: =D30/入力条件!B15 -> 61.831209 | E32: Vdc | F32: 線間rms基準版。
A33: 定常時トルク T_ss | B33: Kt × I_ss | C33: '入力条件'!B6×'入力条件'!B8 | D33: =入力条件!B6*入力条件!B8 -> 30.2 | E33: Nm | F33: KtがNm/ArmsなのでRMS電流をそのまま掛ける。
A34: 定常時機械出力 P_out,ss | B34: T_ss × ω_m,ss | C34: D33×D6 | D34: =D33*D6 -> 31.625366 | E34: W | F34: 機械出力 = トルク × 機械角速度。
A35: 定常時銅損 P_cu,ss | B35: 3 × I_ss² × R_phase | C35: 3×('入力条件'!B8^2)×('入力条件'!B4/2) | D35: =3*(入力条件!B8^2)*(入力条件!B4/2) -> 108.85095 | E35: W | F35: 3相巻線のジュール損。 | G35: R_phase=R_ll/2 | H35: P_cu=3I_rms^2R_phase。
A36: 定常時電気入力 P_in,ss | B36: P_out,ss + P_cu,ss | C36: D34+D35 | D36: =D34+D35 -> 140.47632 | E36: W | F36: 銅損のみを考慮した簡易入力電力。
A37: 定常時効率 η_ss | B37: P_out,ss / P_in,ss | C37: D34/D36 | D37: =D34/D36 -> 0.22512952 | E37: - | F37: 銅損のみ考慮した簡易効率。
A38: 起動時銅損 P_cu,start | B38: 3 × I_start² × R_phase | C38: 3×('入力条件'!B7^2)×('入力条件'!B4/2) | D38: =3*(入力条件!B7^2)*(入力条件!B4/2) -> 435.40381 | E38: W | F38: 起動時の銅損。 | G38: R_phase=R_ll/2
A39: 加速中平均発熱 P_heat,avg | B39: P_cu,start | C39: D38 | D39: =D38 -> 435.40381 | E39: W | F39: 起動電流一定のため起動時銅損と同じ。
A40: 加速中発熱エネルギー Q_acc | B40: P_heat,avg × t_acc | C40: D39×'入力条件'!B10 | D40: =D39*入力条件!B10 -> 435.40381 | E40: J | F40: 加速中に発生する総熱量。
A41: 回生制動（停止時）の計算
A42: 回生開始機械角速度 ω_m,reg,start | B42: n_ss × 2π / 60 | C42: 入力条件!B9×2π/60 | D42: =入力条件!B9*2*PI()/60 -> 1.0471976 | E42: rad/s | F42: 停止直前の機械角速度。定常時回転速度から計算。 | G42: 停止前速度は定常時10 rpmを使用 | H42: 停止開始時の運動エネルギー計算の起点。
...

Sheet 結果概要
A1: 結果概要（Kollmorgen白書準拠） | B1: 結果概要（Kollmorgen白書準拠） | C1: 結果概要（Kollmorgen白書準拠） | D1: 結果概要（Kollmorgen白書準拠）
D2: 黄色セル=定義照合/主要計算確認対象
A3: 指標 | B3: 値 | C3: 単位 | D3: 説明
A4: 選択中の変調方式 | B4: =入力条件!B14 -> SVPWM | C4: - | D4: 入力条件シートの切替セルに連動
A5: 線間基本波rms / Vdc 係数 k_mod | B5: =入力条件!B15 -> 0.70710678 | C5: - | D5: SPWM:0.612 / SVPWM:0.707
A6: 相基本波peak / Vdc 係数 k_ph,max | B6: =入力条件!B16 -> 0.57735027 | C6: - | D6: SPWM:0.500 / SVPWM:0.577
A7: Ke推定（線間rms） | B7: =計算詳細!D9 -> 656.80619 | C7: Vrms/krpm | D7: Kollmorgen白書: Ktから推定した line-line rms 値
A8: Ke有効（線間rms） | B8: =計算詳細!D10 -> 656.80619 | C8: Vrms/krpm | D8: 上書き入力があればその値を使用
A9: 無負荷理想最低DCバス | B9: =SQRT(2)*計算詳細!D12 -> 9.2886423 | C9: V | D9: Vdc_min = √2 × E_ll,rms = line-line crest 逆起電力
A10: 起動時必要DCバス最低電圧 | B10: =MAX(計算詳細!D17,計算詳細!D18) -> 52.207546 | C10: V | D10: Kollmorgen定義 + 選択変調方式
A11: 定常時必要DCバス最低電圧 | B11: =MAX(計算詳細!D24,計算詳細!D25) -> 35.538041 | C11: V | D11: Kollmorgen定義 + 選択変調方式
A12: 起動区間を含む推奨最小DCバス | B12: =MAX(計算詳細!D31,計算詳細!D32) -> 61.831209 | C12: V | D12: 起動電流一定で10 rpmまで加速したワースト条件
A13: 起動時DCバス（相peak基準） | B13: =計算詳細!D17 -> 52.207546 | C13: V | D13: Vph,peak / k_ph,max
A14: 起動時DCバス（線間rms基準） | B14: =計算詳細!D18 -> 52.207546 | C14: V | D14: Vll,rms / k_mod
A15: 定常時DCバス（相peak基準） | B15: =計算詳細!D24 -> 35.538041 | C15: V | D15: Vph,peak / k_ph,max
A16: 定常時DCバス（線間rms基準） | B16: =計算詳細!D25 -> 35.538041 | C16: V | D16: Vll,rms / k_mod
A17: 加速ワーストDCバス（相peak基準） | B17: =計算詳細!D31 -> 61.831209 | C17: V | D17: Vph,peak / k_ph,max
A18: 加速ワーストDCバス（線間rms基準） | B18: =計算詳細!D32 -> 61.831209 | C18: V | D18: Vll,rms / k_mod
A19: 定常時機械出力 | B19: =計算詳細!D34 -> 31.625366 | C19: W | D19: トルク × 機械角速度
A20: 定常時発熱量（銅損） | B20: =計算詳細!D35 -> 108.85095 | C20: W | D20: 巻線ジュール損（R_phase使用）
A21: 定常時効率 | B21: =計算詳細!D37*100 -> 22.512952 | C21: % | D21: 銅損のみ考慮した簡易効率
A23: 回生制動（停止時）結果
A24: 停止前慣性エネルギー | B24: =計算詳細!D49 -> 1.6449341 | C24: J | D24: 停止前に蓄えられた運動エネルギー
A25: 必要減速トルク | B25: =計算詳細!D44 -> 3.1415927 | C25: Nm | D25: 1 sで停止するための制動トルク（大きさ）
A26: 必要回生電流 | B26: =計算詳細!D45 -> 0.35418181 | C26: Arms | D26: 回生方向の相電流実効値（大きさ）
A27: 平均機械回生電力 | B27: =計算詳細!D48 -> 1.6449341 | C27: W | D27: 減速1回の平均機械側回生電力
A28: 回生時銅損 | B28: =計算詳細!D50 -> 1.1779262 | C28: W | D28: 回生制動中の巻線銅損（R_phase使用）
A29: DCバス回収可能エネルギー | B29: =計算詳細!D53 -> 0.46700782 | C29: J | D29: 銅損を差し引いた正味回生エネルギー
A30: 回生後DCバス電圧（理想） | B30: =計算詳細!D54 -> 64.436676 | C30: V | D30: 全慣性エネルギーがC_dcへ入る上限値
A31: 回生後DCバス電圧（銅損考慮） | B31: =計算詳細!D55 -> 62.581946 | C31: V | D31: 銅損考慮後の簡易予測値
A32: 回生電圧上昇 ΔV（理想） | B32: =計算詳細!D56 -> 2.6054671 | C32: V | D32: 上限評価
A33: 回生電圧上昇 ΔV（銅損考慮） | B33: =計算詳細!D57 -> 0.75073705 | C33: V | D33: 実効評価
A34: 回生成立判定 | B34: =計算詳細!D58 -> DCバス上昇あり | C34: - | D34: 正味回生電力が正ならDCバス上昇あり
A35: 起動過渡 L·di/dt 追加評価
A36: 電気時定数 τ_e | B36: =計算詳細!D60 -> 0.0036741214 | C36: s | D36: Y結線では τ_e = L_ll / R_ll
A37: 巻線目安帯域 f_RL | B37: =計算詳細!D61 -> 43.317824 | C37: Hz | D37: 1 / (2π τ_e)
A38: 起動過渡必要DCバス最低電圧 | B38: =MAX(計算詳細!D66,計算詳細!D67) -> 71.389233 | C38: V | D38: 0→I_start の立上り時間を考慮した起動過渡評価
A39: 起動過渡追加効果 ΔVdc | B39: =計算詳細!D68 -> 19.181686 | C39: V | D39: 起動静的評価との差分
A40: 帯域参考 L·di/dt 項 | B40: =計算詳細!D70 -> 69.583461 | C40: Vpeak | D40: small-signal 補正余裕の目安
A41: 起動過渡支配判定 | B41: =計算詳細!D71 -> 起動過渡で必要電圧増加 | C41: - | D41: 起動過渡が静的起動値を上回るかの簡易判定

Sheet グラフ
A1: グラフ | B1: グラフ | C1: グラフ | D1: グラフ
A3: 状態 | B3: 相電流 [Arms]
A4: 起動時 | B4: =入力条件!B7 -> 6.8094701
A5: 定常時 | B5: =入力条件!B8 -> 3.4047351
A8: 項目 | B8: 電力 [W]
A9: 定常時機械出力 | B9: =計算詳細!D34 -> 31.625366
A10: 定常時発熱量 | B10: =計算詳細!D35 -> 108.85095
A11: 起動時銅損 | B11: =計算詳細!D38 -> 435.40381
A12: 加速中平均発熱 | B12: =計算詳細!D39 -> 435.40381
A15: 状態 | B15: 必要DCバス [V]
A16: 起動時 | B16: =計算詳細!D18 -> 52.207546
A17: 定常時 | B17: =計算詳細!D25 -> 35.538041
A18: 加速ワースト | B18: =計算詳細!D32 -> 61.831209
A21: 項目 | B21: エネルギー [J]
A22: 停止前慣性エネルギー | B22: =計算詳細!D49 -> 1.6449341
A23: 回生時銅損エネルギー | B23: =計算詳細!D51 -> 1.1779262
A24: DCバス回収可能エネルギー | B24: =計算詳細!D53 -> 0.46700782
A26: 項目 | B26: 電圧 [V]
A27: 回生開始DCバス | B27: =入力条件!B29 -> 61.831209
A28: 回生後DCバス（理想） | B28: =計算詳細!D54 -> 64.436676
A29: 回生後DCバス（銅損考慮） | B29: =計算詳細!D55 -> 62.581946

Sheet 導出メモ
A1: 導出メモ（Kollmorgen白書準拠） | B1: 導出メモ（Kollmorgen白書準拠） | C1: 導出メモ（Kollmorgen白書準拠）
A3: テーマ | B3: 式 / 要点 | C3: 説明
A4: 1. Kt と Ke の関係
A5: Kollmorgen白書の定義 | B5: Ke_ll,crest [V/(rad/s)] = Kt [Nm/Arms] | C5: 正弦波通電・Y結線前提。Ktと等しいのは line-line crest 値。
A6: 実計算で使う rms 値 | B6: Ke_ll,rms [V/(rad/s)] = Kt / √2 | C6: カタログの Vrms/krpm や SVPWM最低DCバス計算はこの rms 値を使う。
A7: カタログ表記への換算 | B7: Ke_ll,rms [Vrms/krpm] = (Kt/√2) × 1000×2π/60 | C7: Vrms/krpm は Kollmorgenカタログでよく使う表記。
A8: 換算式 | B8: Vll,rms = √(3/2) × Vph,peak | C8: 相peak基準版と線間rms基準版はこの式で相互変換できる。
A9: 3. 変調方式の係数
A10: SPWM | B10: k_mod = 0.612, k_ph,max = 0.500 | C10: Vdc = Vll,rms / 0.612 = Vph,peak / 0.5
A11: SVPWM | B11: k_mod = 1/√2 ≒ 0.707, k_ph,max = 1/√3 ≒ 0.577 | C11: Vdc = Vll,rms / 0.707 = Vph,peak / 0.577
A12: 4. q軸電圧式
A13: 起動時 | B13: v_q,start = R_phase I_start,peak | C13: KollmorgenのRはline-lineなので R_phase = R_ll/2。
A14: 定常時 | B14: v_q,ss = R_phase I_ss,peak + E_ph,peak,ss | C14: Keは line-line rms で保持し、dq式では相peakへ換算して使う。
A15: 5. d軸電圧式
A16: 定常時 / 加速時 | B16: v_d = -ω_e L_phase I_peak | C16: KollmorgenのLはline-lineなので L_phase = L_ll/2。
A17: 6. DCバスの整合チェック
A18: チェック式 | B18: Vph,peak / k_ph,max と Vll,rms / k_mod は同値 | C18: SPWM/SVPWMどちらでも換算整合する。
A19: 7. 出力・損失
A20: 機械出力 | B20: P_out = T ω_m | C20: 機械角速度を使う。
A21: 銅損 | B21: P_cu = 3 I_rms^2 R_phase | C21: R_phase = R_ll/2 を使う。
A22: 効率 | B22: η = P_out / (P_out + P_cu) | C22: 今回は銅損のみ考慮。
A23: 加速中平均発熱 | B23: 起動中6 Arms一定 → P_heat,avg = P_cu,start | C23: 発熱エネルギーは Q=P×t。
A25: 8. 回生制動の基本式
A26: 必要減速トルク | B26: |T_regen| = J × |α_dec| | C26: 一定減速度なら α=-ω0/t_dec。ここでは大きさで整理する。
A27: 必要回生電流 | B27: |I_regen| = |T_regen| / Kt | C27: Kt が Nm/Arms のため、RMS電流の大きさで直接求まる。
A28: 停止前慣性エネルギー | B28: E_k = 0.5 J ω0² | C28: 停止前に機械系が持つ運動エネルギー。
A29: 平均機械回生電力 | B29: P_mech,avg = E_k / t_dec = 0.5 T_regen ω0 | C29: 一定トルク減速なら開始時の回生電力の1/2。
A30: 回生時銅損 | B30: P_cu,regen = 3 I_regen² R_phase | C30: 回生中でも巻線銅損は必ず発生する。
A31: 正味回生エネルギー | B31: E_bus = MAX(E_k - P_cu,regen t_dec, 0) | C31: この値が正のときのみDCバス上昇が起こり得る。
A32: DCバス上昇 | B32: V_final = √(V_init² + 2E/C_dc) | C32: DCコンデンサの蓄積エネルギー 0.5CV² を利用。
A33: 9. 起動過渡 L·di/dt の追加
A34: 電気時定数 | B34: τ_e = L_phase / R_phase = L_ll / R_ll | C34: Y結線では1/2換算が相殺されるため、line-line値から直接求まる。
A35: 巻線目安帯域 | B35: f_RL = 1 / (2π τ_e) | C35: 巻線一次遅れの自然帯域の目安。ドライブ設定帯域そのものではない。
A36: 起動過渡のL·di/dt項 | B36: V_L,start = L_phase × I_start,peak / t_I,start | C36: 0→I_start の立上り時間基準。0 rpm 起動なので逆起電力は0。
A37: 起動過渡必要相電圧 | B37: V_ph,peak,start,tr = R_phase I_start,peak + V_L,start | C37: 起動静的評価に L·di/dt 項を足したもの。
A38: 起動過渡必要DCバス | B38: Vdc_min,start,tr = max(V_ph,peak / k_ph,max, V_ll,rms / k_mod) | C38: 相peak基準版と線間rms基準版の整合を確認する。
A39: 帯域参考項 | B39: V_L,bw,ref = L_phase · 2π f_ci · ΔI_corr,peak | C39: small-signal の補正余裕チェック用。フルスケール起動ステップとは区別する。
A40: Kollmorgen資料との関係 | B40: AKD2Gの current loop gain と Smith predictor は L-R model と IL.BW を用いる | C40: 本シートの追加項目は、その考え方に寄せた実務向け簡易近似。

Sheet 定義整理
A1: 定義整理・整合チェック（Kollmorgen白書準拠） | B1: 定義整理・整合チェック（Kollmorgen白書準拠） | C1: 定義整理・整合チェック（Kollmorgen白書準拠） | D1: 定義整理・整合チェック（Kollmorgen白書準拠） | E1: 定義整理・整合チェック（Kollmorgen白書準拠） | F1: 定義整理・整合チェック（Kollmorgen白書準拠）
A3: 項目 | B3: 式 | C3: 現在値 | D3: 単位 | E3: 説明 | F3: 備考
A4: 選択中の変調方式 | B4: '入力条件'!B14 | C4: =入力条件!B14 -> SVPWM | D4: - | E4: SPWM / SVPWM 切替セル | F4: 設計用
A5: k_mod（線間rms / Vdc） | B5: '入力条件'!B15 | C5: =入力条件!B15 -> 0.70710678 | D5: - | E5: SPWM:0.612 / SVPWM:0.707 | F5: Vdc = Vll,rms / k_mod
A6: k_ph,max（相peak / Vdc） | B6: '入力条件'!B16 | C6: =入力条件!B16 -> 0.57735027 | D6: - | E6: SPWM:0.500 / SVPWM:0.577 | F6: Vdc = Vph,peak / k_ph,max
A7: R_phase | B7: R_ll / 2 | C7: =入力条件!B4/2 -> 3.13 | D7: Ω | E7: Y結線の相抵抗 | F7: KollmorgenのRはline-line
A8: L_phase | B8: L_ll / 2 | C8: =入力条件!B5/2 -> 0.0115 | D8: H | E8: Y結線の相インダクタンス | F8: KollmorgenのLはline-line
A9: Ke推定（線間crest） | B9: Kt | C9: =入力条件!B6 -> 8.87 | D9: V/(rad/s) | E9: Kollmorgen白書の等価関係 | F9: Ke_ll,crest = Kt
A10: Ke推定（線間rms） | B10: Kt / √2 | C10: =入力条件!B6/SQRT(2) -> 6.2720371 | D10: V/(rad/s) | E10: 実計算で使う line-line rms 値 | F10: SVPWM/DCバス計算に使用
A11: Ke推定（線間rms） | B11: 換算 | C11: =計算詳細!D9 -> 656.80619 | D11: Vrms/krpm | E11: Ktからの推定値 | F11: カタログ表記
A12: Ke有効（線間rms） | B12: override優先 | C12: =計算詳細!D10 -> 656.80619 | D12: Vrms/krpm | E12: 空欄なら推定値 | F12: 入力条件!B12で上書き可
A13: 無負荷理想最低DCバス | B13: √2 × E_ll,rms | C13: =結果概要!B9 -> 9.2886423 | D13: V | E13: SVPWM/線形領域の理想値 | F13: Vdc_min = line-line crest 逆起電力
A15: 停止前慣性エネルギー E_k | B15: 0.5 J ω0² | C15: =計算詳細!D49 -> 1.6449341 | D15: J | E15: 機械側の理想回生上限 | F15: 今回条件では低速のため値は小さい
A16: 回生時銅損 E_cu,regen | B16: P_cu,regen t_dec | C16: =計算詳細!D51 -> 1.1779262 | D16: J | E16: 巻線で熱に変わる分 | F16: E_k より大きいとDCバス上昇なし
A17: 正味回生エネルギー E_bus | B17: MAX(E_k-E_cu,0) | C17: =計算詳細!D53 -> 0.46700782 | D17: J | E17: コンデンサへ入る正味エネルギー | F17: 0ならバス上昇予測なし
A18: 理想回生後DCバス | B18: √(V_init²+2E_k/C) | C18: =計算詳細!D54 -> 64.436676 | D18: V | E18: 上限評価 | F18: 抵抗・損失・吸収負荷を無視
A19: 実効回生後DCバス | B19: √(V_init²+2E_bus/C) | C19: =計算詳細!D55 -> 62.581946 | D19: V | E19: 銅損考慮の簡易評価 | F19: 負の正味エネルギーは0扱い
A20: 実効回生後DCバス | B20: √(V_init²+2E_bus/C)

Sheet Kollmorgen定義対応表
A1: Kollmorgen定義対応表（セル番地トレーサビリティ）
A3: 使い方 | B3: このシートは、改訂版Excelの主要セルがどの定義・資料に対応しているかを一覧化したものです。「参照元ID」は下の資料一覧に対応します。青系=Kollmorgen公式定義、橙系=変調方式/TI、灰系=一般式/ユーザー入力です。
A7: 参照元ID | B7: 資料種別 | C7: 資料名 / 役割 | D7: 確認したい定義 | E7: URL | F7: 備考
A8: KM-1 | B8: Kollmorgen公式 | C8: Motor Data Legend | D8: KTrms, KErms, R20, L の基本定義 | E8: https://www.kollmorgen.com/en-us/developer-network/motor-data-legend | F8: 用語集。まず最初に照合する資料
A9: KM-2 | B9: Kollmorgen公式 | C9: Servomotor Parameters and their Proper Conversions for Servo Drive Utilization and Comparison | D9: Kt↔Ke/Kb, Y結線での line-line / line-neutral 換算, R/Lの1/2換算 | E9: https://www.kollmorgen.com/sites/default/files/public_downloads/Servomotor_Parameters_and_Conversions_10_15A_FINALDOC.pdf | F9: 今回のKe修正の基準資料
A10: KM-3 | B10: Kollmorgen公式 | C10: TBM2G Frameless Motor Selection Guide | D10: DDモータ実カタログ表記: Nm/Arms, Vrms/krpm, Resistance(line-line), Inductance(line-line) | E10: https://www.kollmorgen.com/sites/default/files/TBM2G-KM_SG_00396_RevA_EN.pdf | F10: DDモータの実表記確認用
A11: TI-1 | B11: TI公式 | C11: TIDUCY7 / DesignDRIVE Position Manager Tech Ref | D11: SVPWMの線間基本波rms / Vdc係数 0.707 | E11: https://www.ti.com/jp/lit/ug/tiducy7/tiducy7.pdf | F11: 変調方式の係数確認用
A12: GEN-1 | B12: 一般式 | C12: PMSM / Y結線の一般式 | D12: Vll,rms=√(3/2)Vph,peak, dq式, Pcu=3Irms^2R_phase など | E12: — | F12: Kollmorgen定義に整合させて使う一般式
A13: USR-1 | B13: ユーザー入力 | C13: 設計条件入力 | D13: 回転数, トルク, 極ペア数, J, t_acc, t_dec など | E13: — | F13: メーカー定義ではなく使用条件
A14: KM-4 | B14: Kollmorgen公式 | C14: AKD2G User Manual / Current Loop Gain | D14: 電流ループ帯域 IL.BW と line-line インダクタンス LQLL の関係 | E14: https://webhelp.kollmorgen.com/akd2g/english/Content/AKD2G_User_Manual/Current_Loop_Gain.htm | F14: IL.KP = 2π·LQLL·IL.BW
A15: KM-5 | B15: Kollmorgen公式 | C15: Tuning Delay Time Compensation / Smith Predictor | D15: 電流制御を L-R model + dead time で扱う考え方 | E15: https://www.kollmorgen.com/en-us/developer-network/tuning-delay-time-compensation-smith-predictor | F15: L·di/dt 追加の背景確認用
A16: 区分 | B16: シート名 | C16: セル番地 | D16: 項目名 | E16: 現在値(リンク) | F16: 資料対応 | G16: 参照元ID | H16: 確認ポイント | I16: 一致判定 | J16: 補足
A17: 入力 | B17: 入力条件 | C17: B4 | D17: 線間巻線抵抗 R_ll | E17: =入力条件!B4 -> 6.26 | F17: phase-phase / line-line の巻線抵抗 | G17: KM-1 / KM-2 / KM-3 | H17: Kollmorgenでは R は line-line 表記 | I17: 一致 | J17: dq式へ入れるときは R_phase = R_ll / 2
A18: 入力 | B18: 入力条件 | C18: B5 | D18: 線間インダクタンス L_ll | E18: =入力条件!B5 -> 0.023 | F18: phase-phase / line-line の巻線インダクタンス | G18: KM-1 / KM-2 / KM-3 | H18: Kollmorgenでは L は line-line 表記 | I18: 一致 | J18: dq式へ入れるときは L_phase = L_ll / 2
A19: 入力 | B19: 入力条件 | C19: B6 | D19: トルク定数 Kt | E19: =入力条件!B6 -> 8.87 | F19: KTrms = Nm/Arms | G19: KM-1 / KM-2 / KM-3 | H19: 正弦波通電の RMS 電流基準 | I19: 一致 | J19: Y結線では線RMS=相RMS
A20: 入力 | B20: 入力条件 | C20: B7 | D20: 起動時電流 I_start | E20: =入力条件!B7 -> 6.8094701 | F20: 設計条件入力 | G20: USR-1 | H20: メーカー定義ではなく用途条件 | I20: 対象外 | J20: Ktとの積/換算に使う
A21: 入力 | B21: 入力条件 | C21: B8 | D21: 定常時電流 I_ss | E21: =入力条件!B8 -> 3.4047351 | F21: 設計条件入力 | G21: USR-1 | H21: メーカー定義ではなく用途条件 | I21: 対象外 | J21: Ktとの積/換算に使う
A22: 入力 | B22: 入力条件 | C22: B9 | D22: 定常時回転速度 n_ss | E22: =入力条件!B9 -> 10 | F22: 設計条件入力 | G22: USR-1 | H22: メーカー定義ではなく用途条件 | I22: 対象外 | J22: Keと組み合わせて逆起電力を計算
A23: 入力 | B23: 入力条件 | C23: B11 | D23: 極ペア数 p | E23: =入力条件!B11 -> 32 | F23: 設計条件入力 | G23: USR-1 | H23: メーカー定義ではなくモータ仕様入力 | I23: 対象外 | J23: ωe = p ωm
A24: 入力 | B24: 入力条件 | C24: B12 | D24: Ke上書き Ke_ll,rms | E24: =IF(入力条件!B12="","",入力条件!B12) | F24: line-line rms の逆起電力定数 | G24: KM-1 / KM-2 / KM-3 | H24: Kollmorgenカタログの Vrms/krpm に合わせる | I24: 一致 | J24: 空欄ならKtから推定
A25: 入力 | B25: 入力条件 | C25: B15 | D25: k_mod | E25: =入力条件!B15 -> 0.70710678 | F25: Vll,rms / Vdc 係数 | G25: TI-1 | H25: SVPWM=0.707, SPWM=0.612 | I25: 一致 | J25: Kollmorgen定義ではなくインバータ定義
A26: 入力 | B26: 入力条件 | C26: B16 | D26: k_ph,max | E26: =入力条件!B16 -> 0.57735027 | F26: Vph,peak / Vdc 係数 | G26: TI-1 | H26: SVPWM=1/√3, SPWM=0.5 | I26: 一致 | J26: 相peak版DCバス式で使用
A27: 換算 | B27: 計算詳細 | C27: D8 | D27: Ke推定（線間rms / 機械rad/s） | E27: =計算詳細!D8 -> 6.2720371 | F27: Ke_ll,rms = Kt / √2 | G27: KM-2 | H27: Ktと直接等しいのは crest。rms は /√2 | I27: 一致 | J27: 今回の白書準拠修正の中心
A28: 換算 | B28: 計算詳細 | C28: D9 | D28: Ke推定（線間rms / krpm） | E28: =計算詳細!D9 -> 656.80619 | F28: Vrms/krpm への換算 | G28: KM-2 / KM-3 | H28: カタログの Ke 表記に合わせる | I28: 一致 | J28: DDモータカタログ照合用
A29: 換算 | B29: 計算詳細 | C29: D10 | D29: Ke有効（線間rms / krpm） | E29: =計算詳細!D10 -> 656.80619 | F29: override優先 / 推定値フォールバック | G29: KM-2 / KM-3 | H29: Ke入力時も必ず line-line rms 基準で扱う | I29: 一致 | J29: 入力条件!B12 を優先
A30: 換算 | B30: 計算詳細 | C30: D11 | D30: Ke有効（線間rms / 機械rad/s） | E30: =計算詳細!D11 -> 6.2720371 | F30: 計算用 Ke_active | G30: KM-2 | H30: 内部計算用に rad/s 基準へ戻した値 | I30: 一致 | J30: 逆起電力計算に使用
A31: 換算 | B31: 計算詳細 | C31: D12 | D31: 定常時逆起電力 E_ll,rms,ss | E31: =計算詳細!D12 -> 6.5680619 | F31: E_ll,rms = Ke_active × ωm | G31: KM-1 / KM-2 | H31: Kollmorgenの Ke は 2端子間・rms 基準 | I31: 一致 | J31: SVPWM最低DCバス式へ直結
A32: 換算 | B32: 計算詳細 | C32: D13 | D32: 定常時逆起電力 E_ph,peak,ss | E32: =計算詳細!D13 -> 5.3628001 | F32: 線間rms → 相peak 換算 | G32: GEN-1 | H32: dq式へ入れるための一般換算 | I32: 整合 | J32: Kollmorgen定義値を一般式へ接続
A33: 換算 | B33: 計算詳細 | C33: D14 | D33: 起動時 q軸電圧 v_q,start | E33: =計算詳細!D14 -> 30.142041 | F33: R_phase × I_start,peak | G33: KM-2 / GEN-1 | H33: R_phase = R_ll / 2 を適用 | I33: 一致 | J33: 起動時は逆起電力0と仮定
A34: 換算 | B34: 計算詳細 | C34: D20 | D34: 定常時 d軸電圧 v_d,ss | E34: =計算詳細!D20 -> -1.855559 | F34: -ωe × L_phase × I_ss,peak | G34: KM-2 / GEN-1 | H34: L_phase = L_ll / 2 を適用 | I34: 一致 | J34: KollmorgenのL定義を一般dq式へ適用
A35: 換算 | B35: 計算詳細 | C35: D21 | D35: 定常時 q軸電圧 v_q,ss | E35: =計算詳細!D21 -> 20.433821 | F35: R_phase I + E_ph,peak | G35: KM-2 / GEN-1 | H35: RとKeの定義を合わせた q軸電圧式 | I35: 一致 | J35: id=0 前提
A36: DCバス | B36: 計算詳細 | C36: D18 | D36: 起動時必要DCバス（線間rms基準） | E36: =計算詳細!D18 -> 52.207546 | F36: Vdc = Vll,rms / k_mod | G36: KM-2 / TI-1 | H36: Kollmorgenの line-line rms 定義と SVPWM係数の組合せ | I36: 一致 | J36: 線間rms基準の主式
A37: DCバス | B37: 計算詳細 | C37: D24 | D37: 定常時必要DCバス（相peak基準） | E37: =計算詳細!D24 -> 35.538041 | F37: Vdc = Vph,peak / k_ph,max | G37: KM-2 / TI-1 / GEN-1 | H37: 相peak版。線間rms版と同値チェック用 | I37: 一致 | J37: D25と一致することを確認
A38: DCバス | B38: 計算詳細 | C38: D25 | D38: 定常時必要DCバス（線間rms基準） | E38: =計算詳細!D25 -> 35.538041 | F38: Vdc = Vll,rms / k_mod | G38: KM-2 / TI-1 | H38: Kollmorgenの Ke 定義に最も直接的 | I38: 一致 | J38: 推奨の読み方
A39: DCバス | B39: 計算詳細 | C39: D31 | D39: 加速ワースト必要DCバス（相peak基準） | E39: =計算詳細!D31 -> 61.831209 | F39: Vdc = Vph,peak / k_ph,max | G39: KM-2 / TI-1 / GEN-1 | H39: 起動区間全体の支配条件を相peakで評価 | I39: 一致 | J39: D32と整合
A40: DCバス | B40: 計算詳細 | C40: D32 | D40: 加速ワースト必要DCバス（線間rms基準） | E40: =計算詳細!D32 -> 61.831209 | F40: Vdc = Vll,rms / k_mod | G40: KM-2 / TI-1 | H40: 推奨最小DCバスの主出力 | I40: 一致 | J40: 結果概要!B12 に反映
A41: トルク | B41: 計算詳細 | C41: D33 | D41: 定常時トルク T_ss | E41: =計算詳細!D33 -> 30.2 | F41: T = Kt × I_rms | G41: KM-1 / KM-2 | H41: Kt が Nm/Arms なので RMS 電流を直接使用 | I41: 一致 | J41: Y結線で線RMS=相RMS
A42: 損失 | B42: 計算詳細 | C42: D35 | D42: 定常時銅損 P_cu,ss | E42: =計算詳細!D35 -> 108.85095 | F42: P_cu = 3 I_rms^2 R_phase | G42: KM-2 / GEN-1 | H42: R_phase = R_ll/2 を適用 | I42: 一致 | J42: Rの定義が合わないと銅損がずれる
A43: 結果 | B43: 結果概要 | C43: B7 | D43: Ke推定（線間rms） | E43: =結果概要!B7 -> 656.80619 | F43: D9のサマリ表示 | G43: KM-2 / KM-3 | H43: カタログ照合の主要セル | I43: 一致 | J43: まずここでKeの桁を確認
A44: 結果 | B44: 結果概要 | C44: B8 | D44: Ke有効（線間rms） | E44: =結果概要!B8 -> 656.80619 | F44: D10のサマリ表示 | G44: KM-2 / KM-3 | H44: 上書き時はここが変わる | I44: 一致 | J44: 実際の採用値
...

Sheet Kollmorgen定義対応表_詳細
A1: Kollmorgen定義対応表_詳細（セル番地・出典ページ/行・式メモ付き）
A3: 目的: 改訂版Excelの主要セルについて、Kollmorgen公式定義/TI資料/一般式のどれに基づくかを、セル番地・現在値・ページ/行・式メモ付きで追えるようにした詳細対応表です。黄色マーキングした原シート側の重要セルと対応します。
A5: 参照元ID | B5: 資料種別 | C5: 資料名 / 役割 | D5: 主要定義 | E5: ページ/行・式メモ | F5: URL | G5: 補足
A6: KM-1 | B6: Kollmorgen公式 | C6: Motor Data Legend | D6: KTrms, KE, R20, L の基本定義 | E6: HTML L253-L267: I0rms, KTrms, KE, R20, L | F6: https://www.kollmorgen.com/en-us/developer-network/motor-data-legend | G6: 用語定義の起点。KEは2端子間のeffective sinusoidal value / 1000 rpm。
A7: KM-2 | B7: Kollmorgen公式 | C7: Servomotor Parameters and their Proper Conversions for Servo Drive Utilization and Comparison | D7: Kt↔Ke/Kb換算, Y結線 line-line/line-neutral, R/Lの1/2換算 | E7: p.3 L207-L212: Kb=Ke/√2; p.3 L241-L242: Y結線で線電流=相電流; p.4 L309-L317: Kt=A-rms, Kb=Vrms/kRPM, Rm_φ=Rm(L-L)/2 | F7: https://www.kollmorgen.com/sites/default/files/uploaded/Service_and_Support/Knowledge_Center/White_Papers/ServoUnits__10_15A_FINALDOC.pdf | G7: 今回のKe修正とY結線換算の最重要資料。
A8: KM-3 | B8: Kollmorgen公式 | C8: TBM2G Frameless Motor Selection Guide | D8: DDモータ実カタログ表記: Nm/Arms, Vrms/krpm, Resistance(line-line), Inductance(line-line) | E8: p.10 L394-L409: sinusoidal commutation, Kt, Ke; p.34 L1695-L1701: Ke, Resistance(line-line), Inductance Q-Axis(line-line) | F8: https://www.kollmorgen.com/sites/default/files/TBM2G-KM_SG_00396_RevA_EN.pdf | G8: DDモータ系カタログの実表記確認用。
A9: TI-1 | B9: TI公式 | C9: TIDUCY7 / Current Sensing With <1-µs Settling... | D9: SVPWMの線間基本波rms / Vdc 係数 0.707 | E9: p.11 L549-L552: maximum RMS line-to-line voltage = 0.707 × Vdc | F9: https://www.ti.com/lit/ug/tiducy7/tiducy7.pdf | G9: インバータ側の変調係数確認用。
A10: GEN-1 | B10: 一般式 | C10: PMSM / Y結線の一般式 | D10: Vll,rms=√(3/2)Vph,peak, Pcu=3Irms²Rphase, dq式 | E10: 式メモ: Vll,rms=√(3/2)Vph,peak; Rphase=Rll/2; Lphase=Lll/2; Pcu=3Irms²Rphase | F10: — | G10: Kollmorgen定義値をd-q式/電圧換算へ接続する一般式。
A11: USR-1 | B11: ユーザー入力 | C11: 設計条件入力 | D11: 回転数, トルク, 極ペア数, J, t_acc, t_dec, C_dc など | E11: ユーザーが指定した仕様値 | F11: — | G11: メーカー定義ではなく設計条件。
A12: 凡例: 青系=Kollmorgen公式, 橙系=TI/SVPWM, 灰系=一般式, 黄緑系=ユーザー条件。列Iは該当ページ/行または式メモ、列Mの Yes は原シートで黄色マーキング済みです。
A13: 区分 | B13: シート名 | C13: セル番地 | D13: 項目名 | E13: 現在値(リンク) | F13: 入力/Excel式・内容 | G13: 定義/意味 | H13: 参照元ID | I13: ページ/行・式メモ | J13: 公式URL | K13: 一致判定 | L13: 補足 | M13: 黄色マーキング
A14: 入力 | B14: 入力条件 | C14: B4 | D14: 線間巻線抵抗 R_ll | E14: =入力条件!B4 -> 6.26 | F14: ユーザー入力 | G14: Kollmorgenの抵抗はphase-phase / line-line | H14: KM-1 / KM-2 / KM-3 | I14: KM-1 HTML L266; KM-2 p.4 L314-L317; KM-3 p.34 L1700-L1701 | J14: https://www.kollmorgen.com/en-us/developer-network/motor-data-legend | https://www.kollmorgen.com/sites/default/files/uploaded/Service_and_Support/Knowledge_Center/White_Papers/ServoUnits__10_15A_FINALDOC.pdf | https://www.kollmorgen.com/sites/default/files/TBM2G-KM_SG_00396_RevA_EN.pdf | K14: 一致 | L14: d-q式では R_phase = R_ll / 2 | M14: Yes
A15: 入力 | B15: 入力条件 | C15: B5 | D15: 線間インダクタンス L_ll | E15: =入力条件!B5 -> 0.023 | F15: ユーザー入力 | G15: Kollmorgenのインダクタンスはphase-phase / line-line | H15: KM-1 / KM-2 / KM-3 | I15: KM-1 HTML L267; KM-2 p.4 L314-L317(抵抗換算と同流儀); KM-3 p.34-35 L1700-L1701 | J15: https://www.kollmorgen.com/en-us/developer-network/motor-data-legend | https://www.kollmorgen.com/sites/default/files/uploaded/Service_and_Support/Knowledge_Center/White_Papers/ServoUnits__10_15A_FINALDOC.pdf | https://www.kollmorgen.com/sites/default/files/TBM2G-KM_SG_00396_RevA_EN.pdf | K15: 一致 | L15: d-q式では L_phase = L_ll / 2 | M15: Yes
A16: 入力 | B16: 入力条件 | C16: B6 | D16: トルク定数 Kt | E16: =入力条件!B6 -> 8.87 | F16: ユーザー入力 | G16: KTrms = Nm/Arms | H16: KM-1 / KM-2 / KM-3 | I16: KM-1 HTML L258-L260; KM-2 p.4 L309-L311; KM-3 p.10 L402-L409 | J16: https://www.kollmorgen.com/en-us/developer-network/motor-data-legend | https://www.kollmorgen.com/sites/default/files/uploaded/Service_and_Support/Knowledge_Center/White_Papers/ServoUnits__10_15A_FINALDOC.pdf | https://www.kollmorgen.com/sites/default/files/TBM2G-KM_SG_00396_RevA_EN.pdf | K16: 一致 | L16: 正弦波通電。Y結線では線RMS=相RMS | M16: Yes
A17: 入力 | B17: 入力条件 | C17: B7 | D17: 起動時電流 I_start | E17: =入力条件!B7 -> 6.8094701 | F17: ユーザー入力 | G17: 設計条件入力 | H17: USR-1 | I17: ユーザー指定値 | J17: — | K17: 対象外 | L17: メーカー定義ではなく使用条件 | M17: Yes
A18: 入力 | B18: 入力条件 | C18: B8 | D18: 定常時電流 I_ss | E18: =入力条件!B8 -> 3.4047351 | F18: ユーザー入力 | G18: 設計条件入力 | H18: USR-1 | I18: ユーザー指定値 | J18: — | K18: 対象外 | L18: Ktと掛けてトルク計算 | M18: Yes
A19: 入力 | B19: 入力条件 | C19: B9 | D19: 定常時回転速度 n_ss | E19: =入力条件!B9 -> 10 | F19: ユーザー入力 | G19: 設計条件入力 | H19: USR-1 | I19: ユーザー指定値 | J19: — | K19: 対象外 | L19: Keと掛けて逆起電力計算 | M19: Yes
A20: 入力 | B20: 入力条件 | C20: B10 | D20: 加速時間 t_acc | E20: =入力条件!B10 -> 1 | F20: ユーザー入力 | G20: 設計条件入力 | H20: USR-1 | I20: ユーザー指定値 | J20: — | K20: 対象外 | L20: 加速ワースト計算用 | M20: Yes
A21: 入力 | B21: 入力条件 | C21: B11 | D21: 極ペア数 p | E21: =入力条件!B11 -> 32 | F21: ユーザー入力 | G21: 設計条件入力 | H21: USR-1 | I21: ユーザー指定値 | J21: — | K21: 対象外 | L21: ωe = p·ωm | M21: Yes
A22: 入力 | B22: 入力条件 | C22: B26 | D22: 慣性モーメント J | E22: =入力条件!B26 -> 3 | F22: ユーザー入力 | G22: 設計条件入力 | H22: USR-1 | I22: ユーザー指定値 | J22: — | K22: 対象外 | L22: 回生/減速計算用 | M22: Yes
A23: 入力 | B23: 入力条件 | C23: B27 | D23: 減速時間 t_dec | E23: =入力条件!B27 -> 1 | F23: ユーザー入力 | G23: 設計条件入力 | H23: USR-1 | I23: ユーザー指定値 | J23: — | K23: 対象外 | L23: 回生/減速計算用 | M23: Yes
A24: 入力 | B24: 入力条件 | C24: B28 | D24: DCバス容量 C_dc | E24: =入力条件!B28 -> 0.01 | F24: ユーザー入力 | G24: 設計条件入力 | H24: USR-1 | I24: ユーザー指定値 | J24: — | K24: 対象外 | L24: 回生電圧上昇計算用 | M24: Yes
A25: 入力 | B25: 入力条件 | C25: B29 | D25: 回生開始DCバス電圧 Vdc_init | E25: =入力条件!B29 -> 61.831209 | F25: ユーザー入力 | G25: 設計条件入力 | H25: USR-1 | I25: ユーザー指定値 | J25: — | K25: 対象外 | L25: 回生後Vdc計算用 | M25: Yes
A26: 入力 | B26: 入力条件 | C26: B12 | D26: Ke上書き Ke_ll,rms | E26: =入力条件!B12 -> 0 | F26: ユーザー入力 | G26: Kollmorgenカタログ基準の line-line rms Vrms/krpm | H26: KM-1 / KM-2 / KM-3 | I26: KM-1 HTML L260; KM-2 p.3 L207-L212; KM-3 p.10 L408-L409 | J26: https://www.kollmorgen.com/en-us/developer-network/motor-data-legend | https://www.kollmorgen.com/sites/default/files/uploaded/Service_and_Support/Knowledge_Center/White_Papers/ServoUnits__10_15A_FINALDOC.pdf | https://www.kollmorgen.com/sites/default/files/TBM2G-KM_SG_00396_RevA_EN.pdf | K26: 一致 | L26: 空欄ならKtから推定 | M26: Yes
A27: 入力 | B27: 入力条件 | C27: B13 | D27: 変調方式 | E27: =入力条件!B13 -> 0 | F27: SPWM / SVPWM 切替 | G27: インバータ定義 | H27: TI-1 | I27: TI-1 p.11 L549-L552 | J27: https://www.ti.com/lit/ug/tiducy7/tiducy7.pdf | K27: 整合 | L27: Kollmorgen定義ではなくインバータ側条件 | M27: Yes
A28: 入力 | B28: 入力条件 | C28: B15 | D28: 線間基本波rms / Vdc 係数 k_mod | E28: =入力条件!B15 -> 0.70710678 | F28: SVPWM=0.707, SPWM=0.612 | G28: Vll,rms / Vdc 係数 | H28: TI-1 | I28: TI-1 p.11 L549-L552: VLL_RMS,max = 0.707·Vdc | J28: https://www.ti.com/lit/ug/tiducy7/tiducy7.pdf | K28: 一致 | L28: SVPWM計算の主係数 | M28: Yes
A29: 入力 | B29: 入力条件 | C29: B16 | D29: 相基本波peak / Vdc 係数 k_ph,max | E29: =入力条件!B16 -> 0.57735027 | F29: SVPWM=1/√3, SPWM=0.5 | G29: Vph,peak / Vdc 係数 | H29: TI-1 / GEN-1 | I29: TI-1の0.707と Vll,rms=√(3/2)Vph,peak から導出 | J29: https://www.ti.com/lit/ug/tiducy7/tiducy7.pdf | K29: 整合 | L29: 相peak版と線間rms版の同値確認用 | M29: Yes
A30: 換算 | B30: 計算詳細 | C30: D4 | D30: 起動時電流ピーク値 I_start,peak | E30: =計算詳細!D4 -> 9.630045 | F30: SQRT(2)×I_start | G30: RMS→peak換算 | H30: GEN-1 | I30: 式メモ: I_peak=√2·I_rms | J30: — | K30: 整合 | L30: dq式で使用 | M30: Yes
A31: 換算 | B31: 計算詳細 | C31: D5 | D31: 定常時電流ピーク値 I_ss,peak | E31: =計算詳細!D5 -> 4.8150225 | F31: SQRT(2)×I_ss | G31: RMS→peak換算 | H31: GEN-1 | I31: 式メモ: I_peak=√2·I_rms | J31: — | K31: 整合 | L31: dq式で使用 | M31: Yes
A32: 換算 | B32: 計算詳細 | C32: D6 | D32: 定常時機械角速度 ω_m,ss | E32: =計算詳細!D6 -> 1.0471976 | F32: n_ss×2π/60 | G32: 回転速度[rpm]→機械角速度 | H32: GEN-1 | I32: 式メモ: ωm=n·2π/60 | J32: — | K32: 整合 | L32: 機械速度基準 | M32: Yes
A33: 換算 | B33: 計算詳細 | C33: D7 | D33: 定常時電気角速度 ω_e,ss | E33: =計算詳細!D7 -> 33.510322 | F33: p×ω_m | G33: 電気角速度 | H33: GEN-1 / USR-1 | I33: 式メモ: ωe=p·ωm | J33: — | K33: 整合 | L33: 極ペア数を反映 | M33: Yes
A34: 換算 | B34: 計算詳細 | C34: D8 | D34: Ke推定（線間rms / 機械rad/s） | E34: =計算詳細!D8 -> 6.2720371 | F34: Kt/√2 | G34: Kollmorgen白書準拠のKe_ll,rms推定 | H34: KM-2 | I34: p.3 L207-L212: Kb(Vrms/rad/s)=Ke(V/rad/s)/√2 | J34: https://www.kollmorgen.com/sites/default/files/uploaded/Service_and_Support/Knowledge_Center/White_Papers/ServoUnits__10_15A_FINALDOC.pdf | K34: 一致 | L34: Ktと直接等しいのはcrest側 | M34: Yes
A35: 換算 | B35: 計算詳細 | C35: D9 | D35: Ke推定（線間rms / krpm） | E35: =計算詳細!D9 -> 656.80619 | F35: D8×1000×2π/60 | G35: カタログ表記 Vrms/krpm へ換算 | H35: KM-2 / KM-3 | I35: KM-2 p.3 L210-L212; KM-3 p.10 L408-L409 | J35: https://www.kollmorgen.com/sites/default/files/uploaded/Service_and_Support/Knowledge_Center/White_Papers/ServoUnits__10_15A_FINALDOC.pdf | https://www.kollmorgen.com/sites/default/files/TBM2G-KM_SG_00396_RevA_EN.pdf | K35: 一致 | L35: TBM2G表記と同じ単位 | M35: Yes
A36: 換算 | B36: 計算詳細 | C36: D10 | D36: Ke有効（線間rms / krpm） | E36: =計算詳細!D10 -> 656.80619 | F36: IF(override, B12, D9) | G36: 上書き優先の採用Ke | H36: KM-2 / KM-3 | I36: 白書のKb単位 + カタログのKe単位 | J36: https://www.kollmorgen.com/sites/default/files/uploaded/Service_and_Support/Knowledge_Center/White_Papers/ServoUnits__10_15A_FINALDOC.pdf | https://www.kollmorgen.com/sites/default/files/TBM2G-KM_SG_00396_RevA_EN.pdf | K36: 一致 | L36: B12空欄なら推定値 | M36: Yes
A37: 換算 | B37: 計算詳細 | C37: D11 | D37: Ke有効（線間rms / 機械rad/s） | E37: =計算詳細!D11 -> 6.2720371 | F37: D10/(1000×2π/60) | G37: 内部計算用Ke_active | H37: KM-2 | I37: p.3 L207-L212 の逆換算 | J37: https://www.kollmorgen.com/sites/default/files/uploaded/Service_and_Support/Knowledge_Center/White_Papers/ServoUnits__10_15A_FINALDOC.pdf | K37: 一致 | L37: 逆起電力計算で使用 | M37: Yes
A38: 換算 | B38: 計算詳細 | C38: D12 | D38: 定常時逆起電力 E_ll,rms,ss | E38: =計算詳細!D12 -> 6.5680619 | F38: D11×ωm | G38: 線間rms基準の逆起電力 | H38: KM-1 / KM-2 | I38: KM-1 HTML L260; KM-2 p.3 L207-L212 | J38: https://www.kollmorgen.com/en-us/developer-network/motor-data-legend | https://www.kollmorgen.com/sites/default/files/uploaded/Service_and_Support/Knowledge_Center/White_Papers/ServoUnits__10_15A_FINALDOC.pdf | K38: 一致 | L38: KollmorgenのKErmsと同基準 | M38: Yes
A39: 換算 | B39: 計算詳細 | C39: D13 | D39: 定常時逆起電力 E_ph,peak,ss | E39: =計算詳細!D13 -> 5.3628001 | F39: E_ll,rms×√(2/3) | G39: 線間rms→相peak換算 | H39: GEN-1 | I39: 式メモ: Vll,rms=√(3/2)Vph,peak | J39: — | K39: 整合 | L39: dq式のq軸へ接続 | M39: Yes
A40: 電圧 | B40: 計算詳細 | C40: D14 | D40: 起動時 q軸電圧 v_q,start | E40: =計算詳細!D14 -> 30.142041 | F40: (R_ll/2)×I_start,peak | G40: 起動瞬間の抵抗降下 | H40: KM-2 / GEN-1 | I40: KM-2 p.4 L314-L317: Rm_φ=Rm(L-L)/2 | J40: https://www.kollmorgen.com/sites/default/files/uploaded/Service_and_Support/Knowledge_Center/White_Papers/ServoUnits__10_15A_FINALDOC.pdf | K40: 一致 | L40: 起動時は逆起電力0 | M40: Yes
A41: 電圧 | B41: 計算詳細 | C41: D15 | D41: 起動時必要相電圧 V_ph,peak,start | E41: =計算詳細!D15 -> 30.142041 | F41: ABS(v_q,start) | G41: 起動時必要相電圧 | H41: GEN-1 | I41: 式メモ: 起動時はd軸成分0 | J41: — | K41: 整合 | L41: 相peak基準 | M41: Yes
... A44: DCバス | B44: 計算詳細 | C44: D18 | D44: 起動時必要DCバス（線間rms基準） | E44: =計算詳細!D18 -> 52.207546 | F44: Vll,rms/k_mod | G44: 線間rms基準のDCバス式 | H44: TI-1 | I44: p.11 L549-L552: VLL_RMS,max = 0.707·Vdc | J44: https://www.ti.com/lit/ug/tiducy7/tiducy7.pdf | K44: 一致 | L44: SVPWM主式 | M44: Yes
...
