Workbook

Sheet Inputs
A1: Kollmorgen DDモータ / SVPWM 最低DCバス電圧 計算シート（白書整合版） | G1: 結果サマリー
A3: 入力項目 / 設定 | B3: 値 | C3: 単位 | D3: 編集可否 | E3: 備考 | G3: 主要結果 | H3: 値 | I3: 単位 | J3: 意味
A4: 回転速度 n | B4: 10 | C4: rpm | D4: 可 | E4: 機械角速度 | G4: I_rms | H4: =Calculations!B6 -> 3.4047351 | I4: Arms | J4: トルクと Kt から求めた必要RMS電流
A5: 極対数 p | B5: 32 | C5: - | D5: 可 | E5: 電気角速度 = p × 機械角速度 | G5: Ke active | H5: =Calculations!B12 -> 536.28001 | I5: Vrms/krpm | J5: 本ブックで使用する線間RMSの Ke。上書きがあればそれを優先、なければ Kt/√3 から推定
A6: トルク T | B6: 30.2 | C6: Nm | D6: 可 | E6: 要求軸トルク | G6: Vdc_min no-load | H6: =Calculations!B24 -> 7.5841447 | I6: Vdc | J6: SVPWM と線間RMS逆起電力による理想無負荷最低値
A7: Kt | B7: 8.87 | C7: Nm/Arms | D7: 可 | E7: Kollmorgen の正弦波トルク定数（KTrms） | G7: Vdc_min load (design) | H7: =Calculations!B25 -> 33.840879 | I7: Vdc | J7: 入力したR倍率を用いた設計ケース
A8: Ke 上書き | C8: Vrms/krpm（線間RMS） | D8: 任意 | E8: 空欄時は Kollmorgen 白書に基づく Kt からの推定値を使用 | G8: Vdc_min load + margin | H8: =Calculations!B27 -> 37.224967 | I8: Vdc | J8: ユーザー指定マージン込みの設計ケース
A9: R_ll | B9: 6.26 | C9: Ohm | D9: 可 | E9: Kollmorgen データシートの線間抵抗 | G9: Vdc_min load (hot 1.525x) | H9: =Calculations!B26 -> 47.50125 | I9: Vdc | J9: 高温銅抵抗の参照ケース
A10: L_ll | B10: 23 | C10: mH | D10: 可 | E10: Kollmorgen データシートの線間インダクタンス | G10: Vdc_min hot + margin | H10: =Calculations!B28 -> 52.251375 | I10: Vdc | J10: 高温参照ケースにユーザー余裕を加えた値
A11: R倍率（設計ケース） | B11: 1 | C11: x | D11: 可 | E11: 1.0 = データシート/基準温度 | G11: I_start | H11: =Calculations!B30 -> 6.3810598 | I11: Arms | J11: 起動RMS電流 = 倍率 × I_rms
A12: SVPWMマージン | B12: 0.1 | C12: 比率 | D12: 可 | E12: 追加のDCバス余裕。例: 0.10 = 10% | G12: Vdc_min startup | H12: =Calculations!B33 -> 48.922965 | I12: Vdc | J12: ゼロ速度起動。抵抗降下のみを考慮
A13: 結線前提 | B13: Y | C13: - | D13: 固定 | E13: 本シートは内部Y結線を前提 | G13: Vdc_min startup + margin | H13: =Calculations!B34 -> 53.815262 | I13: Vdc | J13: 起動ケースにユーザー余裕を加えた値
A14: 制御前提 | B14: 正弦波 / id = 0 | C14: - | D14: 固定 | E14: Kollmorgen の正弦波通電の慣例 | G14: Vdc_min accel worst | H14: =Calculations!B39 -> 56.827241 | I14: Vdc | J14: 起動電流を目標速度まで維持した加速ワースト。 終速度での逆起電力を含む
A15: 起動電流倍率 | B15: =56.6/30.2 -> 1.8741722 | C15: × I_rms | D15: 可 | E15: 初期値 2.0。起動電流 = 倍率 × I_rms | G15: Vdc_min accel worst + margin | H15: =Calculations!B40 -> 62.509966 | I15: Vdc | J15: 加速ワーストにユーザー余裕を加えた値
A16: 加速ワースト前提 | B16: I_start を目標速度まで維持 | C16: - | D16: 固定 | E16: 詳細版の加速ワースト確認と対応を取るための前提 | G16: 停止前慣性エネルギー | H16: =Calculations!B49 -> 1.6449341 | I16: J | J16: 停止前に蓄えられた運動エネルギー
A17: 慣性モーメント J | B17: 3 | C17: kg·m² | D17: 可 | E17: 停止前の等価慣性モーメント | G17: 必要減速トルク | H17: =Calculations!B44 -> 3.1415927 | I17: Nm | J17: 指定減速時間で停止するための制動トルク（大きさ）
A18: 減速時間 t_dec | B18: 1 | C18: s | D18: 可 | E18: 定常時回転速度から 0 rpm までの停止時間 | G18: 必要回生電流 | H18: =Calculations!B45 -> 0.35418181 | I18: Arms | J18: 回生方向の相電流実効値（大きさ）
A19: DCバス容量 C_dc | B19: 0.01 | C19: F | D19: 可 | E19: 回生電圧上昇予測に使用（例: 10 mF = 0.01 F） | G19: 平均機械回生電力 | H19: =Calculations!B48 -> 1.6449341 | I19: W | J19: 減速1回の平均機械側回生電力
A20: 回生開始DCバス電圧 Vdc_init | B20: =H14 -> 56.827241 | C20: Vdc | D20: 任意 | E20: 初期値は『加速ワースト最低DCバス』。実機のDCバス公称値へ上書き可 | G20: 回生時銅損 | H20: =Calculations!B50 -> 1.1779262 | I20: W | J20: 回生制動中の巻線銅損（R_phase使用）
A21: 回生計算の前提 | B21: 運動エネルギー→DCコンデンサ。理想版と銅損考慮版を併記 | C21: - | D21: 固定 | E21: 理想版: 全慣性エネルギーがC_dcへ流入 / 実効版: 銅損を差し引く | G21: DCバス回収可能エネルギー | H21: =Calculations!B53 -> 0.46700782 | I21: J | J21: 銅損を差し引いた正味回生エネルギー
G22: 回生後DCバス電圧（理想） | H22: =Calculations!B54 -> 59.651674 | I22: V | J22: 全慣性エネルギーがC_dcへ入る上限値
A23: 起動電流立上り時間 | B23: 10 | C23: ms | D23: 可 | E23: 0→I_start までの目標立上り時間（大信号の簡易近似） | G23: 回生後DCバス電圧（銅損考慮） | H23: =Calculations!B55 -> 57.643186 | I23: V | J23: 銅損考慮後の簡易予測値
A24: 電流ループ帯域（参考） | B24: 1000 | C24: Hz | D24: 可 | E24: small-signal の参考値。AKD系の電流ループ補正余裕の参考計算に使用 | G24: 回生電圧上昇 ΔV（理想） | H24: =Calculations!B56 -> 2.8244323 | I24: V | J24: 上限評価
A25: 電流誤差割合（参考） | B25: 0.1 | C25: 比率 | D25: 可 | E25: 帯域ベース参考計算用。例: 0.10 = 起動ピーク電流の10%を補正 | G25: 回生電圧上昇 ΔV（銅損考慮） | H25: =Calculations!B57 -> 0.81594492 | I25: V | J25: 実効評価
A26: 起動Ldi/dtモデル | B26: 大信号：立上り時間基準 / 参考：帯域基準 | C26: - | D26: 固定 | E26: Kollmorgen資料のL-Rモデル/電流ループ帯域の考え方に寄せた簡易追加 | G26: 回生成立判定 | H26: =Calculations!B58 -> DCバス上昇あり | I26: - | J26: 正味回生電力が正ならDCバス上昇あり
A27: チョッパ動作開始電圧 Vdc_chop_on | B27: 75 | C27: Vdc | D27: 可 | E27: ブレーキチョッパがONし始める目安電圧
A28: 許容最大DCバス電圧 Vdc_max | B28: 80 | C28: Vdc | D28: 可 | E28: ドライブ/コンデンサの上限確認用 | G28: τe | H28: =Calculations!B60 -> 0.0036741214 | I28: s | J28: 巻線の電気時定数 = L/R
A29: 判定前提 | B29: 電源は回生吸収しない | C29: - | D29: 固定 | E29: 電源回生ユニットが無い前提で、余剰エネルギーはC_dcまたは回生抵抗で吸収 | G29: f_RL | H29: =Calculations!B61 -> 43.317824 | I29: Hz | J29: 巻線一次遅れの目安帯域 = 1/(2πτe)
A30: 回生抵抗目安 | B30: Vdc_chop_on基準で算出 | C30: - | D30: 固定 | E30: 必要抵抗値は『この値以下』を目安に選定し、許容パルスエネルギーも別途確認 | G30: 起動過渡Vdc_min | H30: =Calculations!B65 -> 66.897857 | I30: Vdc | J30: 起動時にLdi/dtを含めた大信号最低DCバス
G31: 起動過渡Vdc+margin | H31: =Calculations!B66 -> 73.587643 | I31: Vdc | J31: 起動Ldi/dtケースにユーザー余裕を加えた値
G32: 帯域参考V_L | H32: =Calculations!B69 -> 65.205693 | I32: Vpeak | J32: 帯域ベース参考。電流誤差補正に要る相電圧の目安
G33: 正味回生電力（停止開始） | H33: =Calculations!B73 -> 2.1119419 | I33: W | J33: 減速開始瞬間の正味回生電力。抵抗値目安の基準
G34: チョッパ閾値までの吸収余裕 | H34: =Calculations!B74 -> 11.978323 | I34: J | J34: C_dc が Vdc_chop_on に達するまで吸収できるエネルギー
G35: 抵抗で吸収が必要なエネルギー | H35: =Calculations!B75 -> 0 | I35: J | J35: C_dc だけでは足りない正味回生エネルギー
G36: チョッパ動作判定 | H36: =Calculations!B76 -> 動作なし | I36: - | J36: Vdc_final(net) と Vdc_chop_on の比較
G37: 回生抵抗必要判定 | H37: =Calculations!B77 -> 不要 | I37: - | J37: 電源が吸収しない前提での簡易判定
G38: 必要抵抗値の目安（上限） | H38: =Calculations!B78 -> 2663.4256 | I38: Ohm | J38: この値以下であれば、Vdc_chop_on で停止開始時の正味回生電力を吸収しやすい
G39: 抵抗平均電力の目安 | H39: =Calculations!B79 -> 0.46700782 | I39: W | J39: 減速1回の平均正味回生電力
G40: 抵抗パルスエネルギー目安 | H40: =Calculations!B80 -> 0 | I40: J | J40: 1回の減速で抵抗側に逃がす必要があるエネルギー
G41: DCバス上限判定 | H41: =Calculations!B81 -> 上限内 | I41: - | J41: Vdc_final(net) が Vdc_max を超えるかの確認

Sheet Calculations
A1: Kollmorgen の定義に整合させた計算結果
A3: 計算項目 | B3: 式 / 結果 | C3: 単位 | D3: 意味 | E3: Kollmorgen基準 | F3: コメント
A4: 機械角速度 ωm | B4: =Inputs!B4*2*PI()/60 -> 1.0471976 | C4: rad/s | D4: 機械角速度 | E4: -
A5: 電気角速度 ωe | B5: =B4*Inputs!B5 -> 33.510322 | C5: rad/s | D5: 電気角速度 | E5: -
A6: I_rms | B6: =Inputs!B6/Inputs!B7 -> 3.4047351 | C6: Arms | D6: T / Kt から求めたトルク電流 | E6: KTrms = Nm/Arms
A7: I_peak | B7: =SQRT(2)*B6 -> 4.8150225 | C7: Apeak | D7: ピーク相電流 = √2 × I_rms | E7: -
A8: Ke推定 crest（Kt由来） | B8: =Inputs!B7 -> 8.87 | C8: V/(rad/s) | D8: Kt から推定した線間 crest の Ke | E8: Ke_crest[V/(rad/s)] = Kt[Nm/Arms] | F8: Kollmorgen 白書の crest 定義
A9: Ke推定 rms（Kt由来） | B9: =B8/SQRT(3) -> 5.1210969 | C9: V/(rad/s) | D9: Kt から推定した線間 RMS の Ke | E9: Ke_rms = Ke_crest / √3 | F9: 線間RMS逆起電力で使用
A10: Ke推定 rms（Kt由来） | B10: =B9*1000*2*PI()/60 -> 536.28001 | C10: Vrms/krpm | D10: RMS の V/(rad/s) を Vrms/krpm に換算 | E10: - | F10: Ke_rms × 1000rpm 相当の rad/s
A11: 有効Ke | B11: =IF(OR(Inputs!B8="",ISBLANK(Inputs!B8)),B9,Inputs!B8*60/(1000*2*PI())) -> 5.1210969 | C11: V/(rad/s) | D11: Ke override が空欄のときに使用 | E11: SI系の線間RMS有効Ke | F11: override は線間RMSの Vrms/krpm
A12: 有効Ke | B12: =IF(OR(Inputs!B8="",ISBLANK(Inputs!B8)),B10,Inputs!B8) -> 536.28001 | C12: Vrms/krpm | D12: 本ブックで使用する値。override があれば優先 | E12: 線間RMS / krpm | F12: 線間RMSの Vrms/krpm
A13: 相抵抗 R_phase（設計） | B13: =Inputs!B9/2*Inputs!B11 -> 3.13 | C13: Ohm | D13: 相抵抗 = R_ll / 2 × 設計倍率 | E13: R データシート値は線間
A14: 相抵抗 R_phase（高温1.525x） | B14: =Inputs!B9/2*1.525 -> 4.77325 | C14: Ohm | D14: 相抵抗 = R_ll / 2 × 1.525 | E14: 高温銅抵抗の参照 | F14: Kollmorgen 白書文脈の例
A15: 相インダクタンス L_phase | B15: =Inputs!B10/1000/2 -> 0.0115 | C15: H | D15: 相インダクタンス = L_ll / 2 | E15: L データシート値は線間
A16: E_LL_rms | B16: =B11*B4 -> 5.3628001 | C16: Vrms | D16: 回転時の線間逆起電力 RMS | E16: Ke は線間RMS
A17: E_phase_rms | B17: =B16/SQRT(3) -> 3.0962141 | C17: Vrms | D17: 各相の逆起電力 RMS | E17: Y結線
A18: E_phase_peak | B18: =SQRT(2)*B17 -> 4.378708 | C18: Vpeak | D18: 各相の逆起電力 peak | E18: -
A19: V_R_phase_peak（設計） | B19: =B13*B7 -> 15.07102 | C19: Vpeak | D19: 設計倍率時の抵抗降下 | E19: -
A20: V_R_phase_peak（高温1.525x） | B20: =B14*B7 -> 22.983306 | C20: Vpeak | D20: 高温時の抵抗降下 | E20: -
A21: V_L_phase_peak | B21: =B5*B15*B7 -> 1.855559 | C21: Vpeak | D21: 極対数 p を含むインダクタンス降下 | E21: id = 0 近似 | F21: ωe × L_phase × I_peak
A22: V_phase_peak_req（設計） | B22: =SQRT(B21^2+(B18+B19)^2) -> 19.538041 | C22: Vpeak | D22: 必要相ピーク電圧（設計） | E22: id = 0 近似 | F22: sqrt((ωeLIpk)^2 + (Epk + RIpk)^2)
A23: V_phase_peak_req（高温1.525x） | B23: =SQRT(B21^2+(B18+B20)^2) -> 27.424859 | C23: Vpeak | D23: 必要相ピーク電圧（高温） | E23: id = 0 近似 | F23: 高温Rを使用
A24: Vdc_min no-load ideal | B24: =SQRT(2)*B16 -> 7.5841447 | C24: Vdc | D24: SVPWM理想無負荷最低DCバス | E24: SVPWM 線形領域 | F24: √2 × E_LL_rms
A25: Vdc_min load（設計） | B25: =SQRT(3)*B22 -> 33.840879 | C25: Vdc | D25: 要求負荷時の最低DCバス | E25: SVPWM 線形領域 | F25: √3 × V_phase_peak_req
A26: Vdc_min load（高温1.525x） | B26: =SQRT(3)*B23 -> 47.50125 | C26: Vdc | D26: 高温時・要求負荷での最低DCバス | E26: SVPWM 線形領域 | F26: √3 × V_phase_peak_req_hot
A27: Vdc_min load + margin（設計） | B27: =B25*(1+Inputs!B12) -> 37.224967 | C27: Vdc | D27: ユーザー余裕込みの設計DCバス | E27: ユーザー余裕 | F27: 負荷ケース × (1 + margin)
A28: Vdc_min load + margin（高温1.525x） | B28: =B26*(1+Inputs!B12) -> 52.251375 | C28: Vdc | D28: ユーザー余裕込みの高温DCバス | E28: ユーザー余裕 | F28: 高温ケース × (1 + margin)
A29: 起動電流倍率 | B29: =Inputs!B15 -> 1.8741722 | C29: x | D29: 起動電流用のユーザー入力倍率 | E29: - | F29: Inputs シートで編集
A30: I_start | B30: =B6*B29 -> 6.3810598 | C30: Arms | D30: 起動RMS電流 | E30: - | F30: I_start = 倍率 × I_rms
A31: I_start_peak | B31: =SQRT(2)*B30 -> 9.0241812 | C31: Apeak | D31: 起動時ピーク相電流 | E31: - | F31: √2 × I_start
A32: V_R_phase_peak（起動） | B32: =B13*B31 -> 28.245687 | C32: Vpeak | D32: ゼロ速度での抵抗降下 | E32: - | F32: R_phase(design) × I_start_peak
A33: Vdc_min startup | B33: =SQRT(3)*B32 -> 48.922965 | C33: Vdc | D33: ゼロ速度起動時の最低DCバス | E33: SVPWM 線形領域 | F33: √3 × V_R_phase_peak(startup)
A34: Vdc_min startup + margin | B34: =B33*(1+Inputs!B12) -> 53.815262 | C34: Vdc | D34: 起動ケースにユーザー余裕を加えたDCバス | E34: ユーザー余裕 | F34: 起動ケース × (1 + margin)
A35: V_L_phase_peak（加速ワースト） | B35: =B5*B15*B31 -> 3.477637 | C35: Vpeak | D35: I_start と終速度でのインダクタンス降下 | E35: id = 0 近似 | F35: ωe × L_phase × I_start_peak
A36: V_q_phase_peak（加速ワースト） | B36: =B18+B32 -> 32.624395 | C36: Vpeak | D36: 加速ワースト時の抵抗 + 逆起電力項 | E36: id = 0 近似 | F36: E_phase_peak + R_phase(design) × I_start_peak
A37: V_phase_peak_req（加速ワースト） | B37: =SQRT(B35^2 + B36^2) -> 32.809223 | C37: Vpeak | D37: 加速中ワーストの必要相ピーク電圧 | E37: 詳細版対応 | F37: sqrt(VL^2 + Vq^2)
A38: V_ll_rms_req（加速ワースト） | B38: =SQRT(3/2)*B37 -> 40.182928 | C38: Vrms | D38: 加速中ワーストの線間RMS換算 | E38: 詳細版対応 | F38: √(3/2) × V_phase_peak_req
A39: Vdc_min accel worst | B39: =SQRT(3)*B37 -> 56.827241 | C39: Vdc | D39: 加速中ワーストの最低DCバス | E39: SVPWM 線形領域 | F39: √3 × V_phase_peak_req
A40: Vdc_min accel worst + margin | B40: =B39*(1+Inputs!$B$12) -> 62.509966 | C40: Vdc | D40: 加速ワーストにユーザー余裕を加えたDCバス | E40: ユーザー余裕 | F40: 加速ワースト × (1 + margin)
A41: 回生制動（停止時）の計算
...

Sheet Notes
A1: 使用している前提 / 計算式
A3: 項目 | B3: 説明
A4: Kollmorgen の Kt | B4: 正弦波通電時の KTrms（Nm/Arms）として扱います。
A5: Kollmorgen の Ke | B5: 本シートでは Kollmorgen 白書にある crest と RMS の定義を分けて扱います。線間の Ke_crest [V/(rad/s)] は Kt から推定し、線間の Ke_rms [V/(rad/s)] = Ke_crest / sqrt(2) とします。入力/上書きに使う Ke は線間RMSの Vrms/krpm です。
A6: 抵抗 / インダクタンス | B6: Kollmorgen のデータシートでは線間値が載ることが多いため、内部Y結線を前提に R_phase = R_ll / 2、L_phase = L_ll / 2 を使います。
A7: 電流の定義 | B7: I_rms = T / Kt、I_peak = sqrt(2) × I_rms。
A8: 逆起電力 | B8: E_LL_rms = Ke_active_rms × n / 1000 = Ke_active_rms_SI × ωm。E_phase_rms = E_LL_rms / sqrt(3)。
A9: 電圧モデル | B9: id = 0 近似として、V_phase_peak_req = sqrt((ωe L_phase I_peak)^2 + (E_phase_peak + R_phase I_peak)^2)。
A10: SVPWM 最低DCバス | B10: SVPWM 線形領域を仮定し、Vdc_min_no_load = sqrt(2) × E_LL_rms、Vdc_min_load = sqrt(3) × V_phase_peak_req としています。
A11: Kollmorgen 白書との整合 | B11: 本シートは、Kollmorgen のサーボモータ定数変換白書で使われている crest-to-RMS の区別に合わせています。
A12: 高温参照ケース | B12: Kollmorgen 白書文脈の例に合わせ、R を 1.525 倍した高温銅抵抗ケースを含めています。
A13: 安全マージン | B13: 入力した margin に対して、負荷時の Vdc 結果へ (1 + margin) を掛けます。10%の余裕なら 0.10 を入力してください。
A14: 注意 | B14: これは実務向けの簡易計算シートであり、dq軸飽和や弱め界磁まで含む完全モデルではありません。データシートに検証済みの線間RMS Ke がある場合は、override セルへ入力してください。
... A42: DCバス上限判定 | B42: Vdc_final(net) が Vdc_max を超える場合は、コンデンサだけでは危険で、減速条件の緩和・回生電源・ブレーキチョッパ/抵抗などの対策が必要です。
