Workbook

Sheet Summary
A1: EMI Filter Differential-Mode ABCD Model
A3: Purpose | B3: 試験系AC電源＋ライン＋貫通コンデンサ＋入力EMIフィルタ＋負荷のDM周波数特性
A4: Calculation | B4: ABCD行列を実部・虚部に分けてExcel数式で逐次カスケード
A5: Output | B5: Results: Vload/Vsource [dB] for ROUT=0Ω and 50Ω
A6: Frequency | B6: 100 Hz ～ 100 MHz, log-spaced 1201 points
A7: Editable inputs | B7: Parameters!C:C
A8: Python correspondence | B8: Python基準モデルと同じDM等価化
A9: LTspice note | B9: LTspiceでLの既定Rser=1mΩがある場合、外付けDCRを1mΩ引くと一致
A10: Use | B10: パラメータ変更後にExcelで再計算してください。

Sheet Parameters
A1: Block | B1: Parameter | C1: Value (SI) | D1: Unit | E1: Notes
A2: Calculation | B2: f_start | C2: 100 | D2: Hz | E2: Start frequency
A3: Calculation | B3: f_stop | C3: 100000000 | D3: Hz | E3: Stop frequency
A4: Calculation | B4: n_points | C4: 1201 | D4: - | E4: Log-spaced points, 200 points/decade
A5: Source_load | B5: Vsource | C5: 115 | D5: Vrms | E5: Small-signal gain uses AC=1 equivalent
A6: Source_load | B6: Rload | C6: 28.75 | D6: ohm | E6: DUMMY load HOT-RTN
A7: Source_load | B7: Rout_0 | C7: 0 | D7: ohm | E7: Source output resistance case 1
A8: Source_load | B8: Rout_50 | C8: 50 | D8: ohm | E8: Source output resistance case 2
A9: LINE_PS | B9: L_each | C9: 1e-06 | D9: H | E9: Each conductor
A10: LINE_PS | B10: DCR_each | C10: 0.02 | D10: ohm | E10: Each conductor
A11: LINE_PS | B11: C_CHA_each | C11: 5e-11 | D11: F | E11: Line to chassis per conductor
A12: LINE_PS | B12: C_LINE | C12: 5e-11 | D12: F | E12: HOT-RTN capacitance
A13: C_THROUGH | B13: C_each | C13: 1e-05 | D13: F | E13: Each feedthrough capacitor to chassis
... A47: CY | B47: ESR_each | C47: 0.02 | D47: ohm | E47: Each Y capacitor

Sheet Results
A1: Frequency_Hz | B1: log10_f | C1: Gain_ROUT0_dB | D1: Gain_ROUT50_dB | E1: AbsH_ROUT0 | F1: AbsH_ROUT50
A2: =Calc_ABCD!A2 -> 100 | B2: =Calc_ABCD!B2 -> 2 | C2: =Calc_ABCD!FB2 -> -0.10704231 | D2: =Calc_ABCD!FF2 -> -8.8179518 | E2: =Calc_ABCD!FC2 -> 0.98775192 | F2: =Calc_ABCD!FG2 -> 0.36232843
A3: =Calc_ABCD!A3 -> 101.15795 | B3: =Calc_ABCD!B3 -> 2.005 | C3: =Calc_ABCD!FB3 -> -0.10701797 | D3: =Calc_ABCD!FF3 -> -8.8185573 | E3: =Calc_ABCD!FC3 -> 0.98775469 | F3: =Calc_ABCD!FG3 -> 0.36230317
A4: =Calc_ABCD!A4 -> 102.3293 | B4: =Calc_ABCD!B4 -> 2.01 | C4: =Calc_ABCD!FB4 -> -0.10699307 | D4: =Calc_ABCD!FF4 -> -8.8191768 | E4: =Calc_ABCD!FC4 -> 0.98775752 | F4: =Calc_ABCD!FG4 -> 0.36227733
A5: =Calc_ABCD!A5 -> 103.51422 | B5: =Calc_ABCD!B5 -> 2.015 | C5: =Calc_ABCD!FB5 -> -0.10696758 | D5: =Calc_ABCD!FF5 -> -8.8198107 | E5: =Calc_ABCD!FC5 -> 0.98776042 | F5: =Calc_ABCD!FG5 -> 0.36225089
A6: =Calc_ABCD!A6 -> 104.71285 | B6: =Calc_ABCD!B6 -> 2.02 | C6: =Calc_ABCD!FB6 -> -0.1069415 | D6: =Calc_ABCD!FF6 -> -8.8204592 | E6: =Calc_ABCD!FC6 -> 0.98776339 | F6: =Calc_ABCD!FG6 -> 0.36222385
A7: =Calc_ABCD!A7 -> 105.92537 | B7: =Calc_ABCD!B7 -> 2.025 | C7: =Calc_ABCD!FB7 -> -0.10691482 | D7: =Calc_ABCD!FF7 -> -8.8211228 | E7: =Calc_ABCD!FC7 -> 0.98776642 | F7: =Calc_ABCD!FG7 -> 0.36219618
A8: =Calc_ABCD!A8 -> 107.15193 | B8: =Calc_ABCD!B8 -> 2.03 | C8: =Calc_ABCD!FB8 -> -0.10688751 | D8: =Calc_ABCD!FF8 -> -8.8218016 | E8: =Calc_ABCD!FC8 -> 0.98776953 | F8: =Calc_ABCD!FG8 -> 0.36216787
A9: =Calc_ABCD!A9 -> 108.39269 | B9: =Calc_ABCD!B9 -> 2.035 | C9: =Calc_ABCD!FB9 -> -0.10685957 | D9: =Calc_ABCD!FF9 -> -8.8224962 | E9: =Calc_ABCD!FC9 -> 0.98777271 | F9: =Calc_ABCD!FG9 -> 0.36213891
A10: =Calc_ABCD!A10 -> 109.64782 | B10: =Calc_ABCD!B10 -> 2.04 | C10: =Calc_ABCD!FB10 -> -0.10683097 | D10: =Calc_ABCD!FF10 -> -8.8232068 | E10: =Calc_ABCD!FC10 -> 0.98777596 | F10: =Calc_ABCD!FG10 -> 0.36210928
A11: =Calc_ABCD!A11 -> 110.91748 | B11: =Calc_ABCD!B11 -> 2.045 | C11: =Calc_ABCD!FB11 -> -0.10680171 | D11: =Calc_ABCD!FF11 -> -8.8239339 | E11: =Calc_ABCD!FC11 -> 0.98777929 | F11: =Calc_ABCD!FG11 -> 0.36207897
A12: =Calc_ABCD!A12 -> 112.20185 | B12: =Calc_ABCD!B12 -> 2.05 | C12: =Calc_ABCD!FB12 -> -0.10677177 | D12: =Calc_ABCD!FF12 -> -8.8246777 | E12: =Calc_ABCD!FC12 -> 0.98778269 | F12: =Calc_ABCD!FG12 -> 0.36204797
A13: =Calc_ABCD!A13 -> 113.50108 | B13: =Calc_ABCD!B13 -> 2.055 | C13: =Calc_ABCD!FB13 -> -0.10674113 | D13: =Calc_ABCD!FF13 -> -8.8254388 | E13: =Calc_ABCD!FC13 -> 0.98778617 | F13: =Calc_ABCD!FG13 -> 0.36201625
... A1202: =Calc_ABCD!A1202 -> 100000000 | B1202: =Calc_ABCD!B1202 -> 8 | C1202: =Calc_ABCD!FB1202 -> -188.33731 | D1202: =Calc_ABCD!FF1202 -> -188.34394 | E1202: =Calc_ABCD!FC1202 -> 3.8294321e-10 | F1202: =Calc_ABCD!FG1202 -> 3.826513e-10

Sheet Calc_ABCD
A1: f_Hz | B1: log10_f | C1: omega_rad_s | D1: A0_r | E1: A0_i | F1: B0_r | G1: B0_i | H1: C0_r | I1: C0_i | J1: D0_r | K1: D0_i | L1: LINE_PS_SER_Zr | M1: LINE_PS_SER_Zi | N1: LINE_PS_SER_Yr | O1: LINE_PS_SER_Yi | P1: LINE_PS_SER_Ar | Q1: LINE_PS_SER_Ai | R1: LINE_PS_SER_Br | S1: LINE_PS_SER_Bi | T1: LINE_PS_SER_Cr | U1: LINE_PS_SER_Ci | V1: LINE_PS_SER_Dr | W1: LINE_PS_SER_Di | X1: LINE_PS_SH_Zr | Y1: LINE_PS_SH_Zi | Z1: LINE_PS_SH_Yr | AA1: LINE_PS_SH_Yi | AB1: LINE_PS_SH_Ar | AC1: LINE_PS_SH_Ai | AD1: LINE_PS_SH_Br | AE1: LINE_PS_SH_Bi | AF1: LINE_PS_SH_Cr | AG1: LINE_PS_SH_Ci | AH1: LINE_PS_SH_Dr | AI1: LINE_PS_SH_Di | AJ1: C_THROUGH_Zr | AK1: C_THROUGH_Zi | AL1: C_THROUGH_Yr | AM1: C_THROUGH_Yi | AN1: C_THROUGH_Ar | AO1: C_THROUGH_Ai | AP1: C_THROUGH_Br | AQ1: C_THROUGH_Bi | AR1: C_THROUGH_Cr | AS1: C_THROUGH_Ci | AT1: C_THROUGH_Dr | AU1: C_THROUGH_Di | AV1: LINE_INPUT_SER_Zr | AW1: LINE_INPUT_SER_Zi | AX1: LINE_INPUT_SER_Yr | AY1: LINE_INPUT_SER_Yi | AZ1: LINE_INPUT_SER_Ar | BA1: LINE_INPUT_SER_Ai | BB1: LINE_INPUT_SER_Br | BC1: LINE_INPUT_SER_Bi | BD1: LINE_INPUT_SER_Cr | BE1: LINE_INPUT_SER_Ci | BF1: LINE_INPUT_SER_Dr | BG1: LINE_INPUT_SER_Di | BH1: LINE_INPUT_SH_Zr | BI1: LINE_INPUT_SH_Zi | BJ1: LINE_INPUT_SH_Yr | BK1: LINE_INPUT_SH_Yi | BL1: LINE_INPUT_SH_Ar | BM1: LINE_INPUT_SH_Ai | BN1: LINE_INPUT_SH_Br | BO1: LINE_INPUT_SH_Bi | BP1: LINE_INPUT_SH_Cr | BQ1: LINE_INPUT_SH_Ci | BR1: LINE_INPUT_SH_Dr | BS1: LINE_INPUT_SH_Di | BT1: LDM1_Zr | BU1: LDM1_Zi | BV1: LDM1_Yr | BW1: LDM1_Yi | BX1: LDM1_Ar | BY1: LDM1_Ai | BZ1: LDM1_Br | CA1: LDM1_Bi | CB1: LDM1_Cr | CC1: LDM1_Ci | CD1: LDM1_Dr | CE1: LDM1_Di | CF1: CX1_DUMP1_Zr | CG1: CX1_DUMP1_Zi | CH1: CX1_DUMP1_Yr | CI1: CX1_DUMP1_Yi | CJ1: CX1_DUMP1_Ar | CK1: CX1_DUMP1_Ai | CL1: CX1_DUMP1_Br | CM1: CX1_DUMP1_Bi | CN1: CX1_DUMP1_Cr | CO1: CX1_DUMP1_Ci | CP1: CX1_DUMP1_Dr | CQ1: CX1_DUMP1_Di | CR1: LDM2_Zr | CS1: LDM2_Zi | CT1: LDM2_Yr | CU1: LDM2_Yi | CV1: LDM2_Ar | CW1: LDM2_Ai | CX1: LDM2_Br | CY1: LDM2_Bi | CZ1: LDM2_Cr | DA1: LDM2_Ci | DB1: LDM2_Dr | DC1: LDM2_Di | DD1: CX2_DUMP2_Zr | DE1: CX2_DUMP2_Zi | DF1: CX2_DUMP2_Yr | DG1: CX2_DUMP2_Yi | DH1: CX2_DUMP2_Ar | DI1: CX2_DUMP2_Ai | DJ1: CX2_DUMP2_Br | DK1: CX2_DUMP2_Bi | DL1: CX2_DUMP2_Cr | DM1: CX2_DUMP2_Ci | DN1: CX2_DUMP2_Dr | DO1: CX2_DUMP2_Di | DP1: CMC_LEAK_Zr | DQ1: CMC_LEAK_Zi | DR1: CMC_LEAK_Yr | DS1: CMC_LEAK_Yi | DT1: CMC_LEAK_Ar | DU1: CMC_LEAK_Ai | DV1: CMC_LEAK_Br | DW1: CMC_LEAK_Bi | DX1: CMC_LEAK_Cr | DY1: CMC_LEAK_Ci | DZ1: CMC_LEAK_Dr | EA1: CMC_LEAK_Di | EB1: CMC_CLINE_Zr | EC1: CMC_CLINE_Zi | ED1: CMC_CLINE_Yr | EE1: CMC_CLINE_Yi | EF1: CMC_CLINE_Ar | EG1: CMC_CLINE_Ai | EH1: CMC_CLINE_Br | EI1: CMC_CLINE_Bi | EJ1: CMC_CLINE_Cr | EK1: CMC_CLINE_Ci | EL1: CMC_CLINE_Dr | EM1: CMC_CLINE_Di | EN1: CY_PAIR_Zr | EO1: CY_PAIR_Zi | EP1: CY_PAIR_Yr | EQ1: CY_PAIR_Yi | ER1: CY_PAIR_Ar | ES1: CY_PAIR_Ai | ET1: CY_PAIR_Br | EU1: CY_PAIR_Bi | EV1: CY_PAIR_Cr | EW1: CY_PAIR_Ci | EX1: CY_PAIR_Dr | EY1: CY_PAIR_Di | EZ1: Den0_r | FA1: Den0_i | FB1: Gain_Rout0_dB | FC1: AbsH_Rout0 | FD1: Den50_r | FE1: Den50_i | FF1: Gain_Rout50_dB | FG1: AbsH_Rout50
A2: =Parameters!$C$2*(Parameters!$C$3/Parameters!$C$2)^((ROW()-2)/(Parameters!$C$4-1)) -> 100 | B2: =LOG10(A2) -> 2 | C2: =2*PI()*A2 -> 628.31853 | D2: =1 -> 1 | E2: =0 -> 0 | F2: =0 -> 0 | G2: =0 -> 0 | H2: =0 -> 0 | I2: =0 -> 0 | J2: =1 -> 1 | K2: =0 -> 0 | L2: =2*Parameters!$C$10 -> 0.04 | M2: =2*C2*Parameters!$C$9 -> 0.0012566371 | N2: =0 -> 0 | O2: =0 -> 0 | P2: =D2 -> 1 | Q2: =E2 -> 0 | R2: =F2+D2*L2-E2*M2 -> 0.04 | S2: =G2+D2*M2+E2*L2 -> 0.0012566371 | T2: =H2 -> 0 | U2: =I2 -> 0 | V2: =J2+H2*L2-I2*M2 -> 1 | W2: =K2+H2*M2+I2*L2 -> 0 | X2: =0 -> 0 | Y2: =0 -> 0 | Z2: =0 -> 0 | AA2: =C2*(Parameters!$C$12+Parameters!$C$11/2) -> 4.712389e-08 | AB2: =P2+R2*Z2-S2*AA2 -> 1 | AC2: =Q2+R2*AA2+S2*Z2 -> 1.8849556e-09 | AD2: =R2 -> 0.04 | AE2: =S2 -> 0.0012566371 | AF2: =T2+V2*Z2-W2*AA2 -> 0 | AG2: =U2+V2*AA2+W2*Z2 -> 4.712389e-08 | AH2: =V2 -> 1 | AI2: =W2 -> 0 | AJ2: =0 -> 0 | AK2: =0 -> 0 | AL2: =(((2*Parameters!$C$15))/(((2*Parameters!$C$15))^2+((2*(C2*Parameters!$C$14-1/(C2*Parameters!$C$13))))^2)) -> 3.947842e-07 | AM2: =(-((2*(C2*Parameters!$C$14-1/(C2*Parameters!$C$13))))/(((2*Parameters!$C$15))^2+((2*(C2*Parameters!$C$14-1/(C2*Parameters!$C$13))))^2)) -> 0.0031415927 | AN2: =AB2+AD2*AL2-AE2*AM2 -> 0.99999607 | AO2: =AC2+AD2*AM2+AE2*AL2 -> 0.00012566609 | AP2: =AD2 -> 0.04 | AQ2: =AE2 -> 0.0012566371 | AR2: =AF2+AH2*AL2-AI2*AM2 -> 3.947842e-07 | AS2: =AG2+AH2*AM2+AI2*AL2 -> 0.0031416399 | AT2: =AH2 -> 1 | AU2: =AI2 -> 0 | AV2: =2*Parameters!$C$17 -> 0.04 | AW2: =2*C2*Parameters!$C$16 -> 0.0012566371 | AX2: =0 -> 0 | AY2: =0 -> 0 | AZ2: =AN2 -> 0.99999607 | BA2: =AO2 -> 0.00012566609 | BB2: =AP2+AN2*AV2-AO2*AW2 -> 0.079999685 | BC2: =AQ2+AN2*AW2+AO2*AV2 -> 0.0025182958 | BD2: =AR2 -> 3.947842e-07 | BE2: =AS2 -> 0.0031416399 | BF2: =AT2+AR2*AV2-AS2*AW2 -> 0.99999607 | BG2: =AU2+AR2*AW2+AS2*AV2 -> 0.00012566609 | BH2: =0 -> 0 | BI2: =0 -> 0 | BJ2: =0 -> 0 | BK2: =C2*(Parameters!$C$19+Parameters!$C$18/2) -> 4.712389e-08 | BL2: =AZ2+BB2*BJ2-BC2*BK2 -> 0.99999607 | BM2: =BA2+BB2*BK2+BC2*BJ2 -> 0.00012566986 | BN2: =BB2 -> 0.079999685 | BO2: =BC2 -> 0.0025182958 | BP2: =BD2+BF2*BJ2-BG2*BK2 -> 3.9477828e-07 | BQ2: =BE2+BF2*BK2+BG2*BJ2 -> 0.003141687 | BR2: =BF2 -> 0.99999607 | BS2: =BG2 -> 0.00012566609 | BT2: =2*((((Parameters!$C$21)/((Parameters!$C$21)^2+(C2*Parameters!$C$20)^2)))/((((Parameters!$C$21)/((Parameters!$C$21)^2+(C2*Parameters!$C$20)^2)))^2+((-(C2*Parameters!$C$20)/((Parameters!$C$21)^2+(C2*Parameters!$C$20)^2)+C2*Parameters!$C$22))^2)) -> 0.04 | BU2: =2*(-((-(C2*Parameters!$C$20)/((Parameters!$C$21)^2+(C2*Parameters!$C$20)^2)+C2*Parameters!$C$22))/((((Parameters!$C$21)/((Parameters!$C$21)^2+(C2*Parameters!$C$20)^2)))^2+((-(C2*Parameters!$C$20)/((Parameters!$C$21)^2+(C2*Parameters!$C$20)^2)+C2*Parameters!$C$22))^2)) -> 0.08545132 | BV2: =0 -> 0 | BW2: =0 -> 0 | BX2: =BL2 -> 0.99999607 | BY2: =BM2 -> 0.00012566986 | BZ2: =BN2+BL2*BT2-BM2*BU2 -> 0.11998879 | CA2: =BO2+BL2*BU2+BM2*BT2 -> 0.087974307 | CB2: =BP2 -> 3.9477828e-07 | CC2: =BQ2 -> 0.003141687 | CD2: =BR2+BP2*BT2-BQ2*BU2 -> 0.99972762 | CE2: =BS2+BP2*BU2+BQ2*BT2 -> 0.0002513673 | CF2: =0 -> 0 | CG2: =0 -> 0 | CH2: =(((Parameters!$C$25))/(((Parameters!$C$25))^2+((C2*Parameters!$C$24-1/(C2*Parameters!$C$23)))^2))+(((Parameters!$C$29+Parameters!$C$28))/(((Parameters!$C$29+Parameters!$C$28))^2+((C2*Parameters!$C$27-1/(C2*Parameters!$C$26)))^2)) -> 1.3115799e-06 | CI2: =(-((C2*Parameters!$C$24-1/(C2*Parameters!$C$23)))/(((Parameters!$C$25))^2+((C2*Parameters!$C$24-1/(C2*Parameters!$C$23)))^2))+(-((C2*Parameters!$C$27-1/(C2*Parameters!$C$26)))/(((Parameters!$C$29+Parameters!$C$28))^2+((C2*Parameters!$C$27-1/(C2*Parameters!$C$26)))^2)) -> 0.00059061361 | CJ2: =BX2+BZ2*CH2-CA2*CI2 -> 0.99994427 | CK2: =BY2+BZ2*CI2+CA2*CH2 -> 0.00019665226 | CL2: =BZ2 -> 0.11998879 | CM2: =CA2 -> 0.087974307 | CN2: =CB2+CD2*CH2-CE2*CI2 -> 1.55754e-06 | CO2: =CC2+CD2*CI2+CE2*CH2 -> 0.00373214 | CP2: =CD2 -> 0.99972762 | CQ2: =CE2 -> 0.0002513673 | CR2: =2*((((Parameters!$C$31)/((Parameters!$C$31)^2+(C2*Parameters!$C$30)^2)))/((((Parameters!$C$31)/((Parameters!$C$31)^2+(C2*Parameters!$C$30)^2)))^2+((-(C2*Parameters!$C$30)/((Parameters!$C$31)^2+(C2*Parameters!$C$30)^2)+C2*Parameters!$C$32))^2)) -> 0.04 | CS2: =2*(-((-(C2*Parameters!$C$30)/((Parameters!$C$31)^2+(C2*Parameters!$C$30)^2)+C2*Parameters!$C$32))/((((Parameters!$C$31)/((Parameters!$C$31)^2+(C2*Parameters!$C$30)^2)))^2+((-(C2*Parameters!$C$30)/((Parameters!$C$31)^2+(C2*Parameters!$C$30)^2)+C2*Parameters!$C$32))^2)) -> 0.041469023 | CT2: =0 -> 0 | CU2: =0 -> 0 | CV2: =CJ2 -> 0.99994427 | CW2: =CK2 -> 0.00019665226 | CX2: =CL2+CJ2*CR2-CK2*CS2 -> 0.1599784 | CY2: =CM2+CJ2*CS2+CK2*CR2 -> 0.12944888 | CZ2: =CN2 -> 1.55754e-06 | DA2: =CO2 -> 0.00373214 | DB2: =CP2+CN2*CR2-CO2*CS2 -> 0.99957292 | DC2: =CQ2+CN2*CS2+CO2*CR2 -> 0.0004007175 | DD2: =0 -> 0 | DE2: =0 -> 0 | DF2: =(((Parameters!$C$35))/(((Parameters!$C$35))^2+((C2*Parameters!$C$34-1/(C2*Parameters!$C$33)))^2))+(((Parameters!$C$39+Parameters!$C$38))/(((Parameters!$C$39+Parameters!$C$38))^2+((C2*Parameters!$C$37-1/(C2*Parameters!$C$36)))^2)) -> 1.3115799e-06 | DG2: =(-((C2*Parameters!$C$34-1/(C2*Parameters!$C$33)))/(((Parameters!$C$35))^2+((C2*Parameters!$C$34-1/(C2*Parameters!$C$33)))^2))+(-((C2*Parameters!$C$37-1/(C2*Parameters!$C$36)))/(((Parameters!$C$39+Parameters!$C$38))^2+((C2*Parameters!$C$37-1/(C2*Parameters!$C$36)))^2)) -> 0.00059061361 | DH2: =CV2+CX2*DF2-CY2*DG2 -> 0.99986802 | DI2: =CW2+CX2*DG2+CY2*DF2 -> 0.00029130746 | DJ2: =CX2 -> 0.1599784 | DK2: =CY2 -> 0.12944888 | DL2: =CZ2+DB2*DF2-DC2*DG2 -> 2.6318906e-06 | DM2: =DA2+DB2*DG2+DC2*DF2 -> 0.0043225019 | DN2: =DB2 -> 0.99957292 | DO2: =DC2 -> 0.0004007175 | DP2: =2*((((Parameters!$C$41)/((Parameters!$C$41)^2+(C2*(Parameters!$C$40*(1-Parameters!$C$42)))^2)))/((((Parameters!$C$41)/((Parameters!$C$41)^2+(C2*(Parameters!$C$40*(1-Parameters!$C$42)))^2)))^2+((-(C2*(Parameters!$C$40*(1-Parameters!$C$42)))/((Parameters!$C$41)^2+(C2*(Parameters!$C$40*(1-Parameters!$C$42)))^2)+C2*Parameters!$C$43))^2)) -> 0.2 | DQ2: =2*(-((-(C2*(Parameters!$C$40*(1-Parameters!$C$42)))/((Parameters!$C$41)^2+(C2*(Parameters!$C$40*(1-Parameters!$C$42)))^2)+C2*Parameters!$C$43))/((((Parameters!$C$41)/((Parameters!$C$41)^2+(C2*(Parameters!$C$40*(1-Parameters!$C$42)))^2)))^2+((-(C2*(Parameters!$C$40*(1-Parameters!$C$42)))/((Parameters!$C$41)^2+(C2*(Parameters!$C$40*(1-Parameters!$C$42)))^2)+C2*Parameters!$C$43))^2)) -> 0.0037699111 | DR2: =0 -> 0 | DS2: =0 -> 0 | DT2: =DH2 -> 0.99986802 | DU2: =DI2 -> 0.00029130746 | DV2: =DJ2+DH2*DP2-DI2*DQ2 -> 0.35995091 | DW2: =DK2+DH2*DQ2+DI2*DP2 -> 0.13327656 | DX2: =DL2 -> 2.6318906e-06 | DY2: =DM2 -> 0.0043225019 | DZ2: =DN2+DL2*DP2-DM2*DQ2 -> 0.99955715 | EA2: =DO2+DL2*DQ2+DM2*DP2 -> 0.0012652278 | EB2: =0 -> 0 | EC2: =0 -> 0 | ED2: =0 -> 0 | EE2: =C2*Parameters!$C$44 -> 6.2831853e-09 | EF2: =DT2+DV2*ED2-DW2*EE2 -> 0.99986802 | EG2: =DU2+DV2*EE2+DW2*ED2 -> 0.00029130972 | EH2: =DV2 -> 0.35995091 | EI2: =DW2 -> 0.13327656 | EJ2: =DX2+DZ2*ED2-EA2*EE2 -> 2.6318826e-06 | EK2: =DY2+DZ2*EE2+EA2*ED2 -> 0.0043225082 | EL2: =DZ2 -> 0.99955715 | EM2: =EA2 -> 0.0012652278 | EN2: =0 -> 0 | EO2: =0 -> 0 | EP2: =(((2*Parameters!$C$47))/(((2*Parameters!$C$47))^2+((2*(C2*Parameters!$C$46-1/(C2*Parameters!$C$45))))^2)) -> 1.9107554e-14 | EQ2: =(-((2*(C2*Parameters!$C$46-1/(C2*Parameters!$C$45))))/(((2*Parameters!$C$47))^2+((2*(C2*Parameters!$C$46-1/(C2*Parameters!$C$45))))^2)) -> 6.9115038e-07 | ER2: =EF2+EH2*EP2-EI2*EQ2 -> 0.99986793 | ES2: =EG2+EH2*EQ2+EI2*EP2 -> 0.0002915585 | ET2: =EH2 -> 0.35995091 | EU2: =EI2 -> 0.13327656 | EV2: =EJ2+EL2*EP2-EM2*EQ2 -> 2.6310082e-06 | EW2: =EK2+EL2*EQ2+EM2*EP2 -> 0.0043231991 | EX2: =EL2 -> 0.99955715 | EY2: =EM2 -> 0.0012652278 | EZ2: =(ER2+ET2/Parameters!$C$6+Parameters!$C$7*(EV2+EX2/Parameters!$C$6)) -> 1.012388 | FA2: =(ES2+EU2/Parameters!$C$6+Parameters!$C$7*(EW2+EY2/Parameters!$C$6)) -> 0.0049272649 | FB2: =-20*LOG10(SQRT(EZ2^2+FA2^2)) -> -0.10704231 | FC2: =1/SQRT(EZ2^2+FA2^2) -> 0.98775192 | FD2: =(ER2+ET2/Parameters!$C$6+Parameters!$C$8*(EV2+EX2/Parameters!$C$6)) -> 2.7508798 | FE2: =(ES2+EU2/Parameters!$C$6+Parameters!$C$8*(EW2+EY2/Parameters!$C$6)) -> 0.22328761 | FF2: =-20*LOG10(SQRT(FD2^2+FE2^2)) -> -8.8179518 | FG2: =1/SQRT(FD2^2+FE2^2) -> 0.36232843
A3: =Parameters!$C$2*(Parameters!$C$3/Parameters!$C$2)^((ROW()-2)/(Parameters!$C$4-1)) -> 101.15795 | B3: =LOG10(A3) -> 2.005 | C3: =2*PI()*A3 -> 635.59412 | D3: =1 -> 1 | E3: =0 -> 0 | F3: =0 -> 0 | G3: =0 -> 0 | H3: =0 -> 0 | I3: =0 -> 0 | J3: =1 -> 1 | K3: =0 -> 0 | L3: =2*Parameters!$C$10 -> 0.04 | M3: =2*C3*Parameters!$C$9 -> 0.0012711882 | N3: =0 -> 0 | O3: =0 -> 0 | P3: =D3 -> 1 | Q3: =E3 -> 0 | R3: =F3+D3*L3-E3*M3 -> 0.04 | S3: =G3+D3*M3+E3*L3 -> 0.0012711882 | T3: =H3 -> 0 | U3: =I3 -> 0 | V3: =J3+H3*L3-I3*M3 -> 1 | W3: =K3+H3*M3+I3*L3 -> 0 | X3: =0 -> 0 | Y3: =0 -> 0 | Z3: =0 -> 0 | AA3: =C3*(Parameters!$C$12+Parameters!$C$11/2) -> 4.7669559e-08 | AB3: =P3+R3*Z3-S3*AA3 -> 1 | AC3: =Q3+R3*AA3+S3*Z3 -> 1.9067823e-09 | AD3: =R3 -> 0.04 | AE3: =S3 -> 0.0012711882 | AF3: =T3+V3*Z3-W3*AA3 -> 0 | AG3: =U3+V3*AA3+W3*Z3 -> 4.7669559e-08 | AH3: =V3 -> 1 | AI3: =W3 -> 0 | AJ3: =0 -> 0 | AK3: =0 -> 0 | AL3: =(((2*Parameters!$C$15))/(((2*Parameters!$C$15))^2+((2*(C3*Parameters!$C$14-1/(C3*Parameters!$C$13))))^2)) -> 4.0397991e-07 | AM3: =(-((2*(C3*Parameters!$C$14-1/(C3*Parameters!$C$13))))/(((2*Parameters!$C$15))^2+((2*(C3*Parameters!$C$14-1/(C3*Parameters!$C$13))))^2)) -> 0.0031779707 | AN3: =AB3+AD3*AL3-AE3*AM3 -> 0.99999598 | AO3: =AC3+AD3*AM3+AE3*AL3 -> 0.00012712125 | AP3: =AD3 -> 0.04 | AQ3: =AE3 -> 0.0012711882 | AR3: =AF3+AH3*AL3-AI3*AM3 -> 4.0397991e-07 | AS3: =AG3+AH3*AM3+AI3*AL3 -> 0.0031780183 | AT3: =AH3 -> 1 | AU3: =AI3 -> 0 | AV3: =2*Parameters!$C$17 -> 0.04 | AW3: =2*C3*Parameters!$C$16 -> 0.0012711882 | AX3: =0 -> 0 | AY3: =0 -> 0 | AZ3: =AN3 -> 0.99999598 | BA3: =AO3 -> 0.00012712125 | BB3: =AP3+AN3*AV3-AO3*AW3 -> 0.079999677 | BC3: =AQ3+AN3*AW3+AO3*AV3 -> 0.0025474562 | BD3: =AR3 -> 4.0397991e-07 | BE3: =AS3 -> 0.0031780183 | BF3: =AT3+AR3*AV3-AS3*AW3 -> 0.99999598 | BG3: =AU3+AR3*AW3+AS3*AV3 -> 0.00012712125 | BH3: =0 -> 0 | BI3: =0 -> 0 | BJ3: =0 -> 0 | BK3: =C3*(Parameters!$C$19+Parameters!$C$18/2) -> 4.7669559e-08 | BL3: =AZ3+BB3*BJ3-BC3*BK3 -> 0.99999598 | BM3: =BA3+BB3*BK3+BC3*BJ3 -> 0.00012712506 | BN3: =BB3 -> 0.079999677 | BO3: =BC3 -> 0.0025474562 | BP3: =BD3+BF3*BJ3-BG3*BK3 -> 4.0397385e-07 | BQ3: =BE3+BF3*BK3+BG3*BJ3 -> 0.003178066 | BR3: =BF3 -> 0.99999598 | BS3: =BG3 -> 0.00012712125 | BT3: =2*((((Parameters!$C$21)/((Parameters!$C$21)^2+(C3*Parameters!$C$20)^2)))/((((Parameters!$C$21)/((Parameters!$C$21)^2+(C3*Parameters!$C$20)^2)))^2+((-(C3*Parameters!$C$20)/((Parameters!$C$21)^2+(C3*Parameters!$C$20)^2)+C3*Parameters!$C$22))^2)) -> 0.04 | BU3: =2*(-((-(C3*Parameters!$C$20)/((Parameters!$C$21)^2+(C3*Parameters!$C$20)^2)+C3*Parameters!$C$22))/((((Parameters!$C$21)/((Parameters!$C$21)^2+(C3*Parameters!$C$20)^2)))^2+((-(C3*Parameters!$C$20)/((Parameters!$C$21)^2+(C3*Parameters!$C$20)^2)+C3*Parameters!$C$22))^2)) -> 0.0864408 | BV3: =0 -> 0 | BW3: =0 -> 0 | BX3: =BL3 -> 0.99999598 | BY3: =BM3 -> 0.00012712506 | BZ3: =BN3+BL3*BT3-BM3*BU3 -> 0.11998853 | CA3: =BO3+BL3*BU3+BM3*BT3 -> 0.088992993 | CB3: =BP3 -> 4.0397385e-07 | CC3: =BQ3 -> 0.003178066 | CD3: =BR3+BP3*BT3-BQ3*BU3 -> 0.99972128 | CE3: =BS3+BP3*BU3+BQ3*BT3 -> 0.00025427881 | CF3: =0 -> 0 | CG3: =0 -> 0 | CH3: =(((Parameters!$C$25))/(((Parameters!$C$25))^2+((C3*Parameters!$C$24-1/(C3*Parameters!$C$23)))^2))+(((Parameters!$C$29+Parameters!$C$28))/(((Parameters!$C$29+Parameters!$C$28))^2+((C3*Parameters!$C$27-1/(C3*Parameters!$C$26)))^2)) -> 1.3421299e-06 | CI3: =(-((C3*Parameters!$C$24-1/(C3*Parameters!$C$23)))/(((Parameters!$C$25))^2+((C3*Parameters!$C$24-1/(C3*Parameters!$C$23)))^2))+(-((C3*Parameters!$C$27-1/(C3*Parameters!$C$26)))/(((Parameters!$C$29+Parameters!$C$28))^2+((C3*Parameters!$C$27-1/(C3*Parameters!$C$26)))^2)) -> 0.00059745246 | CJ3: =BX3+BZ3*CH3-CA3*CI3 -> 0.99994297 | CK3: =BY3+BZ3*CI3+CA3*CH3 -> 0.00019893194 | CL3: =BZ3 -> 0.11998853 | CM3: =CA3 -> 0.088992993 | CN3: =CB3+CD3*CH3-CE3*CI3 -> 1.5938102e-06 | CO3: =CC3+CD3*CI3+CE3*CH3 -> 0.0037753523 | CP3: =CD3 -> 0.99972128 | CQ3: =CE3 -> 0.00025427881 | CR3: =2*((((Parameters!$C$31)/((Parameters!$C$31)^2+(C3*Parameters!$C$30)^2)))/((((Parameters!$C$31)/((Parameters!$C$31)^2+(C3*Parameters!$C$30)^2)))^2+((-(C3*Parameters!$C$30)/((Parameters!$C$31)^2+(C3*Parameters!$C$30)^2)+C3*Parameters!$C$32))^2)) -> 0.04 | CS3: =2*(-((-(C3*Parameters!$C$30)/((Parameters!$C$31)^2+(C3*Parameters!$C$30)^2)+C3*Parameters!$C$32))/((((Parameters!$C$31)/((Parameters!$C$31)^2+(C3*Parameters!$C$30)^2)))^2+((-(C3*Parameters!$C$30)/((Parameters!$C$31)^2+(C3*Parameters!$C$30)^2)+C3*Parameters!$C$32))^2)) -> 0.041949212 | CT3: =0 -> 0 | CU3: =0 -> 0 | CV3: =CJ3 -> 0.99994297 | CW3: =CK3 -> 0.00019893194 | CX3: =CL3+CJ3*CR3-CK3*CS3 -> 0.1599779 | CY3: =CM3+CJ3*CS3+CK3*CR3 -> 0.13094777 | CZ3: =CN3 -> 1.5938102e-06 | DA3: =CO3 -> 0.0037753523 | DB3: =CP3+CN3*CR3-CO3*CS3 -> 0.99956297 | DC3: =CQ3+CN3*CS3+CO3*CR3 -> 0.00040535976 | DD3: =0 -> 0 | DE3: =0 -> 0 | DF3: =(((Parameters!$C$35))/(((Parameters!$C$35))^2+((C3*Parameters!$C$34-1/(C3*Parameters!$C$33)))^2))+(((Parameters!$C$39+Parameters!$C$38))/(((Parameters!$C$39+Parameters!$C$38))^2+((C3*Parameters!$C$37-1/(C3*Parameters!$C$36)))^2)) -> 1.3421299e-06 | DG3: =(-((C3*Parameters!$C$34-1/(C3*Parameters!$C$33)))/(((Parameters!$C$35))^2+((C3*Parameters!$C$34-1/(C3*Parameters!$C$33)))^2))+(-((C3*Parameters!$C$37-1/(C3*Parameters!$C$36)))/(((Parameters!$C$39+Parameters!$C$38))^2+((C3*Parameters!$C$37-1/(C3*Parameters!$C$36)))^2)) -> 0.00059745246 | DH3: =CV3+CX3*DF3-CY3*DG3 -> 0.99986495 | DI3: =CW3+CX3*DG3+CY3*DF3 -> 0.00029468688 | DJ3: =CX3 -> 0.1599779 | DK3: =CY3 -> 0.13094777 | DL3: =CZ3+DB3*DF3-DC3*DG3 -> 2.6931704e-06 | DM3: =DA3+DB3*DG3+DC3*DF3 -> 0.0043725442 | DN3: =DB3 -> 0.99956297 | DO3: =DC3 -> 0.00040535976 | DP3: =2*((((Parameters!$C$41)/((Parameters!$C$41)^2+(C3*(Parameters!$C$40*(1-Parameters!$C$42)))^2)))/((((Parameters!$C$41)/((Parameters!$C$41)^2+(C3*(Parameters!$C$40*(1-Parameters!$C$42)))^2)))^2+((-(C3*(Parameters!$C$40*(1-Parameters!$C$42)))/((Parameters!$C$41)^2+(C3*(Parameters!$C$40*(1-Parameters!$C$42)))^2)+C3*Parameters!$C$43))^2)) -> 0.2 | DQ3: =2*(-((-(C3*(Parameters!$C$40*(1-Parameters!$C$42)))/((Parameters!$C$41)^2+(C3*(Parameters!$C$40*(1-Parameters!$C$42)))^2)+C3*Parameters!$C$43))/((((Parameters!$C$41)/((Parameters!$C$41)^2+(C3*(Parameters!$C$40*(1-Parameters!$C$42)))^2)))^2+((-(C3*(Parameters!$C$40*(1-Parameters!$C$42)))/((Parameters!$C$41)^2+(C3*(Parameters!$C$40*(1-Parameters!$C$42)))^2)+C3*Parameters!$C$43))^2)) -> 0.0038135646 | DR3: =0 -> 0 | DS3: =0 -> 0 | DT3: =DH3 -> 0.99986495 | DU3: =DI3 -> 0.00029468688 | DV3: =DJ3+DH3*DP3-DI3*DQ3 -> 0.35994977 | DW3: =DK3+DH3*DQ3+DI3*DP3 -> 0.13481976 | DX3: =DL3 -> 2.6931704e-06 | DY3: =DM3 -> 0.0043725442 | DZ3: =DN3+DL3*DP3-DM3*DQ3 -> 0.99954683 | EA3: =DO3+DL3*DQ3+DM3*DP3 -> 0.0012798789 | EB3: =0 -> 0 | EC3: =0 -> 0 | ED3: =0 -> 0 | EE3: =C3*Parameters!$C$44 -> 6.3559412e-09 | EF3: =DT3+DV3*ED3-DW3*EE3 -> 0.99986495 | EG3: =DU3+DV3*EE3+DW3*ED3 -> 0.00029468917 | EH3: =DV3 -> 0.35994977 | EI3: =DW3 -> 0.13481976 | EJ3: =DX3+DZ3*ED3-EA3*EE3 -> 2.6931622e-06 | EK3: =DY3+DZ3*EE3+EA3*ED3 -> 0.0043725505 | EL3: =DZ3 -> 0.99954683 | EM3: =EA3 -> 0.0012798789 | EN3: =0 -> 0 | EO3: =0 -> 0 | EP3: =(((2*Parameters!$C$47))/(((2*Parameters!$C$47))^2+((2*(C3*Parameters!$C$46-1/(C3*Parameters!$C$45))))^2)) -> 1.9552626e-14 | EQ3: =(-((2*(C3*Parameters!$C$46-1/(C3*Parameters!$C$45))))/(((2*Parameters!$C$47))^2+((2*(C3*Parameters!$C$46-1/(C3*Parameters!$C$45))))^2)) -> 6.9915353e-07 | ER3: =EF3+EH3*EP3-EI3*EQ3 -> 0.99986485 | ES3: =EG3+EH3*EQ3+EI3*EP3 -> 0.00029494083 | ET3: =EH3 -> 0.35994977 | EU3: =EI3 -> 0.13481976 | EV3: =EJ3+EL3*EP3-EM3*EQ3 -> 2.6922674e-06 | EW3: =EK3+EL3*EQ3+EM3*EP3 -> 0.0043732494 | EX3: =EL3 -> 0.99954683 | EY3: =EM3 -> 0.0012798789 | EZ3: =(ER3+ET3/Parameters!$C$6+Parameters!$C$7*(EV3+EX3/Parameters!$C$6)) -> 1.0123848 | FA3: =(ES3+EU3/Parameters!$C$6+Parameters!$C$7*(EW3+EY3/Parameters!$C$6)) -> 0.0049843237 | FB3: =-20*LOG10(SQRT(EZ3^2+FA3^2)) -> -0.10701797 | FC3: =1/SQRT(EZ3^2+FA3^2) -> 0.98775469 | FD3: =(ER3+ET3/Parameters!$C$6+Parameters!$C$8*(EV3+EX3/Parameters!$C$6)) -> 2.7508618 | FE3: =(ES3+EU3/Parameters!$C$6+Parameters!$C$8*(EW3+EY3/Parameters!$C$6)) -> 0.22587267 | FF3: =-20*LOG10(SQRT(FD3^2+FE3^2)) -> -8.8185573 | FG3: =1/SQRT(FD3^2+FE3^2) -> 0.36230317
A4: =Parameters!$C$2*(Parameters!$C$3/Parameters!$C$2)^((ROW()-2)/(Parameters!$C$4-1)) -> 102.3293 | B4: =LOG10(A4) -> 2.01 | C4: =2*PI()*A4 -> 642.95395 | D4: =1 -> 1 | E4: =0 -> 0 | F4: =0 -> 0 | G4: =0 -> 0 | H4: =0 -> 0 | I4: =0 -> 0 | J4: =1 -> 1 | K4: =0 -> 0 | L4: =2*Parameters!$C$10 -> 0.04 | M4: =2*C4*Parameters!$C$9 -> 0.0012859079 | N4: =0 -> 0 | O4: =0 -> 0 | P4: =D4 -> 1 | Q4: =E4 -> 0 | R4: =F4+D4*L4-E4*M4 -> 0.04 | S4: =G4+D4*M4+E4*L4 -> 0.0012859079 | T4: =H4 -> 0 | U4: =I4 -> 0 | V4: =J4+H4*L4-I4*M4 -> 1 | W4: =K4+H4*M4+I4*L4 -> 0 | X4: =0 -> 0 | Y4: =0 -> 0 | Z4: =0 -> 0 | AA4: =C4*(Parameters!$C$12+Parameters!$C$11/2) -> 4.8221546e-08 | AB4: =P4+R4*Z4-S4*AA4 -> 1 | AC4: =Q4+R4*AA4+S4*Z4 -> 1.9288618e-09 | AD4: =R4 -> 0.04 | AE4: =S4 -> 0.0012859079 | AF4: =T4+V4*Z4-W4*AA4 -> 0 | AG4: =U4+V4*AA4+W4*Z4 -> 4.8221546e-08 | AH4: =V4 -> 1 | AI4: =W4 -> 0 | AJ4: =0 -> 0 | AK4: =0 -> 0 | AL4: =(((2*Parameters!$C$15))/(((2*Parameters!$C$15))^2+((2*(C4*Parameters!$C$14-1/(C4*Parameters!$C$13))))^2)) -> 4.1338981e-07 | AM4: =(-((2*(C4*Parameters!$C$14-1/(C4*Parameters!$C$13))))/(((2*Parameters!$C$15))^2+((2*(C4*Parameters!$C$14-1/(C4*Parameters!$C$13))))^2)) -> 0.0032147698 | AN4: =AB4+AD4*AL4-AE4*AM4 -> 0.99999588 | AO4: =AC4+AD4*AM4+AE4*AL4 -> 0.00012859325 | AP4: =AD4 -> 0.04 | AQ4: =AE4 -> 0.0012859079 | AR4: =AF4+AH4*AL4-AI4*AM4 -> 4.1338981e-07 | AS4: =AG4+AH4*AM4+AI4*AL4 -> 0.003214818 | AT4: =AH4 -> 1 | AU4: =AI4 -> 0 | AV4: =2*Parameters!$C$17 -> 0.04 | AW4: =2*C4*Parameters!$C$16 -> 0.0012859079 | AX4: =0 -> 0 | AY4: =0 -> 0 | AZ4: =AN4 -> 0.99999588 | BA4: =AO4 -> 0.00012859325 | BB4: =AP4+AN4*AV4-AO4*AW4 -> 0.07999967 | BC4: =AQ4+AN4*AW4+AO4*AV4 -> 0.0025769542 | BD4: =AR4 -> 4.1338981e-07 | BE4: =AS4 -> 0.003214818 | BF4: =AT4+AR4*AV4-AS4*AW4 -> 0.99999588 | BG4: =AU4+AR4*AW4+AS4*AV4 -> 0.00012859325 | BH4: =0 -> 0 | BI4: =0 -> 0 | BJ4: =0 -> 0 | BK4: =C4*(Parameters!$C$19+Parameters!$C$18/2) -> 4.8221546e-08 | BL4: =AZ4+BB4*BJ4-BC4*BK4 -> 0.99999588 | BM4: =BA4+BB4*BK4+BC4*BJ4 -> 0.00012859711 | BN4: =BB4 -> 0.07999967 | BO4: =BC4 -> 0.0025769542 | BP4: =BD4+BF4*BJ4-BG4*BK4 -> 4.1338361e-07 | BQ4: =BE4+BF4*BK4+BG4*BJ4 -> 0.0032148663 | BR4: =BF4 -> 0.99999588 | BS4: =BG4 -> 0.00012859325 | BT4: =2*((((Parameters!$C$21)/((Parameters!$C$21)^2+(C4*Parameters!$C$20)^2)))/((((Parameters!$C$21)/((Parameters!$C$21)^2+(C4*Parameters!$C$20)^2)))^2+((-(C4*Parameters!$C$20)/((Parameters!$C$21)^2+(C4*Parameters!$C$20)^2)+C4*Parameters!$C$22))^2)) -> 0.04 | BU4: =2*(-((-(C4*Parameters!$C$20)/((Parameters!$C$21)^2+(C4*Parameters!$C$20)^2)+C4*Parameters!$C$22))/((((Parameters!$C$21)/((Parameters!$C$21)^2+(C4*Parameters!$C$20)^2)))^2+((-(C4*Parameters!$C$20)/((Parameters!$C$21)^2+(C4*Parameters!$C$20)^2)+C4*Parameters!$C$22))^2)) -> 0.087441737 | BV4: =0 -> 0 | BW4: =0 -> 0 | BX4: =BL4 -> 0.99999588 | BY4: =BM4 -> 0.00012859711 | BZ4: =BN4+BL4*BT4-BM4*BU4 -> 0.11998826 | CA4: =BO4+BL4*BU4+BM4*BT4 -> 0.090023475 | CB4: =BP4 -> 4.1338361e-07 | CC4: =BQ4 -> 0.0032148663 | CD4: =BR4+BP4*BT4-BQ4*BU4 -> 0.99971479 | CE4: =BS4+BP4*BU4+BQ4*BT4 -> 0.00025722405 | CF4: =0 -> 0 | CG4: =0 -> 0 | CH4: =(((Parameters!$C$25))/(((Parameters!$C$25))^2+((C4*Parameters!$C$24-1/(C4*Parameters!$C$23)))^2))+(((Parameters!$C$29+Parameters!$C$28))/(((Parameters!$C$29+Parameters!$C$28))^2+((C4*Parameters!$C$27-1/(C4*Parameters!$C$26)))^2)) -> 1.3733915e-06 | CI4: =(-((C4*Parameters!$C$24-1/(C4*Parameters!$C$23)))/(((Parameters!$C$25))^2+((C4*Parameters!$C$24-1/(C4*Parameters!$C$23)))^2))+(-((C4*Parameters!$C$27-1/(C4*Parameters!$C$26)))/(((Parameters!$C$29+Parameters!$C$28))^2+((C4*Parameters!$C$27-1/(C4*Parameters!$C$26)))^2)) -> 0.00060437049 | CJ4: =BX4+BZ4*CH4-CA4*CI4 -> 0.99994164 | CK4: =BY4+BZ4*CI4+CA4*CH4 -> 0.00020123811 | CL4: =BZ4 -> 0.11998826 | CM4: =CA4 -> 0.090023475 | CN4: =CB4+CD4*CH4-CE4*CI4 -> 1.6309248e-06 | CO4: =CC4+CD4*CI4+CE4*CH4 -> 0.0038190647 | CP4: =CD4 -> 0.99971479 | CQ4: =CE4 -> 0.00025722405 | CR4: =2*((((Parameters!$C$31)/((Parameters!$C$31)^2+(C4*Parameters!$C$30)^2)))/((((Parameters!$C$31)/((Parameters!$C$31)^2+(C4*Parameters!$C$30)^2)))^2+((-(C4*Parameters!$C$30)/((Parameters!$C$31)^2+(C4*Parameters!$C$30)^2)+C4*Parameters!$C$32))^2)) -> 0.04 | CS4: =2*(-((-(C4*Parameters!$C$30)/((Parameters!$C$31)^2+(C4*Parameters!$C$30)^2)+C4*Parameters!$C$32))/((((Parameters!$C$31)/((Parameters!$C$31)^2+(C4*Parameters!$C$30)^2)))^2+((-(C4*Parameters!$C$30)/((Parameters!$C$31)^2+(C4*Parameters!$C$30)^2)+C4*Parameters!$C$32))^2)) -> 0.042434961 | CT4: =0 -> 0 | CU4: =0 -> 0 | CV4: =CJ4 -> 0.99994164 | CW4: =CK4 -> 0.00020123811 | CX4: =CL4+CJ4*CR4-CK4*CS4 -> 0.15997739 | CY4: =CM4+CJ4*CS4+CK4*CR4 -> 0.13246401 | CZ4: =CN4 -> 1.6309248e-06 | DA4: =CO4 -> 0.0038190647 | DB4: =CP4+CN4*CR4-CO4*CS4 -> 0.99955279 | DC4: =CQ4+CN4*CS4+CO4*CR4 -> 0.00041005585 | DD4: =0 -> 0 | DE4: =0 -> 0 | DF4: =(((Parameters!$C$35))/(((Parameters!$C$35))^2+((C4*Parameters!$C$34-1/(C4*Parameters!$C$33)))^2))+(((Parameters!$C$39+Parameters!$C$38))/(((Parameters!$C$39+Parameters!$C$38))^2+((C4*Parameters!$C$37-1/(C4*Parameters!$C$36)))^2)) -> 1.3733915e-06 | DG4: =(-((C4*Parameters!$C$34-1/(C4*Parameters!$C$33)))/(((Parameters!$C$35))^2+((C4*Parameters!$C$34-1/(C4*Parameters!$C$33)))^2))+(-((C4*Parameters!$C$37-1/(C4*Parameters!$C$36)))/(((Parameters!$C$39+Parameters!$C$38))^2+((C4*Parameters!$C$37-1/(C4*Parameters!$C$36)))^2)) -> 0.00060437049 | DH4: =CV4+CX4*DF4-CY4*DG4 -> 0.9998618 | DI4: =CW4+CX4*DG4+CY4*DF4 -> 0.00029810565 | DJ4: =CX4 -> 0.15997739 | DK4: =CY4 -> 0.13246401 | DL4: =CZ4+DB4*DF4-DC4*DG4 -> 2.7558764e-06 | DM4: =DA4+DB4*DG4+DC4*DF4 -> 0.0044231655 | DN4: =DB4 -> 0.99955279 | DO4: =DC4 -> 0.00041005585 | DP4: =2*((((Parameters!$C$41)/((Parameters!$C$41)^2+(C4*(Parameters!$C$40*(1-Parameters!$C$42)))^2)))/((((Parameters!$C$41)/((Parameters!$C$41)^2+(C4*(Parameters!$C$40*(1-Parameters!$C$42)))^2)))^2+((-(C4*(Parameters!$C$40*(1-Parameters!$C$42)))/((Parameters!$C$41)^2+(C4*(Parameters!$C$40*(1-Parameters!$C$42)))^2)+C4*Parameters!$C$43))^2)) -> 0.2 | DQ4: =2*(-((-(C4*(Parameters!$C$40*(1-Parameters!$C$42)))/((Parameters!$C$41)^2+(C4*(Parameters!$C$40*(1-Parameters!$C$42)))^2)+C4*Parameters!$C$43))/((((Parameters!$C$41)/((Parameters!$C$41)^2+(C4*(Parameters!$C$40*(1-Parameters!$C$42)))^2)))^2+((-(C4*(Parameters!$C$40*(1-Parameters!$C$42)))/((Parameters!$C$41)^2+(C4*(Parameters!$C$40*(1-Parameters!$C$42)))^2)+C4*Parameters!$C$43))^2)) -> 0.0038577236 | DR4: =0 -> 0 | DS4: =0 -> 0 | DT4: =DH4 -> 0.9998618 | DU4: =DI4 -> 0.00029810565 | DV4: =DJ4+DH4*DP4-DI4*DQ4 -> 0.3599486 | DW4: =DK4+DH4*DQ4+DI4*DP4 -> 0.13638082 | DX4: =DL4 -> 2.7558764e-06 | DY4: =DM4 -> 0.0044231655 | DZ4: =DN4+DL4*DP4-DM4*DQ4 -> 0.99953628 | EA4: =DO4+DL4*DQ4+DM4*DP4 -> 0.0012946996 | EB4: =0 -> 0 | EC4: =0 -> 0 | ED4: =0 -> 0 | EE4: =C4*Parameters!$C$44 -> 6.4295395e-09 | EF4: =DT4+DV4*ED4-DW4*EE4 -> 0.9998618 | EG4: =DU4+DV4*EE4+DW4*ED4 -> 0.00029810796 | EH4: =DV4 -> 0.3599486 | EI4: =DW4 -> 0.13638082 | EJ4: =DX4+DZ4*ED4-EA4*EE4 -> 2.7558681e-06 | EK4: =DY4+DZ4*EE4+EA4*ED4 -> 0.0044231719 | EL4: =DZ4 -> 0.99953628 | EM4: =EA4 -> 0.0012946996 | EN4: =0 -> 0 | EO4: =0 -> 0 | EP4: =(((2*Parameters!$C$47))/(((2*Parameters!$C$47))^2+((2*(C4*Parameters!$C$46-1/(C4*Parameters!$C$45))))^2)) -> 2.0008065e-14 | EQ4: =(-((2*(C4*Parameters!$C$46-1/(C4*Parameters!$C$45))))/(((2*Parameters!$C$47))^2+((2*(C4*Parameters!$C$46-1/(C4*Parameters!$C$45))))^2)) -> 7.0724934e-07 | ER4: =EF4+EH4*EP4-EI4*EQ4 -> 0.9998617 | ES4: =EG4+EH4*EQ4+EI4*EP4 -> 0.00029836254 | ET4: =EH4 -> 0.3599486 | EU4: =EI4 -> 0.13638082 | EV4: =EJ4+EL4*EP4-EM4*EQ4 -> 2.7549524e-06 | EW4: =EK4+EL4*EQ4+EM4*EP4 -> 0.0044238789 | EX4: =EL4 -> 0.99953628 | EY4: =EM4 -> 0.0012946996 | EZ4: =(ER4+ET4/Parameters!$C$6+Parameters!$C$7*(EV4+EX4/Parameters!$C$6)) -> 1.0123817 | FA4: =(ES4+EU4/Parameters!$C$6+Parameters!$C$7*(EW4+EY4/Parameters!$C$6)) -> 0.0050420432 | FB4: =-20*LOG10(SQRT(EZ4^2+FA4^2)) -> -0.10699307 | FC4: =1/SQRT(EZ4^2+FA4^2) -> 0.98775752 | FD4: =(ER4+ET4/Parameters!$C$6+Parameters!$C$8*(EV4+EX4/Parameters!$C$6)) -> 2.7508434 | FE4: =(ES4+EU4/Parameters!$C$6+Parameters!$C$8*(EW4+EY4/Parameters!$C$6)) -> 0.22848764 | FF4: =-20*LOG10(SQRT(FD4^2+FE4^2)) -> -8.8191768 | FG4: =1/SQRT(FD4^2+FE4^2) -> 0.36227733
A5: =Parameters!$C$2*(Parameters!$C$3/Parameters!$C$2)^((ROW()-2)/(Parameters!$C$4-1)) -> 103.51422 | B5: =LOG10(A5) -> 2.015 | C5: =2*PI()*A5 -> 650.39901 | D5: =1 -> 1 | E5: =0 -> 0 | F5: =0 -> 0 | G5: =0 -> 0 | H5: =0 -> 0 | I5: =0 -> 0 | J5: =1 -> 1 | K5: =0 -> 0 | L5: =2*Parameters!$C$10 -> 0.04 | M5: =2*C5*Parameters!$C$9 -> 0.001300798 | N5: =0 -> 0 | O5: =0 -> 0 | P5: =D5 -> 1 | Q5: =E5 -> 0 | R5: =F5+D5*L5-E5*M5 -> 0.04 | S5: =G5+D5*M5+E5*L5 -> 0.001300798 | T5: =H5 -> 0 | U5: =I5 -> 0 | V5: =J5+H5*L5-I5*M5 -> 1 | W5: =K5+H5*M5+I5*L5 -> 0 | X5: =0 -> 0 | Y5: =0 -> 0 | Z5: =0 -> 0 | AA5: =C5*(Parameters!$C$12+Parameters!$C$11/2) -> 4.8779925e-08 | AB5: =P5+R5*Z5-S5*AA5 -> 1 | AC5: =Q5+R5*AA5+S5*Z5 -> 1.951197e-09 | AD5: =R5 -> 0.04 | AE5: =S5 -> 0.001300798 | AF5: =T5+V5*Z5-W5*AA5 -> 0 | AG5: =U5+V5*AA5+W5*Z5 -> 4.8779925e-08 | AH5: =V5 -> 1 | AI5: =W5 -> 0 | AJ5: =0 -> 0 | AK5: =0 -> 0 | AL5: =(((2*Parameters!$C$15))/(((2*Parameters!$C$15))^2+((2*(C5*Parameters!$C$14-1/(C5*Parameters!$C$13))))^2)) -> 4.2301889e-07 | AM5: =(-((2*(C5*Parameters!$C$14-1/(C5*Parameters!$C$13))))/(((2*Parameters!$C$15))^2+((2*(C5*Parameters!$C$14-1/(C5*Parameters!$C$13))))^2)) -> 0.0032519951 | AN5: =AB5+AD5*AL5-AE5*AM5 -> 0.99999579 | AO5: =AC5+AD5*AM5+AE5*AL5 -> 0.00013008231 | AP5: =AD5 -> 0.04 | AQ5: =AE5 -> 0.001300798 | AR5: =AF5+AH5*AL5-AI5*AM5 -> 4.2301889e-07 | AS5: =AG5+AH5*AM5+AI5*AL5 -> 0.0032520439 | AT5: =AH5 -> 1 | AU5: =AI5 -> 0 | AV5: =2*Parameters!$C$17 -> 0.04 | AW5: =2*C5*Parameters!$C$16 -> 0.001300798 | AX5: =0 -> 0 | AY5: =0 -> 0 | AZ5: =AN5 -> 0.99999579 | BA5: =AO5 -> 0.00013008231 | BB5: =AP5+AN5*AV5-AO5*AW5 -> 0.079999662 | BC5: =AQ5+AN5*AW5+AO5*AV5 -> 0.0026067938 | BD5: =AR5 -> 4.2301889e-07 | BE5: =AS5 -> 0.0032520439 | BF5: =AT5+AR5*AV5-AS5*AW5 -> 0.99999579 | BG5: =AU5+AR5*AW5+AS5*AV5 -> 0.00013008231 | BH5: =0 -> 0 | BI5: =0 -> 0 | BJ5: =0 -> 0 | BK5: =C5*(Parameters!$C$19+Parameters!$C$18/2) -> 4.8779925e-08 | BL5: =AZ5+BB5*BJ5-BC5*BK5 -> 0.99999579 | BM5: =BA5+BB5*BK5+BC5*BJ5 -> 0.00013008621 | BN5: =BB5 -> 0.079999662 | BO5: =BC5 -> 0.0026067938 | BP5: =BD5+BF5*BJ5-BG5*BK5 -> 4.2301255e-07 | BQ5: =BE5+BF5*BK5+BG5*BJ5 -> 0.0032520927 | BR5: =BF5 -> 0.99999579 | BS5: =BG5 -> 0.00013008231 | BT5: =2*((((Parameters!$C$21)/((Parameters!$C$21)^2+(C5*Parameters!$C$20)^2)))/((((Parameters!$C$21)/((Parameters!$C$21)^2+(C5*Parameters!$C$20)^2)))^2+((-(C5*Parameters!$C$20)/((Parameters!$C$21)^2+(C5*Parameters!$C$20)^2)+C5*Parameters!$C$22))^2)) -> 0.04 | BU5: =2*(-((-(C5*Parameters!$C$20)/((Parameters!$C$21)^2+(C5*Parameters!$C$20)^2)+C5*Parameters!$C$22))/((((Parameters!$C$21)/((Parameters!$C$21)^2+(C5*Parameters!$C$20)^2)))^2+((-(C5*Parameters!$C$20)/((Parameters!$C$21)^2+(C5*Parameters!$C$20)^2)+C5*Parameters!$C$22))^2)) -> 0.088454265 | BV5: =0 -> 0 | BW5: =0 -> 0 | BX5: =BL5 -> 0.99999579 | BY5: =BM5 -> 0.00013008621 | BZ5: =BN5+BL5*BT5-BM5*BU5 -> 0.11998799 | CA5: =BO5+BL5*BU5+BM5*BT5 -> 0.091065889 | CB5: =BP5 -> 4.2301255e-07 | CC5: =BQ5 -> 0.0032520927 | CD5: =BR5+BP5*BT5-BQ5*BU5 -> 0.99970814 | CE5: =BS5+BP5*BU5+BQ5*BT5 -> 0.00026020343 | CF5: =0 -> 0 | CG5: =0 -> 0 | CH5: =(((Parameters!$C$25))/(((Parameters!$C$25))^2+((C5*Parameters!$C$24-1/(C5*Parameters!$C$23)))^2))+(((Parameters!$C$29+Parameters!$C$28))/(((Parameters!$C$29+Parameters!$C$28))^2+((C5*Parameters!$C$27-1/(C5*Parameters!$C$26)))^2)) -> 1.4053812e-06 | CI5: =(-((C5*Parameters!$C$24-1/(C5*Parameters!$C$23)))/(((Parameters!$C$25))^2+((C5*Parameters!$C$24-1/(C5*Parameters!$C$23)))^2))+(-((C5*Parameters!$C$27-1/(C5*Parameters!$C$26)))/(((Parameters!$C$29+Parameters!$C$28))^2+((C5*Parameters!$C$27-1/(C5*Parameters!$C$26)))^2)) -> 0.00061136862 | CJ5: =BX5+BZ5*CH5-CA5*CI5 -> 0.99994028 | CK5: =BY5+BZ5*CI5+CA5*CH5 -> 0.00020357108 | CL5: =BZ5 -> 0.11998799 | CM5: =CA5 -> 0.091065889 | CN5: =CB5+CD5*CH5-CE5*CI5 -> 1.6689034e-06 | CO5: =CC5+CD5*CI5+CE5*CH5 -> 0.0038632832 | CP5: =CD5 -> 0.99970814 | CQ5: =CE5 -> 0.00026020343 | CR5: =2*((((Parameters!$C$31)/((Parameters!$C$31)^2+(C5*Parameters!$C$30)^2)))/((((Parameters!$C$31)/((Parameters!$C$31)^2+(C5*Parameters!$C$30)^2)))^2+((-(C5*Parameters!$C$30)/((Parameters!$C$31)^2+(C5*Parameters!$C$30)^2)+C5*Parameters!$C$32))^2)) -> 0.04 | CS5: =2*(-((-(C5*Parameters!$C$30)/((Parameters!$C$31)^2+(C5*Parameters!$C$30)^2)+C5*Parameters!$C$32))/((((Parameters!$C$31)/((Parameters!$C$31)^2+(C5*Parameters!$C$30)^2)))^2+((-(C5*Parameters!$C$30)/((Parameters!$C$31)^2+(C5*Parameters!$C$30)^2)+C5*Parameters!$C$32))^2)) -> 0.042926334 | CT5: =0 -> 0 | CU5: =0 -> 0 | CV5: =CJ5 -> 0.99994028 | CW5: =CK5 -> 0.00020357108 | CX5: =CL5+CJ5*CR5-CK5*CS5 -> 0.15997686 | CY5: =CM5+CJ5*CS5+CK5*CR5 -> 0.1339978 | CZ5: =CN5 -> 1.6689034e-06 | DA5: =CO5 -> 0.0038632832 | DB5: =CP5+CN5*CR5-CO5*CS5 -> 0.99954237 | DC5: =CQ5+CN5*CS5+CO5*CR5 -> 0.0004148064 | DD5: =0 -> 0 | DE5: =0 -> 0 | DF5: =(((Parameters!$C$35))/(((Parameters!$C$35))^2+((C5*Parameters!$C$34-1/(C5*Parameters!$C$33)))^2))+(((Parameters!$C$39+Parameters!$C$38))/(((Parameters!$C$39+Parameters!$C$38))^2+((C5*Parameters!$C$37-1/(C5*Parameters!$C$36)))^2)) -> 1.4053812e-06 | DG5: =(-((C5*Parameters!$C$34-1/(C5*Parameters!$C$33)))/(((Parameters!$C$35))^2+((C5*Parameters!$C$34-1/(C5*Parameters!$C$33)))^2))+(-((C5*Parameters!$C$37-1/(C5*Parameters!$C$36)))/(((Parameters!$C$39+Parameters!$C$38))^2+((C5*Parameters!$C$37-1/(C5*Parameters!$C$36)))^2)) -> 0.00061136862 | DH5: =CV5+CX5*DF5-CY5*DG5 -> 0.99985858 | DI5: =CW5+CX5*DG5+CY5*DF5 -> 0.00030156423 | DJ5: =CX5 -> 0.15997686 | DK5: =CY5 -> 0.1339978 | DL5: =CZ5+DB5*DF5-DC5*DG5 -> 2.8200419e-06 | DM5: =DA5+DB5*DG5+DC5*DF5 -> 0.0044743726 | DN5: =DB5 -> 0.99954237 | DO5: =DC5 -> 0.0004148064 | DP5: =2*((((Parameters!$C$41)/((Parameters!$C$41)^2+(C5*(Parameters!$C$40*(1-Parameters!$C$42)))^2)))/((((Parameters!$C$41)/((Parameters!$C$41)^2+(C5*(Parameters!$C$40*(1-Parameters!$C$42)))^2)))^2+((-(C5*(Parameters!$C$40*(1-Parameters!$C$42)))/((Parameters!$C$41)^2+(C5*(Parameters!$C$40*(1-Parameters!$C$42)))^2)+C5*Parameters!$C$43))^2)) -> 0.2 | DQ5: =2*(-((-(C5*(Parameters!$C$40*(1-Parameters!$C$42)))/((Parameters!$C$41)^2+(C5*(Parameters!$C$40*(1-Parameters!$C$42)))^2)+C5*Parameters!$C$43))/((((Parameters!$C$41)/((Parameters!$C$41)^2+(C5*(Parameters!$C$40*(1-Parameters!$C$42)))^2)))^2+((-(C5*(Parameters!$C$40*(1-Parameters!$C$42)))/((Parameters!$C$41)^2+(C5*(Parameters!$C$40*(1-Parameters!$C$42)))^2)+C5*Parameters!$C$43))^2)) -> 0.003902394 | DR5: =0 -> 0 | DS5: =0 -> 0 | DT5: =DH5 -> 0.99985858 | DU5: =DI5 -> 0.00030156423 | DV5: =DJ5+DH5*DP5-DI5*DQ5 -> 0.3599474 | DW5: =DK5+DH5*DQ5+DI5*DP5 -> 0.13795996 | DX5: =DL5 -> 2.8200419e-06 | DY5: =DM5 -> 0.0044743726 | DZ5: =DN5+DL5*DP5-DM5*DQ5 -> 0.99952548 | EA5: =DO5+DL5*DQ5+DM5*DP5 -> 0.0013096919 | EB5: =0 -> 0 | EC5: =0 -> 0 | ED5: =0 -> 0 | EE5: =C5*Parameters!$C$44 -> 6.5039901e-09 | EF5: =DT5+DV5*ED5-DW5*EE5 -> 0.99985858 | EG5: =DU5+DV5*EE5+DW5*ED5 -> 0.00030156657 | EH5: =DV5 -> 0.3599474 | EI5: =DW5 -> 0.13795996 | EJ5: =DX5+DZ5*ED5-EA5*EE5 -> 2.8200333e-06 | EK5: =DY5+DZ5*EE5+EA5*ED5 -> 0.0044743792 | EL5: =DZ5 -> 0.99952548 | EM5: =EA5 -> 0.0013096919 | EN5: =0 -> 0 | EO5: =0 -> 0 | EP5: =(((2*Parameters!$C$47))/(((2*Parameters!$C$47))^2+((2*(C5*Parameters!$C$46-1/(C5*Parameters!$C$45))))^2)) -> 2.0474113e-14 | EQ5: =(-((2*(C5*Parameters!$C$46-1/(C5*Parameters!$C$45))))/(((2*Parameters!$C$47))^2+((2*(C5*Parameters!$C$46-1/(C5*Parameters!$C$45))))^2)) -> 7.1543891e-07 | ER5: =EF5+EH5*EP5-EI5*EQ5 -> 0.99985848 | ES5: =EG5+EH5*EQ5+EI5*EP5 -> 0.00030182409 | ET5: =EH5 -> 0.3599474 | EU5: =EI5 -> 0.13795996 | EV5: =EJ5+EL5*EP5-EM5*EQ5 -> 2.8190964e-06 | EW5: =EK5+EL5*EQ5+EM5*EP5 -> 0.0044750942 | EX5: =EL5 -> 0.99952548 | EY5: =EM5 -> 0.0013096919 | EZ5: =(ER5+ET5/Parameters!$C$6+Parameters!$C$7*(EV5+EX5/Parameters!$C$6)) -> 1.0123784 | FA5: =(ES5+EU5/Parameters!$C$6+Parameters!$C$7*(EW5+EY5/Parameters!$C$6)) -> 0.0051004313 | FB5: =-20*LOG10(SQRT(EZ5^2+FA5^2)) -> -0.10696758 | FC5: =1/SQRT(EZ5^2+FA5^2) -> 0.98776042 | FD5: =(ER5+ET5/Parameters!$C$6+Parameters!$C$8*(EV5+EX5/Parameters!$C$6)) -> 2.7508245 | FE5: =(ES5+EU5/Parameters!$C$6+Parameters!$C$8*(EW5+EY5/Parameters!$C$6)) -> 0.23113287 | FF5: =-20*LOG10(SQRT(FD5^2+FE5^2)) -> -8.8198107 | FG5: =1/SQRT(FD5^2+FE5^2) -> 0.36225089
A6: =Parameters!$C$2*(Parameters!$C$3/Parameters!$C$2)^((ROW()-2)/(Parameters!$C$4-1)) -> 104.71285 | B6: =LOG10(A6) -> 2.02 | C6: =2*PI()*A6 -> 657.93027 | D6: =1 -> 1 | E6: =0 -> 0 | F6: =0 -> 0 | G6: =0 -> 0 | H6: =0 -> 0 | I6: =0 -> 0 | J6: =1 -> 1 | K6: =0 -> 0 | L6: =2*Parameters!$C$10 -> 0.04 | M6: =2*C6*Parameters!$C$9 -> 0.0013158605 | N6: =0 -> 0 | O6: =0 -> 0 | P6: =D6 -> 1 | Q6: =E6 -> 0 | R6: =F6+D6*L6-E6*M6 -> 0.04 | S6: =G6+D6*M6+E6*L6 -> 0.0013158605 | T6: =H6 -> 0 | U6: =I6 -> 0 | V6: =J6+H6*L6-I6*M6 -> 1 | W6: =K6+H6*M6+I6*L6 -> 0 | X6: =0 -> 0 | Y6: =0 -> 0 | Z6: =0 -> 0 | AA6: =C6*(Parameters!$C$12+Parameters!$C$11/2) -> 4.934477e-08 | AB6: =P6+R6*Z6-S6*AA6 -> 1 | AC6: =Q6+R6*AA6+S6*Z6 -> 1.9737908e-09 | AD6: =R6 -> 0.04 | AE6: =S6 -> 0.0013158605 | AF6: =T6+V6*Z6-W6*AA6 -> 0 | AG6: =U6+V6*AA6+W6*Z6 -> 4.934477e-08 | AH6: =V6 -> 1 | AI6: =W6 -> 0 | AJ6: =0 -> 0 | AK6: =0 -> 0 | AL6: =(((2*Parameters!$C$15))/(((2*Parameters!$C$15))^2+((2*(C6*Parameters!$C$14-1/(C6*Parameters!$C$13))))^2)) -> 4.3287227e-07 | AM6: =(-((2*(C6*Parameters!$C$14-1/(C6*Parameters!$C$13))))/(((2*Parameters!$C$15))^2+((2*(C6*Parameters!$C$14-1/(C6*Parameters!$C$13))))^2)) -> 0.0032896514 | AN6: =AB6+AD6*AL6-AE6*AM6 -> 0.99999569 | AO6: =AC6+AD6*AM6+AE6*AL6 -> 0.0001315886 | AP6: =AD6 -> 0.04 | AQ6: =AE6 -> 0.0013158605 | AR6: =AF6+AH6*AL6-AI6*AM6 -> 4.3287227e-07 | AS6: =AG6+AH6*AM6+AI6*AL6 -> 0.0032897008 | AT6: =AH6 -> 1 | AU6: =AI6 -> 0 | AV6: =2*Parameters!$C$17 -> 0.04 | AW6: =2*C6*Parameters!$C$16 -> 0.0013158605 | AX6: =0 -> 0 | AY6: =0 -> 0 | AZ6: =AN6 -> 0.99999569 | BA6: =AO6 -> 0.0001315886 | BB6: =AP6+AN6*AV6-AO6*AW6 -> 0.079999654 | BC6: =AQ6+AN6*AW6+AO6*AV6 -> 0.002636979 | BD6: =AR6 -> 4.3287227e-07 | BE6: =AS6 -> 0.0032897008 | BF6: =AT6+AR6*AV6-AS6*AW6 -> 0.99999569 | BG6: =AU6+AR6*AW6+AS6*AV6 -> 0.0001315886 | BH6: =0 -> 0 | BI6: =0 -> 0 | BJ6: =0 -> 0 | BK6: =C6*(Parameters!$C$19+Parameters!$C$18/2) -> 4.934477e-08 | BL6: =AZ6+BB6*BJ6-BC6*BK6 -> 0.99999569 | BM6: =BA6+BB6*BK6+BC6*BJ6 -> 0.00013159255 | BN6: =BB6 -> 0.079999654 | BO6: =BC6 -> 0.002636979 | BP6: =BD6+BF6*BJ6-BG6*BK6 -> 4.3286578e-07 | BQ6: =BE6+BF6*BK6+BG6*BJ6 -> 0.0032897501 | BR6: =BF6 -> 0.99999569 | BS6: =BG6 -> 0.0001315886 | BT6: =2*((((Parameters!$C$21)/((Parameters!$C$21)^2+(C6*Parameters!$C$20)^2)))/((((Parameters!$C$21)/((Parameters!$C$21)^2+(C6*Parameters!$C$20)^2)))^2+((-(C6*Parameters!$C$20)/((Parameters!$C$21)^2+(C6*Parameters!$C$20)^2)+C6*Parameters!$C$22))^2)) -> 0.04 | BU6: =2*(-((-(C6*Parameters!$C$20)/((Parameters!$C$21)^2+(C6*Parameters!$C$20)^2)+C6*Parameters!$C$22))/((((Parameters!$C$21)/((Parameters!$C$21)^2+(C6*Parameters!$C$20)^2)))^2+((-(C6*Parameters!$C$20)/((Parameters!$C$21)^2+(C6*Parameters!$C$20)^2)+C6*Parameters!$C$22))^2)) -> 0.089478517 | BV6: =0 -> 0 | BW6: =0 -> 0 | BX6: =BL6 -> 0.99999569 | BY6: =BM6 -> 0.00013159255 | BZ6: =BN6+BL6*BT6-BM6*BU6 -> 0.11998771 | CA6: =BO6+BL6*BU6+BM6*BT6 -> 0.092120374 | CB6: =BP6 -> 4.3286578e-07 | CC6: =BQ6 -> 0.0032897501 | CD6: =BR6+BP6*BT6-BQ6*BU6 -> 0.99970134 | CE6: =BS6+BP6*BU6+BQ6*BT6 -> 0.00026321734 | CF6: =0 -> 0 | CG6: =0 -> 0 | CH6: =(((Parameters!$C$25))/(((Parameters!$C$25))^2+((C6*Parameters!$C$24-1/(C6*Parameters!$C$23)))^2))+(((Parameters!$C$29+Parameters!$C$28))/(((Parameters!$C$29+Parameters!$C$28))^2+((C6*Parameters!$C$27-1/(C6*Parameters!$C$26)))^2)) -> 1.4381161e-06 | CI6: =(-((C6*Parameters!$C$24-1/(C6*Parameters!$C$23)))/(((Parameters!$C$25))^2+((C6*Parameters!$C$24-1/(C6*Parameters!$C$23)))^2))+(-((C6*Parameters!$C$27-1/(C6*Parameters!$C$26)))/(((Parameters!$C$29+Parameters!$C$28))^2+((C6*Parameters!$C$27-1/(C6*Parameters!$C$26)))^2)) -> 0.00061844779 | CJ6: =BX6+BZ6*CH6-CA6*CI6 -> 0.99993889 | CK6: =BY6+BZ6*CI6+CA6*CH6 -> 0.00020593116 | CL6: =BZ6 -> 0.11998771 | CM6: =CA6 -> 0.092120374 | CN6: =CB6+CD6*CH6-CE6*CI6 -> 1.7077662e-06 | CO6: =CC6+CD6*CI6+CE6*CH6 -> 0.0039080136 | CP6: =CD6 -> 0.99970134 | CQ6: =CE6 -> 0.00026321734 | CR6: =2*((((Parameters!$C$31)/((Parameters!$C$31)^2+(C6*Parameters!$C$30)^2)))/((((Parameters!$C$31)/((Parameters!$C$31)^2+(C6*Parameters!$C$30)^2)))^2+((-(C6*Parameters!$C$30)/((Parameters!$C$31)^2+(C6*Parameters!$C$30)^2)+C6*Parameters!$C$32))^2)) -> 0.04 | CS6: =2*(-((-(C6*Parameters!$C$30)/((Parameters!$C$31)^2+(C6*Parameters!$C$30)^2)+C6*Parameters!$C$32))/((((Parameters!$C$31)/((Parameters!$C$31)^2+(C6*Parameters!$C$30)^2)))^2+((-(C6*Parameters!$C$30)/((Parameters!$C$31)^2+(C6*Parameters!$C$30)^2)+C6*Parameters!$C$32))^2)) -> 0.043423398 | CT6: =0 -> 0 | CU6: =0 -> 0 | CV6: =CJ6 -> 0.99993889 | CW6: =CK6 -> 0.00020593116 | CX6: =CL6+CJ6*CR6-CK6*CS6 -> 0.15997632 | CY6: =CM6+CJ6*CS6+CK6*CR6 -> 0.13554936 | CZ6: =CN6 -> 1.7077662e-06 | DA6: =CO6 -> 0.0039080136 | DB6: =CP6+CN6*CR6-CO6*CS6 -> 0.99953171 | DC6: =CQ6+CN6*CS6+CO6*CR6 -> 0.00041961204 | DD6: =0 -> 0 | DE6: =0 -> 0 | DF6: =(((Parameters!$C$35))/(((Parameters!$C$35))^2+((C6*Parameters!$C$34-1/(C6*Parameters!$C$33)))^2))+(((Parameters!$C$39+Parameters!$C$38))/(((Parameters!$C$39+Parameters!$C$38))^2+((C6*Parameters!$C$37-1/(C6*Parameters!$C$36)))^2)) -> 1.4381161e-06 | DG6: =(-((C6*Parameters!$C$34-1/(C6*Parameters!$C$33)))/(((Parameters!$C$35))^2+((C6*Parameters!$C$34-1/(C6*Parameters!$C$33)))^2))+(-((C6*Parameters!$C$37-1/(C6*Parameters!$C$36)))/(((Parameters!$C$39+Parameters!$C$38))^2+((C6*Parameters!$C$37-1/(C6*Parameters!$C$36)))^2)) -> 0.00061844779 | DH6: =CV6+CX6*DF6-CY6*DG6 -> 0.99985529 | DI6: =CW6+CX6*DG6+CY6*DF6 -> 0.0003050631 | DJ6: =CX6 -> 0.15997632 | DK6: =CY6 -> 0.13554936 | DL6: =CZ6+DB6*DF6-DC6*DG6 -> 2.8857006e-06 | DM6: =DA6+DB6*DG6+DC6*DF6 -> 0.0045261724 | DN6: =DB6 -> 0.99953171 | DO6: =DC6 -> 0.00041961204 | DP6: =2*((((Parameters!$C$41)/((Parameters!$C$41)^2+(C6*(Parameters!$C$40*(1-Parameters!$C$42)))^2)))/((((Parameters!$C$41)/((Parameters!$C$41)^2+(C6*(Parameters!$C$40*(1-Parameters!$C$42)))^2)))^2+((-(C6*(Parameters!$C$40*(1-Parameters!$C$42)))/((Parameters!$C$41)^2+(C6*(Parameters!$C$40*(1-Parameters!$C$42)))^2)+C6*Parameters!$C$43))^2)) -> 0.2 | DQ6: =2*(-((-(C6*(Parameters!$C$40*(1-Parameters!$C$42)))/((Parameters!$C$41)^2+(C6*(Parameters!$C$40*(1-Parameters!$C$42)))^2)+C6*Parameters!$C$43))/((((Parameters!$C$41)/((Parameters!$C$41)^2+(C6*(Parameters!$C$40*(1-Parameters!$C$42)))^2)))^2+((-(C6*(Parameters!$C$40*(1-Parameters!$C$42)))/((Parameters!$C$41)^2+(C6*(Parameters!$C$40*(1-Parameters!$C$42)))^2)+C6*Parameters!$C$43))^2)) -> 0.0039475816 | DR6: =0 -> 0 | DS6: =0 -> 0 | DT6: =DH6 -> 0.99985529 | DU6: =DI6 -> 0.0003050631 | DV6: =DJ6+DH6*DP6-DI6*DQ6 -> 0.35994617 | DW6: =DK6+DH6*DQ6+DI6*DP6 -> 0.13955738 | DX6: =DL6 -> 2.8857006e-06 | DY6: =DM6 -> 0.0045261724 | DZ6: =DN6+DL6*DP6-DM6*DQ6 -> 0.99951442 | EA6: =DO6+DL6*DQ6+DM6*DP6 -> 0.0013248579 | EB6: =0 -> 0 | EC6: =0 -> 0 | ED6: =0 -> 0 | EE6: =C6*Parameters!$C$44 -> 6.5793027e-09 | EF6: =DT6+DV6*ED6-DW6*EE6 -> 0.99985529 | EG6: =DU6+DV6*EE6+DW6*ED6 -> 0.00030506547 | EH6: =DV6 -> 0.35994617 | EI6: =DW6 -> 0.13955738 | EJ6: =DX6+DZ6*ED6-EA6*EE6 -> 2.8856919e-06 | EK6: =DY6+DZ6*EE6+EA6*ED6 -> 0.0045261789 | EL6: =DZ6 -> 0.99951442 | EM6: =EA6 -> 0.0013248579 | EN6: =0 -> 0 | EO6: =0 -> 0 | EP6: =(((2*Parameters!$C$47))/(((2*Parameters!$C$47))^2+((2*(C6*Parameters!$C$46-1/(C6*Parameters!$C$45))))^2)) -> 2.0951016e-14 | EQ6: =(-((2*(C6*Parameters!$C$46-1/(C6*Parameters!$C$45))))/(((2*Parameters!$C$47))^2+((2*(C6*Parameters!$C$46-1/(C6*Parameters!$C$45))))^2)) -> 7.237233e-07 | ER6: =EF6+EH6*EP6-EI6*EQ6 -> 0.99985519 | ES6: =EG6+EH6*EQ6+EI6*EP6 -> 0.00030532597 | ET6: =EH6 -> 0.35994617 | EU6: =EI6 -> 0.13955738 | EV6: =EJ6+EL6*EP6-EM6*EQ6 -> 2.8847331e-06 | EW6: =EK6+EL6*EQ6+EM6*EP6 -> 0.0045269023 | EX6: =EL6 -> 0.99951442 | EY6: =EM6 -> 0.0013248579 | EZ6: =(ER6+ET6/Parameters!$C$6+Parameters!$C$7*(EV6+EX6/Parameters!$C$6)) -> 1.0123751 | FA6: =(ES6+EU6/Parameters!$C$6+Parameters!$C$7*(EW6+EY6/Parameters!$C$6)) -> 0.0051594956 | FB6: =-20*LOG10(SQRT(EZ6^2+FA6^2)) -> -0.1069415 | FC6: =1/SQRT(EZ6^2+FA6^2) -> 0.98776339 | FD6: =(ER6+ET6/Parameters!$C$6+Parameters!$C$8*(EV6+EX6/Parameters!$C$6)) -> 2.7508052 | FE6: =(ES6+EU6/Parameters!$C$6+Parameters!$C$8*(EW6+EY6/Parameters!$C$6)) -> 0.23380871 | FF6: =-20*LOG10(SQRT(FD6^2+FE6^2)) -> -8.8204592 | FG6: =1/SQRT(FD6^2+FE6^2) -> 0.36222385
A7: =Parameters!$C$2*(Parameters!$C$3/Parameters!$C$2)^((ROW()-2)/(Parameters!$C$4-1)) -> 105.92537 | B7: =LOG10(A7) -> 2.025 | C7: =2*PI()*A7 -> 665.54874 | D7: =1 -> 1 | E7: =0 -> 0 | F7: =0 -> 0 | G7: =0 -> 0 | H7: =0 -> 0 | I7: =0 -> 0 | J7: =1 -> 1 | K7: =0 -> 0 | L7: =2*Parameters!$C$10 -> 0.04 | M7: =2*C7*Parameters!$C$9 -> 0.0013310975 | N7: =0 -> 0 | O7: =0 -> 0 | P7: =D7 -> 1 | Q7: =E7 -> 0 | R7: =F7+D7*L7-E7*M7 -> 0.04 | S7: =G7+D7*M7+E7*L7 -> 0.0013310975 | T7: =H7 -> 0 | U7: =I7 -> 0 | V7: =J7+H7*L7-I7*M7 -> 1 | W7: =K7+H7*M7+I7*L7 -> 0 | X7: =0 -> 0 | Y7: =0 -> 0 | Z7: =0 -> 0 | AA7: =C7*(Parameters!$C$12+Parameters!$C$11/2) -> 4.9916156e-08 | AB7: =P7+R7*Z7-S7*AA7 -> 1 | AC7: =Q7+R7*AA7+S7*Z7 -> 1.9966462e-09 | AD7: =R7 -> 0.04 | AE7: =S7 -> 0.0013310975 | AF7: =T7+V7*Z7-W7*AA7 -> 0 | AG7: =U7+V7*AA7+W7*Z7 -> 4.9916156e-08 | AH7: =V7 -> 1 | AI7: =W7 -> 0 | AJ7: =0 -> 0 | AK7: =0 -> 0 | AL7: =(((2*Parameters!$C$15))/(((2*Parameters!$C$15))^2+((2*(C7*Parameters!$C$14-1/(C7*Parameters!$C$13))))^2)) -> 4.4295516e-07 | AM7: =(-((2*(C7*Parameters!$C$14-1/(C7*Parameters!$C$13))))/(((2*Parameters!$C$15))^2+((2*(C7*Parameters!$C$14-1/(C7*Parameters!$C$13))))^2)) -> 0.0033277438 | AN7: =AB7+AD7*AL7-AE7*AM7 -> 0.99999559 | AO7: =AC7+AD7*AM7+AE7*AL7 -> 0.00013311234 | AP7: =AD7 -> 0.04 | AQ7: =AE7 -> 0.0013310975 | AR7: =AF7+AH7*AL7-AI7*AM7 -> 4.4295516e-07 | AS7: =AG7+AH7*AM7+AI7*AL7 -> 0.0033277937 | AT7: =AH7 -> 1 | AU7: =AI7 -> 0 | AV7: =2*Parameters!$C$17 -> 0.04 | AW7: =2*C7*Parameters!$C$16 -> 0.0013310975 | AX7: =0 -> 0 | AY7: =0 -> 0 | AZ7: =AN7 -> 0.99999559 | BA7: =AO7 -> 0.00013311234 | BB7: =AP7+AN7*AV7-AO7*AW7 -> 0.079999646 | BC7: =AQ7+AN7*AW7+AO7*AV7 -> 0.0026675136 | BD7: =AR7 -> 4.4295516e-07 | BE7: =AS7 -> 0.0033277937 | BF7: =AT7+AR7*AV7-AS7*AW7 -> 0.99999559 | BG7: =AU7+AR7*AW7+AS7*AV7 -> 0.00013311234 | BH7: =0 -> 0 | BI7: =0 -> 0 | BJ7: =0 -> 0 | BK7: =C7*(Parameters!$C$19+Parameters!$C$18/2) -> 4.9916156e-08 | BL7: =AZ7+BB7*BJ7-BC7*BK7 -> 0.99999559 | BM7: =BA7+BB7*BK7+BC7*BJ7 -> 0.00013311633 | BN7: =BB7 -> 0.079999646 | BO7: =BC7 -> 0.0026675136 | BP7: =BD7+BF7*BJ7-BG7*BK7 -> 4.4294852e-07 | BQ7: =BE7+BF7*BK7+BG7*BJ7 -> 0.0033278436 | BR7: =BF7 -> 0.99999559 | BS7: =BG7 -> 0.00013311234 | BT7: =2*((((Parameters!$C$21)/((Parameters!$C$21)^2+(C7*Parameters!$C$20)^2)))/((((Parameters!$C$21)/((Parameters!$C$21)^2+(C7*Parameters!$C$20)^2)))^2+((-(C7*Parameters!$C$20)/((Parameters!$C$21)^2+(C7*Parameters!$C$20)^2)+C7*Parameters!$C$22))^2)) -> 0.04 | BU7: =2*(-((-(C7*Parameters!$C$20)/((Parameters!$C$21)^2+(C7*Parameters!$C$20)^2)+C7*Parameters!$C$22))/((((Parameters!$C$21)/((Parameters!$C$21)^2+(C7*Parameters!$C$20)^2)))^2+((-(C7*Parameters!$C$20)/((Parameters!$C$21)^2+(C7*Parameters!$C$20)^2)+C7*Parameters!$C$22))^2)) -> 0.090514629 | BV7: =0 -> 0 | BW7: =0 -> 0 | BX7: =BL7 -> 0.99999559 | BY7: =BM7 -> 0.00013311633 | BZ7: =BN7+BL7*BT7-BM7*BU7 -> 0.11998742 | CA7: =BO7+BL7*BU7+BM7*BT7 -> 0.093187068 | CB7: =BP7 -> 4.4294852e-07 | CC7: =BQ7 -> 0.0033278436 | CD7: =BR7+BP7*BT7-BQ7*BU7 -> 0.99969439 | CE7: =BS7+BP7*BU7+BQ7*BT7 -> 0.00026626618 | CF7: =0 -> 0 | CG7: =0 -> 0 | CH7: =(((Parameters!$C$25))/(((Parameters!$C$25))^2+((C7*Parameters!$C$24-1/(C7*Parameters!$C$23)))^2))+(((Parameters!$C$29+Parameters!$C$28))/(((Parameters!$C$29+Parameters!$C$28))^2+((C7*Parameters!$C$27-1/(C7*Parameters!$C$26)))^2)) -> 1.4716133e-06 | CI7: =(-((C7*Parameters!$C$24-1/(C7*Parameters!$C$23)))/(((Parameters!$C$25))^2+((C7*Parameters!$C$24-1/(C7*Parameters!$C$23)))^2))+(-((C7*Parameters!$C$27-1/(C7*Parameters!$C$26)))/(((Parameters!$C$29+Parameters!$C$28))^2+((C7*Parameters!$C$27-1/(C7*Parameters!$C$26)))^2)) -> 0.00062560892 | CJ7: =BX7+BZ7*CH7-CA7*CI7 -> 0.99993747 | CK7: =BY7+BZ7*CI7+CA7*CH7 -> 0.00020831867 | CL7: =BZ7 -> 0.11998742 | CM7: =CA7 -> 0.093187068 | CN7: =CB7+CD7*CH7-CE7*CI7 -> 1.7475336e-06 | CO7: =CC7+CD7*CI7+CE7*CH7 -> 0.0039532618 | CP7: =CD7 -> 0.99969439 | CQ7: =CE7 -> 0.00026626618 | CR7: =2*((((Parameters!$C$31)/((Parameters!$C$31)^2+(C7*Parameters!$C$30)^2)))/((((Parameters!$C$31)/((Parameters!$C$31)^2+(C7*Parameters!$C$30)^2)))^2+((-(C7*Parameters!$C$30)/((Parameters!$C$31)^2+(C7*Parameters!$C$30)^2)+C7*Parameters!$C$32))^2)) -> 0.04 | CS7: =2*(-((-(C7*Parameters!$C$30)/((Parameters!$C$31)^2+(C7*Parameters!$C$30)^2)+C7*Parameters!$C$32))/((((Parameters!$C$31)/((Parameters!$C$31)^2+(C7*Parameters!$C$30)^2)))^2+((-(C7*Parameters!$C$30)/((Parameters!$C$31)^2+(C7*Parameters!$C$30)^2)+C7*Parameters!$C$32))^2)) -> 0.043926217 | CT7: =0 -> 0 | CU7: =0 -> 0 | CV7: =CJ7 -> 0.99993747 | CW7: =CK7 -> 0.00020831867 | CX7: =CL7+CJ7*CR7-CK7*CS7 -> 0.15997577 | CY7: =CM7+CJ7*CS7+CK7*CR7 -> 0.13711887 | CZ7: =CN7 -> 1.7475336e-06 | DA7: =CO7 -> 0.0039532618 | DB7: =CP7+CN7*CR7-CO7*CS7 -> 0.99952081 | DC7: =CQ7+CN7*CS7+CO7*CR7 -> 0.00042447341 | DD7: =0 -> 0 | DE7: =0 -> 0 | DF7: =(((Parameters!$C$35))/(((Parameters!$C$35))^2+((C7*Parameters!$C$34-1/(C7*Parameters!$C$33)))^2))+(((Parameters!$C$39+Parameters!$C$38))/(((Parameters!$C$39+Parameters!$C$38))^2+((C7*Parameters!$C$37-1/(C7*Parameters!$C$36)))^2)) -> 1.4716133e-06 | DG7: =(-((C7*Parameters!$C$34-1/(C7*Parameters!$C$33)))/(((Parameters!$C$35))^2+((C7*Parameters!$C$34-1/(C7*Parameters!$C$33)))^2))+(-((C7*Parameters!$C$37-1/(C7*Parameters!$C$36)))/(((Parameters!$C$39+Parameters!$C$38))^2+((C7*Parameters!$C$37-1/(C7*Parameters!$C$36)))^2)) -> 0.00062560892 | DH7: =CV7+CX7*DF7-CY7*DG7 -> 0.99985192 | DI7: =CW7+CX7*DG7+CY7*DF7 -> 0.00030860272 | DJ7: =CX7 -> 0.15997577 | DK7: =CY7 -> 0.13711887 | DL7: =CZ7+DB7*DF7-DC7*DG7 -> 2.9528874e-06 | DM7: =DA7+DB7*DG7+DC7*DF7 -> 0.0045785715 | DN7: =DB7 -> 0.99952081 | DO7: =DC7 -> 0.00042447341 | DP7: =2*((((Parameters!$C$41)/((Parameters!$C$41)^2+(C7*(Parameters!$C$40*(1-Parameters!$C$42)))^2)))/((((Parameters!$C$41)/((Parameters!$C$41)^2+(C7*(Parameters!$C$40*(1-Parameters!$C$42)))^2)))^2+((-(C7*(Parameters!$C$40*(1-Parameters!$C$42)))/((Parameters!$C$41)^2+(C7*(Parameters!$C$40*(1-Parameters!$C$42)))^2)+C7*Parameters!$C$43))^2)) -> 0.2 | DQ7: =2*(-((-(C7*(Parameters!$C$40*(1-Parameters!$C$42)))/((Parameters!$C$41)^2+(C7*(Parameters!$C$40*(1-Parameters!$C$42)))^2)+C7*Parameters!$C$43))/((((Parameters!$C$41)/((Parameters!$C$41)^2+(C7*(Parameters!$C$40*(1-Parameters!$C$42)))^2)))^2+((-(C7*(Parameters!$C$40*(1-Parameters!$C$42)))/((Parameters!$C$41)^2+(C7*(Parameters!$C$40*(1-Parameters!$C$42)))^2)+C7*Parameters!$C$43))^2)) -> 0.0039932924 | DR7: =0 -> 0 | DS7: =0 -> 0 | DT7: =DH7 -> 0.99985192 | DU7: =DI7 -> 0.00030860272 | DV7: =DJ7+DH7*DP7-DI7*DQ7 -> 0.35994492 | DW7: =DK7+DH7*DQ7+DI7*DP7 -> 0.14117329 | DX7: =DL7 -> 2.9528874e-06 | DY7: =DM7 -> 0.0045785715 | DZ7: =DN7+DL7*DP7-DM7*DQ7 -> 0.99950311 | EA7: =DO7+DL7*DQ7+DM7*DP7 -> 0.0013401995 | EB7: =0 -> 0 | EC7: =0 -> 0 | ED7: =0 -> 0 | EE7: =C7*Parameters!$C$44 -> 6.6554874e-09 | EF7: =DT7+DV7*ED7-DW7*EE7 -> 0.99985192 | EG7: =DU7+DV7*EE7+DW7*ED7 -> 0.00030860512 | EH7: =DV7 -> 0.35994492 | EI7: =DW7 -> 0.14117329 | EJ7: =DX7+DZ7*ED7-EA7*EE7 -> 2.9528785e-06 | EK7: =DY7+DZ7*EE7+EA7*ED7 -> 0.0045785782 | EL7: =DZ7 -> 0.99950311 | EM7: =EA7 -> 0.0013401995 | EN7: =0 -> 0 | EO7: =0 -> 0 | EP7: =(((2*Parameters!$C$47))/(((2*Parameters!$C$47))^2+((2*(C7*Parameters!$C$46-1/(C7*Parameters!$C$45))))^2)) -> 2.1439028e-14 | EQ7: =(-((2*(C7*Parameters!$C$46-1/(C7*Parameters!$C$45))))/(((2*Parameters!$C$47))^2+((2*(C7*Parameters!$C$46-1/(C7*Parameters!$C$45))))^2)) -> 7.3210362e-07 | ER7: =EF7+EH7*EP7-EI7*EQ7 -> 0.99985181 | ES7: =EG7+EH7*EQ7+EI7*EP7 -> 0.00030886863 | ET7: =EH7 -> 0.35994492 | EU7: =EI7 -> 0.14117329 | EV7: =EJ7+EL7*EP7-EM7*EQ7 -> 2.9518974e-06 | EW7: =EK7+EL7*EQ7+EM7*EP7 -> 0.0045793099 | EX7: =EL7 -> 0.99950311 | EY7: =EM7 -> 0.0013401995 | EZ7: =(ER7+ET7/Parameters!$C$6+Parameters!$C$7*(EV7+EX7/Parameters!$C$6)) -> 1.0123716 | FA7: =(ES7+EU7/Parameters!$C$6+Parameters!$C$7*(EW7+EY7/Parameters!$C$6)) -> 0.005219244 | FB7: =-20*LOG10(SQRT(EZ7^2+FA7^2)) -> -0.10691482 | FC7: =1/SQRT(EZ7^2+FA7^2) -> 0.98776642 | FD7: =(ER7+ET7/Parameters!$C$6+Parameters!$C$8*(EV7+EX7/Parameters!$C$6)) -> 2.7507855 | FE7: =(ES7+EU7/Parameters!$C$6+Parameters!$C$8*(EW7+EY7/Parameters!$C$6)) -> 0.23651552 | FF7: =-20*LOG10(SQRT(FD7^2+FE7^2)) -> -8.8211228 | FG7: =1/SQRT(FD7^2+FE7^2) -> 0.36219618
