Workbook

Sheet Dashboard
A1: WR90 TE10 許容電力ダッシュボード - Ragan短パルス式 / VSWR / 熱 拡張モデル ※Inputs!B87=1 で35,000ft高度ケース
A2: ※誤読防止：このDashboardは現在の入力条件1ケースの判定です。絶縁破壊評価と熱評価の最悪ケースは分けて確認してください。詳細は「誤読防止_使い方」シート参照。
A3: 指標 | B3: Value | C3: 単位 | D3: コメント
A4: ダッシュボード用ピーク進行波電力 | B4: =Inputs!B41 -> 16 | C4: kW | D4: ユーザー試算値
A5: デューティ比 | B5: =Inputs!B40 -> 0.0275 | C5: - | D5: パルス幅 × PRF
A6: 平均進行波電力 | B6: =B4*B5 -> 0.44 | C6: kW | D6: 熱計算の入力基準
A7: VSWRを正味電力基準で見る場合の供給ピーク電力 | B7: =B4*Inputs!B44 -> 15.36 | C7: kW | D7: 進行波 × (1-|Γ|^2)
A8: TE10 カットオフ周波数 | B8: =Inputs!B19/1000000000 -> 6.5571404 | C8: GHz | D8: 動作周波数より低い必要あり
A9: TE10 波動インピーダンス Z_TE | B9: =Inputs!B21 -> 540.14902 | C9: Ω | D9: TE10モードの波動インピーダンス
A10: 合計挿入損失 | B10: =Components!F10 -> 0.011826696 | C10: dB | D10: 有効化した部品を含む
A11: ダッシュボード電力での合計RF損失 | B11: =B6*1000*Components!J10 -> 1.1965769 | C11: W | D11: 平均損失。ピークではない
A12: 最大部品電界係数 K_E | B12: =Components!G10 -> 1 | C12: - | D12: 有効化した部品の局所電界係数の最大値
A13: 反射係数 |Γ| | B13: =Inputs!B43 -> 0.2 | C13: - | D13: VSWRから算出
A14: 進行波ピーク電界 E_peak | B14: =SQRT(4*Inputs!B21*B4*1000/(Inputs!B10*Inputs!B11))/1000 -> 385.79964 | C14: kV/m | D14: 進行波ピーク電力に対する値
A15: 定在波ピーク電界 E_peak | B15: =B14*(1+Inputs!B43) -> 462.95957 | C15: kV/m | D15: VSWRによる最大電界
A16: 部品K_E反映後の局所ピーク電界 | B16: =B15*B12 -> 462.95957 | C16: kV/m | D16: 絶縁破壊判定で比較する値
A17: 補正後絶縁破壊電界 | B17: =Inputs!B62/1000 -> 2893.3242 | C17: kV/m | D17: 安全率を掛ける前
A18: 設計許容電界 | B18: =Inputs!B63/1000 -> 1446.6621 | C18: kV/m | D18: 電界安全率適用後
A19: 電界利用率 | B19: =B16/B18 -> 0.32001915 | C19: - | D19: 1未満なら許容
A20: 絶縁破壊で制限されるピーク進行波電力 | B20: =(Inputs!B63/(Components!G10*(1+Inputs!B43)))^2*Inputs!B10*Inputs!B11/(4*Inputs!B21)/1000 -> 156.23131 | C20: kW | D20: 進行波ピーク電力基準
A21: 熱で制限されるピーク進行波電力 | B21: =Components!N10 -> 173.76622 | C21: kW | D21: 部品ごとの熱制限の最小値
A22: 最終許容ピーク進行波電力 | B22: =MIN(B20,B21) -> 156.23131 | C22: kW | D22: 絶縁破壊制限と熱制限の小さい方
A23: 支配要因 | B23: =IF(B20<B21,"電界 / 絶縁破壊","平均発熱") -> 電界 / 絶縁破壊 | C23: - | D23: 現在の入力条件での判定
A24: ダッシュボード総合判定 | B24: =IF(B4<=B22,"合格","NG") -> 合格 | C24: - | D24: ダッシュボード用ピーク進行波電力に対する判定
A25: 臨界パルス幅 τc | B25: =Inputs!B65*1000000 -> 1.3157858 | C25: µs | D25: スクリーニング用
A26: パルス幅 / τc | B26: =Inputs!B38/Inputs!B65 -> 33.440092 | C26: - | D26: >>1ならCW/マルチパルス相当
A27: パルス領域スクリーニング | B27: =Inputs!B66 -> CW/マルチパルス相当: パルスによる許容上昇は推奨しない | C27: - | D27: 検証なしではパルスによる許容電界上昇を見込まない
A29: Ragan単発破壊電界 Eb | B29: =Inputs!B72 -> 22.373272
A30: Ragan電圧改善係数 Fv | B30: =Inputs!B74 -> 1 | C30: - | D30: 短パルス時のみ1以上。tau>=tau_cではKtau=1に戻す
A31: 使用Ktau | B31: =Inputs!B60 -> 1 | C31: - | D31: Inputs!B60。補正後絶縁破壊電界に反映
A32: PRFパルス間隔 | B32: =Inputs!B77*1000 -> 1.6 | C32: ms | D32: 1/PRF
A33: パルス間隔/tau_c | B33: =Inputs!B78 -> 1216.0034 | C33: - | D33: 大きいほど単発近似に近い
A34: PRF/multipulse判定 | B34: =Inputs!B79 -> 単発近似の余裕あり。ただし実機では残留電離を確認 | C34: - | D34: 残留電離・履歴効果の確認用
A35: 半解析式 Ep peak換算 | B35: =Inputs!B83/1000 -> 4013.0848 | C35: kV/m | D35: Anderson/Yu系式による参考値。RMSからpeak換算。最終判定には直接使用しない
A36: 重要 | B36: 本版ではRagan短パルス式をKtauへ組み込みました。ただしtau>=tau_cでは自動的にKtau=1とし、PRFの厳密効果はB61の保守係数で扱います。
A38: 高度・加圧モデル確認
A39: 高度モード | B39: =Inputs!B87 -> 1 | C39: 1/0 | D39: Inputs!B87
A40: 圧力モード | B40: =Inputs!B90 -> 2 | C40: 0/1/2/3 | D40: 0:外気圧, 1:海面1atm, 2:指定絶対圧, 3:外気圧+ゲージ
A41: 運用高度 | B41: =Inputs!B88 -> 35000 | C41: ft
A42: 高度周囲圧 | B42: =Inputs!B96/1000 -> 23.842264 | C42: kPa
...

Sheet Inputs
A1: WR90 TE10 許容電力入力 - パルス / VSWR / 熱 拡張版
A2: パラメータ | B2: Value | C2: 単位 | D2: 注記
A3: 物理定数
A4: 光速 c0 | B4: 299792458 | C4: m/s | D4: 真空中の光速
A5: 自由空間波インピーダンス eta0 | B5: 376.73031 | C5: Ω | D5: 自由空間の波動インピーダンス
A6: 真空の透磁率 mu0 | B6: 1.2566371e-06 | C6: H/m | D6: 真空の透磁率
A7: ステファン・ボルツマン定数 sigma_SB | B7: 5.6703744e-08 | C7: W/m2/K4 | D7: 放射熱伝達の定数
A9: 導波管 / TE10
A10: 内側幅 a_inner | B10: 0.02286 | C10: m | D10: WR90 広壁側の内寸
A11: 内側高さ b_inner | B11: 0.01016 | C11: m | D11: WR90 狭壁側の内寸
A12: 肉厚 wall_thickness | B12: 0.00127 | C12: m | D12: WR90の代表的肉厚。実部品に合わせて変更
A13: 直管長 straight_waveguide_length | B13: 0.1 | C13: m | D13: 直管部の導体損と放熱面積に使用
A14: 周波数 frequency | B14: 9150000000 | C14: Hz | D14: 動作周波数
A15: 比誘電率 relative_permittivity | B15: 1 | C15: - | D15: 空気/窒素では概ね1.0
A16: 導電率 conductivity | B16: 58000000 | C16: S/m | D16: 銅を基準。めっき・表面状態に応じて有効値を変更
A17: 表面損失倍率 surface_loss_multiplier | B17: 1 | C17: - | D17: 粗さ、めっき、継手、経年劣化を見込む場合は1より大
A18: 外周長 outer_perimeter | B18: =2*((B10+2*B12)+(B11+2*B12)) -> 0.0762 | C18: m | D18: 外形寸法から計算
A19: TE10カットオフ周波数 | B19: =B4/(2*B10*SQRT(B15)) -> 6.5571404e+09 | C19: Hz | D19: fc = c/(2a√eps_r)
A20: 伝搬係数 chi | B20: =SQRT(1-(B19/B14)^2) -> 0.69745625 | C20: - | D20: sqrt(1-(fc/f)^2)
A21: TE10波動インピーダンス Z_TE | B21: =(B5/SQRT(B15))/B20 -> 540.14902 | C21: Ω | D21: eta/sqrt(1-(fc/f)^2)
A22: 表面抵抗 Rs | B22: =SQRT(PI()*B14*B6/B16)*B17 -> 0.024956083 | C22: Ω/sq | D22: Rs = sqrt(pi*f*mu0/sigma)
A23: TE10導体損 | B23: =B22*B21/(B10*B11)*(B10*(1/B21^2+(PI()/(2*PI()*B14*B6*B10))^2)+2*B11*(PI()/(2*PI()*B14*B6*B10))^2) -> 0.013615814 | C23: Np/m | D23: TE10の壁面電流から算出
A24: TE10導体損 | B24: =8.686*B23 -> 0.11826696 | C24: dB/m | D24: Componentsの直管行で使用
A26: 熱 / 環境
A27: 周囲温度 ambient_temperature | B27: =IF($B$87=1,B95,50) -> -54.3 | C27: degC | D27: 周囲空気温度
A28: ホットスポット許容温度 | B28: 100 | C28: degC | D28: 局所部品/ホットスポットの許容温度
A29: 自然対流熱伝達率 h | B29: 7 | C29: W/m2/K | D29: ユーザー入力。静止空気の概算値
A30: 放射率 emissivity | B30: 0.8 | C30: - | D30: 表面状態に依存するユーザー入力
A31: 平均表面温度 | B31: 75 | C31: degC | D31: 線形化放射熱伝達率 h_rad の計算に使用
A32: 追加接触・熱拡がり熱抵抗 | B32: 0 | C32: degC/W | D32: フランジ/接触/熱拡がり分を加算
A33: 線形化放射熱伝達率 h_rad | B33: =4*B30*B7*(B31+273.15)^3 -> 7.65704 | C33: W/m2/K | D33: 4*eps*sigma*Tmean^3
A34: 有効熱伝達率 h_eff | B34: =IF($B$87=1,B99,B29)+B33 -> 11.052616 | C34: W/m2/K | D34: h_conv + h_rad。高度モード時は低圧補正した h_conv を使用
A35: 直管WR90熱抵抗推定 | B35: =1/(B34*B18*B13)+B32 -> 11.873532 | C35: degC/W | D35: 1/(h_eff*外周長*長さ)+追加分
A37: パルス / 電力 / 不整合
A38: パルス幅 pulse_width | B38: 4.4e-05 | C38: s | D38: RFパルス幅
A39: パルス繰返し周波数 PRF | B39: 625 | C39: Hz | D39: PRF
A40: デューティ比 duty | B40: =B38*B39 -> 0.0275 | C40: - | D40: pulse_width * PRF
A41: ダッシュボード用ピーク進行波電力 | B41: 16 | C41: kW | D41: Dashboard用の試算/入力値
A42: VSWR | B42: 1.5 | C42: - | D42: 定在波電界増加に使用
A43: 反射係数絶対値 |Γ| | B43: =(B42-1)/(B42+1) -> 0.2 | C43: - | D43: (VSWR-1)/(VSWR+1)
...

Sheet Components
A1: 部品ディレーティングおよび熱ホットスポット表
A2: 部品 | B2: 使用 1/0 | C2: 根拠 | D2: 長さ m | E2: 単位長さIL dB/m | F2: IL合計 dB | G2: 電界係数 K_E | H2: 有効Rθ degC/W | I2: 温度上限 degC | J2: 損失率 | K2: Dashboard時P_loss W | L2: Dashboard時ΔT degC | M2: ホットスポット温度 degC | N2: 熱制限ピーク kW | O2: 注記
A3: WR90直管部 | B3: 1 | C3: TE10導体損から自動計算 | D3: =Inputs!B13 -> 0.1 | E3: =Inputs!B24 -> 0.11826696 | F3: =B3*D3*E3 -> 0.011826696 | G3: 1 | H3: =Inputs!B35 -> 11.873532 | I3: =Inputs!B28 -> 100 | J3: =IF(B3=1,1-10^(-F3/10),0) -> 0.0027194929 | K3: =Inputs!B41*1000*Inputs!B40*J3 -> 1.1965769 | L3: =K3*H3 -> 14.207594 | M3: =Inputs!B27+L3 -> -40.092406 | N3: =IF(OR(B3=0,J3=0,H3=0),1E+099,(I3-Inputs!B27)/Inputs!B48/(Inputs!B40*J3*H3)/1000) -> 173.76622 | O3: 銅直管部。長さはInputsから参照
A4: フランジ対 / 接触部 | B4: 0 | C4: ユーザー入力 | D4: 0 | E4: 0 | F4: 0.005 | G4: 1.1 | H4: 15 | I4: =Inputs!B28 -> 100 | J4: =IF(B4=1,1-10^(-F4/10),0) -> 0 | K4: =Inputs!B41*1000*Inputs!B40*J4 -> 0 | L4: =K4*H4 -> 0 | M4: =Inputs!B27+L4 -> -54.3 | N4: =IF(OR(B4=0,J4=0,H4=0),1E+099,(I4-Inputs!B27)/Inputs!B48/(Inputs!B40*J4*H4)/1000) -> 1e+99 | O4: 仮値。試験値またはメーカー値に置換
A5: E/H面ベンド | B5: 0 | C5: ユーザー入力 | D5: 0 | E5: 0 | F5: 0.02 | G5: 1.2 | H5: 10 | I5: =Inputs!B28 -> 100 | J5: =IF(B5=1,1-10^(-F5/10),0) -> 0 | K5: =Inputs!B41*1000*Inputs!B40*J5 -> 0 | L5: =K5*H5 -> 0 | M5: =Inputs!B27+L5 -> -54.3 | N5: =IF(OR(B5=0,J5=0,H5=0),1E+099,(I5-Inputs!B27)/Inputs!B48/(Inputs!B40*J5*H5)/1000) -> 1e+99 | O5: 仮値。局所電界と損失は形状に依存
A6: トップウォールカップラー | B6: 0 | C6: ユーザー入力 | D6: 0 | E6: 0 | F6: 0.05 | G6: 1.5 | H6: 8 | I6: =Inputs!B28 -> 100 | J6: =IF(B6=1,1-10^(-F6/10),0) -> 0 | K6: =Inputs!B41*1000*Inputs!B40*J6 -> 0 | L6: =K6*H6 -> 0 | M6: =Inputs!B27+L6 -> -54.3 | N6: =IF(OR(B6=0,J6=0,H6=0),1E+099,(I6-Inputs!B27)/Inputs!B48/(Inputs!B40*J6*H6)/1000) -> 1e+99 | O6: 仮値。プローブ/スロット部が電界支配になる場合あり
A7: ロータリージョイント | B7: 0 | C7: ユーザー入力 | D7: 0 | E7: 0 | F7: 0.1 | G7: 2 | H7: 5 | I7: =Inputs!B28 -> 100 | J7: =IF(B7=1,1-10^(-F7/10),0) -> 0 | K7: =Inputs!B41*1000*Inputs!B40*J7 -> 0 | L7: =K7*H7 -> 0 | M7: =Inputs!B27+L7 -> -54.3 | N7: =IF(OR(B7=0,J7=0,H7=0),1E+099,(I7-Inputs!B27)/Inputs!B48/(Inputs!B40*J7*H7)/1000) -> 1e+99 | O7: 仮値。可能ならメーカーの高電力定格を使用
A8: 窓 / 加圧シール | B8: 0 | C8: ユーザー入力 | D8: 0 | E8: 0 | F8: 0.05 | G8: 2 | H8: 8 | I8: =Inputs!B28 -> 100 | J8: =IF(B8=1,1-10^(-F8/10),0) -> 0 | K8: =Inputs!B41*1000*Inputs!B40*J8 -> 0 | L8: =K8*H8 -> 0 | M8: =Inputs!B27+L8 -> -54.3 | N8: =IF(OR(B8=0,J8=0,H8=0),1E+099,(I8-Inputs!B27)/Inputs!B48/(Inputs!B40*J8*H8)/1000) -> 1e+99 | O8: 仮値。誘電体表面フラッシオーバが支配的な場合あり
A10: 合計 / 制限値 | F10: =SUMPRODUCT(B3:B8,F3:F8) -> 0.011826696 | G10: =MAX(1,IF(B3=1,G3,0),IF(B4=1,G4,0),IF(B5=1,G5,0),IF(B6=1,G6,0),IF(B7=1,G7,0),IF(B8=1,G8,0)) -> 1 | J10: =1-10^(-F10/10) -> 0.0027194929 | K10: =Inputs!B41*1000*Inputs!B40*J10 -> 1.1965769 | M10: =MAX(M3:M8) -> -40.092406 | N10: =MIN(N3:N8) -> 173.76622 | O10: F10:合計IL、G10:最大K_E、N10:熱制限ピーク

Sheet Power_Sweep
A1: ピーク電力スイープ - 絶縁破壊・熱判定 (Inputs!B87 のモードに連動)
A3: ピーク進行波電力 kW | B3: 供給ピーク電力 kW | C3: 進行波E kV/m | D3: 定在波E kV/m | E3: 局所E kV/m | F3: 設計許容E kV/m | G3: 電界利用率 | H3: 平均電力 kW | I3: 合計RF損失 W | J3: 熱制限 kW | K3: 熱利用率 | L3: 絶縁破壊判定 | M3: 熱判定 | N3: 総合判定
A4: 1 | B4: =A4*Inputs!B44 -> 0.96 | C4: =SQRT(4*Inputs!B21*A4*1000/(Inputs!B10*Inputs!B11))/1000 -> 96.44991 | D4: =C4*(1+Inputs!B43) -> 115.73989 | E4: =D4*Components!G10 -> 115.73989 | F4: =Inputs!B63/1000 -> 1446.6621 | G4: =E4/F4 -> 0.080004786 | H4: =A4*Inputs!B40 -> 0.0275 | I4: =H4*1000*Components!J10 -> 0.074786055 | J4: =Components!N10 -> 173.76622 | K4: =A4/J4 -> 0.0057548583 | L4: =IF(G4<1,"合格","NG") -> 合格 | M4: =IF(K4<1,"合格","NG") -> 合格 | N4: =IF(AND(L4="合格",M4="合格"),"合格","NG") -> 合格
A5: 2 | B5: =A5*Inputs!B44 -> 1.92 | C5: =SQRT(4*Inputs!B21*A5*1000/(Inputs!B10*Inputs!B11))/1000 -> 136.40077 | D5: =C5*(1+Inputs!B43) -> 163.68092 | E5: =D5*Components!G10 -> 163.68092 | F5: =Inputs!B63/1000 -> 1446.6621 | G5: =E5/F5 -> 0.11314385 | H5: =A5*Inputs!B40 -> 0.055 | I5: =H5*1000*Components!J10 -> 0.14957211 | J5: =Components!N10 -> 173.76622 | K5: =A5/J5 -> 0.011509717 | L5: =IF(G5<1,"合格","NG") -> 合格 | M5: =IF(K5<1,"合格","NG") -> 合格 | N5: =IF(AND(L5="合格",M5="合格"),"合格","NG") -> 合格
A6: 3 | B6: =A6*Inputs!B44 -> 2.88 | C6: =SQRT(4*Inputs!B21*A6*1000/(Inputs!B10*Inputs!B11))/1000 -> 167.05614 | D6: =C6*(1+Inputs!B43) -> 200.46737 | E6: =D6*Components!G10 -> 200.46737 | F6: =Inputs!B63/1000 -> 1446.6621 | G6: =E6/F6 -> 0.13857235 | H6: =A6*Inputs!B40 -> 0.0825 | I6: =H6*1000*Components!J10 -> 0.22435816 | J6: =Components!N10 -> 173.76622 | K6: =A6/J6 -> 0.017264575 | L6: =IF(G6<1,"合格","NG") -> 合格 | M6: =IF(K6<1,"合格","NG") -> 合格 | N6: =IF(AND(L6="合格",M6="合格"),"合格","NG") -> 合格
A7: 4 | B7: =A7*Inputs!B44 -> 3.84 | C7: =SQRT(4*Inputs!B21*A7*1000/(Inputs!B10*Inputs!B11))/1000 -> 192.89982 | D7: =C7*(1+Inputs!B43) -> 231.47978 | E7: =D7*Components!G10 -> 231.47978 | F7: =Inputs!B63/1000 -> 1446.6621 | G7: =E7/F7 -> 0.16000957 | H7: =A7*Inputs!B40 -> 0.11 | I7: =H7*1000*Components!J10 -> 0.29914422 | J7: =Components!N10 -> 173.76622 | K7: =A7/J7 -> 0.023019433 | L7: =IF(G7<1,"合格","NG") -> 合格 | M7: =IF(K7<1,"合格","NG") -> 合格 | N7: =IF(AND(L7="合格",M7="合格"),"合格","NG") -> 合格
A8: 5 | B8: =A8*Inputs!B44 -> 4.8 | C8: =SQRT(4*Inputs!B21*A8*1000/(Inputs!B10*Inputs!B11))/1000 -> 215.66856 | D8: =C8*(1+Inputs!B43) -> 258.80227 | E8: =D8*Components!G10 -> 258.80227 | F8: =Inputs!B63/1000 -> 1446.6621 | G8: =E8/F8 -> 0.17889614 | H8: =A8*Inputs!B40 -> 0.1375 | I8: =H8*1000*Components!J10 -> 0.37393027 | J8: =Components!N10 -> 173.76622 | K8: =A8/J8 -> 0.028774292 | L8: =IF(G8<1,"合格","NG") -> 合格 | M8: =IF(K8<1,"合格","NG") -> 合格 | N8: =IF(AND(L8="合格",M8="合格"),"合格","NG") -> 合格
A9: 6 | B9: =A9*Inputs!B44 -> 5.76 | C9: =SQRT(4*Inputs!B21*A9*1000/(Inputs!B10*Inputs!B11))/1000 -> 236.25307 | D9: =C9*(1+Inputs!B43) -> 283.50368 | E9: =D9*Components!G10 -> 283.50368 | F9: =Inputs!B63/1000 -> 1446.6621 | G9: =E9/F9 -> 0.1959709 | H9: =A9*Inputs!B40 -> 0.165 | I9: =H9*1000*Components!J10 -> 0.44871633 | J9: =Components!N10 -> 173.76622 | K9: =A9/J9 -> 0.03452915 | L9: =IF(G9<1,"合格","NG") -> 合格 | M9: =IF(K9<1,"合格","NG") -> 合格 | N9: =IF(AND(L9="合格",M9="合格"),"合格","NG") -> 合格
A10: 7 | B10: =A10*Inputs!B44 -> 6.72 | C10: =SQRT(4*Inputs!B21*A10*1000/(Inputs!B10*Inputs!B11))/1000 -> 255.18248 | D10: =C10*(1+Inputs!B43) -> 306.21897 | E10: =D10*Components!G10 -> 306.21897 | F10: =Inputs!B63/1000 -> 1446.6621 | G10: =E10/F10 -> 0.21167277 | H10: =A10*Inputs!B40 -> 0.1925 | I10: =H10*1000*Components!J10 -> 0.52350238 | J10: =Components!N10 -> 173.76622 | K10: =A10/J10 -> 0.040284008 | L10: =IF(G10<1,"合格","NG") -> 合格 | M10: =IF(K10<1,"合格","NG") -> 合格 | N10: =IF(AND(L10="合格",M10="合格"),"合格","NG") -> 合格
A11: 8 | B11: =A11*Inputs!B44 -> 7.68 | C11: =SQRT(4*Inputs!B21*A11*1000/(Inputs!B10*Inputs!B11))/1000 -> 272.80154 | D11: =C11*(1+Inputs!B43) -> 327.36185 | E11: =D11*Components!G10 -> 327.36185 | F11: =Inputs!B63/1000 -> 1446.6621 | G11: =E11/F11 -> 0.22628771 | H11: =A11*Inputs!B40 -> 0.22 | I11: =H11*1000*Components!J10 -> 0.59828844 | J11: =Components!N10 -> 173.76622 | K11: =A11/J11 -> 0.046038867 | L11: =IF(G11<1,"合格","NG") -> 合格 | M11: =IF(K11<1,"合格","NG") -> 合格 | N11: =IF(AND(L11="合格",M11="合格"),"合格","NG") -> 合格
A12: 9 | B12: =A12*Inputs!B44 -> 8.64 | C12: =SQRT(4*Inputs!B21*A12*1000/(Inputs!B10*Inputs!B11))/1000 -> 289.34973 | D12: =C12*(1+Inputs!B43) -> 347.21968 | E12: =D12*Components!G10 -> 347.21968 | F12: =Inputs!B63/1000 -> 1446.6621 | G12: =E12/F12 -> 0.24001436 | H12: =A12*Inputs!B40 -> 0.2475 | I12: =H12*1000*Components!J10 -> 0.67307449 | J12: =Components!N10 -> 173.76622 | K12: =A12/J12 -> 0.051793725 | L12: =IF(G12<1,"合格","NG") -> 合格 | M12: =IF(K12<1,"合格","NG") -> 合格 | N12: =IF(AND(L12="合格",M12="合格"),"合格","NG") -> 合格
A13: 10 | B13: =A13*Inputs!B44 -> 9.6 | C13: =SQRT(4*Inputs!B21*A13*1000/(Inputs!B10*Inputs!B11))/1000 -> 305.0014 | D13: =C13*(1+Inputs!B43) -> 366.00167 | E13: =D13*Components!G10 -> 366.00167 | F13: =Inputs!B63/1000 -> 1446.6621 | G13: =E13/F13 -> 0.25299735 | H13: =A13*Inputs!B40 -> 0.275 | I13: =H13*1000*Components!J10 -> 0.74786055 | J13: =Components!N10 -> 173.76622 | K13: =A13/J13 -> 0.057548583 | L13: =IF(G13<1,"合格","NG") -> 合格 | M13: =IF(K13<1,"合格","NG") -> 合格 | N13: =IF(AND(L13="合格",M13="合格"),"合格","NG") -> 合格
A14: 11 | B14: =A14*Inputs!B44 -> 10.56 | C14: =SQRT(4*Inputs!B21*A14*1000/(Inputs!B10*Inputs!B11))/1000 -> 319.88816 | D14: =C14*(1+Inputs!B43) -> 383.8658 | E14: =D14*Components!G10 -> 383.8658 | F14: =Inputs!B63/1000 -> 1446.6621 | G14: =E14/F14 -> 0.26534586 | H14: =A14*Inputs!B40 -> 0.3025 | I14: =H14*1000*Components!J10 -> 0.8226466 | J14: =Components!N10 -> 173.76622 | K14: =A14/J14 -> 0.063303442 | L14: =IF(G14<1,"合格","NG") -> 合格 | M14: =IF(K14<1,"合格","NG") -> 合格 | N14: =IF(AND(L14="合格",M14="合格"),"合格","NG") -> 合格
A15: 12 | B15: =A15*Inputs!B44 -> 11.52 | C15: =SQRT(4*Inputs!B21*A15*1000/(Inputs!B10*Inputs!B11))/1000 -> 334.11229 | D15: =C15*(1+Inputs!B43) -> 400.93475 | E15: =D15*Components!G10 -> 400.93475 | F15: =Inputs!B63/1000 -> 1446.6621 | G15: =E15/F15 -> 0.27714471 | H15: =A15*Inputs!B40 -> 0.33 | I15: =H15*1000*Components!J10 -> 0.89743265 | J15: =Components!N10 -> 173.76622 | K15: =A15/J15 -> 0.0690583 | L15: =IF(G15<1,"合格","NG") -> 合格 | M15: =IF(K15<1,"合格","NG") -> 合格 | N15: =IF(AND(L15="合格",M15="合格"),"合格","NG") -> 合格
A16: 13 | B16: =A16*Inputs!B44 -> 12.48 | C16: =SQRT(4*Inputs!B21*A16*1000/(Inputs!B10*Inputs!B11))/1000 -> 347.7551 | D16: =C16*(1+Inputs!B43) -> 417.30612 | E16: =D16*Components!G10 -> 417.30612 | F16: =Inputs!B63/1000 -> 1446.6621 | G16: =E16/F16 -> 0.28846136 | H16: =A16*Inputs!B40 -> 0.3575 | I16: =H16*1000*Components!J10 -> 0.97221871 | J16: =Components!N10 -> 173.76622 | K16: =A16/J16 -> 0.074813158 | L16: =IF(G16<1,"合格","NG") -> 合格 | M16: =IF(K16<1,"合格","NG") -> 合格 | N16: =IF(AND(L16="合格",M16="合格"),"合格","NG") -> 合格
A17: 14 | B17: =A17*Inputs!B44 -> 13.44 | C17: =SQRT(4*Inputs!B21*A17*1000/(Inputs!B10*Inputs!B11))/1000 -> 360.88252 | D17: =C17*(1+Inputs!B43) -> 433.05902 | E17: =D17*Components!G10 -> 433.05902 | F17: =Inputs!B63/1000 -> 1446.6621 | G17: =E17/F17 -> 0.2993505 | H17: =A17*Inputs!B40 -> 0.385 | I17: =H17*1000*Components!J10 -> 1.0470048 | J17: =Components!N10 -> 173.76622 | K17: =A17/J17 -> 0.080568017 | L17: =IF(G17<1,"合格","NG") -> 合格 | M17: =IF(K17<1,"合格","NG") -> 合格 | N17: =IF(AND(L17="合格",M17="合格"),"合格","NG") -> 合格
A18: 15 | B18: =A18*Inputs!B44 -> 14.4 | C18: =SQRT(4*Inputs!B21*A18*1000/(Inputs!B10*Inputs!B11))/1000 -> 373.5489 | D18: =C18*(1+Inputs!B43) -> 448.25867 | E18: =D18*Components!G10 -> 448.25867 | F18: =Inputs!B63/1000 -> 1446.6621 | G18: =E18/F18 -> 0.30985721 | H18: =A18*Inputs!B40 -> 0.4125 | I18: =H18*1000*Components!J10 -> 1.1217908 | J18: =Components!N10 -> 173.76622 | K18: =A18/J18 -> 0.086322875 | L18: =IF(G18<1,"合格","NG") -> 合格 | M18: =IF(K18<1,"合格","NG") -> 合格 | N18: =IF(AND(L18="合格",M18="合格"),"合格","NG") -> 合格
A19: 16 | B19: =A19*Inputs!B44 -> 15.36 | C19: =SQRT(4*Inputs!B21*A19*1000/(Inputs!B10*Inputs!B11))/1000 -> 385.79964 | D19: =C19*(1+Inputs!B43) -> 462.95957 | E19: =D19*Components!G10 -> 462.95957 | F19: =Inputs!B63/1000 -> 1446.6621 | G19: =E19/F19 -> 0.32001915 | H19: =A19*Inputs!B40 -> 0.44 | I19: =H19*1000*Components!J10 -> 1.1965769 | J19: =Components!N10 -> 173.76622 | K19: =A19/J19 -> 0.092077733 | L19: =IF(G19<1,"合格","NG") -> 合格 | M19: =IF(K19<1,"合格","NG") -> 合格 | N19: =IF(AND(L19="合格",M19="合格"),"合格","NG") -> 合格
A20: 17 | B20: =A20*Inputs!B44 -> 16.32 | C20: =SQRT(4*Inputs!B21*A20*1000/(Inputs!B10*Inputs!B11))/1000 -> 397.67317 | D20: =C20*(1+Inputs!B43) -> 477.2078 | E20: =D20*Components!G10 -> 477.2078 | F20: =Inputs!B63/1000 -> 1446.6621 | G20: =E20/F20 -> 0.32986818 | H20: =A20*Inputs!B40 -> 0.4675 | I20: =H20*1000*Components!J10 -> 1.2713629 | J20: =Components!N10 -> 173.76622 | K20: =A20/J20 -> 0.097832592 | L20: =IF(G20<1,"合格","NG") -> 合格 | M20: =IF(K20<1,"合格","NG") -> 合格 | N20: =IF(AND(L20="合格",M20="合格"),"合格","NG") -> 合格
A21: 18 | B21: =A21*Inputs!B44 -> 17.28 | C21: =SQRT(4*Inputs!B21*A21*1000/(Inputs!B10*Inputs!B11))/1000 -> 409.20231 | D21: =C21*(1+Inputs!B43) -> 491.04277 | E21: =D21*Components!G10 -> 491.04277 | F21: =Inputs!B63/1000 -> 1446.6621 | G21: =E21/F21 -> 0.33943156 | H21: =A21*Inputs!B40 -> 0.495 | I21: =H21*1000*Components!J10 -> 1.346149 | J21: =Components!N10 -> 173.76622 | K21: =A21/J21 -> 0.10358745 | L21: =IF(G21<1,"合格","NG") -> 合格 | M21: =IF(K21<1,"合格","NG") -> 合格 | N21: =IF(AND(L21="合格",M21="合格"),"合格","NG") -> 合格
A22: 19 | B22: =A22*Inputs!B44 -> 18.24 | C22: =SQRT(4*Inputs!B21*A22*1000/(Inputs!B10*Inputs!B11))/1000 -> 420.41541 | D22: =C22*(1+Inputs!B43) -> 504.49849 | E22: =D22*Components!G10 -> 504.49849 | F22: =Inputs!B63/1000 -> 1446.6621 | G22: =E22/F22 -> 0.34873278 | H22: =A22*Inputs!B40 -> 0.5225 | I22: =H22*1000*Components!J10 -> 1.420935 | J22: =Components!N10 -> 173.76622 | K22: =A22/J22 -> 0.10934231 | L22: =IF(G22<1,"合格","NG") -> 合格 | M22: =IF(K22<1,"合格","NG") -> 合格 | N22: =IF(AND(L22="合格",M22="合格"),"合格","NG") -> 合格
A23: 20 | B23: =A23*Inputs!B44 -> 19.2 | C23: =SQRT(4*Inputs!B21*A23*1000/(Inputs!B10*Inputs!B11))/1000 -> 431.33711 | D23: =C23*(1+Inputs!B43) -> 517.60453 | E23: =D23*Components!G10 -> 517.60453 | F23: =Inputs!B63/1000 -> 1446.6621 | G23: =E23/F23 -> 0.35779228 | H23: =A23*Inputs!B40 -> 0.55 | I23: =H23*1000*Components!J10 -> 1.4957211 | J23: =Components!N10 -> 173.76622 | K23: =A23/J23 -> 0.11509717 | L23: =IF(G23<1,"合格","NG") -> 合格 | M23: =IF(K23<1,"合格","NG") -> 合格 | N23: =IF(AND(L23="合格",M23="合格"),"合格","NG") -> 合格
A24: 21 | B24: =A24*Inputs!B44 -> 20.16 | C24: =SQRT(4*Inputs!B21*A24*1000/(Inputs!B10*Inputs!B11))/1000 -> 441.98901 | D24: =C24*(1+Inputs!B43) -> 530.38682 | E24: =D24*Components!G10 -> 530.38682 | F24: =Inputs!B63/1000 -> 1446.6621 | G24: =E24/F24 -> 0.36662799 | H24: =A24*Inputs!B40 -> 0.5775 | I24: =H24*1000*Components!J10 -> 1.5705071 | J24: =Components!N10 -> 173.76622 | K24: =A24/J24 -> 0.12085202 | L24: =IF(G24<1,"合格","NG") -> 合格 | M24: =IF(K24<1,"合格","NG") -> 合格 | N24: =IF(AND(L24="合格",M24="合格"),"合格","NG") -> 合格
A25: 22 | B25: =A25*Inputs!B44 -> 21.12 | C25: =SQRT(4*Inputs!B21*A25*1000/(Inputs!B10*Inputs!B11))/1000 -> 452.39018 | D25: =C25*(1+Inputs!B43) -> 542.86821 | E25: =D25*Components!G10 -> 542.86821 | F25: =Inputs!B63/1000 -> 1446.6621 | G25: =E25/F25 -> 0.37525571 | H25: =A25*Inputs!B40 -> 0.605 | I25: =H25*1000*Components!J10 -> 1.6452932 | J25: =Components!N10 -> 173.76622 | K25: =A25/J25 -> 0.12660688 | L25: =IF(G25<1,"合格","NG") -> 合格 | M25: =IF(K25<1,"合格","NG") -> 合格 | N25: =IF(AND(L25="合格",M25="合格"),"合格","NG") -> 合格
A26: 23 | B26: =A26*Inputs!B44 -> 22.08 | C26: =SQRT(4*Inputs!B21*A26*1000/(Inputs!B10*Inputs!B11))/1000 -> 462.55752 | D26: =C26*(1+Inputs!B43) -> 555.06902 | E26: =D26*Components!G10 -> 555.06902 | F26: =Inputs!B63/1000 -> 1446.6621 | G26: =E26/F26 -> 0.38368948 | H26: =A26*Inputs!B40 -> 0.6325 | I26: =H26*1000*Components!J10 -> 1.7200793 | J26: =Components!N10 -> 173.76622 | K26: =A26/J26 -> 0.13236174 | L26: =IF(G26<1,"合格","NG") -> 合格 | M26: =IF(K26<1,"合格","NG") -> 合格 | N26: =IF(AND(L26="合格",M26="合格"),"合格","NG") -> 合格
A27: 24 | B27: =A27*Inputs!B44 -> 23.04 | C27: =SQRT(4*Inputs!B21*A27*1000/(Inputs!B10*Inputs!B11))/1000 -> 472.50613 | D27: =C27*(1+Inputs!B43) -> 567.00736 | E27: =D27*Components!G10 -> 567.00736 | F27: =Inputs!B63/1000 -> 1446.6621 | G27: =E27/F27 -> 0.39194181 | H27: =A27*Inputs!B40 -> 0.66 | I27: =H27*1000*Components!J10 -> 1.7948653 | J27: =Components!N10 -> 173.76622 | K27: =A27/J27 -> 0.1381166 | L27: =IF(G27<1,"合格","NG") -> 合格 | M27: =IF(K27<1,"合格","NG") -> 合格 | N27: =IF(AND(L27="合格",M27="合格"),"合格","NG") -> 合格
A28: 25 | B28: =A28*Inputs!B44 -> 24 | C28: =SQRT(4*Inputs!B21*A28*1000/(Inputs!B10*Inputs!B11))/1000 -> 482.24955 | D28: =C28*(1+Inputs!B43) -> 578.69946 | E28: =D28*Components!G10 -> 578.69946 | F28: =Inputs!B63/1000 -> 1446.6621 | G28: =E28/F28 -> 0.40002393 | H28: =A28*Inputs!B40 -> 0.6875 | I28: =H28*1000*Components!J10 -> 1.8696514 | J28: =Components!N10 -> 173.76622 | K28: =A28/J28 -> 0.14387146 | L28: =IF(G28<1,"合格","NG") -> 合格 | M28: =IF(K28<1,"合格","NG") -> 合格 | N28: =IF(AND(L28="合格",M28="合格"),"合格","NG") -> 合格
A29: 26 | B29: =A29*Inputs!B44 -> 24.96 | C29: =SQRT(4*Inputs!B21*A29*1000/(Inputs!B10*Inputs!B11))/1000 -> 491.79997 | D29: =C29*(1+Inputs!B43) -> 590.15997 | E29: =D29*Components!G10 -> 590.15997 | F29: =Inputs!B63/1000 -> 1446.6621 | G29: =E29/F29 -> 0.40794597 | H29: =A29*Inputs!B40 -> 0.715 | I29: =H29*1000*Components!J10 -> 1.9444374 | J29: =Components!N10 -> 173.76622 | K29: =A29/J29 -> 0.14962632 | L29: =IF(G29<1,"合格","NG") -> 合格 | M29: =IF(K29<1,"合格","NG") -> 合格 | N29: =IF(AND(L29="合格",M29="合格"),"合格","NG") -> 合格
A30: 27 | B30: =A30*Inputs!B44 -> 25.92 | C30: =SQRT(4*Inputs!B21*A30*1000/(Inputs!B10*Inputs!B11))/1000 -> 501.16843 | D30: =C30*(1+Inputs!B43) -> 601.40212 | E30: =D30*Components!G10 -> 601.40212 | F30: =Inputs!B63/1000 -> 1446.6621 | G30: =E30/F30 -> 0.41571706 | H30: =A30*Inputs!B40 -> 0.7425 | I30: =H30*1000*Components!J10 -> 2.0192235 | J30: =Components!N10 -> 173.76622 | K30: =A30/J30 -> 0.15538117 | L30: =IF(G30<1,"合格","NG") -> 合格 | M30: =IF(K30<1,"合格","NG") -> 合格 | N30: =IF(AND(L30="合格",M30="合格"),"合格","NG") -> 合格
A31: 28 | B31: =A31*Inputs!B44 -> 26.88 | C31: =SQRT(4*Inputs!B21*A31*1000/(Inputs!B10*Inputs!B11))/1000 -> 510.36495 | D31: =C31*(1+Inputs!B43) -> 612.43794 | E31: =D31*Components!G10 -> 612.43794 | F31: =Inputs!B63/1000 -> 1446.6621 | G31: =E31/F31 -> 0.42334554 | H31: =A31*Inputs!B40 -> 0.77 | I31: =H31*1000*Components!J10 -> 2.0940095 | J31: =Components!N10 -> 173.76622 | K31: =A31/J31 -> 0.16113603 | L31: =IF(G31<1,"合格","NG") -> 合格 | M31: =IF(K31<1,"合格","NG") -> 合格 | N31: =IF(AND(L31="合格",M31="合格"),"合格","NG") -> 合格
A32: 29 | B32: =A32*Inputs!B44 -> 27.84 | C32: =SQRT(4*Inputs!B21*A32*1000/(Inputs!B10*Inputs!B11))/1000 -> 519.39866 | D32: =C32*(1+Inputs!B43) -> 623.27839 | E32: =D32*Components!G10 -> 623.27839 | F32: =Inputs!B63/1000 -> 1446.6621 | G32: =E32/F32 -> 0.43083896 | H32: =A32*Inputs!B40 -> 0.7975 | I32: =H32*1000*Components!J10 -> 2.1687956 | J32: =Components!N10 -> 173.76622 | K32: =A32/J32 -> 0.16689089 | L32: =IF(G32<1,"合格","NG") -> 合格 | M32: =IF(K32<1,"合格","NG") -> 合格 | N32: =IF(AND(L32="合格",M32="合格"),"合格","NG") -> 合格
A33: 30 | B33: =A33*Inputs!B44 -> 28.8 | C33: =SQRT(4*Inputs!B21*A33*1000/(Inputs!B10*Inputs!B11))/1000 -> 528.27791 | D33: =C33*(1+Inputs!B43) -> 633.9335 | E33: =D33*Components!G10 -> 633.9335 | F33: =Inputs!B63/1000 -> 1446.6621 | G33: =E33/F33 -> 0.43820426 | H33: =A33*Inputs!B40 -> 0.825 | I33: =H33*1000*Components!J10 -> 2.2435816 | J33: =Components!N10 -> 173.76622 | K33: =A33/J33 -> 0.17264575 | L33: =IF(G33<1,"合格","NG") -> 合格 | M33: =IF(K33<1,"合格","NG") -> 合格 | N33: =IF(AND(L33="合格",M33="合格"),"合格","NG") -> 合格
A34: 31 | B34: =A34*Inputs!B44 -> 29.76 | C34: =SQRT(4*Inputs!B21*A34*1000/(Inputs!B10*Inputs!B11))/1000 -> 537.01037 | D34: =C34*(1+Inputs!B43) -> 644.41245 | E34: =D34*Components!G10 -> 644.41245 | F34: =Inputs!B63/1000 -> 1446.6621 | G34: =E34/F34 -> 0.4454478 | H34: =A34*Inputs!B40 -> 0.8525 | I34: =H34*1000*Components!J10 -> 2.3183677 | J34: =Components!N10 -> 173.76622 | K34: =A34/J34 -> 0.17840061 | L34: =IF(G34<1,"合格","NG") -> 合格 | M34: =IF(K34<1,"合格","NG") -> 合格 | N34: =IF(AND(L34="合格",M34="合格"),"合格","NG") -> 合格
A35: 32 | B35: =A35*Inputs!B44 -> 30.72 | C35: =SQRT(4*Inputs!B21*A35*1000/(Inputs!B10*Inputs!B11))/1000 -> 545.60308 | D35: =C35*(1+Inputs!B43) -> 654.7237 | E35: =D35*Components!G10 -> 654.7237 | F35: =Inputs!B63/1000 -> 1446.6621 | G35: =E35/F35 -> 0.45257542 | H35: =A35*Inputs!B40 -> 0.88 | I35: =H35*1000*Components!J10 -> 2.3931537 | J35: =Components!N10 -> 173.76622 | K35: =A35/J35 -> 0.18415547 | L35: =IF(G35<1,"合格","NG") -> 合格 | M35: =IF(K35<1,"合格","NG") -> 合格 | N35: =IF(AND(L35="合格",M35="合格"),"合格","NG") -> 合格
A36: 33 | B36: =A36*Inputs!B44 -> 31.68 | C36: =SQRT(4*Inputs!B21*A36*1000/(Inputs!B10*Inputs!B11))/1000 -> 554.06255 | D36: =C36*(1+Inputs!B43) -> 664.87506 | E36: =D36*Components!G10 -> 664.87506 | F36: =Inputs!B63/1000 -> 1446.6621 | G36: =E36/F36 -> 0.45959251 | H36: =A36*Inputs!B40 -> 0.9075 | I36: =H36*1000*Components!J10 -> 2.4679398 | J36: =Components!N10 -> 173.76622 | K36: =A36/J36 -> 0.18991032 | L36: =IF(G36<1,"合格","NG") -> 合格 | M36: =IF(K36<1,"合格","NG") -> 合格 | N36: =IF(AND(L36="合格",M36="合格"),"合格","NG") -> 合格
A37: 34 | B37: =A37*Inputs!B44 -> 32.64 | C37: =SQRT(4*Inputs!B21*A37*1000/(Inputs!B10*Inputs!B11))/1000 -> 562.39479 | D37: =C37*(1+Inputs!B43) -> 674.87374 | E37: =D37*Components!G10 -> 674.87374 | F37: =Inputs!B63/1000 -> 1446.6621 | G37: =E37/F37 -> 0.46650406 | H37: =A37*Inputs!B40 -> 0.935 | I37: =H37*1000*Components!J10 -> 2.5427259 | J37: =Components!N10 -> 173.76622 | K37: =A37/J37 -> 0.19566518 | L37: =IF(G37<1,"合格","NG") -> 合格 | M37: =IF(K37<1,"合格","NG") -> 合格 | N37: =IF(AND(L37="合格",M37="合格"),"合格","NG") -> 合格
A38: 35 | B38: =A38*Inputs!B44 -> 33.6 | C38: =SQRT(4*Inputs!B21*A38*1000/(Inputs!B10*Inputs!B11))/1000 -> 570.60536 | D38: =C38*(1+Inputs!B43) -> 684.72644 | E38: =D38*Components!G10 -> 684.72644 | F38: =Inputs!B63/1000 -> 1446.6621 | G38: =E38/F38 -> 0.4733147 | H38: =A38*Inputs!B40 -> 0.9625 | I38: =H38*1000*Components!J10 -> 2.6175119 | J38: =Components!N10 -> 173.76622 | K38: =A38/J38 -> 0.20142004 | L38: =IF(G38<1,"合格","NG") -> 合格 | M38: =IF(K38<1,"合格","NG") -> 合格 | N38: =IF(AND(L38="合格",M38="合格"),"合格","NG") -> 合格
A39: 36 | B39: =A39*Inputs!B44 -> 34.56 | C39: =SQRT(4*Inputs!B21*A39*1000/(Inputs!B10*Inputs!B11))/1000 -> 578.69946 | D39: =C39*(1+Inputs!B43) -> 694.43935 | E39: =D39*Components!G10 -> 694.43935 | F39: =Inputs!B63/1000 -> 1446.6621 | G39: =E39/F39 -> 0.48002872 | H39: =A39*Inputs!B40 -> 0.99 | I39: =H39*1000*Components!J10 -> 2.692298 | J39: =Components!N10 -> 173.76622 | K39: =A39/J39 -> 0.2071749 | L39: =IF(G39<1,"合格","NG") -> 合格 | M39: =IF(K39<1,"合格","NG") -> 合格 | N39: =IF(AND(L39="合格",M39="合格"),"合格","NG") -> 合格
A40: 37 | B40: =A40*Inputs!B44 -> 35.52 | C40: =SQRT(4*Inputs!B21*A40*1000/(Inputs!B10*Inputs!B11))/1000 -> 586.6819 | D40: =C40*(1+Inputs!B43) -> 704.01828 | E40: =D40*Components!G10 -> 704.01828 | F40: =Inputs!B63/1000 -> 1446.6621 | G40: =E40/F40 -> 0.48665012 | H40: =A40*Inputs!B40 -> 1.0175 | I40: =H40*1000*Components!J10 -> 2.767084 | J40: =Components!N10 -> 173.76622 | K40: =A40/J40 -> 0.21292976 | L40: =IF(G40<1,"合格","NG") -> 合格 | M40: =IF(K40<1,"合格","NG") -> 合格 | N40: =IF(AND(L40="合格",M40="合格"),"合格","NG") -> 合格
A41: 38 | B41: =A41*Inputs!B44 -> 36.48 | C41: =SQRT(4*Inputs!B21*A41*1000/(Inputs!B10*Inputs!B11))/1000 -> 594.55718 | D41: =C41*(1+Inputs!B43) -> 713.46861 | E41: =D41*Components!G10 -> 713.46861 | F41: =Inputs!B63/1000 -> 1446.6621 | G41: =E41/F41 -> 0.49318263 | H41: =A41*Inputs!B40 -> 1.045 | I41: =H41*1000*Components!J10 -> 2.8418701 | J41: =Components!N10 -> 173.76622 | K41: =A41/J41 -> 0.21868462 | L41: =IF(G41<1,"合格","NG") -> 合格 | M41: =IF(K41<1,"合格","NG") -> 合格 | N41: =IF(AND(L41="合格",M41="合格"),"合格","NG") -> 合格
...

Sheet Derivation
A1: 主要式と判定フロー
A3: 項目 | B3: 式 / ロジック | C3: 注記
A4: TE10カットオフ | B4: fc = c0/(2 a sqrt(eps_r)) | C4: aは広壁側の内寸。
A5: TEインピーダンス | B5: Z_TE = eta/sqrt(1-(fc/f)^2) | C5: eta = eta0/sqrt(eps_r)。
A6: TE10進行波ピーク電力 | B6: P_peak = a b E_peak^2/(4 Z_TE) | C6: E_peakは正弦波のピーク電界振幅。RMSではない。
A7: VSWR電界係数 | B7: |Γ|=(VSWR-1)/(VSWR+1), E_max = E_travel(1+|Γ|) | C7: 最大定在波電界の評価に使用。
A8: 部品局所電界 | B8: E_local = K_E E_max | C8: K_Eは有効化した部品の最大局所電界集中係数。
A9: 絶縁破壊判定 | B9: E_local < E_bd_corrected / SF_E | C9: 補正後破壊電界には圧力、ガス、湿度、汚損、パルス、マルチパルス係数を含める。
A10: デューティ比 | B10: D = pulse_width × PRF | C10: 1以下であること。
A11: 平均電力 | B11: P_avg = D × P_peak | C11: P_peakを指定した場合、Dは瞬時電界を下げない。
A12: RF損失による発熱 | B12: P_loss_avg = P_avg × (1 - 10^(-IL/10)) | C12: ILは部品または経路全体の挿入損失[dB]。
A13: 熱判定 | B13: T_hotspot = T_ambient + P_loss_avg Rθ < T_limit | C13: 熱制限は平均損失に基づく。
A14: 熱制限ピーク電力 | B14: P_peak_allow = (T_limit-T_ambient)/(SF_T × D × loss_fraction × Rθ) | C14: 部品ごとに計算し、有効部品の最小値が経路を制限。
... A17: 最終許容ピーク電力 | B17: P_allow = MIN(P_breakdown_allow, P_thermal_allow) | C17: 進行波ピーク電力基準。
A19: Ragan / 短パルス補正
A20: 臨界パルス幅 | B20: tau_c = 1e-3 / p[torr] | C20: tau > tau_c ではCW相当として扱う
A21: 単発短パルス破壊電界 | B21: Eb[kV/cm] = 22.22 + 87.24/(1+(tau/2.47e-9)^0.648) | C21: Ragan曲線近似式としてInputs/Ragan_Pulseへ実装
A22: 電圧改善係数 | B22: Fv = Eb/22.8 | C22: 本ブックでは1未満にせず、tau < tau_cの場合だけKtauへ適用
A23: PRF | B23: Duty=tau*PRF, pulse interval=1/PRF | C23: Dutyは熱、pulse intervalはmultipulseスクリーニングに使用
A24: マルチパルス | B24: Ebd_used = Ebd_ref*density*gas*humidity*pollution*Ktau*Kmulti | C24: KmultiはInputs!B61でユーザー入力。残留電離リスクがあれば1未満
A25: 半解析式 | B25: Ep=3.75p sqrt(1+w^2/(25e18p^2))(... )^(3/16) | C25: Ragan_Pulseに参考値として実装。RMS V/cmからpeak V/mに換算
A27: 注意 | B27: Ragan式は短パルス/単発の上昇を見込む式であり、44 usなど長いパルスではKtau=1に戻す | C27: 最終設計ではメーカー定格・高電力試験で確認

Sheet Sources_Assumptions
A1: 参考資料・仮定・ユーザー置換可能な入力値
A3: 分類 | B3: 仮定 / 出典 | C3: URL / 場所 | D3: 使用方法 | E3: 注意
A4: 導波管寸法 | B4: WR90 a=22.86 mm, b=10.16 mm を初期値に使用 | C4: https://www.nikoha.co.jp/technology/pdf/02_waveguide.pdf | D4: Inputsの初期ジオメトリ | E4: 実部品の寸法・肉厚を確認すること。
A5: 許容電力の考え方 | B5: 導波管の許容電力は電圧破壊と発熱で制限される | C5: https://www.microwaves101.com/encyclopedias/power-handling-in-waveguide | D5: 二系統制限の判定フロー | E5: 最終設計ではメーカー値を使用すること。
A6: 矩形導波管理論 | B6: TE/TM矩形導波管の電磁界関係 | C6: https://eng.libretexts.org/Bookshelves/Electrical_Engineering/Electro-Optics/Electromagnetic_Field_Theory%3A_A_Problem_Solving_Approach_%28Zahn%29/08%3A_Guided_Electromagnetic_Waves/8.06%3A_The_Rectangular_Waveguide | D6: TE10式とカットオフの基礎 | E6: ピーク値/RMS値の規約に注意。
A7: マイクロ波絶縁破壊 | B7: Gould & Roberts, Breakdown of Air at Microwave Frequencies | C7: https://pubs.aip.org/aip/jap/article-pdf/27/10/1162/7922849/1162_1_online.pdf | D7: CW / 単発パルス / マルチパルスの考え方 | E7: スプレッドシートには形状固有の破壊式は埋め込んでいない。
A8: Ragan文献 | B8: G. L. Ragan, Microwave Transmission Circuits, MIT Radiation Laboratory Series Vol. 9 | C8: https://books.google.com/books/about/Microwave_Transmission_Circuits.html?id=B7Y8AAAAIAAJ | D8: 導波管伝送・許容電力の古典的参考文献 | E8: 具体的な式/表を提示いただければKtau/multipulse係数に反映可能。
A9: 臨界パルス幅 | B9: tau_c = 1e-3/p[torr] をスクリーニング規則として使用 | C9: https://www.dielectric.com/wp-content/uploads/2018/04/Schadler-ATSC-3-Voltage.pdf | D9: Inputs!B65のパルス領域判定 | E9: これはスクリーニング指標であり、最終認定ではない。
A10: 熱対流 | B10: 自然対流hはユーザー入力。初期値7 W/m2/K | C10: https://www.qats.com/Qpedia-Article/Qpedia_May09_Estimating_the_inside_temp_of_natural_convection_sealed_enclosure | D10: 直管部Rθの推定 | E10: 姿勢、筐体、風速に強く依存。
A11: 放射熱伝達 | B11: 線形化放射 h_rad ≈ 4 eps sigma T^3 | C11: https://www.engineeringtoolbox.com/radiation-heat-transfer-d_431.html | D11: Inputs!B33 | E11: 小さい温度差に対する近似。
A12: 部品係数 | B12: ベンド/カップラー/ロータリージョイントのK_E、挿入損失、Rθは仮値 | C12: Components sheet | D12: 初期設計用ディレーティング | E12: メーカー高電力定格または実測値に置換。
A14: 追加出典 / Raganパルス式
A15: Schadler, ATSC 3.0 Ready – Designing Antennas for Higher OFDM PAPR | B15: https://www.dielectric.com/wp-content/uploads/2018/04/Schadler-ATSC-3-Voltage.pdf | C15: Ragan pp.239、Anderson/Lisak、Anderson/Yu等を参照し、tau_c、Ragan単発式、VSWR補正、半解析式を掲載
A16: G. L. Ragan, Microwave Transmission Circuits, MIT Radiation Laboratory Series Vol.9 | B16: https://books.google.com/books/about/Microwave_Transmission_Circuits.html?id=B7Y8AAAAIAAJ | C16: 書誌情報。原典の式は公開資料の引用式として本ブックに反映
A17: Microwaves101, Power Handling in Waveguide | B17: https://www.microwaves101.com/encyclopedias/power-handling-in-waveguide | C17: 導波管許容電力は平均発熱とピーク絶縁破壊の両制限で決まること、矩形導波管の概算式
A18: 注意 | B18: Ragan/短パルス式の適用範囲は空気・短パルス・単発近似が基本。PRF/multipulseは入力係数B61で安全側に扱う。

Sheet Ragan_Pulse
A1: Ragan / Anderson 短パルス・PRF 絶縁破壊モデル
A3: 項目 | B3: 値 | C3: 単位 | D3: 説明
A4: パルス幅 tau | B4: =Inputs!B38 -> 4.4e-05 | C4: s | D4: Inputsから参照
A5: PRF | B5: =Inputs!B39 -> 625 | C5: Hz | D5: Inputsから参照
A6: Duty | B6: =Inputs!B40 -> 0.0275 | C6: - | D6: tau×PRF
A7: 絶対圧 p0 | B7: =Inputs!B64 -> 760.0021 | C7: torr | D7: Inputsから参照
A8: 温度補正後圧力 p | B8: =Inputs!B81 -> 948.69947 | C8: torr | D8: p=p0×273/(273+Tgas)
A9: 臨界パルス幅 tau_c | B9: =Inputs!B65 -> 1.3157858e-06 | C9: s | D9: tau_c=1e-3/p0[torr]
A10: Ragan単発Eb | B10: =Inputs!B72 -> 22.373272 | C10: kV/cm | D10: Eb=22.22+87.24/(1+(tau/2.47e-9)^0.648)
A11: CW相当Eb | B11: =Inputs!B73 -> 22.8 | C11: kV/cm | D11: 代表値
A12: 電圧改善係数 Fv | B12: =Inputs!B74 -> 1 | C12: - | D12: MAX(1,Eb/22.8)
A13: 使用Ktau | B13: =Inputs!B60 -> 1 | C13: - | D13: tau<tau_cならFv、それ以外は1
A14: パルス間隔 | B14: =Inputs!B77 -> 0.0016 | C14: s | D14: 1/PRF
A15: パルス間隔/tau_c | B15: =Inputs!B78 -> 1216.0034 | C15: - | D15: PRF/multipulseの一次スクリーニング
A16: PRF/multipulse判定 | B16: =Inputs!B79 -> 単発近似の余裕あり。ただし実機では残留電離を確認 | C16: - | D16: 係数入力はInputs!B61
A17: 半解析式 Ep peak | B17: =Inputs!B83 -> 4013084.8 | C17: V/m | D17: Eq.(10)参考値
A19: 計算式
A20: 臨界パルス幅 | B20: tau_c = 1e-3 / p[torr] | D20: この値より長いパルスではCW相当として扱う
A21: Ragan単発式 | B21: Eb[kV/cm] = 22.22 + 87.24/(1+(tau/2.47e-9)^0.648) | D21: 海面高度近傍・単発パルスの近似
A22: 短パルス係数 | B22: Fv = Eb / 22.8 | D22: 本ブックでは MAX(1,Fv) とし、tau<tau_c の場合だけKtauに反映
A23: VSWR電界倍率 | B23: Cvswr = 1+|Gamma| = 2*VSWR/(VSWR+1) | D23: Dashboard/Power_Sweepの定在波電界で反映済み
A24: PRF | B24: Duty=tau*PRF は熱へ反映。1/PRF はmultipulse判定へ使用。 | D24: 厳密なPRF補正は実験条件・残留電離・ガス・形状依存
A25: 運用上の推奨 | B25: tau>=tau_c ではKtau=1、PRFが高い場合はInputs!B61を1未満にするか試験値で置換 | D25: 安全側の一次設計
A27: 出典URL | B27: https://www.dielectric.com/wp-content/uploads/2018/04/Schadler-ATSC-3-Voltage.pdf | D27: Ragan, Anderson/Lisak, Anderson/Yu系式を参照している公開資料

Sheet Altitude_Pressure
A1: 高度・加圧モデル チェックシート
A3: 項目 | B3: 値 | C3: 単位 | D3: 参照 | E3: 判定/コメント | F3: 備考
A4: 運用高度 | B4: =Inputs!B88 -> 35000 | C4: ft | D4: Inputs!B88 | E4: =IF(B5<11000,"OK: 対流圏式の適用範囲内","注意: 11km超のため標準大気式を変更") -> OK: 対流圏式の適用範囲内 | F4: 35,000 ftは約10.668 km
A5: 高度 | B5: =Inputs!B89 -> 10668 | C5: m | D5: Inputs!B89 | E5: =IF(B5<11000,"対流圏近似OK","成層圏式に変更推奨") -> 対流圏近似OK
A6: 標準大気温度 | B6: =Inputs!B93 -> -54.3 | C6: degC | D6: Inputs!B93 | E6: ="外気温度" -> 外気温度 | F6: ISA対流圏式
A7: 適用外気温度 | B7: =Inputs!B95 -> -54.3 | C7: degC | D7: Inputs!B95 | E7: ="内部ガス温度とは分けて考える" -> 内部ガス温度とは分けて考える | F7: 外気温度オーバーライド可
A8: 高度周囲圧 | B8: =Inputs!B96 -> 23842.264 | C8: Pa | D8: Inputs!B96 | E8: ="高度で低下" -> 高度で低下
A9: 内部圧力モード | B9: =Inputs!B90 -> 2 | C9: - | D9: Inputs!B90 | E9: =IF(B9=2,"指定絶対圧維持",IF(B9=3,"外気圧+ゲージ",IF(B9=1,"海面1atm固定","外気圧と同じ"))) -> 指定絶対圧維持 | F9: 0:外気圧,1:海面1atm,2:指定絶対圧,3:外気圧+ゲージ
A10: 指定絶対圧 | B10: =Inputs!B91 -> 101325 | C10: Pa | D10: Inputs!B91 | E10: =IF(B9=2,"使用中","参考") -> 使用中 | F10: モード2で使用
A11: ゲージ加圧 | B11: =Inputs!B52 -> 0 | C11: Pa | D11: Inputs!B52 | E11: =IF(B9=3,"使用中","未使用") -> 未使用 | F11: モード3で使用
A12: 導波管内部絶対圧 | B12: =Inputs!B97 -> 101325 | C12: Pa | D12: Inputs!B97 | E12: ="絶縁破壊計算に使用" -> 絶縁破壊計算に使用
A13: 導波管内部ガス温度 | B13: =Inputs!B53 -> -54.3 | C13: degC | D13: Inputs!B53 | E13: =IF(Inputs!B100="","外気温連動：内部が暖かい場合はB100入力推奨","内部温度オーバーライド中") -> 外気温連動：内部が暖かい場合はB100入力推奨 | F13: B100でオーバーライド可
A14: ガス密度比 δ | B14: =Inputs!B56 -> 1.3395019 | C14: - | D14: Inputs!B56 | E14: =IF(B14>1,"密度上昇によりEbd上昇側","密度低下によりEbd低下側") -> 密度上昇によりEbd上昇側 | F14: 絶縁破壊電界の一次スケーリング
A15: 設計許容電界 | B15: =Inputs!B63 -> 1446662.1 | C15: V/m | D15: Inputs!B63 | E15: ="Ebd補正/安全率込み" -> Ebd補正/安全率込み | F15: 安全率込み
A16: 高度補正後 h_conv | B16: =Inputs!B99 -> 3.3955762 | C16: W/m2/K | D16: Inputs!B99 | E16: ="低圧で対流低下" -> 低圧で対流低下 | F16: 自然対流は低圧で低下
A17: WR90直管熱抵抗 | B17: =Inputs!B35 -> 11.873532 | C17: degC/W | D17: Inputs!B35 | E17: ="直管10cmの概算" -> 直管10cmの概算 | F17: 放射+対流で概算
A20: 設計上の注意
A21: 1 | B21: B90=2 は導波管内部の絶対圧が指定値に維持される前提です。
A22: 2 | B22: 密閉固定質量の場合、温度低下で圧力も下がるため、B90=2で低温だけ反映すると楽観側になる場合があります。
A23: 3 | B23: ゲージ加圧で管理する場合は B90=3 とし、B52にゲージ圧を入力してください。
A24: 4 | B24: 絶縁破壊は導波管内部ガス温度、熱は外気温度/放熱条件で評価するため、必要に応じて分離してください。
A25: 5 | B25: 35,000 ftは標準大気の対流圏式の上限11 kmに近いので、高度余裕がある場合は式の適用範囲を確認してください。
A26: 6 | B26: 最終値は部品の高電力定格、加圧保持試験、温度試験、アーク検出試験で確認してください。
A28: 参考 | B28: このシートはRagan短パルス式に加え、高度・加圧モードの入力整合を確認するための補助シートです。
A29: 誤読防止メモ
A30: 7 | B30: Dashboardの最終許容ピーク電力は、この時点の入力条件1ケースに対する値です。高度/低圧ケースと地上/高温ケースを分けて評価してください。
A31: 8 | B31: Inputs!B81:B83の半解析式Epは参考表示です。低温で大きく出ても、Dashboardの最終判定に直接使っていません。
A32: 9 | B32: B90=2は指定絶対圧を維持する供給系/レギュレータ前提です。密閉固定質量では、温度変化後の内部圧力を別途計算して入力してください。
A33: 10 | B33: ホットスポット温度が氷点下でも数式エラーではありません。ただし熱設計の最悪ケースは高温周囲条件で別途確認してください。
A34: 11 | B34: 最終設計では、部品ごとの挿入損失・局所電界係数・熱抵抗をメーカー値または実測値で置き換えてください。

Sheet 誤読防止_使い方
A1: WR90 TE10 許容電力計算シート：誤読防止・運用ガイド
A3: 最重要：このブックの判定は「現在入力されている1ケース」に対する結果です。絶縁破壊の最悪条件と熱の最悪条件は一致しないことが多いため、少なくとも高度/低圧ケースと地上/高温ケースを分けて確認してください。
A5: 項目 | B5: 誤読しやすい点 | C5: 正しい読み方 | D5: 確認セル | E5: 推奨操作 | F5: 備考
A6: 最終許容ピーク電力 | B6: 全運用条件の保証値に見える | C6: Dashboardは現在の入力条件1点での判定。運用包絡線全体の保証値ではない | D6: Dashboard!B22 | E6: 複数ケースを保存/比較する | F6: 例：高度低温、地上高温、最大VSWR、最大部品損失
A7: Ragan短パルス補正 Ktau | B7: パルス運用なので必ず許容電界が上がると解釈する | C7: τ >= τc では自動的に Ktau=1。短パルス上昇は見込まない | D7: Inputs!B60, B65:B66 | E7: 44 µsなど τ>>τc ではCW/マルチパルス相当として扱う | F7: 実測/メーカー定格がある場合のみ補正を許可
A8: B81/B83 半解析式 Ep | B8: Dashboardの最終判定に使われていると誤解する | C8: 表示用の参考値。最終判定のEbd補正はInputs!B62/B63を使用 | D8: Inputs!B81:B83, Dashboard!B35 | E8: B83は参考として読み、合否判断はDashboard!B18:B24を確認 | F8: 低温では密度効果で大きく見えることがある
A9: 圧力モード B90=2 | B9: 密閉封入でも絶対圧101.325kPaが維持されると思い込む | C9: B90=2は供給/レギュレータで指定絶対圧を維持する前提 | D9: Inputs!B90:B97 | E9: 密閉固定質量なら、運用温度での内部絶対圧を別途算出して指定する | F9: 外気圧+ゲージ管理ならB90=3
A10: 低温時のホットスポット温度 | B10: −40℃などの表示を熱的に常に安全と解釈する | C10: 低温高度ケースでは熱制限が緩く見える。熱の最悪条件は地上高温側で別途評価 | D10: Dashboard!B10:B21, Components | E10: B94に高温周囲条件、B100に内部ガス温度を入力して再評価 | F10: 高温待機/地上運用が熱的に厳しい場合が多い
A11: DUTYの扱い | B11: 電界もDUTYで下がると誤解する | C11: ピーク電力入力時、瞬時電界はピーク電力で決まる。DUTYは平均電力/発熱に効く | D11: Dashboard!B4:B6, B14:B16 | E11: 平均電力仕様から逆算する場合だけ Ppeak=Pavg/D を使う | F11: 絶縁破壊はピーク電界、発熱は平均損失
A12: VSWR補正 | B12: 正味電力基準と進行波電力基準を混同する | C12: 電界判定は進行波ピーク電力に対する定在波最大電界で比較 | D12: Dashboard!B12:B16 | E12: 入力電力の定義を明確にしてから比較する | F12: 正味電力基準の供給電力もDashboardに表示
A14: 推奨するケース分け
A15: ケース | B15: 主目的 | C15: 代表的な入力 | D15: 主に見る結果 | E15: NG時の対策 | F15: 注意
A16: A. 高度・低圧/加圧ケース | B16: 絶縁破壊余裕 | C16: B87=1, B88=高度, B90=実機の加圧方式, B100=導波管内ガス温度 | D16: Dashboard!B16:B24, Altitude_Pressure | E16: 加圧、乾燥、VSWR改善、部品K_E低減、安全率見直し | F16: 熱の最悪ケースとは限らない
A17: B. 地上・高温ケース | B17: 平均発熱/温度上昇 | C17: B87=1のままB88=0(ft), B94=最高周囲温度, B100=内部ガス最高温度, B90=実機の加圧方式 | D17: Dashboard!B10:B21, Power_Sweep | E17: 挿入損失低減、放熱改善、DUTY低減、冷却追加 | F17: 低温高度ケースだけでは熱評価不足。B87=0では B94 が無効(B27が固定50℃)になるため B87=1+B88=0 とする
A18: C. 最大ミスマッチケース | B18: 定在波最大電界 | C18: VSWRをワースト値に設定 | D18: Dashboard!B12:B19 | E18: マッチング改善、保護回路、電力低減 | F18: 電界は(1+|Γ|)で増加
A19: D. 部品ワーストケース | B19: 局所電界/局所発熱 | C19: Componentsでベンド/カップラー/ロータリーを有効化 | D19: Dashboard!B11:B21, Components | E19: 部品定格確認、K_E/IL/Rθの実測反映 | F19: 部品定格を優先
A20: E. 密閉固定質量ケース | B20: 温度変化時の内部圧確認 | C20: 運用温度での内部絶対圧を計算し、B90=2/B91に入力 | D20: Altitude_Pressure, Dashboard!B16:B19 | E20: 封入圧見直し、レギュレータ化、圧力監視 | F20: B90=2は「維持」前提。密閉封入とは別
A22: 合否判定前チェックリスト
A23: □ 入力電力は進行波ピーク電力か、正味電力かを確認した
A24: □ パルス幅 τ と臨界パルス幅 τc の関係を確認した
A25: □ Ktauが1を超える場合、根拠データ/試験データがあるか確認した
A26: □ 圧力モードB90が実機の加圧方式と一致しているか確認した
A27: □ 導波管内ガス温度B100を必要に応じて設定した
A28: □ 高度低温ケースとは別に地上高温ケースを確認した
A29: □ ベンド、カップラー、ロータリージョイントのIL/K_E/Rθを部品実測値またはメーカー値に置き換えた
A30: □ 最終設計では高電力試験、加圧保持試験、温度試験、アーク検出で確認する
