Workbook

Sheet 入力・概要
A1: MVVS 0.5sq×2芯＋UL1007 AWG20 差動／3導体同相解析
A2: 同相解析は、P＝2芯一括、S＝編組シールド、G＝AWG20 GND線の3物理導体モデルです。理想シールド近似により、内部モード(P-S)と外部モード(S-G)へ厳密に変換して解きます。
A3: 差動パラメータ B30:B37 は、同一5 mケーブルの遠端開放・遠端短絡測定を同時フィッティングした値です。本ブックでは線路長を6 mに設定し、線路定数 Z0・VF・損失は5 m測定から得た単位長さ特性として使用します。短絡端R/Lおよび測定治具R/Lは長さに比例させず、フィット値をそのまま使用します。
A5: 形状・代表物性（黄色セルを変更） | D5: 派生値
A6: 線路長 | B6: 6 | C6: m | D6: ケーブル・GND線中心間距離 | E6: =(B7+B10)/2 -> 4 | F6: mm
A7: MVVSケーブル仕上外径 | B7: 6.2 | C7: mm | D7: シールド－GND導体最短距離 | E7: =E6-B8/2-B11/2 -> 1.375 | F7: mm
A8: MVVSシールド外径 | B8: 4.3 | C8: mm | D8: 外部2円柱パラメータ χ | E8: =ACOSH(((E6/1000)^2-(B8/2000)^2-(B11/2000)^2)/(2*(B8/2000)*(B11/2000))) -> 2.3820865 | F8: －
A9: MVVS 1芯絶縁外径 | B9: 1.9 | C9: mm | D9: 内部モード Z01 | E9: =1/(299792458*B13*B12*0.000000000001) -> 26.90033 | F9: Ω
A10: UL1007仕上外径 | B10: 1.8 | C10: mm | D10: 内部モード L1 | E10: =E9/(299792458*B13)*1000000000 -> 144.72555 | F10: nH/m
A11: UL1007導体外径 | B11: 0.95 | C11: mm | D11: 内部モード片道遅延 | E11: =B6/(299792458*B13)*1000000000 -> 32.280396 | F11: ns
A12: 内部モード C(P-S) | B12: 200 | C12: pF/m（代表値） | D12: 内部モード 1/4波長 | E12: =1/(4*E11*0.000000001)/1000000 -> 7.7446385 | F12: MHz
A13: 内部モード速度係数 | B13: 0.62 | C13: － | D13: 外部モード C2 | E13: =2*PI()*8.854187817E-12*B14/E8*1000000000000 -> 51.379958 | F13: pF/m
A14: 外部モード実効比誘電率 | B14: 2.2 | C14: －（PVC＋空気の代表値） | D14: 外部モード L2 | E14: =4*PI()*0.0000001*E8/(2*PI())*1000000000 -> 476.4173 | F14: nH/m
A15: 内部誘電損失 tanδ | B15: 0.03 | C15: － | D15: 外部モード Z02 | E15: =SQRT(E14*0.000000001/(E13*0.000000000001)) -> 96.293481 | F15: Ω
A16: 外部誘電損失 tanδ | B16: 0.02 | C16: － | D16: 外部モード速度係数 | E16: =1/SQRT(B14) -> 0.67419986 | F16: －
A17: 1芯導体抵抗 | B17: 0.0378 | C17: Ω/m（37.8 Ω/km） | D17: 外部モード片道遅延 | E17: =B6/(299792458*E16)*1000000000 -> 29.68533 | F17: ns
A18: シールド長手抵抗 | B18: 0.025 | C18: Ω/m（代表値） | D18: 外部モード 1/4波長 | E18: =1/(4*E17*0.000000001)/1000000 -> 8.4216681 | F18: MHz
A19: GND線導体抵抗 | B19: 0.035 | C19: Ω/m（代表値） | D19: P導体束抵抗 | E19: =B17/2 -> 0.0189 | F19: Ω/m
A20: 内部追加損失 k√f | B20: 0.003 | C20: Np/√MHz | D20: 内部モード直流ループ抵抗 | E20: =(E19+B18)*B6 -> 0.2634 | F20: Ω（6m）
A21: 外部追加損失 k√f | B21: 0.004 | C21: Np/√MHz | D21: 外部モード直流ループ抵抗 | E21: =(B18+B19)*B6 -> 0.36 | F21: Ω（6m）
D22: 2個Cの低周波合成容量 | E22: =B24+B27 -> 20 | F22: µF
A23: 遠端負荷・差動条件 | D23: 同一値時の合成ESR | E23: =IF(AND(B25=B28),B25/2,NA()) -> 0.025 | F23: Ω
A24: コンデンサ1 容量 | B24: 10 | C24: µF | D24: 同一値時の合成ESL | E24: =IF(AND(B26=B29),B26/2,NA()) -> 10 | F24: nH
A25: コンデンサ1 ESR | B25: 0.05 | C25: Ω | D25: 概算低周波直列共振 | E25: =1/(2*PI()*SQRT(((E10+E14)*0.000000001*B6+E24*0.000000001)*E22*0.000001))/1000 -> 18.409919 | F25: kHz
A26: コンデンサ1 ESL | B26: 20 | C26: nH | D26: 差動1/4波長 | E26: =B31*299792458/(4*B6)/1000000 -> 6.8400128 | F26: MHz
A27: コンデンサ2 容量 | B27: 10 | C27: µF | D27: 差動1/2波長 | E27: =B31*299792458/(2*B6)/1000000 -> 13.680026 | F27: MHz
A28: コンデンサ2 ESR | B28: 0.05 | C28: Ω
A29: コンデンサ2 ESL | B29: 20 | C29: nH | D29: 3導体モデルの境界条件
A30: 差動特性インピーダンス Z0d（同時フィット） | B30: 74.967864 | C30: Ω | D30: 近端：SとGはFG1で短絡 → VSG(0)=0。 遠端：Sは開放 → IS(l)=0。Pは10 µF×2の並列負荷でGへ接続。 モード電圧：v1=VP−VS（内部）、v2=VS−VG（外部） モード電流：i1=IP、i2=IP+IS=−IG 遠端IS=0より i2(l)=i1(l)。外部モードを近端短絡線路として遠端から見たZext=Z02·tanh(γ2l)を、コンデンサ負荷へ直列加算し、内部モードを終端します。
A31: 差動速度係数 VFd（同時フィット） | B31: 0.54757984 | C31: －
A32: 差動有効 tanδ（同時フィット） | B32: 0.084499825 | C32: －（有効値）
A33: 差動追加損失 k√f（同時フィット） | B33: 0.00033667212 | C33: Np/√MHz
A34: 遠端短絡抵抗（同時フィット） | B34: 0.1351019 | C34: Ω
A35: 遠端短絡インダクタンス（同時フィット） | B35: 12.540612 | C35: nH
A36: 測定治具直列抵抗（共通フィット） | B36: 2.5604562e-13 | C36: Ω
A37: 測定治具直列インダクタンス（共通フィット） | B37: 33.842608 | C37: nH
A38: 開始周波数 | B38: 1000 | C38: Hz
A39: 終了周波数 | B39: 25000000 | C39: Hz
A40: 計算点数 | B40: 501 | C40: 点（最大801）

Sheet 3導体RLGC
A1: 3導体MTLのモード定数とRLGC行列
A2: 導体座標：V=[VP−VG, VS−VG]ᵀ、I=[IP, IS]ᵀ。理想シールド近似では、内部(P-S)・外部(S-G)モードへ対角化できます。
A5: モード | B5: Z0 [Ω] | C5: L [nH/m] | D5: C [pF/m]
A6: 内部 P-S | B6: =入力・概要!E9 -> 26.90033 | C6: =入力・概要!E10 -> 144.72555 | D6: =入力・概要!B12 -> 200
A7: 外部 S-G | B7: =入力・概要!E15 -> 96.293481 | C7: =入力・概要!E14 -> 476.4173 | D7: =入力・概要!E13 -> 51.379958
A8: 備考 | B8: 代表値 | C8: 単位長 | D8: 低損失近似
A11: L行列 [nH/m] | B11: P | C11: S | E11: C行列 [pF/m] | F11: P | G11: S
A12: P | B12: =入力・概要!E10+入力・概要!E14 -> 621.14286 | C12: =入力・概要!E14 -> 476.4173 | E12: P | F12: =入力・概要!B12 -> 200 | G12: =-入力・概要!B12 -> -200
A13: S | B13: =入力・概要!E14 -> 476.4173 | C13: =入力・概要!E14 -> 476.4173 | E13: S | F13: =-入力・概要!B12 -> -200 | G13: =入力・概要!B12+入力・概要!E13 -> 251.37996
A14: 変換式 | B14: L11=L1+L2 | C14: L12=L22=L2 | E14: 変換式 | F14: C11=C1 | G14: C12=-C1, C22=C1+C2
A17: R行列 DC [Ω/m] | B17: P | C17: S | E17: G行列 @1MHz [µS/m] | F17: P | G17: S
A18: P | B18: =(入力・概要!E19+入力・概要!B18)+(入力・概要!B18+入力・概要!B19) -> 0.1039 | C18: =(入力・概要!B18+入力・概要!B19) -> 0.06 | E18: P | F18: =2*PI()*1000000*入力・概要!B12*0.000000000001*入力・概要!B15*1000000 -> 37.699112 | G18: =-2*PI()*1000000*入力・概要!B12*0.000000000001*入力・概要!B15*1000000 -> -37.699112
A19: S | B19: =(入力・概要!B18+入力・概要!B19) -> 0.06 | C19: =(入力・概要!B18+入力・概要!B19) -> 0.06 | E19: S | F19: =-2*PI()*1000000*入力・概要!B12*0.000000000001*入力・概要!B15*1000000 -> -37.699112 | G19: =2*PI()*1000000*(入力・概要!B12*0.000000000001*入力・概要!B15+入力・概要!E13*0.000000000001*入力・概要!B16)*1000000 -> 44.155708
A20: 変換式 | B20: R11=r1+r2 | C20: R12=R22=r2 | E20: 変換式 | F20: G11=g1 | G20: G12=-g1, G22=g1+g2
A23: 行列形：dV/dz=−(R+jωL)I、dI/dz=−(G+jωC)V。 本ブックの同相計算は、このRLGC行列を内部・外部の固有モードへ変換した解析解です。分割ラダー近似ではなく、理想シールド構造に対する3導体MTLのモード解になります。 ただし編組の開口による直接P-G結合、シールド移送インピーダンス、配置のねじれは含みません。

Sheet 差動モデル
A1: 差動モード：AC115VU－AC115VN
A3: No. | B3: 周波数 [Hz] | C3: ω | D3: 減衰A | E3: 電気角θ | F3: tanh Re | G3: tanh Im | H3: 負荷 Re | I3: 負荷 Im | J3: 分子 Re | K3: 分子 Im | L3: 分母 Re | M3: 分母 Im | N3: 線路 Re | O3: 線路 Im | P3: 最終 Re | Q3: 最終 Im | R3: |ZDM| [Ω] | S3: 位相 [deg] | T3: log10(f) | U3: log10(|ZDM|)
A4: 1 | B4: =IF(A4<=入力・概要!$B$40,10^(LOG10(入力・概要!$B$38)+(A4-1)*(LOG10(入力・概要!$B$39)-LOG10(入力・概要!$B$38))/(入力・概要!$B$40-1)),"") -> 1000 | C4: =IF(B4="","",2*PI()*B4) -> 6283.1853 | D4: =IF(B4="","",ATANH(MIN(0.999999,(2*入力・概要!$B$17*入力・概要!$B$6)/入力・概要!$B$30))+入力・概要!$B$33*SQRT(B4/1000000)+(2*PI()*B4*入力・概要!$B$6/(299792458*入力・概要!$B$31))*入力・概要!$B$32/2) -> 0.0060710155 | E4: =IF(B4="","",2*PI()*B4*入力・概要!$B$6/(299792458*入力・概要!$B$31)) -> 0.00022964816 | F4: =IF(B4="","",SINH(2*D4)/(COSH(2*D4)+COS(2*E4))) -> 0.0060709413 | G4: =IF(B4="","",SIN(2*E4)/(COSH(2*D4)+COS(2*E4))) -> 0.0002296397 | H4: =IF(B4="","",入力・概要!$B$34) -> 0.1351019 | I4: =IF(B4="","",C4*入力・概要!$B$35*0.000000001) -> 7.879499e-05 | J4: =IF(B4="","",H4+入力・概要!$B$30*F4) -> 0.5902274 | K4: =IF(B4="","",I4+入力・概要!$B$30*G4) -> 0.017294392 | L4: =IF(B4="","",入力・概要!$B$30+H4*F4-I4*G4) -> 74.968684 | M4: =IF(B4="","",H4*G4+I4*F4) -> 3.1503118e-05 | N4: =IF(B4="","",入力・概要!$B$30*(J4*L4+K4*M4)/(L4^2+M4^2)) -> 0.59022095 | O4: =IF(B4="","",入力・概要!$B$30*(K4*L4-J4*M4)/(L4^2+M4^2)) -> 0.017293955 | P4: =IF(B4="","",N4+入力・概要!$B$36) -> 0.59022095 | Q4: =IF(B4="","",O4+C4*入力・概要!$B$37*0.000000001) -> 0.017506595 | R4: =IF(B4="","",SQRT(P4^2+Q4^2)) -> 0.59048052 | S4: =IF(B4="","",IF(P4>0,DEGREES(ATAN(Q4/P4)),IF(P4<0,IF(Q4>=0,DEGREES(ATAN(Q4/P4))+180,DEGREES(ATAN(Q4/P4))-180),IF(Q4>0,90,IF(Q4<0,-90,0))))) -> 1.698957 | T4: =IF(B4="","",LOG10(B4)) -> 3 | U4: =IF(R4="","",LOG10(MAX(R4,0.000000000001))) -> -0.22879442
A5: 2 | B5: =IF(A5<=入力・概要!$B$40,10^(LOG10(入力・概要!$B$38)+(A5-1)*(LOG10(入力・概要!$B$39)-LOG10(入力・概要!$B$38))/(入力・概要!$B$40-1)),"") -> 1020.4598 | C5: =IF(B5="","",2*PI()*B5) -> 6411.7377 | D5: =IF(B5="","",ATANH(MIN(0.999999,(2*入力・概要!$B$17*入力・概要!$B$6)/入力・概要!$B$30))+入力・概要!$B$33*SQRT(B5/1000000)+(2*PI()*B5*入力・概要!$B$6/(299792458*入力・概要!$B$31))*入力・概要!$B$32/2) -> 0.0060713224 | E5: =IF(B5="","",2*PI()*B5*入力・概要!$B$6/(299792458*入力・概要!$B$31)) -> 0.0002343467 | F5: =IF(B5="","",SINH(2*D5)/(COSH(2*D5)+COS(2*E5))) -> 0.0060712482 | G5: =IF(B5="","",SIN(2*E5)/(COSH(2*D5)+COS(2*E5))) -> 0.00023433807 | H5: =IF(B5="","",入力・概要!$B$34) -> 0.1351019 | I5: =IF(B5="","",C5*入力・概要!$B$35*0.000000001) -> 8.0407115e-05 | J5: =IF(B5="","",H5+入力・概要!$B$30*F5) -> 0.5902504 | K5: =IF(B5="","",I5+入力・概要!$B$30*G5) -> 0.017648231 | L5: =IF(B5="","",入力・概要!$B$30+H5*F5-I5*G5) -> 74.968684 | M5: =IF(B5="","",H5*G5+I5*F5) -> 3.2147689e-05 | N5: =IF(B5="","",入力・概要!$B$30*(J5*L5+K5*M5)/(L5^2+M5^2)) -> 0.59024395 | O5: =IF(B5="","",入力・概要!$B$30*(K5*L5-J5*M5)/(L5^2+M5^2)) -> 0.017647785 | P5: =IF(B5="","",N5+入力・概要!$B$36) -> 0.59024395 | Q5: =IF(B5="","",O5+C5*入力・概要!$B$37*0.000000001) -> 0.017864775 | R5: =IF(B5="","",SQRT(P5^2+Q5^2)) -> 0.59051424 | S5: =IF(B5="","",IF(P5>0,DEGREES(ATAN(Q5/P5)),IF(P5<0,IF(Q5>=0,DEGREES(ATAN(Q5/P5))+180,DEGREES(ATAN(Q5/P5))-180),IF(Q5>0,90,IF(Q5<0,-90,0))))) -> 1.7336287 | T5: =IF(B5="","",LOG10(B5)) -> 3.0087959 | U5: =IF(R5="","",LOG10(MAX(R5,0.000000000001))) -> -0.22876962
A6: 3 | B6: =IF(A6<=入力・概要!$B$40,10^(LOG10(入力・概要!$B$38)+(A6-1)*(LOG10(入力・概要!$B$39)-LOG10(入力・概要!$B$38))/(入力・概要!$B$40-1)),"") -> 1041.3381 | C6: =IF(B6="","",2*PI()*B6) -> 6542.9203 | D6: =IF(B6="","",ATANH(MIN(0.999999,(2*入力・概要!$B$17*入力・概要!$B$6)/入力・概要!$B$30))+入力・概要!$B$33*SQRT(B6/1000000)+(2*PI()*B6*入力・概要!$B$6/(299792458*入力・概要!$B$31))*入力・概要!$B$32/2) -> 0.0060716345 | E6: =IF(B6="","",2*PI()*B6*入力・概要!$B$6/(299792458*入力・概要!$B$31)) -> 0.00023914138 | F6: =IF(B6="","",SINH(2*D6)/(COSH(2*D6)+COS(2*E6))) -> 0.0060715602 | G6: =IF(B6="","",SIN(2*E6)/(COSH(2*D6)+COS(2*E6))) -> 0.00023913256 | H6: =IF(B6="","",入力・概要!$B$34) -> 0.1351019 | I6: =IF(B6="","",C6*入力・概要!$B$35*0.000000001) -> 8.2052225e-05 | J6: =IF(B6="","",H6+入力・概要!$B$30*F6) -> 0.59027379 | K6: =IF(B6="","",I6+入力・概要!$B$30*G6) -> 0.01800931 | L6: =IF(B6="","",入力・概要!$B$30+H6*F6-I6*G6) -> 74.968684 | M6: =IF(B6="","",H6*G6+I6*F6) -> 3.2805448e-05 | N6: =IF(B6="","",入力・概要!$B$30*(J6*L6+K6*M6)/(L6^2+M6^2)) -> 0.59026734 | O6: =IF(B6="","",入力・概要!$B$30*(K6*L6-J6*M6)/(L6^2+M6^2)) -> 0.018008854 | P6: =IF(B6="","",N6+入力・概要!$B$36) -> 0.59026734 | Q6: =IF(B6="","",O6+C6*入力・概要!$B$37*0.000000001) -> 0.018230284 | R6: =IF(B6="","",SQRT(P6^2+Q6^2)) -> 0.5905488 | S6: =IF(B6="","",IF(P6>0,DEGREES(ATAN(Q6/P6)),IF(P6<0,IF(Q6>=0,DEGREES(ATAN(Q6/P6))+180,DEGREES(ATAN(Q6/P6))-180),IF(Q6>0,90,IF(Q6<0,-90,0))))) -> 1.7690059 | T6: =IF(B6="","",LOG10(B6)) -> 3.0175918 | U6: =IF(R6="","",LOG10(MAX(R6,0.000000000001))) -> -0.22874421
A7: 4 | B7: =IF(A7<=入力・概要!$B$40,10^(LOG10(入力・概要!$B$38)+(A7-1)*(LOG10(入力・概要!$B$39)-LOG10(入力・概要!$B$38))/(入力・概要!$B$40-1)),"") -> 1062.6436 | C7: =IF(B7="","",2*PI()*B7) -> 6676.7868 | D7: =IF(B7="","",ATANH(MIN(0.999999,(2*入力・概要!$B$17*入力・概要!$B$6)/入力・概要!$B$30))+入力・概要!$B$33*SQRT(B7/1000000)+(2*PI()*B7*入力・概要!$B$6/(299792458*入力・概要!$B$31))*入力・概要!$B$32/2) -> 0.0060719518 | E7: =IF(B7="","",2*PI()*B7*入力・概要!$B$6/(299792458*入力・概要!$B$31)) -> 0.00024403415 | F7: =IF(B7="","",SINH(2*D7)/(COSH(2*D7)+COS(2*E7))) -> 0.0060718775 | G7: =IF(B7="","",SIN(2*E7)/(COSH(2*D7)+COS(2*E7))) -> 0.00024402516 | H7: =IF(B7="","",入力・概要!$B$34) -> 0.1351019 | I7: =IF(B7="","",C7*入力・概要!$B$35*0.000000001) -> 8.3730993e-05 | J7: =IF(B7="","",H7+入力・概要!$B$30*F7) -> 0.59029758 | K7: =IF(B7="","",I7+入力・概要!$B$30*G7) -> 0.018377776 | L7: =IF(B7="","",入力・概要!$B$30+H7*F7-I7*G7) -> 74.968684 | M7: =IF(B7="","",H7*G7+I7*F7) -> 3.3476666e-05 | N7: =IF(B7="","",入力・概要!$B$30*(J7*L7+K7*M7)/(L7^2+M7^2)) -> 0.59029113 | O7: =IF(B7="","",入力・概要!$B$30*(K7*L7-J7*M7)/(L7^2+M7^2)) -> 0.018377311 | P7: =IF(B7="","",N7+入力・概要!$B$36) -> 0.59029113 | Q7: =IF(B7="","",O7+C7*入力・概要!$B$37*0.000000001) -> 0.018603271 | R7: =IF(B7="","",SQRT(P7^2+Q7^2)) -> 0.5905842 | S7: =IF(B7="","",IF(P7>0,DEGREES(ATAN(Q7/P7)),IF(P7<0,IF(Q7>=0,DEGREES(ATAN(Q7/P7))+180,DEGREES(ATAN(Q7/P7))-180),IF(Q7>0,90,IF(Q7<0,-90,0))))) -> 1.8051029 | T7: =IF(B7="","",LOG10(B7)) -> 3.0263876 | U7: =IF(R7="","",LOG10(MAX(R7,0.000000000001))) -> -0.22871817
A8: 5 | B8: =IF(A8<=入力・概要!$B$40,10^(LOG10(入力・概要!$B$38)+(A8-1)*(LOG10(入力・概要!$B$39)-LOG10(入力・概要!$B$38))/(入力・概要!$B$40-1)),"") -> 1084.385 | C8: =IF(B8="","",2*PI()*B8) -> 6813.3922 | D8: =IF(B8="","",ATANH(MIN(0.999999,(2*入力・概要!$B$17*入力・概要!$B$6)/入力・概要!$B$30))+入力・概要!$B$33*SQRT(B8/1000000)+(2*PI()*B8*入力・概要!$B$6/(299792458*入力・概要!$B$31))*入力・概要!$B$32/2) -> 0.0060722744 | E8: =IF(B8="","",2*PI()*B8*入力・概要!$B$6/(299792458*入力・概要!$B$31)) -> 0.00024902703 | F8: =IF(B8="","",SINH(2*D8)/(COSH(2*D8)+COS(2*E8))) -> 0.0060722002 | G8: =IF(B8="","",SIN(2*E8)/(COSH(2*D8)+COS(2*E8))) -> 0.00024901785 | H8: =IF(B8="","",入力・概要!$B$34) -> 0.1351019 | I8: =IF(B8="","",C8*入力・概要!$B$35*0.000000001) -> 8.5444108e-05 | J8: =IF(B8="","",H8+入力・概要!$B$30*F8) -> 0.59032177 | K8: =IF(B8="","",I8+入力・概要!$B$30*G8) -> 0.01875378 | L8: =IF(B8="","",入力・概要!$B$30+H8*F8-I8*G8) -> 74.968684 | M8: =IF(B8="","",H8*G8+I8*F8) -> 3.4161618e-05 | N8: =IF(B8="","",入力・概要!$B$30*(J8*L8+K8*M8)/(L8^2+M8^2)) -> 0.59031532 | O8: =IF(B8="","",入力・概要!$B$30*(K8*L8-J8*M8)/(L8^2+M8^2)) -> 0.018753306 | P8: =IF(B8="","",N8+入力・概要!$B$36) -> 0.59031532 | Q8: =IF(B8="","",O8+C8*入力・概要!$B$37*0.000000001) -> 0.018983889 | R8: =IF(B8="","",SQRT(P8^2+Q8^2)) -> 0.59062049 | S8: =IF(B8="","",IF(P8>0,DEGREES(ATAN(Q8/P8)),IF(P8<0,IF(Q8>=0,DEGREES(ATAN(Q8/P8))+180,DEGREES(ATAN(Q8/P8))-180),IF(Q8>0,90,IF(Q8<0,-90,0))))) -> 1.8419342 | T8: =IF(B8="","",LOG10(B8)) -> 3.0351835 | U8: =IF(R8="","",LOG10(MAX(R8,0.000000000001))) -> -0.22869149
A9: 6 | B9: =IF(A9<=入力・概要!$B$40,10^(LOG10(入力・概要!$B$38)+(A9-1)*(LOG10(入力・概要!$B$39)-LOG10(入力・概要!$B$38))/(入力・概要!$B$40-1)),"") -> 1106.5713 | C9: =IF(B9="","",2*PI()*B9) -> 6952.7925 | D9: =IF(B9="","",ATANH(MIN(0.999999,(2*入力・概要!$B$17*入力・概要!$B$6)/入力・概要!$B$30))+入力・概要!$B$33*SQRT(B9/1000000)+(2*PI()*B9*入力・概要!$B$6/(299792458*入力・概要!$B$31))*入力・概要!$B$32/2) -> 0.0060726025 | E9: =IF(B9="","",2*PI()*B9*入力・概要!$B$6/(299792458*入力・概要!$B$31)) -> 0.00025412206 | F9: =IF(B9="","",SINH(2*D9)/(COSH(2*D9)+COS(2*E9))) -> 0.0060725283 | G9: =IF(B9="","",SIN(2*E9)/(COSH(2*D9)+COS(2*E9))) -> 0.00025411269 | H9: =IF(B9="","",入力・概要!$B$34) -> 0.1351019 | I9: =IF(B9="","",C9*入力・概要!$B$35*0.000000001) -> 8.7192274e-05 | J9: =IF(B9="","",H9+入力・概要!$B$30*F9) -> 0.59034637 | K9: =IF(B9="","",I9+入力・概要!$B$30*G9) -> 0.019137478 | L9: =IF(B9="","",入力・概要!$B$30+H9*F9-I9*G9) -> 74.968684 | M9: =IF(B9="","",H9*G9+I9*F9) -> 3.4860584e-05 | N9: =IF(B9="","",入力・概要!$B$30*(J9*L9+K9*M9)/(L9^2+M9^2)) -> 0.59033992 | O9: =IF(B9="","",入力・概要!$B$30*(K9*L9-J9*M9)/(L9^2+M9^2)) -> 0.019136994 | P9: =IF(B9="","",N9+入力・概要!$B$36) -> 0.59033992 | Q9: =IF(B9="","",O9+C9*入力・概要!$B$37*0.000000001) -> 0.019372295 | R9: =IF(B9="","",SQRT(P9^2+Q9^2)) -> 0.59065769 | S9: =IF(B9="","",IF(P9>0,DEGREES(ATAN(Q9/P9)),IF(P9<0,IF(Q9>=0,DEGREES(ATAN(Q9/P9))+180,DEGREES(ATAN(Q9/P9))-180),IF(Q9>0,90,IF(Q9<0,-90,0))))) -> 1.8795147 | T9: =IF(B9="","",LOG10(B9)) -> 3.0439794 | U9: =IF(R9="","",LOG10(MAX(R9,0.000000000001))) -> -0.22866414
A10: 7 | B10: =IF(A10<=入力・概要!$B$40,10^(LOG10(入力・概要!$B$38)+(A10-1)*(LOG10(入力・概要!$B$39)-LOG10(入力・概要!$B$38))/(入力・概要!$B$40-1)),"") -> 1129.2115 | C10: =IF(B10="","",2*PI()*B10) -> 7095.0449 | D10: =IF(B10="","",ATANH(MIN(0.999999,(2*入力・概要!$B$17*入力・概要!$B$6)/入力・概要!$B$30))+入力・概要!$B$33*SQRT(B10/1000000)+(2*PI()*B10*入力・概要!$B$6/(299792458*入力・概要!$B$31))*入力・概要!$B$32/2) -> 0.0060729362 | E10: =IF(B10="","",2*PI()*B10*入力・概要!$B$6/(299792458*入力・概要!$B$31)) -> 0.00025932133 | F10: =IF(B10="","",SINH(2*D10)/(COSH(2*D10)+COS(2*E10))) -> 0.0060728619 | G10: =IF(B10="","",SIN(2*E10)/(COSH(2*D10)+COS(2*E10))) -> 0.00025931177 | H10: =IF(B10="","",入力・概要!$B$34) -> 0.1351019 | I10: =IF(B10="","",C10*入力・概要!$B$35*0.000000001) -> 8.8976206e-05 | J10: =IF(B10="","",H10+入力・概要!$B$30*F10) -> 0.59037138 | K10: =IF(B10="","",I10+入力・概要!$B$30*G10) -> 0.019529026 | L10: =IF(B10="","",入力・概要!$B$30+H10*F10-I10*G10) -> 74.968684 | M10: =IF(B10="","",H10*G10+I10*F10) -> 3.5573853e-05 | N10: =IF(B10="","",入力・概要!$B$30*(J10*L10+K10*M10)/(L10^2+M10^2)) -> 0.59036493 | O10: =IF(B10="","",入力・概要!$B$30*(K10*L10-J10*M10)/(L10^2+M10^2)) -> 0.019528532 | P10: =IF(B10="","",N10+入力・概要!$B$36) -> 0.59036493 | Q10: =IF(B10="","",O10+C10*入力・概要!$B$37*0.000000001) -> 0.019768647 | R10: =IF(B10="","",SQRT(P10^2+Q10^2)) -> 0.59069582 | S10: =IF(B10="","",IF(P10>0,DEGREES(ATAN(Q10/P10)),IF(P10<0,IF(Q10>=0,DEGREES(ATAN(Q10/P10))+180,DEGREES(ATAN(Q10/P10))-180),IF(Q10>0,90,IF(Q10<0,-90,0))))) -> 1.9178595 | T10: =IF(B10="","",LOG10(B10)) -> 3.0527753 | U10: =IF(R10="","",LOG10(MAX(R10,0.000000000001))) -> -0.2286361
A11: 8 | B11: =IF(A11<=入力・概要!$B$40,10^(LOG10(入力・概要!$B$38)+(A11-1)*(LOG10(入力・概要!$B$39)-LOG10(入力・概要!$B$38))/(入力・概要!$B$40-1)),"") -> 1152.3149 | C11: =IF(B11="","",2*PI()*B11) -> 7240.2078 | D11: =IF(B11="","",ATANH(MIN(0.999999,(2*入力・概要!$B$17*入力・概要!$B$6)/入力・概要!$B$30))+入力・概要!$B$33*SQRT(B11/1000000)+(2*PI()*B11*入力・概要!$B$6/(299792458*入力・概要!$B$31))*入力・概要!$B$32/2) -> 0.0060732755 | E11: =IF(B11="","",2*PI()*B11*入力・概要!$B$6/(299792458*入力・概要!$B$31)) -> 0.00026462698 | F11: =IF(B11="","",SINH(2*D11)/(COSH(2*D11)+COS(2*E11))) -> 0.0060732012 | G11: =IF(B11="","",SIN(2*E11)/(COSH(2*D11)+COS(2*E11))) -> 0.00026461723 | H11: =IF(B11="","",入力・概要!$B$34) -> 0.1351019 | I11: =IF(B11="","",C11*入力・概要!$B$35*0.000000001) -> 9.0796637e-05 | J11: =IF(B11="","",H11+入力・概要!$B$30*F11) -> 0.59039682 | K11: =IF(B11="","",I11+入力・概要!$B$30*G11) -> 0.019928585 | L11: =IF(B11="","",入力・概要!$B$30+H11*F11-I11*G11) -> 74.968684 | M11: =IF(B11="","",H11*G11+I11*F11) -> 3.6301716e-05 | N11: =IF(B11="","",入力・概要!$B$30*(J11*L11+K11*M11)/(L11^2+M11^2)) -> 0.59039037 | O11: =IF(B11="","",入力・概要!$B$30*(K11*L11-J11*M11)/(L11^2+M11^2)) -> 0.019928081 | P11: =IF(B11="","",N11+入力・概要!$B$36) -> 0.59039037 | Q11: =IF(B11="","",O11+C11*入力・概要!$B$37*0.000000001) -> 0.020173108 | R11: =IF(B11="","",SQRT(P11^2+Q11^2)) -> 0.59073492 | S11: =IF(B11="","",IF(P11>0,DEGREES(ATAN(Q11/P11)),IF(P11<0,IF(Q11>=0,DEGREES(ATAN(Q11/P11))+180,DEGREES(ATAN(Q11/P11))-180),IF(Q11>0,90,IF(Q11<0,-90,0))))) -> 1.9569839 | T11: =IF(B11="","",LOG10(B11)) -> 3.0615712 | U11: =IF(R11="","",LOG10(MAX(R11,0.000000000001))) -> -0.22860736
A12: 9 | B12: =IF(A12<=入力・概要!$B$40,10^(LOG10(入力・概要!$B$38)+(A12-1)*(LOG10(入力・概要!$B$39)-LOG10(入力・概要!$B$38))/(入力・概要!$B$40-1)),"") -> 1175.8909 | C12: =IF(B12="","",2*PI()*B12) -> 7388.3406 | D12: =IF(B12="","",ATANH(MIN(0.999999,(2*入力・概要!$B$17*入力・概要!$B$6)/入力・概要!$B$30))+入力・概要!$B$33*SQRT(B12/1000000)+(2*PI()*B12*入力・概要!$B$6/(299792458*入力・概要!$B$31))*入力・概要!$B$32/2) -> 0.0060736206 | E12: =IF(B12="","",2*PI()*B12*入力・概要!$B$6/(299792458*入力・概要!$B$31)) -> 0.00027004118 | F12: =IF(B12="","",SINH(2*D12)/(COSH(2*D12)+COS(2*E12))) -> 0.0060735463 | G12: =IF(B12="","",SIN(2*E12)/(COSH(2*D12)+COS(2*E12))) -> 0.00027003123 | H12: =IF(B12="","",入力・概要!$B$34) -> 0.1351019 | I12: =IF(B12="","",C12*入力・概要!$B$35*0.000000001) -> 9.2654313e-05 | J12: =IF(B12="","",H12+入力・概要!$B$30*F12) -> 0.59042269 | K12: =IF(B12="","",I12+入力・概要!$B$30*G12) -> 0.020336319 | L12: =IF(B12="","",入力・概要!$B$30+H12*F12-I12*G12) -> 74.968684 | M12: =IF(B12="","",H12*G12+I12*F12) -> 3.7044472e-05 | N12: =IF(B12="","",入力・概要!$B$30*(J12*L12+K12*M12)/(L12^2+M12^2)) -> 0.59041624 | O12: =IF(B12="","",入力・概要!$B$30*(K12*L12-J12*M12)/(L12^2+M12^2)) -> 0.020335804 | P12: =IF(B12="","",N12+入力・概要!$B$36) -> 0.59041624 | Q12: =IF(B12="","",O12+C12*入力・概要!$B$37*0.000000001) -> 0.020585845 | R12: =IF(B12="","",SQRT(P12^2+Q12^2)) -> 0.59077501 | S12: =IF(B12="","",IF(P12>0,DEGREES(ATAN(Q12/P12)),IF(P12<0,IF(Q12>=0,DEGREES(ATAN(Q12/P12))+180,DEGREES(ATAN(Q12/P12))-180),IF(Q12>0,90,IF(Q12<0,-90,0))))) -> 1.9969038 | T12: =IF(B12="","",LOG10(B12)) -> 3.070367 | U12: =IF(R12="","",LOG10(MAX(R12,0.000000000001))) -> -0.22857789
A13: 10 | B13: =IF(A13<=入力・概要!$B$40,10^(LOG10(入力・概要!$B$38)+(A13-1)*(LOG10(入力・概要!$B$39)-LOG10(入力・概要!$B$38))/(入力・概要!$B$40-1)),"") -> 1199.9494 | C13: =IF(B13="","",2*PI()*B13) -> 7539.5042 | D13: =IF(B13="","",ATANH(MIN(0.999999,(2*入力・概要!$B$17*入力・概要!$B$6)/入力・概要!$B$30))+入力・概要!$B$33*SQRT(B13/1000000)+(2*PI()*B13*入力・概要!$B$6/(299792458*入力・概要!$B$31))*入力・概要!$B$32/2) -> 0.0060739715 | E13: =IF(B13="","",2*PI()*B13*入力・概要!$B$6/(299792458*入力・概要!$B$31)) -> 0.00027556616 | F13: =IF(B13="","",SINH(2*D13)/(COSH(2*D13)+COS(2*E13))) -> 0.0060738973 | G13: =IF(B13="","",SIN(2*E13)/(COSH(2*D13)+COS(2*E13))) -> 0.000275556 | H13: =IF(B13="","",入力・概要!$B$34) -> 0.1351019 | I13: =IF(B13="","",C13*入力・概要!$B$35*0.000000001) -> 9.4549998e-05 | J13: =IF(B13="","",H13+入力・概要!$B$30*F13) -> 0.590449 | K13: =IF(B13="","",I13+入力・概要!$B$30*G13) -> 0.020752395 | L13: =IF(B13="","",入力・概要!$B$30+H13*F13-I13*G13) -> 74.968684 | M13: =IF(B13="","",H13*G13+I13*F13) -> 3.7802425e-05 | N13: =IF(B13="","",入力・概要!$B$30*(J13*L13+K13*M13)/(L13^2+M13^2)) -> 0.59044255 | O13: =IF(B13="","",入力・概要!$B$30*(K13*L13-J13*M13)/(L13^2+M13^2)) -> 0.02075187 | P13: =IF(B13="","",N13+入力・概要!$B$36) -> 0.59044255 | Q13: =IF(B13="","",O13+C13*入力・概要!$B$37*0.000000001) -> 0.021007026 | R13: =IF(B13="","",SQRT(P13^2+Q13^2)) -> 0.59081613 | S13: =IF(B13="","",IF(P13>0,DEGREES(ATAN(Q13/P13)),IF(P13<0,IF(Q13>=0,DEGREES(ATAN(Q13/P13))+180,DEGREES(ATAN(Q13/P13))-180),IF(Q13>0,90,IF(Q13<0,-90,0))))) -> 2.0376351 | T13: =IF(B13="","",LOG10(B13)) -> 3.0791629 | U13: =IF(R13="","",LOG10(MAX(R13,0.000000000001))) -> -0.22854766
A14: 11 | B14: =IF(A14<=入力・概要!$B$40,10^(LOG10(入力・概要!$B$38)+(A14-1)*(LOG10(入力・概要!$B$39)-LOG10(入力・概要!$B$38))/(入力・概要!$B$40-1)),"") -> 1224.5 | C14: =IF(B14="","",2*PI()*B14) -> 7693.7606 | D14: =IF(B14="","",ATANH(MIN(0.999999,(2*入力・概要!$B$17*入力・概要!$B$6)/入力・概要!$B$30))+入力・概要!$B$33*SQRT(B14/1000000)+(2*PI()*B14*入力・概要!$B$6/(299792458*入力・概要!$B$31))*入力・概要!$B$32/2) -> 0.0060743284 | E14: =IF(B14="","",2*PI()*B14*入力・概要!$B$6/(299792458*入力・概要!$B$31)) -> 0.00028120417 | F14: =IF(B14="","",SINH(2*D14)/(COSH(2*D14)+COS(2*E14))) -> 0.0060742542 | G14: =IF(B14="","",SIN(2*E14)/(COSH(2*D14)+COS(2*E14))) -> 0.00028119381 | H14: =IF(B14="","",入力・概要!$B$34) -> 0.1351019 | I14: =IF(B14="","",C14*入力・概要!$B$35*0.000000001) -> 9.6484467e-05 | J14: =IF(B14="","",H14+入力・概要!$B$30*F14) -> 0.59047576 | K14: =IF(B14="","",I14+入力・概要!$B$30*G14) -> 0.021176983 | L14: =IF(B14="","",入力・概要!$B$30+H14*F14-I14*G14) -> 74.968684 | M14: =IF(B14="","",H14*G14+I14*F14) -> 3.8575888e-05 | N14: =IF(B14="","",入力・概要!$B$30*(J14*L14+K14*M14)/(L14^2+M14^2)) -> 0.5904693 | O14: =IF(B14="","",入力・概要!$B$30*(K14*L14-J14*M14)/(L14^2+M14^2)) -> 0.021176448 | P14: =IF(B14="","",N14+入力・概要!$B$36) -> 0.5904693 | Q14: =IF(B14="","",O14+C14*入力・概要!$B$37*0.000000001) -> 0.021436825 | R14: =IF(B14="","",SQRT(P14^2+Q14^2)) -> 0.5908583 | S14: =IF(B14="","",IF(P14>0,DEGREES(ATAN(Q14/P14)),IF(P14<0,IF(Q14>=0,DEGREES(ATAN(Q14/P14))+180,DEGREES(ATAN(Q14/P14))-180),IF(Q14>0,90,IF(Q14<0,-90,0))))) -> 2.0791943 | T14: =IF(B14="","",LOG10(B14)) -> 3.0879588 | U14: =IF(R14="","",LOG10(MAX(R14,0.000000000001))) -> -0.22851666
A15: 12 | B15: =IF(A15<=入力・概要!$B$40,10^(LOG10(入力・概要!$B$38)+(A15-1)*(LOG10(入力・概要!$B$39)-LOG10(入力・概要!$B$38))/(入力・概要!$B$40-1)),"") -> 1249.553 | C15: =IF(B15="","",2*PI()*B15) -> 7851.173 | D15: =IF(B15="","",ATANH(MIN(0.999999,(2*入力・概要!$B$17*入力・概要!$B$6)/入力・概要!$B$30))+入力・概要!$B$33*SQRT(B15/1000000)+(2*PI()*B15*入力・概要!$B$6/(299792458*入力・概要!$B$31))*入力・概要!$B$32/2) -> 0.0060746914 | E15: =IF(B15="","",2*PI()*B15*入力・概要!$B$6/(299792458*入力・概要!$B$31)) -> 0.00028695754 | F15: =IF(B15="","",SINH(2*D15)/(COSH(2*D15)+COS(2*E15))) -> 0.0060746172 | G15: =IF(B15="","",SIN(2*E15)/(COSH(2*D15)+COS(2*E15))) -> 0.00028694696 | H15: =IF(B15="","",入力・概要!$B$34) -> 0.1351019 | I15: =IF(B15="","",C15*入力・概要!$B$35*0.000000001) -> 9.8458515e-05 | J15: =IF(B15="","",H15+入力・概要!$B$30*F15) -> 0.59050297 | K15: =IF(B15="","",I15+入力・概要!$B$30*G15) -> 0.021610259 | L15: =IF(B15="","",入力・概要!$B$30+H15*F15-I15*G15) -> 74.968684 | M15: =IF(B15="","",H15*G15+I15*F15) -> 3.9365176e-05 | N15: =IF(B15="","",入力・概要!$B$30*(J15*L15+K15*M15)/(L15^2+M15^2)) -> 0.59049652 | O15: =IF(B15="","",入力・概要!$B$30*(K15*L15-J15*M15)/(L15^2+M15^2)) -> 0.021609712 | P15: =IF(B15="","",N15+入力・概要!$B$36) -> 0.59049652 | Q15: =IF(B15="","",O15+C15*入力・概要!$B$37*0.000000001) -> 0.021875417 | R15: =IF(B15="","",SQRT(P15^2+Q15^2)) -> 0.59090157 | S15: =IF(B15="","",IF(P15>0,DEGREES(ATAN(Q15/P15)),IF(P15<0,IF(Q15>=0,DEGREES(ATAN(Q15/P15))+180,DEGREES(ATAN(Q15/P15))-180),IF(Q15>0,90,IF(Q15<0,-90,0))))) -> 2.1215979 | T15: =IF(B15="","",LOG10(B15)) -> 3.0967547 | U15: =IF(R15="","",LOG10(MAX(R15,0.000000000001))) -> -0.22848485
... A804: 801 | B804: =IF(A804<=入力・概要!$B$40,10^(LOG10(入力・概要!$B$38)+(A804-1)*(LOG10(入力・概要!$B$39)-LOG10(入力・概要!$B$38))/(入力・概要!$B$40-1)),"") | C804: =IF(B804="","",2*PI()*B804) | D804: =IF(B804="","",ATANH(MIN(0.999999,(2*入力・概要!$B$17*入力・概要!$B$6)/入力・概要!$B$30))+入力・概要!$B$33*SQRT(B804/1000000)+(2*PI()*B804*入力・概要!$B$6/(299792458*入力・概要!$B$31))*入力・概要!$B$32/2) | E804: =IF(B804="","",2*PI()*B804*入力・概要!$B$6/(299792458*入力・概要!$B$31)) | F804: =IF(B804="","",SINH(2*D804)/(COSH(2*D804)+COS(2*E804))) | G804: =IF(B804="","",SIN(2*E804)/(COSH(2*D804)+COS(2*E804))) | H804: =IF(B804="","",入力・概要!$B$34) | I804: =IF(B804="","",C804*入力・概要!$B$35*0.000000001) | J804: =IF(B804="","",H804+入力・概要!$B$30*F804) | K804: =IF(B804="","",I804+入力・概要!$B$30*G804) | L804: =IF(B804="","",入力・概要!$B$30+H804*F804-I804*G804) | M804: =IF(B804="","",H804*G804+I804*F804) | N804: =IF(B804="","",入力・概要!$B$30*(J804*L804+K804*M804)/(L804^2+M804^2)) | O804: =IF(B804="","",入力・概要!$B$30*(K804*L804-J804*M804)/(L804^2+M804^2)) | P804: =IF(B804="","",N804+入力・概要!$B$36) | Q804: =IF(B804="","",O804+C804*入力・概要!$B$37*0.000000001) | R804: =IF(B804="","",SQRT(P804^2+Q804^2)) | S804: =IF(B804="","",IF(P804>0,DEGREES(ATAN(Q804/P804)),IF(P804<0,IF(Q804>=0,DEGREES(ATAN(Q804/P804))+180,DEGREES(ATAN(Q804/P804))-180),IF(Q804>0,90,IF(Q804<0,-90,0))))) | T804: =IF(B804="","",LOG10(B804)) | U804: =IF(R804="","",LOG10(MAX(R804,0.000000000001)))

Sheet 同相3導体
A1: 同相モード：P(2芯一括)－FG1 3導体MTLモード解
A3: No. | B3: 周波数 [Hz] | C3: ω | D3: 内部A1 | E3: 内部θ1 | F3: tanh1 Re | G3: tanh1 Im | H3: 外部A2 | I3: 外部θ2 | J3: tanh2 Re | K3: tanh2 Im | L3: C1 Re | M3: C1 Im | N3: C2 Re | O3: C2 Im | P3: 負荷 Re | Q3: 負荷 Im | R3: 外部Zext Re | S3: 外部Zext Im | T3: 内部実効負荷 Re | U3: 内部実効負荷 Im | V3: 分子 Re | W3: 分子 Im | X3: 分母 Re | Y3: 分母 Im | Z3: Zin Re | AA3: Zin Im | AB3: |ZCM| [Ω] | AC3: 位相 [deg] | AD3: log10(f) | AE3: log10(|ZCM|) | AF3: |Zload| | AG3: |Zext|
A4: 1 | B4: =IF(A4<=入力・概要!$B$40,10^(LOG10(入力・概要!$B$38)+(A4-1)*(LOG10(入力・概要!$B$39)-LOG10(入力・概要!$B$38))/(入力・概要!$B$40-1)),"") -> 1000 | C4: =IF(B4="","",2*PI()*B4) -> 6283.1853 | D4: =IF(B4="","",ATANH(MIN(0.999999,入力・概要!$E$20/入力・概要!$E$9))+入力・概要!$B$20*SQRT(B4/1000000)+E4*入力・概要!$B$15/2) -> 0.009889925 | E4: =IF(B4="","",C4*(入力・概要!$E$11*0.000000001)) -> 0.00020282371 | F4: =IF(B4="","",SINH(2*D4)/(COSH(2*D4)+COS(2*E4))) -> 0.009889603 | G4: =IF(B4="","",SIN(2*E4)/(COSH(2*D4)+COS(2*E4))) -> 0.00020280388 | H4: =IF(B4="","",ATANH(MIN(0.999999,入力・概要!$E$21/入力・概要!$E$15))+入力・概要!$B$21*SQRT(B4/1000000)+I4*入力・概要!$B$16/2) -> 0.0038669445 | I4: =IF(B4="","",C4*(入力・概要!$E$17*0.000000001)) -> 0.00018651843 | J4: =IF(B4="","",SINH(2*H4)/(COSH(2*H4)+COS(2*I4))) -> 0.0038669254 | K4: =IF(B4="","",SIN(2*I4)/(COSH(2*H4)+COS(2*I4))) -> 0.00018651565 | L4: =IF(B4="","",入力・概要!$B$25) -> 0.05 | M4: =IF(B4="","",C4*入力・概要!$B$26*0.000000001-1/(C4*入力・概要!$B$24*0.000001)) -> -15.915369 | N4: =IF(B4="","",入力・概要!$B$28) -> 0.05 | O4: =IF(B4="","",C4*入力・概要!$B$29*0.000000001-1/(C4*入力・概要!$B$27*0.000001)) -> -15.915369 | P4: =IF(B4="","",((L4*N4-M4*O4)*(L4+N4)+(L4*O4+M4*N4)*(M4+O4))/((L4+N4)^2+(M4+O4)^2)) -> 0.025 | Q4: =IF(B4="","",((L4*O4+M4*N4)*(L4+N4)-(L4*N4-M4*O4)*(M4+O4))/((L4+N4)^2+(M4+O4)^2)) -> -7.9576843 | R4: =IF(B4="","",入力・概要!$E$15*J4) -> 0.37235971 | S4: =IF(B4="","",入力・概要!$E$15*K4) -> 0.017960241 | T4: =IF(B4="","",P4+R4) -> 0.39735971 | U4: =IF(B4="","",Q4+S4) -> -7.9397241 | V4: =IF(B4="","",T4+入力・概要!$E$9*F4) -> 0.66339329 | W4: =IF(B4="","",U4+入力・概要!$E$9*G4) -> -7.9342686 | X4: =IF(B4="","",入力・概要!$E$9+T4*F4-U4*G4) -> 26.90587 | Y4: =IF(B4="","",T4*G4+U4*F4) -> -0.078440133 | Z4: =IF(B4="","",入力・概要!$E$9*(V4*X4+W4*Y4)/(X4^2+Y4^2)+入力・概要!$B$36) -> 0.6863773 | AA4: =IF(B4="","",入力・概要!$E$9*(W4*X4-V4*Y4)/(X4^2+Y4^2)+C4*入力・概要!$B$37*0.000000001) -> -7.9304212 | AB4: =IF(B4="","",SQRT(Z4^2+AA4^2)) -> 7.9600688 | AC4: =IF(B4="","",IF(Z4>0,DEGREES(ATAN(AA4/Z4)),IF(Z4<0,IF(AA4>=0,DEGREES(ATAN(AA4/Z4))+180,DEGREES(ATAN(AA4/Z4))-180),IF(AA4>0,90,IF(AA4<0,-90,0))))) -> -85.053382 | AD4: =IF(B4="","",LOG10(B4)) -> 3 | AE4: =IF(AB4="","",LOG10(MAX(AB4,0.000000000001))) -> 0.90091682 | AF4: =IF(B4="","",SQRT(P4^2+Q4^2)) -> 7.9577236 | AG4: =IF(B4="","",SQRT(R4^2+S4^2)) -> 0.3727926
A5: 2 | B5: =IF(A5<=入力・概要!$B$40,10^(LOG10(入力・概要!$B$38)+(A5-1)*(LOG10(入力・概要!$B$39)-LOG10(入力・概要!$B$38))/(入力・概要!$B$40-1)),"") -> 1020.4598 | C5: =IF(B5="","",2*PI()*B5) -> 6411.7377 | D5: =IF(B5="","",ATANH(MIN(0.999999,入力・概要!$E$20/入力・概要!$E$9))+入力・概要!$B$20*SQRT(B5/1000000)+E5*入力・概要!$B$15/2) -> 0.0098909528 | E5: =IF(B5="","",C5*(入力・概要!$E$11*0.000000001)) -> 0.00020697343 | F5: =IF(B5="","",SINH(2*D5)/(COSH(2*D5)+COS(2*E5))) -> 0.0098906307 | G5: =IF(B5="","",SIN(2*E5)/(COSH(2*D5)+COS(2*E5))) -> 0.00020695319 | H5: =IF(B5="","",ATANH(MIN(0.999999,入力・概要!$E$21/入力・概要!$E$15))+入力・概要!$B$21*SQRT(B5/1000000)+I5*入力・概要!$B$16/2) -> 0.0038682701 | I5: =IF(B5="","",C5*(入力・概要!$E$17*0.000000001)) -> 0.00019033455 | J5: =IF(B5="","",SINH(2*H5)/(COSH(2*H5)+COS(2*I5))) -> 0.003868251 | K5: =IF(B5="","",SIN(2*I5)/(COSH(2*H5)+COS(2*I5))) -> 0.00019033171 | L5: =IF(B5="","",入力・概要!$B$25) -> 0.05 | M5: =IF(B5="","",C5*入力・概要!$B$26*0.000000001-1/(C5*入力・概要!$B$24*0.000001)) -> -15.596268 | N5: =IF(B5="","",入力・概要!$B$28) -> 0.05 | O5: =IF(B5="","",C5*入力・概要!$B$29*0.000000001-1/(C5*入力・概要!$B$27*0.000001)) -> -15.596268 | P5: =IF(B5="","",((L5*N5-M5*O5)*(L5+N5)+(L5*O5+M5*N5)*(M5+O5))/((L5+N5)^2+(M5+O5)^2)) -> 0.025 | Q5: =IF(B5="","",((L5*O5+M5*N5)*(L5+N5)-(L5*N5-M5*O5)*(M5+O5))/((L5+N5)^2+(M5+O5)^2)) -> -7.7981338 | R5: =IF(B5="","",入力・概要!$E$15*J5) -> 0.37248735 | S5: =IF(B5="","",入力・概要!$E$15*K5) -> 0.018327703 | T5: =IF(B5="","",P5+R5) -> 0.39748735 | U5: =IF(B5="","",Q5+S5) -> -7.7798061 | V5: =IF(B5="","",T5+入力・概要!$E$9*F5) -> 0.66354859 | W5: =IF(B5="","",U5+入力・概要!$E$9*G5) -> -7.774239 | X5: =IF(B5="","",入力・概要!$E$9+T5*F5-U5*G5) -> 26.905872 | Y5: =IF(B5="","",T5*G5+U5*F5) -> -0.076864928 | Z5: =IF(B5="","",入力・概要!$E$9*(V5*X5+W5*Y5)/(X5^2+Y5^2)+入力・概要!$B$36) -> 0.68561127 | AA5: =IF(B5="","",入力・概要!$E$9*(W5*X5-V5*Y5)/(X5^2+Y5^2)+C5*入力・概要!$B$37*0.000000001) -> -7.7704622 | AB5: =IF(B5="","",SQRT(Z5^2+AA5^2)) -> 7.8006504 | AC5: =IF(B5="","",IF(Z5>0,DEGREES(ATAN(AA5/Z5)),IF(Z5<0,IF(AA5>=0,DEGREES(ATAN(AA5/Z5))+180,DEGREES(ATAN(AA5/Z5))-180),IF(AA5>0,90,IF(AA5<0,-90,0))))) -> -84.957679 | AD5: =IF(B5="","",LOG10(B5)) -> 3.0087959 | AE5: =IF(AB5="","",LOG10(MAX(AB5,0.000000000001))) -> 0.89213081 | AF5: =IF(B5="","",SQRT(P5^2+Q5^2)) -> 7.7981739 | AG5: =IF(B5="","",SQRT(R5^2+S5^2)) -> 0.37293797
A6: 3 | B6: =IF(A6<=入力・概要!$B$40,10^(LOG10(入力・概要!$B$38)+(A6-1)*(LOG10(入力・概要!$B$39)-LOG10(入力・概要!$B$38))/(入力・概要!$B$40-1)),"") -> 1041.3381 | C6: =IF(B6="","",2*PI()*B6) -> 6542.9203 | D6: =IF(B6="","",ATANH(MIN(0.999999,入力・概要!$E$20/入力・概要!$E$9))+入力・概要!$B$20*SQRT(B6/1000000)+E6*入力・概要!$B$15/2) -> 0.0098919917 | E6: =IF(B6="","",C6*(入力・概要!$E$11*0.000000001)) -> 0.00021120806 | F6: =IF(B6="","",SINH(2*D6)/(COSH(2*D6)+COS(2*E6))) -> 0.0098916695 | G6: =IF(B6="","",SIN(2*E6)/(COSH(2*D6)+COS(2*E6))) -> 0.0002111874 | H6: =IF(B6="","",ATANH(MIN(0.999999,入力・概要!$E$21/入力・概要!$E$15))+入力・概要!$B$21*SQRT(B6/1000000)+I6*入力・概要!$B$16/2) -> 0.0038696096 | I6: =IF(B6="","",C6*(入力・概要!$E$17*0.000000001)) -> 0.00019422875 | J6: =IF(B6="","",SINH(2*H6)/(COSH(2*H6)+COS(2*I6))) -> 0.0038695904 | K6: =IF(B6="","",SIN(2*I6)/(COSH(2*H6)+COS(2*I6))) -> 0.00019422584 | L6: =IF(B6="","",入力・概要!$B$25) -> 0.05 | M6: =IF(B6="","",C6*入力・概要!$B$26*0.000000001-1/(C6*入力・概要!$B$24*0.000001)) -> -15.283564 | N6: =IF(B6="","",入力・概要!$B$28) -> 0.05 | O6: =IF(B6="","",C6*入力・概要!$B$29*0.000000001-1/(C6*入力・概要!$B$27*0.000001)) -> -15.283564 | P6: =IF(B6="","",((L6*N6-M6*O6)*(L6+N6)+(L6*O6+M6*N6)*(M6+O6))/((L6+N6)^2+(M6+O6)^2)) -> 0.025 | Q6: =IF(B6="","",((L6*O6+M6*N6)*(L6+N6)-(L6*N6-M6*O6)*(M6+O6))/((L6+N6)^2+(M6+O6)^2)) -> -7.6417822 | R6: =IF(B6="","",入力・概要!$E$15*J6) -> 0.37261634 | S6: =IF(B6="","",入力・概要!$E$15*K6) -> 0.018702683 | T6: =IF(B6="","",P6+R6) -> 0.39761634 | U6: =IF(B6="","",Q6+S6) -> -7.6230796 | V6: =IF(B6="","",T6+入力・概要!$E$9*F6) -> 0.66370551 | W6: =IF(B6="","",U6+入力・概要!$E$9*G6) -> -7.6173985 | X6: =IF(B6="","",入力・概要!$E$9+T6*F6-U6*G6) -> 26.905873 | Y6: =IF(B6="","",T6*G6+U6*F6) -> -0.075321012 | Z6: =IF(B6="","",入力・概要!$E$9*(V6*X6+W6*Y6)/(X6^2+Y6^2)+入力・概要!$B$36) -> 0.68488337 | AA6: =IF(B6="","",入力・概要!$E$9*(W6*X6-V6*Y6)/(X6^2+Y6^2)+C6*入力・概要!$B$37*0.000000001) -> -7.6136905 | AB6: =IF(B6="","",SQRT(Z6^2+AA6^2)) -> 7.6444325 | AC6: =IF(B6="","",IF(Z6>0,DEGREES(ATAN(AA6/Z6)),IF(Z6<0,IF(AA6>=0,DEGREES(ATAN(AA6/Z6))+180,DEGREES(ATAN(AA6/Z6))-180),IF(AA6>0,90,IF(AA6<0,-90,0))))) -> -84.859839 | AD6: =IF(B6="","",LOG10(B6)) -> 3.0175918 | AE6: =IF(AB6="","",LOG10(MAX(AB6,0.000000000001))) -> 0.88334525 | AF6: =IF(B6="","",SQRT(P6^2+Q6^2)) -> 7.6418231 | AG6: =IF(B6="","",SQRT(R6^2+S6^2)) -> 0.37308541
A7: 4 | B7: =IF(A7<=入力・概要!$B$40,10^(LOG10(入力・概要!$B$38)+(A7-1)*(LOG10(入力・概要!$B$39)-LOG10(入力・概要!$B$38))/(入力・概要!$B$40-1)),"") -> 1062.6436 | C7: =IF(B7="","",2*PI()*B7) -> 6676.7868 | D7: =IF(B7="","",ATANH(MIN(0.999999,入力・概要!$E$20/入力・概要!$E$9))+入力・概要!$B$20*SQRT(B7/1000000)+E7*入力・概要!$B$15/2) -> 0.0098930419 | E7: =IF(B7="","",C7*(入力・概要!$E$11*0.000000001)) -> 0.00021552932 | F7: =IF(B7="","",SINH(2*D7)/(COSH(2*D7)+COS(2*E7))) -> 0.0098927196 | G7: =IF(B7="","",SIN(2*E7)/(COSH(2*D7)+COS(2*E7))) -> 0.00021550823 | H7: =IF(B7="","",ATANH(MIN(0.999999,入力・概要!$E$21/入力・概要!$E$15))+入力・概要!$B$21*SQRT(B7/1000000)+I7*入力・概要!$B$16/2) -> 0.0038709631 | I7: =IF(B7="","",C7*(入力・概要!$E$17*0.000000001)) -> 0.00019820262 | J7: =IF(B7="","",SINH(2*H7)/(COSH(2*H7)+COS(2*I7))) -> 0.0038709439 | K7: =IF(B7="","",SIN(2*I7)/(COSH(2*H7)+COS(2*I7))) -> 0.00019819966 | L7: =IF(B7="","",入力・概要!$B$25) -> 0.05 | M7: =IF(B7="","",C7*入力・概要!$B$26*0.000000001-1/(C7*入力・概要!$B$24*0.000001)) -> -14.977131 | N7: =IF(B7="","",入力・概要!$B$28) -> 0.05 | O7: =IF(B7="","",C7*入力・概要!$B$29*0.000000001-1/(C7*入力・概要!$B$27*0.000001)) -> -14.977131 | P7: =IF(B7="","",((L7*N7-M7*O7)*(L7+N7)+(L7*O7+M7*N7)*(M7+O7))/((L7+N7)^2+(M7+O7)^2)) -> 0.025 | Q7: =IF(B7="","",((L7*O7+M7*N7)*(L7+N7)-(L7*N7-M7*O7)*(M7+O7))/((L7+N7)^2+(M7+O7)^2)) -> -7.4885653 | R7: =IF(B7="","",入力・概要!$E$15*J7) -> 0.37274667 | S7: =IF(B7="","",入力・概要!$E$15*K7) -> 0.019085335 | T7: =IF(B7="","",P7+R7) -> 0.39774667 | U7: =IF(B7="","",Q7+S7) -> -7.46948 | V7: =IF(B7="","",T7+入力・概要!$E$9*F7) -> 0.66386409 | W7: =IF(B7="","",U7+入力・概要!$E$9*G7) -> -7.4636828 | X7: =IF(B7="","",入力・概要!$E$9+T7*F7-U7*G7) -> 26.905875 | Y7: =IF(B7="","",T7*G7+U7*F7) -> -0.073807754 | Z7: =IF(B7="","",入力・概要!$E$9*(V7*X7+W7*Y7)/(X7^2+Y7^2)+入力・概要!$B$36) -> 0.68419217 | AA7: =IF(B7="","",入力・概要!$E$9*(W7*X7-V7*Y7)/(X7^2+Y7^2)+C7*入力・概要!$B$37*0.000000001) -> -7.4600419 | AB7: =IF(B7="","",SQRT(Z7^2+AA7^2)) -> 7.4913513 | AC7: =IF(B7="","",IF(Z7>0,DEGREES(ATAN(AA7/Z7)),IF(Z7<0,IF(AA7>=0,DEGREES(ATAN(AA7/Z7))+180,DEGREES(ATAN(AA7/Z7))-180),IF(AA7>0,90,IF(AA7<0,-90,0))))) -> -84.75982 | AD7: =IF(B7="","",LOG10(B7)) -> 3.0263876 | AE7: =IF(AB7="","",LOG10(MAX(AB7,0.000000000001))) -> 0.87456016 | AF7: =IF(B7="","",SQRT(P7^2+Q7^2)) -> 7.4886071 | AG7: =IF(B7="","",SQRT(R7^2+S7^2)) -> 0.37323495
A8: 5 | B8: =IF(A8<=入力・概要!$B$40,10^(LOG10(入力・概要!$B$38)+(A8-1)*(LOG10(入力・概要!$B$39)-LOG10(入力・概要!$B$38))/(入力・概要!$B$40-1)),"") -> 1084.385 | C8: =IF(B8="","",2*PI()*B8) -> 6813.3922 | D8: =IF(B8="","",ATANH(MIN(0.999999,入力・概要!$E$20/入力・概要!$E$9))+入力・概要!$B$20*SQRT(B8/1000000)+E8*入力・概要!$B$15/2) -> 0.0098941034 | E8: =IF(B8="","",C8*(入力・概要!$E$11*0.000000001)) -> 0.000219939 | F8: =IF(B8="","",SINH(2*D8)/(COSH(2*D8)+COS(2*E8))) -> 0.009893781 | G8: =IF(B8="","",SIN(2*E8)/(COSH(2*D8)+COS(2*E8))) -> 0.00021991747 | H8: =IF(B8="","",ATANH(MIN(0.999999,入力・概要!$E$21/入力・概要!$E$15))+入力・概要!$B$21*SQRT(B8/1000000)+I8*入力・概要!$B$16/2) -> 0.0038723308 | I8: =IF(B8="","",C8*(入力・概要!$E$17*0.000000001)) -> 0.0002022578 | J8: =IF(B8="","",SINH(2*H8)/(COSH(2*H8)+COS(2*I8))) -> 0.0038723116 | K8: =IF(B8="","",SIN(2*I8)/(COSH(2*H8)+COS(2*I8))) -> 0.00020225477 | L8: =IF(B8="","",入力・概要!$B$25) -> 0.05 | M8: =IF(B8="","",C8*入力・概要!$B$26*0.000000001-1/(C8*入力・概要!$B$24*0.000001)) -> -14.676841 | N8: =IF(B8="","",入力・概要!$B$28) -> 0.05 | O8: =IF(B8="","",C8*入力・概要!$B$29*0.000000001-1/(C8*入力・概要!$B$27*0.000001)) -> -14.676841 | P8: =IF(B8="","",((L8*N8-M8*O8)*(L8+N8)+(L8*O8+M8*N8)*(M8+O8))/((L8+N8)^2+(M8+O8)^2)) -> 0.025 | Q8: =IF(B8="","",((L8*O8+M8*N8)*(L8+N8)-(L8*N8-M8*O8)*(M8+O8))/((L8+N8)^2+(M8+O8)^2)) -> -7.3384203 | R8: =IF(B8="","",入力・概要!$E$15*J8) -> 0.37287837 | S8: =IF(B8="","",入力・概要!$E$15*K8) -> 0.019475816 | T8: =IF(B8="","",P8+R8) -> 0.39787837 | U8: =IF(B8="","",Q8+S8) -> -7.3189445 | V8: =IF(B8="","",T8+入力・概要!$E$9*F8) -> 0.66402435 | W8: =IF(B8="","",U8+入力・概要!$E$9*G8) -> -7.3130287 | X8: =IF(B8="","",入力・概要!$E$9+T8*F8-U8*G8) -> 26.905876 | Y8: =IF(B8="","",T8*G8+U8*F8) -> -0.072324534 | Z8: =IF(B8="","",入力・概要!$E$9*(V8*X8+W8*Y8)/(X8^2+Y8^2)+入力・概要!$B$36) -> 0.68353632 | AA8: =IF(B8="","",入力・概要!$E$9*(W8*X8-V8*Y8)/(X8^2+Y8^2)+C8*入力・概要!$B$37*0.000000001) -> -7.3094533 | AB8: =IF(B8="","",SQRT(Z8^2+AA8^2)) -> 7.3413438 | AC8: =IF(B8="","",IF(Z8>0,DEGREES(ATAN(AA8/Z8)),IF(Z8<0,IF(AA8>=0,DEGREES(ATAN(AA8/Z8))+180,DEGREES(ATAN(AA8/Z8))-180),IF(AA8>0,90,IF(AA8<0,-90,0))))) -> -84.657578 | AD8: =IF(B8="","",LOG10(B8)) -> 3.0351835 | AE8: =IF(AB8="","",LOG10(MAX(AB8,0.000000000001))) -> 0.86577556 | AF8: =IF(B8="","",SQRT(P8^2+Q8^2)) -> 7.3384629 | AG8: =IF(B8="","",SQRT(R8^2+S8^2)) -> 0.37338664
A9: 6 | B9: =IF(A9<=入力・概要!$B$40,10^(LOG10(入力・概要!$B$38)+(A9-1)*(LOG10(入力・概要!$B$39)-LOG10(入力・概要!$B$38))/(入力・概要!$B$40-1)),"") -> 1106.5713 | C9: =IF(B9="","",2*PI()*B9) -> 6952.7925 | D9: =IF(B9="","",ATANH(MIN(0.999999,入力・概要!$E$20/入力・概要!$E$9))+入力・概要!$B$20*SQRT(B9/1000000)+E9*入力・概要!$B$15/2) -> 0.0098951764 | E9: =IF(B9="","",C9*(入力・概要!$E$11*0.000000001)) -> 0.0002244389 | F9: =IF(B9="","",SINH(2*D9)/(COSH(2*D9)+COS(2*E9))) -> 0.0098948539 | G9: =IF(B9="","",SIN(2*E9)/(COSH(2*D9)+COS(2*E9))) -> 0.00022441693 | H9: =IF(B9="","",ATANH(MIN(0.999999,入力・概要!$E$21/入力・概要!$E$15))+入力・概要!$B$21*SQRT(B9/1000000)+I9*入力・概要!$B$16/2) -> 0.0038737129 | I9: =IF(B9="","",C9*(入力・概要!$E$17*0.000000001)) -> 0.00020639594 | J9: =IF(B9="","",SINH(2*H9)/(COSH(2*H9)+COS(2*I9))) -> 0.0038736937 | K9: =IF(B9="","",SIN(2*I9)/(COSH(2*H9)+COS(2*I9))) -> 0.00020639285 | L9: =IF(B9="","",入力・概要!$B$25) -> 0.05 | M9: =IF(B9="","",C9*入力・概要!$B$26*0.000000001-1/(C9*入力・概要!$B$24*0.000001)) -> -14.382571 | N9: =IF(B9="","",入力・概要!$B$28) -> 0.05 | O9: =IF(B9="","",C9*入力・概要!$B$29*0.000000001-1/(C9*入力・概要!$B$27*0.000001)) -> -14.382571 | P9: =IF(B9="","",((L9*N9-M9*O9)*(L9+N9)+(L9*O9+M9*N9)*(M9+O9))/((L9+N9)^2+(M9+O9)^2)) -> 0.025 | Q9: =IF(B9="","",((L9*O9+M9*N9)*(L9+N9)-(L9*N9-M9*O9)*(M9+O9))/((L9+N9)^2+(M9+O9)^2)) -> -7.1912856 | R9: =IF(B9="","",入力・概要!$E$15*J9) -> 0.37301145 | S9: =IF(B9="","",入力・概要!$E$15*K9) -> 0.019874286 | T9: =IF(B9="","",P9+R9) -> 0.39801145 | U9: =IF(B9="","",Q9+S9) -> -7.1714113 | V9: =IF(B9="","",T9+入力・概要!$E$9*F9) -> 0.66418629 | W9: =IF(B9="","",U9+入力・概要!$E$9*G9) -> -7.1653744 | X9: =IF(B9="","",入力・概要!$E$9+T9*F9-U9*G9) -> 26.905878 | Y9: =IF(B9="","",T9*G9+U9*F9) -> -0.070870747 | Z9: =IF(B9="","",入力・概要!$E$9*(V9*X9+W9*Y9)/(X9^2+Y9^2)+入力・概要!$B$36) -> 0.68291448 | AA9: =IF(B9="","",入力・概要!$E$9*(W9*X9-V9*Y9)/(X9^2+Y9^2)+C9*入力・概要!$B$37*0.000000001) -> -7.1618629 | AB9: =IF(B9="","",SQRT(Z9^2+AA9^2)) -> 7.1943486 | AC9: =IF(B9="","",IF(Z9>0,DEGREES(ATAN(AA9/Z9)),IF(Z9<0,IF(AA9>=0,DEGREES(ATAN(AA9/Z9))+180,DEGREES(ATAN(AA9/Z9))-180),IF(AA9>0,90,IF(AA9<0,-90,0))))) -> -84.553069 | AD9: =IF(B9="","",LOG10(B9)) -> 3.0439794 | AE9: =IF(AB9="","",LOG10(MAX(AB9,0.000000000001))) -> 0.85699148 | AF9: =IF(B9="","",SQRT(P9^2+Q9^2)) -> 7.1913291 | AG9: =IF(B9="","",SQRT(R9^2+S9^2)) -> 0.37354053
A10: 7 | B10: =IF(A10<=入力・概要!$B$40,10^(LOG10(入力・概要!$B$38)+(A10-1)*(LOG10(入力・概要!$B$39)-LOG10(入力・概要!$B$38))/(入力・概要!$B$40-1)),"") -> 1129.2115 | C10: =IF(B10="","",2*PI()*B10) -> 7095.0449 | D10: =IF(B10="","",ATANH(MIN(0.999999,入力・概要!$E$20/入力・概要!$E$9))+入力・概要!$B$20*SQRT(B10/1000000)+E10*入力・概要!$B$15/2) -> 0.009896261 | E10: =IF(B10="","",C10*(入力・概要!$E$11*0.000000001)) -> 0.00022903086 | F10: =IF(B10="","",SINH(2*D10)/(COSH(2*D10)+COS(2*E10))) -> 0.0098959385 | G10: =IF(B10="","",SIN(2*E10)/(COSH(2*D10)+COS(2*E10))) -> 0.00022900844 | H10: =IF(B10="","",ATANH(MIN(0.999999,入力・概要!$E$21/入力・概要!$E$15))+入力・概要!$B$21*SQRT(B10/1000000)+I10*入力・概要!$B$16/2) -> 0.0038751094 | I10: =IF(B10="","",C10*(入力・概要!$E$17*0.000000001)) -> 0.00021061875 | J10: =IF(B10="","",SINH(2*H10)/(COSH(2*H10)+COS(2*I10))) -> 0.0038750902 | K10: =IF(B10="","",SIN(2*I10)/(COSH(2*H10)+COS(2*I10))) -> 0.00021061559 | L10: =IF(B10="","",入力・概要!$B$25) -> 0.05 | M10: =IF(B10="","",C10*入力・概要!$B$26*0.000000001-1/(C10*入力・概要!$B$24*0.000001)) -> -14.094202 | N10: =IF(B10="","",入力・概要!$B$28) -> 0.05 | O10: =IF(B10="","",C10*入力・概要!$B$29*0.000000001-1/(C10*入力・概要!$B$27*0.000001)) -> -14.094202 | P10: =IF(B10="","",((L10*N10-M10*O10)*(L10+N10)+(L10*O10+M10*N10)*(M10+O10))/((L10+N10)^2+(M10+O10)^2)) -> 0.025 | Q10: =IF(B10="","",((L10*O10+M10*N10)*(L10+N10)-(L10*N10-M10*O10)*(M10+O10))/((L10+N10)^2+(M10+O10)^2)) -> -7.0471008 | R10: =IF(B10="","",入力・概要!$E$15*J10) -> 0.37314592 | S10: =IF(B10="","",入力・概要!$E$15*K10) -> 0.020280909 | T10: =IF(B10="","",P10+R10) -> 0.39814592 | U10: =IF(B10="","",Q10+S10) -> -7.0268199 | V10: =IF(B10="","",T10+入力・概要!$E$9*F10) -> 0.66434994 | W10: =IF(B10="","",U10+入力・概要!$E$9*G10) -> -7.0206595 | X10: =IF(B10="","",入力・概要!$E$9+T10*F10-U10*G10) -> 26.905879 | Y10: =IF(B10="","",T10*G10+U10*F10) -> -0.069445798 | Z10: =IF(B10="","",入力・概要!$E$9*(V10*X10+W10*Y10)/(X10^2+Y10^2)+入力・概要!$B$36) -> 0.68232541 | AA10: =IF(B10="","",入力・概要!$E$9*(W10*X10-V10*Y10)/(X10^2+Y10^2)+C10*入力・概要!$B$37*0.000000001) -> -7.0172103 | AB10: =IF(B10="","",SQRT(Z10^2+AA10^2)) -> 7.0503055 | AC10: =IF(B10="","",IF(Z10>0,DEGREES(ATAN(AA10/Z10)),IF(Z10<0,IF(AA10>=0,DEGREES(ATAN(AA10/Z10))+180,DEGREES(ATAN(AA10/Z10))-180),IF(AA10>0,90,IF(AA10<0,-90,0))))) -> -84.446247 | AD10: =IF(B10="","",LOG10(B10)) -> 3.0527753 | AE10: =IF(AB10="","",LOG10(MAX(AB10,0.000000000001))) -> 0.84820794 | AF10: =IF(B10="","",SQRT(P10^2+Q10^2)) -> 7.0471451 | AG10: =IF(B10="","",SQRT(R10^2+S10^2)) -> 0.37369666
A11: 8 | B11: =IF(A11<=入力・概要!$B$40,10^(LOG10(入力・概要!$B$38)+(A11-1)*(LOG10(入力・概要!$B$39)-LOG10(入力・概要!$B$38))/(入力・概要!$B$40-1)),"") -> 1152.3149 | C11: =IF(B11="","",2*PI()*B11) -> 7240.2078 | D11: =IF(B11="","",ATANH(MIN(0.999999,入力・概要!$E$20/入力・概要!$E$9))+入力・概要!$B$20*SQRT(B11/1000000)+E11*入力・概要!$B$15/2) -> 0.0098973573 | E11: =IF(B11="","",C11*(入力・概要!$E$11*0.000000001)) -> 0.00023371678 | F11: =IF(B11="","",SINH(2*D11)/(COSH(2*D11)+COS(2*E11))) -> 0.0098970347 | G11: =IF(B11="","",SIN(2*E11)/(COSH(2*D11)+COS(2*E11))) -> 0.00023369389 | H11: =IF(B11="","",ATANH(MIN(0.999999,入力・概要!$E$21/入力・概要!$E$15))+入力・概要!$B$21*SQRT(B11/1000000)+I11*入力・概要!$B$16/2) -> 0.0038765206 | I11: =IF(B11="","",C11*(入力・概要!$E$17*0.000000001)) -> 0.00021492796 | J11: =IF(B11="","",SINH(2*H11)/(COSH(2*H11)+COS(2*I11))) -> 0.0038765013 | K11: =IF(B11="","",SIN(2*I11)/(COSH(2*H11)+COS(2*I11))) -> 0.00021492473 | L11: =IF(B11="","",入力・概要!$B$25) -> 0.05 | M11: =IF(B11="","",C11*入力・概要!$B$26*0.000000001-1/(C11*入力・概要!$B$24*0.000001)) -> -13.811614 | N11: =IF(B11="","",入力・概要!$B$28) -> 0.05 | O11: =IF(B11="","",C11*入力・概要!$B$29*0.000000001-1/(C11*入力・概要!$B$27*0.000001)) -> -13.811614 | P11: =IF(B11="","",((L11*N11-M11*O11)*(L11+N11)+(L11*O11+M11*N11)*(M11+O11))/((L11+N11)^2+(M11+O11)^2)) -> 0.025 | Q11: =IF(B11="","",((L11*O11+M11*N11)*(L11+N11)-(L11*N11-M11*O11)*(M11+O11))/((L11+N11)^2+(M11+O11)^2)) -> -6.9058068 | R11: =IF(B11="","",入力・概要!$E$15*J11) -> 0.37328181 | S11: =IF(B11="","",入力・概要!$E$15*K11) -> 0.020695851 | T11: =IF(B11="","",P11+R11) -> 0.39828181 | U11: =IF(B11="","",Q11+S11) -> -6.8851109 | V11: =IF(B11="","",T11+入力・概要!$E$9*F11) -> 0.66451531 | W11: =IF(B11="","",U11+入力・概要!$E$9*G11) -> -6.8788245 | X11: =IF(B11="","",入力・概要!$E$9+T11*F11-U11*G11) -> 26.905881 | Y11: =IF(B11="","",T11*G11+U11*F11) -> -0.068049106 | Z11: =IF(B11="","",入力・概要!$E$9*(V11*X11+W11*Y11)/(X11^2+Y11^2)+入力・概要!$B$36) -> 0.68176787 | AA11: =IF(B11="","",入力・概要!$E$9*(W11*X11-V11*Y11)/(X11^2+Y11^2)+C11*入力・概要!$B$37*0.000000001) -> -6.875436 | AB11: =IF(B11="","",SQRT(Z11^2+AA11^2)) -> 6.9091554 | AC11: =IF(B11="","",IF(Z11>0,DEGREES(ATAN(AA11/Z11)),IF(Z11<0,IF(AA11>=0,DEGREES(ATAN(AA11/Z11))+180,DEGREES(ATAN(AA11/Z11))-180),IF(AA11>0,90,IF(AA11<0,-90,0))))) -> -84.337066 | AD11: =IF(B11="","",LOG10(B11)) -> 3.0615712 | AE11: =IF(AB11="","",LOG10(MAX(AB11,0.000000000001))) -> 0.83942496 | AF11: =IF(B11="","",SQRT(P11^2+Q11^2)) -> 6.905852 | AG11: =IF(B11="","",SQRT(R11^2+S11^2)) -> 0.37385509
A12: 9 | B12: =IF(A12<=入力・概要!$B$40,10^(LOG10(入力・概要!$B$38)+(A12-1)*(LOG10(入力・概要!$B$39)-LOG10(入力・概要!$B$38))/(入力・概要!$B$40-1)),"") -> 1175.8909 | C12: =IF(B12="","",2*PI()*B12) -> 7388.3406 | D12: =IF(B12="","",ATANH(MIN(0.999999,入力・概要!$E$20/入力・概要!$E$9))+入力・概要!$B$20*SQRT(B12/1000000)+E12*入力・概要!$B$15/2) -> 0.0098984656 | E12: =IF(B12="","",C12*(入力・概要!$E$11*0.000000001)) -> 0.00023849856 | F12: =IF(B12="","",SINH(2*D12)/(COSH(2*D12)+COS(2*E12))) -> 0.0098981429 | G12: =IF(B12="","",SIN(2*E12)/(COSH(2*D12)+COS(2*E12))) -> 0.0002384752 | H12: =IF(B12="","",ATANH(MIN(0.999999,入力・概要!$E$21/入力・概要!$E$15))+入力・概要!$B$21*SQRT(B12/1000000)+I12*入力・概要!$B$16/2) -> 0.0038779466 | I12: =IF(B12="","",C12*(入力・概要!$E$17*0.000000001)) -> 0.00021932533 | J12: =IF(B12="","",SINH(2*H12)/(COSH(2*H12)+COS(2*I12))) -> 0.0038779273 | K12: =IF(B12="","",SIN(2*I12)/(COSH(2*H12)+COS(2*I12))) -> 0.00021932204 | L12: =IF(B12="","",入力・概要!$B$25) -> 0.05 | M12: =IF(B12="","",C12*入力・概要!$B$26*0.000000001-1/(C12*入力・概要!$B$24*0.000001)) -> -13.534691 | N12: =IF(B12="","",入力・概要!$B$28) -> 0.05 | O12: =IF(B12="","",C12*入力・概要!$B$29*0.000000001-1/(C12*入力・概要!$B$27*0.000001)) -> -13.534691 | P12: =IF(B12="","",((L12*N12-M12*O12)*(L12+N12)+(L12*O12+M12*N12)*(M12+O12))/((L12+N12)^2+(M12+O12)^2)) -> 0.025 | Q12: =IF(B12="","",((L12*O12+M12*N12)*(L12+N12)-(L12*N12-M12*O12)*(M12+O12))/((L12+N12)^2+(M12+O12)^2)) -> -6.7673456 | R12: =IF(B12="","",入力・概要!$E$15*J12) -> 0.37341912 | S12: =IF(B12="","",入力・概要!$E$15*K12) -> 0.021119283 | T12: =IF(B12="","",P12+R12) -> 0.39841912 | U12: =IF(B12="","",Q12+S12) -> -6.7462263 | V12: =IF(B12="","",T12+入力・概要!$E$9*F12) -> 0.66468243 | W12: =IF(B12="","",U12+入力・概要!$E$9*G12) -> -6.7398112 | X12: =IF(B12="","",入力・概要!$E$9+T12*F12-U12*G12) -> 26.905883 | Y12: =IF(B12="","",T12*G12+U12*F12) -> -0.066680099 | Z12: =IF(B12="","",入力・概要!$E$9*(V12*X12+W12*Y12)/(X12^2+Y12^2)+入力・概要!$B$36) -> 0.68124072 | AA12: =IF(B12="","",入力・概要!$E$9*(W12*X12-V12*Y12)/(X12^2+Y12^2)+C12*入力・概要!$B$37*0.000000001) -> -6.736482 | AB12: =IF(B12="","",SQRT(Z12^2+AA12^2)) -> 6.7708404 | AC12: =IF(B12="","",IF(Z12>0,DEGREES(ATAN(AA12/Z12)),IF(Z12<0,IF(AA12>=0,DEGREES(ATAN(AA12/Z12))+180,DEGREES(ATAN(AA12/Z12))-180),IF(AA12>0,90,IF(AA12<0,-90,0))))) -> -84.225477 | AD12: =IF(B12="","",LOG10(B12)) -> 3.070367 | AE12: =IF(AB12="","",LOG10(MAX(AB12,0.000000000001))) -> 0.83064257 | AF12: =IF(B12="","",SQRT(P12^2+Q12^2)) -> 6.7673918 | AG12: =IF(B12="","",SQRT(R12^2+S12^2)) -> 0.37401586
A13: 10 | B13: =IF(A13<=入力・概要!$B$40,10^(LOG10(入力・概要!$B$38)+(A13-1)*(LOG10(入力・概要!$B$39)-LOG10(入力・概要!$B$38))/(入力・概要!$B$40-1)),"") -> 1199.9494 | C13: =IF(B13="","",2*PI()*B13) -> 7539.5042 | D13: =IF(B13="","",ATANH(MIN(0.999999,入力・概要!$E$20/入力・概要!$E$9))+入力・概要!$B$20*SQRT(B13/1000000)+E13*入力・概要!$B$15/2) -> 0.0098995858 | E13: =IF(B13="","",C13*(入力・概要!$E$11*0.000000001)) -> 0.00024337818 | F13: =IF(B13="","",SINH(2*D13)/(COSH(2*D13)+COS(2*E13))) -> 0.009899263 | G13: =IF(B13="","",SIN(2*E13)/(COSH(2*D13)+COS(2*E13))) -> 0.00024335434 | H13: =IF(B13="","",ATANH(MIN(0.999999,入力・概要!$E$21/入力・概要!$E$15))+入力・概要!$B$21*SQRT(B13/1000000)+I13*入力・概要!$B$16/2) -> 0.0038793875 | I13: =IF(B13="","",C13*(入力・概要!$E$17*0.000000001)) -> 0.00022381267 | J13: =IF(B13="","",SINH(2*H13)/(COSH(2*H13)+COS(2*I13))) -> 0.0038793682 | K13: =IF(B13="","",SIN(2*I13)/(COSH(2*H13)+COS(2*I13))) -> 0.00022380931 | L13: =IF(B13="","",入力・概要!$B$25) -> 0.05 | M13: =IF(B13="","",C13*入力・概要!$B$26*0.000000001-1/(C13*入力・概要!$B$24*0.000001)) -> -13.263321 | N13: =IF(B13="","",入力・概要!$B$28) -> 0.05 | O13: =IF(B13="","",C13*入力・概要!$B$29*0.000000001-1/(C13*入力・概要!$B$27*0.000001)) -> -13.263321 | P13: =IF(B13="","",((L13*N13-M13*O13)*(L13+N13)+(L13*O13+M13*N13)*(M13+O13))/((L13+N13)^2+(M13+O13)^2)) -> 0.025 | Q13: =IF(B13="","",((L13*O13+M13*N13)*(L13+N13)-(L13*N13-M13*O13)*(M13+O13))/((L13+N13)^2+(M13+O13)^2)) -> -6.6316604 | R13: =IF(B13="","",入力・概要!$E$15*J13) -> 0.37355787 | S13: =IF(B13="","",入力・概要!$E$15*K13) -> 0.021551378 | T13: =IF(B13="","",P13+R13) -> 0.39855787 | U13: =IF(B13="","",Q13+S13) -> -6.610109 | V13: =IF(B13="","",T13+入力・概要!$E$9*F13) -> 0.66485132 | W13: =IF(B13="","",U13+入力・概要!$E$9*G13) -> -6.6035627 | X13: =IF(B13="","",入力・概要!$E$9+T13*F13-U13*G13) -> 26.905884 | Y13: =IF(B13="","",T13*G13+U13*F13) -> -0.065338217 | Z13: =IF(B13="","",入力・概要!$E$9*(V13*X13+W13*Y13)/(X13^2+Y13^2)+入力・概要!$B$36) -> 0.68074284 | AA13: =IF(B13="","",入力・概要!$E$9*(W13*X13-V13*Y13)/(X13^2+Y13^2)+C13*入力・概要!$B$37*0.000000001) -> -6.6002913 | AB13: =IF(B13="","",SQRT(Z13^2+AA13^2)) -> 6.6353038 | AC13: =IF(B13="","",IF(Z13>0,DEGREES(ATAN(AA13/Z13)),IF(Z13<0,IF(AA13>=0,DEGREES(ATAN(AA13/Z13))+180,DEGREES(ATAN(AA13/Z13))-180),IF(AA13>0,90,IF(AA13<0,-90,0))))) -> -84.111432 | AD13: =IF(B13="","",LOG10(B13)) -> 3.0791629 | AE13: =IF(AB13="","",LOG10(MAX(AB13,0.000000000001))) -> 0.82186081 | AF13: =IF(B13="","",SQRT(P13^2+Q13^2)) -> 6.6317075 | AG13: =IF(B13="","",SQRT(R13^2+S13^2)) -> 0.37417903
A14: 11 | B14: =IF(A14<=入力・概要!$B$40,10^(LOG10(入力・概要!$B$38)+(A14-1)*(LOG10(入力・概要!$B$39)-LOG10(入力・概要!$B$38))/(入力・概要!$B$40-1)),"") -> 1224.5 | C14: =IF(B14="","",2*PI()*B14) -> 7693.7606 | D14: =IF(B14="","",ATANH(MIN(0.999999,入力・概要!$E$20/入力・概要!$E$9))+入力・概要!$B$20*SQRT(B14/1000000)+E14*入力・概要!$B$15/2) -> 0.0099007182 | E14: =IF(B14="","",C14*(入力・概要!$E$11*0.000000001)) -> 0.00024835764 | F14: =IF(B14="","",SINH(2*D14)/(COSH(2*D14)+COS(2*E14))) -> 0.0099003954 | G14: =IF(B14="","",SIN(2*E14)/(COSH(2*D14)+COS(2*E14))) -> 0.0002483333 | H14: =IF(B14="","",ATANH(MIN(0.999999,入力・概要!$E$21/入力・概要!$E$15))+入力・概要!$B$21*SQRT(B14/1000000)+I14*入力・概要!$B$16/2) -> 0.0038808436 | I14: =IF(B14="","",C14*(入力・概要!$E$17*0.000000001)) -> 0.00022839183 | J14: =IF(B14="","",SINH(2*H14)/(COSH(2*H14)+COS(2*I14))) -> 0.0038808243 | K14: =IF(B14="","",SIN(2*I14)/(COSH(2*H14)+COS(2*I14))) -> 0.00022838839 | L14: =IF(B14="","",入力・概要!$B$25) -> 0.05 | M14: =IF(B14="","",C14*入力・概要!$B$26*0.000000001-1/(C14*入力・概要!$B$24*0.000001)) -> -12.997391 | N14: =IF(B14="","",入力・概要!$B$28) -> 0.05 | O14: =IF(B14="","",C14*入力・概要!$B$29*0.000000001-1/(C14*入力・概要!$B$27*0.000001)) -> -12.997391 | P14: =IF(B14="","",((L14*N14-M14*O14)*(L14+N14)+(L14*O14+M14*N14)*(M14+O14))/((L14+N14)^2+(M14+O14)^2)) -> 0.025 | Q14: =IF(B14="","",((L14*O14+M14*N14)*(L14+N14)-(L14*N14-M14*O14)*(M14+O14))/((L14+N14)^2+(M14+O14)^2)) -> -6.4986956 | R14: =IF(B14="","",入力・概要!$E$15*J14) -> 0.37369808 | S14: =IF(B14="","",入力・概要!$E$15*K14) -> 0.021992313 | T14: =IF(B14="","",P14+R14) -> 0.39869808 | U14: =IF(B14="","",Q14+S14) -> -6.4767033 | V14: =IF(B14="","",T14+入力・概要!$E$9*F14) -> 0.66502199 | W14: =IF(B14="","",U14+入力・概要!$E$9*G14) -> -6.470023 | X14: =IF(B14="","",入力・概要!$E$9+T14*F14-U14*G14) -> 26.905886 | Y14: =IF(B14="","",T14*G14+U14*F14) -> -0.064022913 | Z14: =IF(B14="","",入力・概要!$E$9*(V14*X14+W14*Y14)/(X14^2+Y14^2)+入力・概要!$B$36) -> 0.68027315 | AA14: =IF(B14="","",入力・概要!$E$9*(W14*X14-V14*Y14)/(X14^2+Y14^2)+C14*入力・概要!$B$37*0.000000001) -> -6.466808 | AB14: =IF(B14="","",SQRT(Z14^2+AA14^2)) -> 6.5024901 | AC14: =IF(B14="","",IF(Z14>0,DEGREES(ATAN(AA14/Z14)),IF(Z14<0,IF(AA14>=0,DEGREES(ATAN(AA14/Z14))+180,DEGREES(ATAN(AA14/Z14))-180),IF(AA14>0,90,IF(AA14<0,-90,0))))) -> -83.99488 | AD14: =IF(B14="","",LOG10(B14)) -> 3.0879588 | AE14: =IF(AB14="","",LOG10(MAX(AB14,0.000000000001))) -> 0.8130797 | AF14: =IF(B14="","",SQRT(P14^2+Q14^2)) -> 6.4987437 | AG14: =IF(B14="","",SQRT(R14^2+S14^2)) -> 0.37434465
A15: 12 | B15: =IF(A15<=入力・概要!$B$40,10^(LOG10(入力・概要!$B$38)+(A15-1)*(LOG10(入力・概要!$B$39)-LOG10(入力・概要!$B$38))/(入力・概要!$B$40-1)),"") -> 1249.553 | C15: =IF(B15="","",2*PI()*B15) -> 7851.173 | D15: =IF(B15="","",ATANH(MIN(0.999999,入力・概要!$E$20/入力・概要!$E$9))+入力・概要!$B$20*SQRT(B15/1000000)+E15*入力・概要!$B$15/2) -> 0.0099018629 | E15: =IF(B15="","",C15*(入力・概要!$E$11*0.000000001)) -> 0.00025343898 | F15: =IF(B15="","",SINH(2*D15)/(COSH(2*D15)+COS(2*E15))) -> 0.00990154 | G15: =IF(B15="","",SIN(2*E15)/(COSH(2*D15)+COS(2*E15))) -> 0.00025341413 | H15: =IF(B15="","",ATANH(MIN(0.999999,入力・概要!$E$21/入力・概要!$E$15))+入力・概要!$B$21*SQRT(B15/1000000)+I15*入力・概要!$B$16/2) -> 0.003882315 | I15: =IF(B15="","",C15*(入力・概要!$E$17*0.000000001)) -> 0.00023306467 | J15: =IF(B15="","",SINH(2*H15)/(COSH(2*H15)+COS(2*I15))) -> 0.0038822957 | K15: =IF(B15="","",SIN(2*I15)/(COSH(2*H15)+COS(2*I15))) -> 0.00023306116 | L15: =IF(B15="","",入力・概要!$B$25) -> 0.05 | M15: =IF(B15="","",C15*入力・概要!$B$26*0.000000001-1/(C15*入力・概要!$B$24*0.000001)) -> -12.736793 | N15: =IF(B15="","",入力・概要!$B$28) -> 0.05 | O15: =IF(B15="","",C15*入力・概要!$B$29*0.000000001-1/(C15*入力・概要!$B$27*0.000001)) -> -12.736793 | P15: =IF(B15="","",((L15*N15-M15*O15)*(L15+N15)+(L15*O15+M15*N15)*(M15+O15))/((L15+N15)^2+(M15+O15)^2)) -> 0.025 | Q15: =IF(B15="","",((L15*O15+M15*N15)*(L15+N15)-(L15*N15-M15*O15)*(M15+O15))/((L15+N15)^2+(M15+O15)^2)) -> -6.3683966 | R15: =IF(B15="","",入力・概要!$E$15*J15) -> 0.37383977 | S15: =IF(B15="","",入力・概要!$E$15*K15) -> 0.02244227 | T15: =IF(B15="","",P15+R15) -> 0.39883977 | U15: =IF(B15="","",Q15+S15) -> -6.3459543 | V15: =IF(B15="","",T15+入力・概要!$E$9*F15) -> 0.66519446 | W15: =IF(B15="","",U15+入力・概要!$E$9*G15) -> -6.3391374 | X15: =IF(B15="","",入力・概要!$E$9+T15*F15-U15*G15) -> 26.905888 | Y15: =IF(B15="","",T15*G15+U15*F15) -> -0.062733649 | Z15: =IF(B15="","",入力・概要!$E$9*(V15*X15+W15*Y15)/(X15^2+Y15^2)+入力・概要!$B$36) -> 0.67983062 | AA15: =IF(B15="","",入力・概要!$E$9*(W15*X15-V15*Y15)/(X15^2+Y15^2)+C15*入力・概要!$B$37*0.000000001) -> -6.3359773 | AB15: =IF(B15="","",SQRT(Z15^2+AA15^2)) -> 6.3723448 | AC15: =IF(B15="","",IF(Z15>0,DEGREES(ATAN(AA15/Z15)),IF(Z15<0,IF(AA15>=0,DEGREES(ATAN(AA15/Z15))+180,DEGREES(ATAN(AA15/Z15))-180),IF(AA15>0,90,IF(AA15<0,-90,0))))) -> -83.875772 | AD15: =IF(B15="","",LOG10(B15)) -> 3.0967547 | AE15: =IF(AB15="","",LOG10(MAX(AB15,0.000000000001))) -> 0.80429927 | AF15: =IF(B15="","",SQRT(P15^2+Q15^2)) -> 6.3684457 | AG15: =IF(B15="","",SQRT(R15^2+S15^2)) -> 0.37451278
... A804: 801 | B804: =IF(A804<=入力・概要!$B$40,10^(LOG10(入力・概要!$B$38)+(A804-1)*(LOG10(入力・概要!$B$39)-LOG10(入力・概要!$B$38))/(入力・概要!$B$40-1)),"") | C804: =IF(B804="","",2*PI()*B804) | D804: =IF(B804="","",ATANH(MIN(0.999999,入力・概要!$E$20/入力・概要!$E$9))+入力・概要!$B$20*SQRT(B804/1000000)+E804*入力・概要!$B$15/2) | E804: =IF(B804="","",C804*(入力・概要!$E$11*0.000000001)) | F804: =IF(B804="","",SINH(2*D804)/(COSH(2*D804)+COS(2*E804))) | G804: =IF(B804="","",SIN(2*E804)/(COSH(2*D804)+COS(2*E804))) | H804: =IF(B804="","",ATANH(MIN(0.999999,入力・概要!$E$21/入力・概要!$E$15))+入力・概要!$B$21*SQRT(B804/1000000)+I804*入力・概要!$B$16/2) | I804: =IF(B804="","",C804*(入力・概要!$E$17*0.000000001)) | J804: =IF(B804="","",SINH(2*H804)/(COSH(2*H804)+COS(2*I804))) | K804: =IF(B804="","",SIN(2*I804)/(COSH(2*H804)+COS(2*I804))) | L804: =IF(B804="","",入力・概要!$B$25) | M804: =IF(B804="","",C804*入力・概要!$B$26*0.000000001-1/(C804*入力・概要!$B$24*0.000001)) | N804: =IF(B804="","",入力・概要!$B$28) | O804: =IF(B804="","",C804*入力・概要!$B$29*0.000000001-1/(C804*入力・概要!$B$27*0.000001)) | P804: =IF(B804="","",((L804*N804-M804*O804)*(L804+N804)+(L804*O804+M804*N804)*(M804+O804))/((L804+N804)^2+(M804+O804)^2)) | Q804: =IF(B804="","",((L804*O804+M804*N804)*(L804+N804)-(L804*N804-M804*O804)*(M804+O804))/((L804+N804)^2+(M804+O804)^2)) | R804: =IF(B804="","",入力・概要!$E$15*J804) | S804: =IF(B804="","",入力・概要!$E$15*K804) | T804: =IF(B804="","",P804+R804) | U804: =IF(B804="","",Q804+S804) | V804: =IF(B804="","",T804+入力・概要!$E$9*F804) | W804: =IF(B804="","",U804+入力・概要!$E$9*G804) | X804: =IF(B804="","",入力・概要!$E$9+T804*F804-U804*G804) | Y804: =IF(B804="","",T804*G804+U804*F804) | Z804: =IF(B804="","",入力・概要!$E$9*(V804*X804+W804*Y804)/(X804^2+Y804^2)+入力・概要!$B$36) | AA804: =IF(B804="","",入力・概要!$E$9*(W804*X804-V804*Y804)/(X804^2+Y804^2)+C804*入力・概要!$B$37*0.000000001) | AB804: =IF(B804="","",SQRT(Z804^2+AA804^2)) | AC804: =IF(B804="","",IF(Z804>0,DEGREES(ATAN(AA804/Z804)),IF(Z804<0,IF(AA804>=0,DEGREES(ATAN(AA804/Z804))+180,DEGREES(ATAN(AA804/Z804))-180),IF(AA804>0,90,IF(AA804<0,-90,0))))) | AD804: =IF(B804="","",LOG10(B804)) | AE804: =IF(AB804="","",LOG10(MAX(AB804,0.000000000001))) | AF804: =IF(B804="","",SQRT(P804^2+Q804^2)) | AG804: =IF(B804="","",SQRT(R804^2+S804^2))

Sheet 実測比較_差動
A1: 実測比較：差動モード
A2: A～C列へ周波数[Hz]・実測|Z|[Ω]・実測位相[deg]を貼り付けます。最も近いモデル周波数を参照します。
A4: 周波数 [Hz] | B4: 実測 |Z| [Ω] | C4: 実測位相 [deg] | D4: モデル |Z| [Ω] | E4: モデル位相 [deg] | F4: 振幅誤差 [%] | G4: 位相誤差 [deg] | H4: log10(f) | I4: log10(実測) | J4: log10(モデル) | K4: モデル行 | L4: モデル周波数 | M4: 判定
D5: =IF(K5="","",INDEX(差動モデル!$R:$R,K5)) | E5: =IF(K5="","",INDEX(差動モデル!$S:$S,K5)) | F5: =IF(OR(A5="",B5=""),"",100*(D5-B5)/MAX(B5,0.000000000001)) | G5: =IF(OR(A5="",C5=""),"",E5-C5) | H5: =IF(A5="","",LOG10(A5)) | I5: =IF(B5="","",LOG10(MAX(B5,0.000000000001))) | J5: =IF(D5="","",LOG10(MAX(D5,0.000000000001))) | K5: =IF(A5="","",ROUND(1+(LOG10(A5)-LOG10(入力・概要!$B$38))*(入力・概要!$B$40-1)/(LOG10(入力・概要!$B$39)-LOG10(入力・概要!$B$38)),0)+3) | L5: =IF(K5="","",INDEX(差動モデル!$B:$B,K5)) | M5: =IF(A5="","",IF(ABS(L5/A5-1)<0.01,"周波数差<1%","周波数差あり"))
D6: =IF(K6="","",INDEX(差動モデル!$R:$R,K6)) | E6: =IF(K6="","",INDEX(差動モデル!$S:$S,K6)) | F6: =IF(OR(A6="",B6=""),"",100*(D6-B6)/MAX(B6,0.000000000001)) | G6: =IF(OR(A6="",C6=""),"",E6-C6) | H6: =IF(A6="","",LOG10(A6)) | I6: =IF(B6="","",LOG10(MAX(B6,0.000000000001))) | J6: =IF(D6="","",LOG10(MAX(D6,0.000000000001))) | K6: =IF(A6="","",ROUND(1+(LOG10(A6)-LOG10(入力・概要!$B$38))*(入力・概要!$B$40-1)/(LOG10(入力・概要!$B$39)-LOG10(入力・概要!$B$38)),0)+3) | L6: =IF(K6="","",INDEX(差動モデル!$B:$B,K6)) | M6: =IF(A6="","",IF(ABS(L6/A6-1)<0.01,"周波数差<1%","周波数差あり"))
D7: =IF(K7="","",INDEX(差動モデル!$R:$R,K7)) | E7: =IF(K7="","",INDEX(差動モデル!$S:$S,K7)) | F7: =IF(OR(A7="",B7=""),"",100*(D7-B7)/MAX(B7,0.000000000001)) | G7: =IF(OR(A7="",C7=""),"",E7-C7) | H7: =IF(A7="","",LOG10(A7)) | I7: =IF(B7="","",LOG10(MAX(B7,0.000000000001))) | J7: =IF(D7="","",LOG10(MAX(D7,0.000000000001))) | K7: =IF(A7="","",ROUND(1+(LOG10(A7)-LOG10(入力・概要!$B$38))*(入力・概要!$B$40-1)/(LOG10(入力・概要!$B$39)-LOG10(入力・概要!$B$38)),0)+3) | L7: =IF(K7="","",INDEX(差動モデル!$B:$B,K7)) | M7: =IF(A7="","",IF(ABS(L7/A7-1)<0.01,"周波数差<1%","周波数差あり"))
D8: =IF(K8="","",INDEX(差動モデル!$R:$R,K8)) | E8: =IF(K8="","",INDEX(差動モデル!$S:$S,K8)) | F8: =IF(OR(A8="",B8=""),"",100*(D8-B8)/MAX(B8,0.000000000001)) | G8: =IF(OR(A8="",C8=""),"",E8-C8) | H8: =IF(A8="","",LOG10(A8)) | I8: =IF(B8="","",LOG10(MAX(B8,0.000000000001))) | J8: =IF(D8="","",LOG10(MAX(D8,0.000000000001))) | K8: =IF(A8="","",ROUND(1+(LOG10(A8)-LOG10(入力・概要!$B$38))*(入力・概要!$B$40-1)/(LOG10(入力・概要!$B$39)-LOG10(入力・概要!$B$38)),0)+3) | L8: =IF(K8="","",INDEX(差動モデル!$B:$B,K8)) | M8: =IF(A8="","",IF(ABS(L8/A8-1)<0.01,"周波数差<1%","周波数差あり"))
D9: =IF(K9="","",INDEX(差動モデル!$R:$R,K9)) | E9: =IF(K9="","",INDEX(差動モデル!$S:$S,K9)) | F9: =IF(OR(A9="",B9=""),"",100*(D9-B9)/MAX(B9,0.000000000001)) | G9: =IF(OR(A9="",C9=""),"",E9-C9) | H9: =IF(A9="","",LOG10(A9)) | I9: =IF(B9="","",LOG10(MAX(B9,0.000000000001))) | J9: =IF(D9="","",LOG10(MAX(D9,0.000000000001))) | K9: =IF(A9="","",ROUND(1+(LOG10(A9)-LOG10(入力・概要!$B$38))*(入力・概要!$B$40-1)/(LOG10(入力・概要!$B$39)-LOG10(入力・概要!$B$38)),0)+3) | L9: =IF(K9="","",INDEX(差動モデル!$B:$B,K9)) | M9: =IF(A9="","",IF(ABS(L9/A9-1)<0.01,"周波数差<1%","周波数差あり"))
